mesg: ttyname failed: Inappropriate ioctl for device
cassandra replica_side_filtering_test.py::TestAllowFiltering::test_count false true
log_dst_dir = /root/vm_images/ZebraConf/app_meta/logs
the_test is replica_side_filtering_test.py::TestAllowFiltering::test_count
rm: cannot remove '/tmp/my_log.txt': No such file or directory
============================= test session starts ==============================
platform linux -- Python 3.6.9, pytest-3.6.4, py-1.11.0, pluggy-0.7.1 -- /root/dtest/bin/python
cachedir: .pytest_cache
rootdir: /root/cassandra-dtest, inifile: pytest.ini
plugins: flaky-3.7.0, timeout-1.4.2, repeat-0.9.1
timeout: 1200.0s
timeout method: signal
timeout func_only: False
collecting ... collected 1 item

replica_side_filtering_test.py::TestAllowFiltering::test_count 
-------------------------------- live log call ---------------------------------
08:40:33,885 cassandra.cluster WARNING Failed to create connection pool for new host 127.0.0.2:9042:
Traceback (most recent call last):
  File "cassandra/cluster.py", line 3175, in cassandra.cluster.Session.add_or_renew_pool.run_add_or_renew_pool
  File "cassandra/pool.py", line 402, in cassandra.pool.HostConnection.__init__
  File "cassandra/cluster.py", line 1620, in cassandra.cluster.Cluster.connection_factory
  File "cassandra/connection.py", line 831, in cassandra.connection.Connection.factory
  File "/root/dtest/src/cassandra-driver/cassandra/io/libevreactor.py", line 267, in __init__
    self._connect_socket()
  File "cassandra/connection.py", line 898, in cassandra.connection.Connection._connect_socket
ConnectionRefusedError: [Errno 111] Tried connecting to [('127.0.0.2', 9042)]. Last error: Connection refused
08:40:33,889 cassandra.cluster WARNING Host 127.0.0.2:9042 has been marked down
08:40:34,998 cassandra.pool WARNING Error attempting to reconnect to 127.0.0.2:9042, scheduling retry in 1.88 seconds: [Errno 111] Tried connecting to [('127.0.0.2', 9042)]. Last error: Connection refused
08:40:36,906 cassandra.pool WARNING Error attempting to reconnect to 127.0.0.2:9042, scheduling retry in 4.44 seconds: [Errno 111] Tried connecting to [('127.0.0.2', 9042)]. Last error: Connection refused
08:40:41,421 cassandra.pool WARNING Error attempting to reconnect to 127.0.0.2:9042, scheduling retry in 6.88 seconds: [Errno 111] Tried connecting to [('127.0.0.2', 9042)]. Last error: Connection refused
08:40:43,275 cassandra.protocol WARNING Server warning: Aggregation query used without partition key
08:40:43,302 cassandra.protocol WARNING Server warning: Aggregation query used without partition key
08:40:43,319 cassandra.protocol WARNING Server warning: Aggregation query used without partition key
PASSED                                                                   [100%]
===Flaky Test Report===

test_count passed 1 out of the required 1 times. Success!

===End Flaky Test Report===

========================== 1 passed in 41.35 seconds ===========================
[msx] rc = 0
mv /tmp/my_log.txt /root/vm_images/ZebraConf/app_meta/logs/replica_side_filtering_test.py::TestAllowFiltering::test_count-output_1644050454105_31522041.txt
