mesg: ttyname failed: Inappropriate ioctl for device
cassandra replica_side_filtering_test.py::TestSecondaryIndexes::test_partition_deletion_on_wide_table false true
log_dst_dir = /root/vm_images/ZebraConf/app_meta/logs
the_test is replica_side_filtering_test.py::TestSecondaryIndexes::test_partition_deletion_on_wide_table
rm: cannot remove '/tmp/my_log.txt': No such file or directory
============================= test session starts ==============================
platform linux -- Python 3.6.9, pytest-3.6.4, py-1.11.0, pluggy-0.7.1 -- /root/dtest/bin/python
cachedir: .pytest_cache
rootdir: /root/cassandra-dtest, inifile: pytest.ini
plugins: flaky-3.7.0, timeout-1.4.2, repeat-0.9.1
timeout: 1200.0s
timeout method: signal
timeout func_only: False
collecting ... collected 1 item

replica_side_filtering_test.py::TestSecondaryIndexes::test_partition_deletion_on_wide_table 
-------------------------------- live log call ---------------------------------
07:54:30,971 cassandra.cluster WARNING Host 127.0.0.2:9042 has been marked down
07:54:38,142 cassandra.cluster WARNING Failed to create connection pool for new host 127.0.0.2:9042:
Traceback (most recent call last):
  File "cassandra/cluster.py", line 3175, in cassandra.cluster.Session.add_or_renew_pool.run_add_or_renew_pool
  File "cassandra/pool.py", line 402, in cassandra.pool.HostConnection.__init__
  File "cassandra/cluster.py", line 1620, in cassandra.cluster.Cluster.connection_factory
  File "cassandra/connection.py", line 831, in cassandra.connection.Connection.factory
  File "/root/dtest/src/cassandra-driver/cassandra/io/libevreactor.py", line 267, in __init__
    self._connect_socket()
  File "cassandra/connection.py", line 898, in cassandra.connection.Connection._connect_socket
ConnectionRefusedError: [Errno 111] Tried connecting to [('127.0.0.2', 9042)]. Last error: Connection refused
07:54:38,144 cassandra.cluster WARNING Host 127.0.0.2:9042 has been marked down
07:54:39,152 cassandra.pool WARNING Error attempting to reconnect to 127.0.0.2:9042, scheduling retry in 2.24 seconds: [Errno 111] Tried connecting to [('127.0.0.2', 9042)]. Last error: Connection refused
07:54:41,459 cassandra.pool WARNING Error attempting to reconnect to 127.0.0.2:9042, scheduling retry in 3.48 seconds: [Errno 111] Tried connecting to [('127.0.0.2', 9042)]. Last error: Connection refused
07:54:44,970 cassandra.pool WARNING Error attempting to reconnect to 127.0.0.2:9042, scheduling retry in 7.2 seconds: [Errno 111] Tried connecting to [('127.0.0.2', 9042)]. Last error: Connection refused
07:54:52,193 cassandra.pool WARNING Error attempting to reconnect to 127.0.0.2:9042, scheduling retry in 16.8 seconds: [Errno 111] Tried connecting to [('127.0.0.2', 9042)]. Last error: Connection refused
07:54:56,274 cassandra.cluster WARNING Host 127.0.0.1:9042 has been marked down
07:54:56,276 cassandra.cluster WARNING [control connection] Error connecting to 127.0.0.1:9042:
Traceback (most recent call last):
  File "cassandra/cluster.py", line 3522, in cassandra.cluster.ControlConnection._reconnect_internal
  File "cassandra/cluster.py", line 3544, in cassandra.cluster.ControlConnection._try_connect
  File "cassandra/cluster.py", line 1620, in cassandra.cluster.Cluster.connection_factory
  File "cassandra/connection.py", line 831, in cassandra.connection.Connection.factory
  File "/root/dtest/src/cassandra-driver/cassandra/io/libevreactor.py", line 267, in __init__
    self._connect_socket()
  File "cassandra/connection.py", line 898, in cassandra.connection.Connection._connect_socket
ConnectionRefusedError: [Errno 111] Tried connecting to [('127.0.0.1', 9042)]. Last error: Connection refused
07:54:57,90 cassandra.cluster WARNING Failed to create connection pool for new host 127.0.0.1:9042:
Traceback (most recent call last):
  File "cassandra/cluster.py", line 3175, in cassandra.cluster.Session.add_or_renew_pool.run_add_or_renew_pool
  File "cassandra/pool.py", line 402, in cassandra.pool.HostConnection.__init__
  File "cassandra/cluster.py", line 1620, in cassandra.cluster.Cluster.connection_factory
  File "cassandra/connection.py", line 831, in cassandra.connection.Connection.factory
  File "/root/dtest/src/cassandra-driver/cassandra/io/libevreactor.py", line 267, in __init__
    self._connect_socket()
  File "cassandra/connection.py", line 898, in cassandra.connection.Connection._connect_socket
ConnectionRefusedError: [Errno 111] Tried connecting to [('127.0.0.1', 9042)]. Last error: Connection refused
07:54:57,91 cassandra.cluster WARNING Host 127.0.0.1:9042 has been marked down
07:54:57,495 cassandra.pool WARNING Error attempting to reconnect to 127.0.0.1:9042, scheduling retry in 2.12 seconds: [Errno 111] Tried connecting to [('127.0.0.1', 9042)]. Last error: Connection refused
07:54:58,98 cassandra.pool WARNING Error attempting to reconnect to 127.0.0.1:9042, scheduling retry in 1.7 seconds: [Errno 111] Tried connecting to [('127.0.0.1', 9042)]. Last error: Connection refused
07:54:59,702 cassandra.pool WARNING Error attempting to reconnect to 127.0.0.1:9042, scheduling retry in 4.12 seconds: [Errno 111] Tried connecting to [('127.0.0.1', 9042)]. Last error: Connection refused
07:54:59,809 cassandra.pool WARNING Error attempting to reconnect to 127.0.0.1:9042, scheduling retry in 4.44 seconds: [Errno 111] Tried connecting to [('127.0.0.1', 9042)]. Last error: Connection refused
07:55:03,913 cassandra.pool WARNING Error attempting to reconnect to 127.0.0.1:9042, scheduling retry in 8.72 seconds: [Errno 111] Tried connecting to [('127.0.0.1', 9042)]. Last error: Connection refused
07:55:04,322 cassandra.pool WARNING Error attempting to reconnect to 127.0.0.1:9042, scheduling retry in 8.32 seconds: [Errno 111] Tried connecting to [('127.0.0.1', 9042)]. Last error: Connection refused
07:55:08,141 cassandra.cluster WARNING Host 127.0.0.1:9042 has been marked down
07:55:08,143 cassandra.cluster WARNING [control connection] Error connecting to 127.0.0.1:9042:
Traceback (most recent call last):
  File "cassandra/cluster.py", line 3522, in cassandra.cluster.ControlConnection._reconnect_internal
  File "cassandra/cluster.py", line 3544, in cassandra.cluster.ControlConnection._try_connect
  File "cassandra/cluster.py", line 1620, in cassandra.cluster.Cluster.connection_factory
  File "cassandra/connection.py", line 831, in cassandra.connection.Connection.factory
  File "/root/dtest/src/cassandra-driver/cassandra/io/libevreactor.py", line 267, in __init__
    self._connect_socket()
  File "cassandra/connection.py", line 898, in cassandra.connection.Connection._connect_socket
ConnectionRefusedError: [Errno 111] Tried connecting to [('127.0.0.1', 9042)]. Last error: Connection refused
07:55:09,240 cassandra.pool WARNING Error attempting to reconnect to 127.0.0.1:9042, scheduling retry in 2.26 seconds: [Errno 111] Tried connecting to [('127.0.0.1', 9042)]. Last error: Connection refused
07:55:11,554 cassandra.pool WARNING Error attempting to reconnect to 127.0.0.1:9042, scheduling retry in 4.16 seconds: [Errno 111] Tried connecting to [('127.0.0.1', 9042)]. Last error: Connection refused
PASSED                                                                   [100%]
===Flaky Test Report===

test_partition_deletion_on_wide_table passed 1 out of the required 1 times. Success!

===End Flaky Test Report===

========================== 1 passed in 67.73 seconds ===========================
[msx] rc = 0
mv /tmp/my_log.txt /root/vm_images/ZebraConf/app_meta/logs/replica_side_filtering_test.py::TestSecondaryIndexes::test_partition_deletion_on_wide_table-output_1644047723866_797729815.txt
