cassandra commitlog_test.py::TestCommitLog::test_commitlog_replay_on_startup true true
log_dts_dir = /users/masix/vm_images/ZebraConf/app_meta/logs
the_test is commitlog_test.py::TestCommitLog::test_commitlog_replay_on_startup
rm: cannot remove '/tmp/my_log.txt': No such file or directory
============================= test session starts ==============================
platform linux -- Python 3.6.9, pytest-3.6.4, py-1.11.0, pluggy-0.7.1 -- /users/masix/dtest/bin/python
cachedir: .pytest_cache
rootdir: /users/masix/cassandra-dtest, inifile: pytest.ini
plugins: flaky-3.7.0, timeout-1.4.2, repeat-0.9.1
timeout: 900.0s
timeout method: signal
timeout func_only: False
collecting ... collected 1 item

commitlog_test.py::TestCommitLog::test_commitlog_replay_on_startup 
-------------------------------- live log call ---------------------------------
21:46:42,998 ccmlib.node WARNING [msx] ccmlib:node.py:start(), self.name= node1, self.pid= 18552
21:46:52,542 cassandra.cluster WARNING Host 127.0.0.1:9042 has been marked down
21:46:53,75 ccmlib.node WARNING [msx] ccmlib:node.py:start(), self.name= node1, self.pid= 19067
21:46:53,749 cassandra.pool WARNING Error attempting to reconnect to 127.0.0.1:9042, scheduling retry in 1.94 seconds: [Errno 111] Tried connecting to [('127.0.0.1', 9042)]. Last error: Connection refused
21:46:55,754 cassandra.pool WARNING Error attempting to reconnect to 127.0.0.1:9042, scheduling retry in 4.08 seconds: [Errno 111] Tried connecting to [('127.0.0.1', 9042)]. Last error: Connection refused
PASSED                                                                   [100%]
===Flaky Test Report===

test_commitlog_replay_on_startup passed 1 out of the required 1 times. Success!

===End Flaky Test Report===

========================== 1 passed in 19.01 seconds ===========================
[msx] rc = 0
