cassandra consistency_test.py::TestAvailability::test_simple_strategy true true
log_dts_dir = /users/masix/vm_images/ZebraConf/app_meta/logs
the_test is consistency_test.py::TestAvailability::test_simple_strategy
rm: cannot remove '/tmp/my_log.txt': No such file or directory
============================= test session starts ==============================
platform linux -- Python 3.6.9, pytest-3.6.4, py-1.11.0, pluggy-0.7.1 -- /users/masix/dtest/bin/python
cachedir: .pytest_cache
rootdir: /users/masix/cassandra-dtest, inifile: pytest.ini
plugins: flaky-3.7.0, timeout-1.4.2, repeat-0.9.1
timeout: 900.0s
timeout method: signal
timeout func_only: False
collecting ... collected 1 item

consistency_test.py::TestAvailability::test_simple_strategy 
-------------------------------- live log call ---------------------------------
00:00:51,648 ccmlib.node WARNING [msx] ccmlib:node.py:start(), self.name= node1, self.pid= 40386
00:00:51,649 ccmlib.cluster WARNING [msx] ccmlib:cluster.py:start() p.pid= 40289 node.name= node1 node.pid= 40386
00:01:00,622 ccmlib.node WARNING [msx] ccmlib:node.py:start(), self.name= node2, self.pid= 40850
00:01:00,623 ccmlib.cluster WARNING [msx] ccmlib:cluster.py:start() p.pid= 40754 node.name= node2 node.pid= 40850
00:01:10,636 ccmlib.node WARNING [msx] ccmlib:node.py:start(), self.name= node3, self.pid= 876
00:01:10,637 ccmlib.cluster WARNING [msx] ccmlib:cluster.py:start() p.pid= 760 node.name= node3 node.pid= 876
00:01:56,854 cassandra.cluster WARNING Host 127.0.0.1:9042 has been marked down
00:01:56,856 cassandra.cluster WARNING [control connection] Error connecting to 127.0.0.1:9042:
Traceback (most recent call last):
  File "cassandra/cluster.py", line 3522, in cassandra.cluster.ControlConnection._reconnect_internal
  File "cassandra/cluster.py", line 3544, in cassandra.cluster.ControlConnection._try_connect
  File "cassandra/cluster.py", line 1620, in cassandra.cluster.Cluster.connection_factory
  File "cassandra/connection.py", line 831, in cassandra.connection.Connection.factory
  File "/users/masix/dtest/src/cassandra-driver/cassandra/io/libevreactor.py", line 267, in __init__
    self._connect_socket()
  File "cassandra/connection.py", line 898, in cassandra.connection.Connection._connect_socket
ConnectionRefusedError: [Errno 111] Tried connecting to [('127.0.0.1', 9042)]. Last error: Connection refused
00:01:57,861 cassandra.pool WARNING Error attempting to reconnect to 127.0.0.1:9042, scheduling retry in 2.02 seconds: [Errno 111] Tried connecting to [('127.0.0.1', 9042)]. Last error: Connection refused
00:01:59,966 cassandra.pool WARNING Error attempting to reconnect to 127.0.0.1:9042, scheduling retry in 4.12 seconds: [Errno 111] Tried connecting to [('127.0.0.1', 9042)]. Last error: Connection refused
00:02:04,175 cassandra.pool WARNING Error attempting to reconnect to 127.0.0.1:9042, scheduling retry in 7.52 seconds: [Errno 111] Tried connecting to [('127.0.0.1', 9042)]. Last error: Connection refused
00:02:11,796 cassandra.pool WARNING Error attempting to reconnect to 127.0.0.1:9042, scheduling retry in 14.88 seconds: [Errno 111] Tried connecting to [('127.0.0.1', 9042)]. Last error: Connection refused
00:02:18,917 cassandra.cluster WARNING Host 127.0.0.1:9042 has been marked down
00:02:18,917 cassandra.cluster WARNING [control connection] Error connecting to 127.0.0.1:9042:
Traceback (most recent call last):
  File "cassandra/cluster.py", line 3522, in cassandra.cluster.ControlConnection._reconnect_internal
  File "cassandra/cluster.py", line 3544, in cassandra.cluster.ControlConnection._try_connect
  File "cassandra/cluster.py", line 1620, in cassandra.cluster.Cluster.connection_factory
  File "cassandra/connection.py", line 831, in cassandra.connection.Connection.factory
  File "/users/masix/dtest/src/cassandra-driver/cassandra/io/libevreactor.py", line 267, in __init__
    self._connect_socket()
  File "cassandra/connection.py", line 898, in cassandra.connection.Connection._connect_socket
ConnectionRefusedError: [Errno 111] Tried connecting to [('127.0.0.1', 9042)]. Last error: Connection refused
00:02:19,925 cassandra.pool WARNING Error attempting to reconnect to 127.0.0.1:9042, scheduling retry in 1.88 seconds: [Errno 111] Tried connecting to [('127.0.0.1', 9042)]. Last error: Connection refused
00:02:21,831 cassandra.pool WARNING Error attempting to reconnect to 127.0.0.1:9042, scheduling retry in 4.12 seconds: [Errno 111] Tried connecting to [('127.0.0.1', 9042)]. Last error: Connection refused
00:02:26,48 cassandra.pool WARNING Error attempting to reconnect to 127.0.0.1:9042, scheduling retry in 6.88 seconds: [Errno 111] Tried connecting to [('127.0.0.1', 9042)]. Last error: Connection refused
00:02:26,744 cassandra.pool WARNING Error attempting to reconnect to 127.0.0.1:9042, scheduling retry in 34.24 seconds: [Errno 111] Tried connecting to [('127.0.0.1', 9042)]. Last error: Connection refused
00:02:32,968 cassandra.pool WARNING Error attempting to reconnect to 127.0.0.1:9042, scheduling retry in 16.0 seconds: [Errno 111] Tried connecting to [('127.0.0.1', 9042)]. Last error: Connection refused
00:02:39,181 cassandra.cluster WARNING Host 127.0.0.2:9042 has been marked down
00:02:39,182 cassandra.cluster WARNING [control connection] Error connecting to 127.0.0.2:9042:
Traceback (most recent call last):
  File "cassandra/cluster.py", line 3522, in cassandra.cluster.ControlConnection._reconnect_internal
  File "cassandra/cluster.py", line 3544, in cassandra.cluster.ControlConnection._try_connect
  File "cassandra/cluster.py", line 1620, in cassandra.cluster.Cluster.connection_factory
  File "cassandra/connection.py", line 831, in cassandra.connection.Connection.factory
  File "/users/masix/dtest/src/cassandra-driver/cassandra/io/libevreactor.py", line 267, in __init__
    self._connect_socket()
  File "cassandra/connection.py", line 898, in cassandra.connection.Connection._connect_socket
ConnectionRefusedError: [Errno 111] Tried connecting to [('127.0.0.2', 9042)]. Last error: Connection refused
00:02:40,287 cassandra.pool WARNING Error attempting to reconnect to 127.0.0.2:9042, scheduling retry in 2.24 seconds: [Errno 111] Tried connecting to [('127.0.0.2', 9042)]. Last error: Connection refused
00:02:42,592 cassandra.pool WARNING Error attempting to reconnect to 127.0.0.2:9042, scheduling retry in 4.04 seconds: [Errno 111] Tried connecting to [('127.0.0.2', 9042)]. Last error: Connection refused
00:02:46,701 cassandra.pool WARNING Error attempting to reconnect to 127.0.0.2:9042, scheduling retry in 7.28 seconds: [Errno 111] Tried connecting to [('127.0.0.2', 9042)]. Last error: Connection refused
00:02:49,5 cassandra.pool WARNING Error attempting to reconnect to 127.0.0.1:9042, scheduling retry in 28.48 seconds: [Errno 111] Tried connecting to [('127.0.0.1', 9042)]. Last error: Connection refused
00:02:54,38 cassandra.pool WARNING Error attempting to reconnect to 127.0.0.2:9042, scheduling retry in 14.4 seconds: [Errno 111] Tried connecting to [('127.0.0.2', 9042)]. Last error: Connection refused
00:03:01,24 cassandra.pool WARNING Error attempting to reconnect to 127.0.0.1:9042, scheduling retry in 71.68 seconds: [Errno 111] Tried connecting to [('127.0.0.1', 9042)]. Last error: Connection refused
PASSED                                                                   [100%]
===Flaky Test Report===

test_simple_strategy passed 1 out of the required 1 times. Success!

===End Flaky Test Report===

========================== 1 passed in 138.47 seconds ==========================
[msx] rc = 0
