cassandra hintedhandoff_test.py::TestHintedHandoffConfig::test_hintedhandoff_setmaxwindow true true
log_dts_dir = /users/masix/vm_images/ZebraConf/app_meta/logs
the_test is hintedhandoff_test.py::TestHintedHandoffConfig::test_hintedhandoff_setmaxwindow
rm: cannot remove '/tmp/my_log.txt': No such file or directory
============================= test session starts ==============================
platform linux -- Python 3.6.9, pytest-3.6.4, py-1.11.0, pluggy-0.7.1 -- /users/masix/dtest/bin/python
cachedir: .pytest_cache
rootdir: /users/masix/cassandra-dtest, inifile: pytest.ini
plugins: flaky-3.7.0, timeout-1.4.2, repeat-0.9.1
timeout: 900.0s
timeout method: signal
timeout func_only: False
collecting ... collected 1 item

hintedhandoff_test.py::TestHintedHandoffConfig::test_hintedhandoff_setmaxwindow 
-------------------------------- live log call ---------------------------------
04:29:32,996 ccmlib.node WARNING [msx] ccmlib:node.py:start(), self.name= node1, self.pid= 9063
04:29:32,998 ccmlib.cluster WARNING [msx] ccmlib:cluster.py:start() p.pid= 8966 node.name= node1 node.pid= 9063
04:29:41,956 ccmlib.node WARNING [msx] ccmlib:node.py:start(), self.name= node2, self.pid= 9530
04:29:41,958 ccmlib.cluster WARNING [msx] ccmlib:cluster.py:start() p.pid= 9434 node.name= node2 node.pid= 9530
04:30:13,934 ccmlib.node WARNING [msx] ccmlib:node.py:start(), self.name= node2, self.pid= 10935
04:30:49,603 ccmlib.node WARNING [msx] ccmlib:node.py:start(), self.name= node1, self.pid= 11566
04:30:56,54 cassandra.cluster WARNING Host 127.0.0.1:9042 has been marked down
04:31:02,2 cassandra.cluster WARNING Host 127.0.0.2:9042 has been marked down
04:31:02,396 cassandra.cluster WARNING Host 127.0.0.2:9042 has been marked down
04:31:03,601 cassandra.pool WARNING Error attempting to reconnect to 127.0.0.2:9042, scheduling retry in 2.14 seconds: [Errno 111] Tried connecting to [('127.0.0.2', 9042)]. Last error: Connection refused
04:31:05,806 cassandra.pool WARNING Error attempting to reconnect to 127.0.0.2:9042, scheduling retry in 3.64 seconds: [Errno 111] Tried connecting to [('127.0.0.2', 9042)]. Last error: Connection refused
04:31:09,515 cassandra.pool WARNING Error attempting to reconnect to 127.0.0.2:9042, scheduling retry in 7.2 seconds: [Errno 111] Tried connecting to [('127.0.0.2', 9042)]. Last error: Connection refused
04:31:16,739 cassandra.pool WARNING Error attempting to reconnect to 127.0.0.2:9042, scheduling retry in 14.88 seconds: [Errno 111] Tried connecting to [('127.0.0.2', 9042)]. Last error: Connection refused
04:31:18,123 ccmlib.node WARNING [msx] ccmlib:node.py:start(), self.name= node2, self.pid= 13123
04:31:24,924 cassandra.cluster WARNING Host 127.0.0.1:9042 has been marked down
04:31:24,925 cassandra.cluster WARNING [control connection] Error connecting to 127.0.0.1:9042:
Traceback (most recent call last):
  File "cassandra/cluster.py", line 3522, in cassandra.cluster.ControlConnection._reconnect_internal
  File "cassandra/cluster.py", line 3544, in cassandra.cluster.ControlConnection._try_connect
  File "cassandra/cluster.py", line 1620, in cassandra.cluster.Cluster.connection_factory
  File "cassandra/connection.py", line 831, in cassandra.connection.Connection.factory
  File "/users/masix/dtest/src/cassandra-driver/cassandra/io/libevreactor.py", line 267, in __init__
    self._connect_socket()
  File "cassandra/connection.py", line 898, in cassandra.connection.Connection._connect_socket
ConnectionRefusedError: [Errno 111] Tried connecting to [('127.0.0.1', 9042)]. Last error: Connection refused
04:31:25,930 cassandra.pool WARNING Error attempting to reconnect to 127.0.0.1:9042, scheduling retry in 2.08 seconds: [Errno 111] Tried connecting to [('127.0.0.1', 9042)]. Last error: Connection refused
04:31:26,55 cassandra.cluster WARNING Host 127.0.0.1:9042 has been marked down
04:31:26,56 cassandra.cluster WARNING [control connection] Error connecting to 127.0.0.1:9042:
Traceback (most recent call last):
  File "cassandra/cluster.py", line 3522, in cassandra.cluster.ControlConnection._reconnect_internal
  File "cassandra/cluster.py", line 3544, in cassandra.cluster.ControlConnection._try_connect
  File "cassandra/cluster.py", line 1620, in cassandra.cluster.Cluster.connection_factory
  File "cassandra/connection.py", line 831, in cassandra.connection.Connection.factory
  File "/users/masix/dtest/src/cassandra-driver/cassandra/io/libevreactor.py", line 267, in __init__
    self._connect_socket()
  File "cassandra/connection.py", line 898, in cassandra.connection.Connection._connect_socket
ConnectionRefusedError: [Errno 111] Tried connecting to [('127.0.0.1', 9042)]. Last error: Connection refused
PASSED                                                                   [100%]
===Flaky Test Report===

test_hintedhandoff_setmaxwindow passed 1 out of the required 1 times. Success!

===End Flaky Test Report===

========================== 1 passed in 116.31 seconds ==========================
[msx] rc = 0
