cassandra auth_test.py::TestAuthRoles::test_drop_role_revokes_permissions_granted_on_it true true
log_dts_dir = /users/masix/vm_images/ZebraConf/app_meta/logs
the_test is auth_test.py::TestAuthRoles::test_drop_role_revokes_permissions_granted_on_it
rm: cannot remove '/tmp/my_log.txt': No such file or directory
============================= test session starts ==============================
platform linux -- Python 3.6.9, pytest-3.6.4, py-1.11.0, pluggy-0.7.1 -- /users/masix/dtest/bin/python
cachedir: .pytest_cache
rootdir: /users/masix/cassandra-dtest, inifile: pytest.ini
plugins: flaky-3.7.0, timeout-1.4.2, repeat-0.9.1
timeout: 900.0s
timeout method: signal
timeout func_only: False
collecting ... collected 1 item

auth_test.py::TestAuthRoles::test_drop_role_revokes_permissions_granted_on_it 
-------------------------------- live log setup --------------------------------
02:23:42,291 ccmlib.node WARNING [msx] ccmlib:node.py:start(), self.name= node1, self.pid= None
02:23:42,293 ccmlib.cluster WARNING [msx] ccmlib:cluster.py:start() p.pid= 2135 node.name= node1 node.pid= None
02:23:50,546 cassandra.cluster WARNING [control connection] Error connecting to 127.0.0.1:9042:
Traceback (most recent call last):
  File "cassandra/cluster.py", line 3522, in cassandra.cluster.ControlConnection._reconnect_internal
  File "cassandra/cluster.py", line 3544, in cassandra.cluster.ControlConnection._try_connect
  File "cassandra/cluster.py", line 1620, in cassandra.cluster.Cluster.connection_factory
  File "cassandra/connection.py", line 837, in cassandra.connection.Connection.factory
  File "cassandra/connection.py", line 600, in cassandra.connection.defunct_on_error.wrapper
  File "cassandra/connection.py", line 1421, in cassandra.connection.Connection._handle_auth_response
cassandra.AuthenticationFailed: Failed to authenticate to 127.0.0.1:9042: Error from server: code=0100 [Bad credentials] message="Provided username cassandra and/or password are incorrect"
02:23:50,550 cassandra.cluster ERROR Control connection failed to connect, shutting down Cluster:
Traceback (most recent call last):
  File "cassandra/cluster.py", line 1690, in cassandra.cluster.Cluster.connect
  File "cassandra/cluster.py", line 3488, in cassandra.cluster.ControlConnection.connect
  File "cassandra/cluster.py", line 3533, in cassandra.cluster.ControlConnection._reconnect_internal
cassandra.cluster.NoHostAvailable: ('Unable to connect to any servers', {'127.0.0.1:9042': AuthenticationFailed('Failed to authenticate to 127.0.0.1:9042: Error from server: code=0100 [Bad credentials] message="Provided username cassandra and/or password are incorrect"',)})
02:23:50,810 cassandra.cluster WARNING [control connection] Error connecting to 127.0.0.1:9042:
Traceback (most recent call last):
  File "cassandra/cluster.py", line 3522, in cassandra.cluster.ControlConnection._reconnect_internal
  File "cassandra/cluster.py", line 3544, in cassandra.cluster.ControlConnection._try_connect
  File "cassandra/cluster.py", line 1620, in cassandra.cluster.Cluster.connection_factory
  File "cassandra/connection.py", line 837, in cassandra.connection.Connection.factory
  File "cassandra/connection.py", line 600, in cassandra.connection.defunct_on_error.wrapper
  File "cassandra/connection.py", line 1421, in cassandra.connection.Connection._handle_auth_response
cassandra.AuthenticationFailed: Failed to authenticate to 127.0.0.1:9042: Error from server: code=0100 [Bad credentials] message="Provided username cassandra and/or password are incorrect"
02:23:50,811 cassandra.cluster ERROR Control connection failed to connect, shutting down Cluster:
Traceback (most recent call last):
  File "cassandra/cluster.py", line 1690, in cassandra.cluster.Cluster.connect
  File "cassandra/cluster.py", line 3488, in cassandra.cluster.ControlConnection.connect
  File "cassandra/cluster.py", line 3533, in cassandra.cluster.ControlConnection._reconnect_internal
cassandra.cluster.NoHostAvailable: ('Unable to connect to any servers', {'127.0.0.1:9042': AuthenticationFailed('Failed to authenticate to 127.0.0.1:9042: Error from server: code=0100 [Bad credentials] message="Provided username cassandra and/or password are incorrect"',)})
02:23:51,70 cassandra.cluster WARNING [control connection] Error connecting to 127.0.0.1:9042:
Traceback (most recent call last):
  File "cassandra/cluster.py", line 3522, in cassandra.cluster.ControlConnection._reconnect_internal
  File "cassandra/cluster.py", line 3544, in cassandra.cluster.ControlConnection._try_connect
  File "cassandra/cluster.py", line 1620, in cassandra.cluster.Cluster.connection_factory
  File "cassandra/connection.py", line 837, in cassandra.connection.Connection.factory
  File "cassandra/connection.py", line 600, in cassandra.connection.defunct_on_error.wrapper
  File "cassandra/connection.py", line 1421, in cassandra.connection.Connection._handle_auth_response
cassandra.AuthenticationFailed: Failed to authenticate to 127.0.0.1:9042: Error from server: code=0100 [Bad credentials] message="Provided username cassandra and/or password are incorrect"
02:23:51,71 cassandra.cluster ERROR Control connection failed to connect, shutting down Cluster:
Traceback (most recent call last):
  File "cassandra/cluster.py", line 1690, in cassandra.cluster.Cluster.connect
  File "cassandra/cluster.py", line 3488, in cassandra.cluster.ControlConnection.connect
  File "cassandra/cluster.py", line 3533, in cassandra.cluster.ControlConnection._reconnect_internal
cassandra.cluster.NoHostAvailable: ('Unable to connect to any servers', {'127.0.0.1:9042': AuthenticationFailed('Failed to authenticate to 127.0.0.1:9042: Error from server: code=0100 [Bad credentials] message="Provided username cassandra and/or password are incorrect"',)})
02:23:51,331 cassandra.cluster WARNING [control connection] Error connecting to 127.0.0.1:9042:
Traceback (most recent call last):
  File "cassandra/cluster.py", line 3522, in cassandra.cluster.ControlConnection._reconnect_internal
  File "cassandra/cluster.py", line 3544, in cassandra.cluster.ControlConnection._try_connect
  File "cassandra/cluster.py", line 1620, in cassandra.cluster.Cluster.connection_factory
  File "cassandra/connection.py", line 837, in cassandra.connection.Connection.factory
  File "cassandra/connection.py", line 600, in cassandra.connection.defunct_on_error.wrapper
  File "cassandra/connection.py", line 1421, in cassandra.connection.Connection._handle_auth_response
cassandra.AuthenticationFailed: Failed to authenticate to 127.0.0.1:9042: Error from server: code=0100 [Bad credentials] message="Provided username cassandra and/or password are incorrect"
02:23:51,332 cassandra.cluster ERROR Control connection failed to connect, shutting down Cluster:
Traceback (most recent call last):
  File "cassandra/cluster.py", line 1690, in cassandra.cluster.Cluster.connect
  File "cassandra/cluster.py", line 3488, in cassandra.cluster.ControlConnection.connect
  File "cassandra/cluster.py", line 3533, in cassandra.cluster.ControlConnection._reconnect_internal
cassandra.cluster.NoHostAvailable: ('Unable to connect to any servers', {'127.0.0.1:9042': AuthenticationFailed('Failed to authenticate to 127.0.0.1:9042: Error from server: code=0100 [Bad credentials] message="Provided username cassandra and/or password are incorrect"',)})
02:23:51,591 cassandra.cluster WARNING [control connection] Error connecting to 127.0.0.1:9042:
Traceback (most recent call last):
  File "cassandra/cluster.py", line 3522, in cassandra.cluster.ControlConnection._reconnect_internal
  File "cassandra/cluster.py", line 3544, in cassandra.cluster.ControlConnection._try_connect
  File "cassandra/cluster.py", line 1620, in cassandra.cluster.Cluster.connection_factory
  File "cassandra/connection.py", line 837, in cassandra.connection.Connection.factory
  File "cassandra/connection.py", line 600, in cassandra.connection.defunct_on_error.wrapper
  File "cassandra/connection.py", line 1421, in cassandra.connection.Connection._handle_auth_response
cassandra.AuthenticationFailed: Failed to authenticate to 127.0.0.1:9042: Error from server: code=0100 [Bad credentials] message="Provided username cassandra and/or password are incorrect"
02:23:51,592 cassandra.cluster ERROR Control connection failed to connect, shutting down Cluster:
Traceback (most recent call last):
  File "cassandra/cluster.py", line 1690, in cassandra.cluster.Cluster.connect
  File "cassandra/cluster.py", line 3488, in cassandra.cluster.ControlConnection.connect
  File "cassandra/cluster.py", line 3533, in cassandra.cluster.ControlConnection._reconnect_internal
cassandra.cluster.NoHostAvailable: ('Unable to connect to any servers', {'127.0.0.1:9042': AuthenticationFailed('Failed to authenticate to 127.0.0.1:9042: Error from server: code=0100 [Bad credentials] message="Provided username cassandra and/or password are incorrect"',)})
02:23:51,851 cassandra.cluster WARNING [control connection] Error connecting to 127.0.0.1:9042:
Traceback (most recent call last):
  File "cassandra/cluster.py", line 3522, in cassandra.cluster.ControlConnection._reconnect_internal
  File "cassandra/cluster.py", line 3544, in cassandra.cluster.ControlConnection._try_connect
  File "cassandra/cluster.py", line 1620, in cassandra.cluster.Cluster.connection_factory
  File "cassandra/connection.py", line 837, in cassandra.connection.Connection.factory
  File "cassandra/connection.py", line 600, in cassandra.connection.defunct_on_error.wrapper
  File "cassandra/connection.py", line 1421, in cassandra.connection.Connection._handle_auth_response
cassandra.AuthenticationFailed: Failed to authenticate to 127.0.0.1:9042: Error from server: code=0100 [Bad credentials] message="Provided username cassandra and/or password are incorrect"
02:23:51,852 cassandra.cluster ERROR Control connection failed to connect, shutting down Cluster:
Traceback (most recent call last):
  File "cassandra/cluster.py", line 1690, in cassandra.cluster.Cluster.connect
  File "cassandra/cluster.py", line 3488, in cassandra.cluster.ControlConnection.connect
  File "cassandra/cluster.py", line 3533, in cassandra.cluster.ControlConnection._reconnect_internal
cassandra.cluster.NoHostAvailable: ('Unable to connect to any servers', {'127.0.0.1:9042': AuthenticationFailed('Failed to authenticate to 127.0.0.1:9042: Error from server: code=0100 [Bad credentials] message="Provided username cassandra and/or password are incorrect"',)})
02:23:52,133 cassandra.cluster WARNING [control connection] Error connecting to 127.0.0.1:9042:
Traceback (most recent call last):
  File "cassandra/cluster.py", line 3522, in cassandra.cluster.ControlConnection._reconnect_internal
  File "cassandra/cluster.py", line 3544, in cassandra.cluster.ControlConnection._try_connect
  File "cassandra/cluster.py", line 1620, in cassandra.cluster.Cluster.connection_factory
  File "cassandra/connection.py", line 837, in cassandra.connection.Connection.factory
  File "cassandra/connection.py", line 600, in cassandra.connection.defunct_on_error.wrapper
  File "cassandra/connection.py", line 1421, in cassandra.connection.Connection._handle_auth_response
cassandra.AuthenticationFailed: Failed to authenticate to 127.0.0.1:9042: Error from server: code=0100 [Bad credentials] message="Provided username cassandra and/or password are incorrect"
02:23:52,136 cassandra.cluster ERROR Control connection failed to connect, shutting down Cluster:
Traceback (most recent call last):
  File "cassandra/cluster.py", line 1690, in cassandra.cluster.Cluster.connect
  File "cassandra/cluster.py", line 3488, in cassandra.cluster.ControlConnection.connect
  File "cassandra/cluster.py", line 3533, in cassandra.cluster.ControlConnection._reconnect_internal
cassandra.cluster.NoHostAvailable: ('Unable to connect to any servers', {'127.0.0.1:9042': AuthenticationFailed('Failed to authenticate to 127.0.0.1:9042: Error from server: code=0100 [Bad credentials] message="Provided username cassandra and/or password are incorrect"',)})
02:23:52,397 cassandra.cluster WARNING [control connection] Error connecting to 127.0.0.1:9042:
Traceback (most recent call last):
  File "cassandra/cluster.py", line 3522, in cassandra.cluster.ControlConnection._reconnect_internal
  File "cassandra/cluster.py", line 3544, in cassandra.cluster.ControlConnection._try_connect
  File "cassandra/cluster.py", line 1620, in cassandra.cluster.Cluster.connection_factory
  File "cassandra/connection.py", line 837, in cassandra.connection.Connection.factory
  File "cassandra/connection.py", line 600, in cassandra.connection.defunct_on_error.wrapper
  File "cassandra/connection.py", line 1421, in cassandra.connection.Connection._handle_auth_response
cassandra.AuthenticationFailed: Failed to authenticate to 127.0.0.1:9042: Error from server: code=0100 [Bad credentials] message="Provided username cassandra and/or password are incorrect"
02:23:52,398 cassandra.cluster ERROR Control connection failed to connect, shutting down Cluster:
Traceback (most recent call last):
  File "cassandra/cluster.py", line 1690, in cassandra.cluster.Cluster.connect
  File "cassandra/cluster.py", line 3488, in cassandra.cluster.ControlConnection.connect
  File "cassandra/cluster.py", line 3533, in cassandra.cluster.ControlConnection._reconnect_internal
cassandra.cluster.NoHostAvailable: ('Unable to connect to any servers', {'127.0.0.1:9042': AuthenticationFailed('Failed to authenticate to 127.0.0.1:9042: Error from server: code=0100 [Bad credentials] message="Provided username cassandra and/or password are incorrect"',)})
02:23:52,659 cassandra.cluster WARNING [control connection] Error connecting to 127.0.0.1:9042:
Traceback (most recent call last):
  File "cassandra/cluster.py", line 3522, in cassandra.cluster.ControlConnection._reconnect_internal
  File "cassandra/cluster.py", line 3544, in cassandra.cluster.ControlConnection._try_connect
  File "cassandra/cluster.py", line 1620, in cassandra.cluster.Cluster.connection_factory
  File "cassandra/connection.py", line 837, in cassandra.connection.Connection.factory
  File "cassandra/connection.py", line 600, in cassandra.connection.defunct_on_error.wrapper
  File "cassandra/connection.py", line 1421, in cassandra.connection.Connection._handle_auth_response
cassandra.AuthenticationFailed: Failed to authenticate to 127.0.0.1:9042: Error from server: code=0100 [Bad credentials] message="Provided username cassandra and/or password are incorrect"
02:23:52,660 cassandra.cluster ERROR Control connection failed to connect, shutting down Cluster:
Traceback (most recent call last):
  File "cassandra/cluster.py", line 1690, in cassandra.cluster.Cluster.connect
  File "cassandra/cluster.py", line 3488, in cassandra.cluster.ControlConnection.connect
  File "cassandra/cluster.py", line 3533, in cassandra.cluster.ControlConnection._reconnect_internal
cassandra.cluster.NoHostAvailable: ('Unable to connect to any servers', {'127.0.0.1:9042': AuthenticationFailed('Failed to authenticate to 127.0.0.1:9042: Error from server: code=0100 [Bad credentials] message="Provided username cassandra and/or password are incorrect"',)})
02:23:52,919 cassandra.cluster WARNING [control connection] Error connecting to 127.0.0.1:9042:
Traceback (most recent call last):
  File "cassandra/cluster.py", line 3522, in cassandra.cluster.ControlConnection._reconnect_internal
  File "cassandra/cluster.py", line 3544, in cassandra.cluster.ControlConnection._try_connect
  File "cassandra/cluster.py", line 1620, in cassandra.cluster.Cluster.connection_factory
  File "cassandra/connection.py", line 837, in cassandra.connection.Connection.factory
  File "cassandra/connection.py", line 600, in cassandra.connection.defunct_on_error.wrapper
  File "cassandra/connection.py", line 1421, in cassandra.connection.Connection._handle_auth_response
cassandra.AuthenticationFailed: Failed to authenticate to 127.0.0.1:9042: Error from server: code=0100 [Bad credentials] message="Provided username cassandra and/or password are incorrect"
02:23:52,920 cassandra.cluster ERROR Control connection failed to connect, shutting down Cluster:
Traceback (most recent call last):
  File "cassandra/cluster.py", line 1690, in cassandra.cluster.Cluster.connect
  File "cassandra/cluster.py", line 3488, in cassandra.cluster.ControlConnection.connect
  File "cassandra/cluster.py", line 3533, in cassandra.cluster.ControlConnection._reconnect_internal
cassandra.cluster.NoHostAvailable: ('Unable to connect to any servers', {'127.0.0.1:9042': AuthenticationFailed('Failed to authenticate to 127.0.0.1:9042: Error from server: code=0100 [Bad credentials] message="Provided username cassandra and/or password are incorrect"',)})
02:23:53,178 cassandra.cluster WARNING [control connection] Error connecting to 127.0.0.1:9042:
Traceback (most recent call last):
  File "cassandra/cluster.py", line 3522, in cassandra.cluster.ControlConnection._reconnect_internal
  File "cassandra/cluster.py", line 3544, in cassandra.cluster.ControlConnection._try_connect
  File "cassandra/cluster.py", line 1620, in cassandra.cluster.Cluster.connection_factory
  File "cassandra/connection.py", line 837, in cassandra.connection.Connection.factory
  File "cassandra/connection.py", line 600, in cassandra.connection.defunct_on_error.wrapper
  File "cassandra/connection.py", line 1421, in cassandra.connection.Connection._handle_auth_response
cassandra.AuthenticationFailed: Failed to authenticate to 127.0.0.1:9042: Error from server: code=0100 [Bad credentials] message="Provided username cassandra and/or password are incorrect"
02:23:53,179 cassandra.cluster ERROR Control connection failed to connect, shutting down Cluster:
Traceback (most recent call last):
  File "cassandra/cluster.py", line 1690, in cassandra.cluster.Cluster.connect
  File "cassandra/cluster.py", line 3488, in cassandra.cluster.ControlConnection.connect
  File "cassandra/cluster.py", line 3533, in cassandra.cluster.ControlConnection._reconnect_internal
cassandra.cluster.NoHostAvailable: ('Unable to connect to any servers', {'127.0.0.1:9042': AuthenticationFailed('Failed to authenticate to 127.0.0.1:9042: Error from server: code=0100 [Bad credentials] message="Provided username cassandra and/or password are incorrect"',)})
02:23:53,438 cassandra.cluster WARNING [control connection] Error connecting to 127.0.0.1:9042:
Traceback (most recent call last):
  File "cassandra/cluster.py", line 3522, in cassandra.cluster.ControlConnection._reconnect_internal
  File "cassandra/cluster.py", line 3544, in cassandra.cluster.ControlConnection._try_connect
  File "cassandra/cluster.py", line 1620, in cassandra.cluster.Cluster.connection_factory
  File "cassandra/connection.py", line 837, in cassandra.connection.Connection.factory
  File "cassandra/connection.py", line 600, in cassandra.connection.defunct_on_error.wrapper
  File "cassandra/connection.py", line 1421, in cassandra.connection.Connection._handle_auth_response
cassandra.AuthenticationFailed: Failed to authenticate to 127.0.0.1:9042: Error from server: code=0100 [Bad credentials] message="Provided username cassandra and/or password are incorrect"
02:23:53,439 cassandra.cluster ERROR Control connection failed to connect, shutting down Cluster:
Traceback (most recent call last):
  File "cassandra/cluster.py", line 1690, in cassandra.cluster.Cluster.connect
  File "cassandra/cluster.py", line 3488, in cassandra.cluster.ControlConnection.connect
  File "cassandra/cluster.py", line 3533, in cassandra.cluster.ControlConnection._reconnect_internal
cassandra.cluster.NoHostAvailable: ('Unable to connect to any servers', {'127.0.0.1:9042': AuthenticationFailed('Failed to authenticate to 127.0.0.1:9042: Error from server: code=0100 [Bad credentials] message="Provided username cassandra and/or password are incorrect"',)})
02:23:53,698 cassandra.cluster WARNING [control connection] Error connecting to 127.0.0.1:9042:
Traceback (most recent call last):
  File "cassandra/cluster.py", line 3522, in cassandra.cluster.ControlConnection._reconnect_internal
  File "cassandra/cluster.py", line 3544, in cassandra.cluster.ControlConnection._try_connect
  File "cassandra/cluster.py", line 1620, in cassandra.cluster.Cluster.connection_factory
  File "cassandra/connection.py", line 837, in cassandra.connection.Connection.factory
  File "cassandra/connection.py", line 600, in cassandra.connection.defunct_on_error.wrapper
  File "cassandra/connection.py", line 1421, in cassandra.connection.Connection._handle_auth_response
cassandra.AuthenticationFailed: Failed to authenticate to 127.0.0.1:9042: Error from server: code=0100 [Bad credentials] message="Provided username cassandra and/or password are incorrect"
02:23:53,699 cassandra.cluster ERROR Control connection failed to connect, shutting down Cluster:
Traceback (most recent call last):
  File "cassandra/cluster.py", line 1690, in cassandra.cluster.Cluster.connect
  File "cassandra/cluster.py", line 3488, in cassandra.cluster.ControlConnection.connect
  File "cassandra/cluster.py", line 3533, in cassandra.cluster.ControlConnection._reconnect_internal
cassandra.cluster.NoHostAvailable: ('Unable to connect to any servers', {'127.0.0.1:9042': AuthenticationFailed('Failed to authenticate to 127.0.0.1:9042: Error from server: code=0100 [Bad credentials] message="Provided username cassandra and/or password are incorrect"',)})
02:23:53,958 cassandra.cluster WARNING [control connection] Error connecting to 127.0.0.1:9042:
Traceback (most recent call last):
  File "cassandra/cluster.py", line 3522, in cassandra.cluster.ControlConnection._reconnect_internal
  File "cassandra/cluster.py", line 3544, in cassandra.cluster.ControlConnection._try_connect
  File "cassandra/cluster.py", line 1620, in cassandra.cluster.Cluster.connection_factory
  File "cassandra/connection.py", line 837, in cassandra.connection.Connection.factory
  File "cassandra/connection.py", line 600, in cassandra.connection.defunct_on_error.wrapper
  File "cassandra/connection.py", line 1421, in cassandra.connection.Connection._handle_auth_response
cassandra.AuthenticationFailed: Failed to authenticate to 127.0.0.1:9042: Error from server: code=0100 [Bad credentials] message="Provided username cassandra and/or password are incorrect"
02:23:53,960 cassandra.cluster ERROR Control connection failed to connect, shutting down Cluster:
Traceback (most recent call last):
  File "cassandra/cluster.py", line 1690, in cassandra.cluster.Cluster.connect
  File "cassandra/cluster.py", line 3488, in cassandra.cluster.ControlConnection.connect
  File "cassandra/cluster.py", line 3533, in cassandra.cluster.ControlConnection._reconnect_internal
cassandra.cluster.NoHostAvailable: ('Unable to connect to any servers', {'127.0.0.1:9042': AuthenticationFailed('Failed to authenticate to 127.0.0.1:9042: Error from server: code=0100 [Bad credentials] message="Provided username cassandra and/or password are incorrect"',)})
02:23:54,220 cassandra.cluster WARNING [control connection] Error connecting to 127.0.0.1:9042:
Traceback (most recent call last):
  File "cassandra/cluster.py", line 3522, in cassandra.cluster.ControlConnection._reconnect_internal
  File "cassandra/cluster.py", line 3544, in cassandra.cluster.ControlConnection._try_connect
  File "cassandra/cluster.py", line 1620, in cassandra.cluster.Cluster.connection_factory
  File "cassandra/connection.py", line 837, in cassandra.connection.Connection.factory
  File "cassandra/connection.py", line 600, in cassandra.connection.defunct_on_error.wrapper
  File "cassandra/connection.py", line 1421, in cassandra.connection.Connection._handle_auth_response
cassandra.AuthenticationFailed: Failed to authenticate to 127.0.0.1:9042: Error from server: code=0100 [Bad credentials] message="Provided username cassandra and/or password are incorrect"
02:23:54,221 cassandra.cluster ERROR Control connection failed to connect, shutting down Cluster:
Traceback (most recent call last):
  File "cassandra/cluster.py", line 1690, in cassandra.cluster.Cluster.connect
  File "cassandra/cluster.py", line 3488, in cassandra.cluster.ControlConnection.connect
  File "cassandra/cluster.py", line 3533, in cassandra.cluster.ControlConnection._reconnect_internal
cassandra.cluster.NoHostAvailable: ('Unable to connect to any servers', {'127.0.0.1:9042': AuthenticationFailed('Failed to authenticate to 127.0.0.1:9042: Error from server: code=0100 [Bad credentials] message="Provided username cassandra and/or password are incorrect"',)})
02:23:54,480 cassandra.cluster WARNING [control connection] Error connecting to 127.0.0.1:9042:
Traceback (most recent call last):
  File "cassandra/cluster.py", line 3522, in cassandra.cluster.ControlConnection._reconnect_internal
  File "cassandra/cluster.py", line 3544, in cassandra.cluster.ControlConnection._try_connect
  File "cassandra/cluster.py", line 1620, in cassandra.cluster.Cluster.connection_factory
  File "cassandra/connection.py", line 837, in cassandra.connection.Connection.factory
  File "cassandra/connection.py", line 600, in cassandra.connection.defunct_on_error.wrapper
  File "cassandra/connection.py", line 1421, in cassandra.connection.Connection._handle_auth_response
cassandra.AuthenticationFailed: Failed to authenticate to 127.0.0.1:9042: Error from server: code=0100 [Bad credentials] message="Provided username cassandra and/or password are incorrect"
02:23:54,481 cassandra.cluster ERROR Control connection failed to connect, shutting down Cluster:
Traceback (most recent call last):
  File "cassandra/cluster.py", line 1690, in cassandra.cluster.Cluster.connect
  File "cassandra/cluster.py", line 3488, in cassandra.cluster.ControlConnection.connect
  File "cassandra/cluster.py", line 3533, in cassandra.cluster.ControlConnection._reconnect_internal
cassandra.cluster.NoHostAvailable: ('Unable to connect to any servers', {'127.0.0.1:9042': AuthenticationFailed('Failed to authenticate to 127.0.0.1:9042: Error from server: code=0100 [Bad credentials] message="Provided username cassandra and/or password are incorrect"',)})
02:23:54,740 cassandra.cluster WARNING [control connection] Error connecting to 127.0.0.1:9042:
Traceback (most recent call last):
  File "cassandra/cluster.py", line 3522, in cassandra.cluster.ControlConnection._reconnect_internal
  File "cassandra/cluster.py", line 3544, in cassandra.cluster.ControlConnection._try_connect
  File "cassandra/cluster.py", line 1620, in cassandra.cluster.Cluster.connection_factory
  File "cassandra/connection.py", line 837, in cassandra.connection.Connection.factory
  File "cassandra/connection.py", line 600, in cassandra.connection.defunct_on_error.wrapper
  File "cassandra/connection.py", line 1421, in cassandra.connection.Connection._handle_auth_response
cassandra.AuthenticationFailed: Failed to authenticate to 127.0.0.1:9042: Error from server: code=0100 [Bad credentials] message="Provided username cassandra and/or password are incorrect"
02:23:54,815 cassandra.cluster ERROR Control connection failed to connect, shutting down Cluster:
Traceback (most recent call last):
  File "cassandra/cluster.py", line 1690, in cassandra.cluster.Cluster.connect
  File "cassandra/cluster.py", line 3488, in cassandra.cluster.ControlConnection.connect
  File "cassandra/cluster.py", line 3533, in cassandra.cluster.ControlConnection._reconnect_internal
cassandra.cluster.NoHostAvailable: ('Unable to connect to any servers', {'127.0.0.1:9042': AuthenticationFailed('Failed to authenticate to 127.0.0.1:9042: Error from server: code=0100 [Bad credentials] message="Provided username cassandra and/or password are incorrect"',)})
02:23:55,73 cassandra.cluster WARNING [control connection] Error connecting to 127.0.0.1:9042:
Traceback (most recent call last):
  File "cassandra/cluster.py", line 3522, in cassandra.cluster.ControlConnection._reconnect_internal
  File "cassandra/cluster.py", line 3544, in cassandra.cluster.ControlConnection._try_connect
  File "cassandra/cluster.py", line 1620, in cassandra.cluster.Cluster.connection_factory
  File "cassandra/connection.py", line 837, in cassandra.connection.Connection.factory
  File "cassandra/connection.py", line 600, in cassandra.connection.defunct_on_error.wrapper
  File "cassandra/connection.py", line 1421, in cassandra.connection.Connection._handle_auth_response
cassandra.AuthenticationFailed: Failed to authenticate to 127.0.0.1:9042: Error from server: code=0100 [Bad credentials] message="Provided username cassandra and/or password are incorrect"
02:23:55,75 cassandra.cluster ERROR Control connection failed to connect, shutting down Cluster:
Traceback (most recent call last):
  File "cassandra/cluster.py", line 1690, in cassandra.cluster.Cluster.connect
  File "cassandra/cluster.py", line 3488, in cassandra.cluster.ControlConnection.connect
  File "cassandra/cluster.py", line 3533, in cassandra.cluster.ControlConnection._reconnect_internal
cassandra.cluster.NoHostAvailable: ('Unable to connect to any servers', {'127.0.0.1:9042': AuthenticationFailed('Failed to authenticate to 127.0.0.1:9042: Error from server: code=0100 [Bad credentials] message="Provided username cassandra and/or password are incorrect"',)})
02:23:55,334 cassandra.cluster WARNING [control connection] Error connecting to 127.0.0.1:9042:
Traceback (most recent call last):
  File "cassandra/cluster.py", line 3522, in cassandra.cluster.ControlConnection._reconnect_internal
  File "cassandra/cluster.py", line 3544, in cassandra.cluster.ControlConnection._try_connect
  File "cassandra/cluster.py", line 1620, in cassandra.cluster.Cluster.connection_factory
  File "cassandra/connection.py", line 837, in cassandra.connection.Connection.factory
  File "cassandra/connection.py", line 600, in cassandra.connection.defunct_on_error.wrapper
  File "cassandra/connection.py", line 1421, in cassandra.connection.Connection._handle_auth_response
cassandra.AuthenticationFailed: Failed to authenticate to 127.0.0.1:9042: Error from server: code=0100 [Bad credentials] message="Provided username cassandra and/or password are incorrect"
02:23:55,334 cassandra.cluster ERROR Control connection failed to connect, shutting down Cluster:
Traceback (most recent call last):
  File "cassandra/cluster.py", line 1690, in cassandra.cluster.Cluster.connect
  File "cassandra/cluster.py", line 3488, in cassandra.cluster.ControlConnection.connect
  File "cassandra/cluster.py", line 3533, in cassandra.cluster.ControlConnection._reconnect_internal
cassandra.cluster.NoHostAvailable: ('Unable to connect to any servers', {'127.0.0.1:9042': AuthenticationFailed('Failed to authenticate to 127.0.0.1:9042: Error from server: code=0100 [Bad credentials] message="Provided username cassandra and/or password are incorrect"',)})
02:23:55,593 cassandra.cluster WARNING [control connection] Error connecting to 127.0.0.1:9042:
Traceback (most recent call last):
  File "cassandra/cluster.py", line 3522, in cassandra.cluster.ControlConnection._reconnect_internal
  File "cassandra/cluster.py", line 3544, in cassandra.cluster.ControlConnection._try_connect
  File "cassandra/cluster.py", line 1620, in cassandra.cluster.Cluster.connection_factory
  File "cassandra/connection.py", line 837, in cassandra.connection.Connection.factory
  File "cassandra/connection.py", line 600, in cassandra.connection.defunct_on_error.wrapper
  File "cassandra/connection.py", line 1421, in cassandra.connection.Connection._handle_auth_response
cassandra.AuthenticationFailed: Failed to authenticate to 127.0.0.1:9042: Error from server: code=0100 [Bad credentials] message="Provided username cassandra and/or password are incorrect"
02:23:55,594 cassandra.cluster ERROR Control connection failed to connect, shutting down Cluster:
Traceback (most recent call last):
  File "cassandra/cluster.py", line 1690, in cassandra.cluster.Cluster.connect
  File "cassandra/cluster.py", line 3488, in cassandra.cluster.ControlConnection.connect
  File "cassandra/cluster.py", line 3533, in cassandra.cluster.ControlConnection._reconnect_internal
cassandra.cluster.NoHostAvailable: ('Unable to connect to any servers', {'127.0.0.1:9042': AuthenticationFailed('Failed to authenticate to 127.0.0.1:9042: Error from server: code=0100 [Bad credentials] message="Provided username cassandra and/or password are incorrect"',)})
02:23:55,860 cassandra.cluster WARNING [control connection] Error connecting to 127.0.0.1:9042:
Traceback (most recent call last):
  File "cassandra/cluster.py", line 3522, in cassandra.cluster.ControlConnection._reconnect_internal
  File "cassandra/cluster.py", line 3544, in cassandra.cluster.ControlConnection._try_connect
  File "cassandra/cluster.py", line 1620, in cassandra.cluster.Cluster.connection_factory
  File "cassandra/connection.py", line 837, in cassandra.connection.Connection.factory
  File "cassandra/connection.py", line 600, in cassandra.connection.defunct_on_error.wrapper
  File "cassandra/connection.py", line 1421, in cassandra.connection.Connection._handle_auth_response
cassandra.AuthenticationFailed: Failed to authenticate to 127.0.0.1:9042: Error from server: code=0100 [Bad credentials] message="Provided username cassandra and/or password are incorrect"
02:23:55,861 cassandra.cluster ERROR Control connection failed to connect, shutting down Cluster:
Traceback (most recent call last):
  File "cassandra/cluster.py", line 1690, in cassandra.cluster.Cluster.connect
  File "cassandra/cluster.py", line 3488, in cassandra.cluster.ControlConnection.connect
  File "cassandra/cluster.py", line 3533, in cassandra.cluster.ControlConnection._reconnect_internal
cassandra.cluster.NoHostAvailable: ('Unable to connect to any servers', {'127.0.0.1:9042': AuthenticationFailed('Failed to authenticate to 127.0.0.1:9042: Error from server: code=0100 [Bad credentials] message="Provided username cassandra and/or password are incorrect"',)})
02:23:56,119 cassandra.cluster WARNING [control connection] Error connecting to 127.0.0.1:9042:
Traceback (most recent call last):
  File "cassandra/cluster.py", line 3522, in cassandra.cluster.ControlConnection._reconnect_internal
  File "cassandra/cluster.py", line 3544, in cassandra.cluster.ControlConnection._try_connect
  File "cassandra/cluster.py", line 1620, in cassandra.cluster.Cluster.connection_factory
  File "cassandra/connection.py", line 837, in cassandra.connection.Connection.factory
  File "cassandra/connection.py", line 600, in cassandra.connection.defunct_on_error.wrapper
  File "cassandra/connection.py", line 1421, in cassandra.connection.Connection._handle_auth_response
cassandra.AuthenticationFailed: Failed to authenticate to 127.0.0.1:9042: Error from server: code=0100 [Bad credentials] message="Provided username cassandra and/or password are incorrect"
02:23:56,120 cassandra.cluster ERROR Control connection failed to connect, shutting down Cluster:
Traceback (most recent call last):
  File "cassandra/cluster.py", line 1690, in cassandra.cluster.Cluster.connect
  File "cassandra/cluster.py", line 3488, in cassandra.cluster.ControlConnection.connect
  File "cassandra/cluster.py", line 3533, in cassandra.cluster.ControlConnection._reconnect_internal
cassandra.cluster.NoHostAvailable: ('Unable to connect to any servers', {'127.0.0.1:9042': AuthenticationFailed('Failed to authenticate to 127.0.0.1:9042: Error from server: code=0100 [Bad credentials] message="Provided username cassandra and/or password are incorrect"',)})
02:23:56,378 cassandra.cluster WARNING [control connection] Error connecting to 127.0.0.1:9042:
Traceback (most recent call last):
  File "cassandra/cluster.py", line 3522, in cassandra.cluster.ControlConnection._reconnect_internal
  File "cassandra/cluster.py", line 3544, in cassandra.cluster.ControlConnection._try_connect
  File "cassandra/cluster.py", line 1620, in cassandra.cluster.Cluster.connection_factory
  File "cassandra/connection.py", line 837, in cassandra.connection.Connection.factory
  File "cassandra/connection.py", line 600, in cassandra.connection.defunct_on_error.wrapper
  File "cassandra/connection.py", line 1421, in cassandra.connection.Connection._handle_auth_response
cassandra.AuthenticationFailed: Failed to authenticate to 127.0.0.1:9042: Error from server: code=0100 [Bad credentials] message="Provided username cassandra and/or password are incorrect"
02:23:56,380 cassandra.cluster ERROR Control connection failed to connect, shutting down Cluster:
Traceback (most recent call last):
  File "cassandra/cluster.py", line 1690, in cassandra.cluster.Cluster.connect
  File "cassandra/cluster.py", line 3488, in cassandra.cluster.ControlConnection.connect
  File "cassandra/cluster.py", line 3533, in cassandra.cluster.ControlConnection._reconnect_internal
cassandra.cluster.NoHostAvailable: ('Unable to connect to any servers', {'127.0.0.1:9042': AuthenticationFailed('Failed to authenticate to 127.0.0.1:9042: Error from server: code=0100 [Bad credentials] message="Provided username cassandra and/or password are incorrect"',)})
02:23:56,639 cassandra.cluster WARNING [control connection] Error connecting to 127.0.0.1:9042:
Traceback (most recent call last):
  File "cassandra/cluster.py", line 3522, in cassandra.cluster.ControlConnection._reconnect_internal
  File "cassandra/cluster.py", line 3544, in cassandra.cluster.ControlConnection._try_connect
  File "cassandra/cluster.py", line 1620, in cassandra.cluster.Cluster.connection_factory
  File "cassandra/connection.py", line 837, in cassandra.connection.Connection.factory
  File "cassandra/connection.py", line 600, in cassandra.connection.defunct_on_error.wrapper
  File "cassandra/connection.py", line 1421, in cassandra.connection.Connection._handle_auth_response
cassandra.AuthenticationFailed: Failed to authenticate to 127.0.0.1:9042: Error from server: code=0100 [Bad credentials] message="Provided username cassandra and/or password are incorrect"
02:23:56,640 cassandra.cluster ERROR Control connection failed to connect, shutting down Cluster:
Traceback (most recent call last):
  File "cassandra/cluster.py", line 1690, in cassandra.cluster.Cluster.connect
  File "cassandra/cluster.py", line 3488, in cassandra.cluster.ControlConnection.connect
  File "cassandra/cluster.py", line 3533, in cassandra.cluster.ControlConnection._reconnect_internal
cassandra.cluster.NoHostAvailable: ('Unable to connect to any servers', {'127.0.0.1:9042': AuthenticationFailed('Failed to authenticate to 127.0.0.1:9042: Error from server: code=0100 [Bad credentials] message="Provided username cassandra and/or password are incorrect"',)})
02:23:56,900 cassandra.cluster WARNING [control connection] Error connecting to 127.0.0.1:9042:
Traceback (most recent call last):
  File "cassandra/cluster.py", line 3522, in cassandra.cluster.ControlConnection._reconnect_internal
  File "cassandra/cluster.py", line 3544, in cassandra.cluster.ControlConnection._try_connect
  File "cassandra/cluster.py", line 1620, in cassandra.cluster.Cluster.connection_factory
  File "cassandra/connection.py", line 837, in cassandra.connection.Connection.factory
  File "cassandra/connection.py", line 600, in cassandra.connection.defunct_on_error.wrapper
  File "cassandra/connection.py", line 1421, in cassandra.connection.Connection._handle_auth_response
cassandra.AuthenticationFailed: Failed to authenticate to 127.0.0.1:9042: Error from server: code=0100 [Bad credentials] message="Provided username cassandra and/or password are incorrect"
02:23:56,902 cassandra.cluster ERROR Control connection failed to connect, shutting down Cluster:
Traceback (most recent call last):
  File "cassandra/cluster.py", line 1690, in cassandra.cluster.Cluster.connect
  File "cassandra/cluster.py", line 3488, in cassandra.cluster.ControlConnection.connect
  File "cassandra/cluster.py", line 3533, in cassandra.cluster.ControlConnection._reconnect_internal
cassandra.cluster.NoHostAvailable: ('Unable to connect to any servers', {'127.0.0.1:9042': AuthenticationFailed('Failed to authenticate to 127.0.0.1:9042: Error from server: code=0100 [Bad credentials] message="Provided username cassandra and/or password are incorrect"',)})
02:23:57,161 cassandra.cluster WARNING [control connection] Error connecting to 127.0.0.1:9042:
Traceback (most recent call last):
  File "cassandra/cluster.py", line 3522, in cassandra.cluster.ControlConnection._reconnect_internal
  File "cassandra/cluster.py", line 3544, in cassandra.cluster.ControlConnection._try_connect
  File "cassandra/cluster.py", line 1620, in cassandra.cluster.Cluster.connection_factory
  File "cassandra/connection.py", line 837, in cassandra.connection.Connection.factory
  File "cassandra/connection.py", line 600, in cassandra.connection.defunct_on_error.wrapper
  File "cassandra/connection.py", line 1421, in cassandra.connection.Connection._handle_auth_response
cassandra.AuthenticationFailed: Failed to authenticate to 127.0.0.1:9042: Error from server: code=0100 [Bad credentials] message="Provided username cassandra and/or password are incorrect"
02:23:57,162 cassandra.cluster ERROR Control connection failed to connect, shutting down Cluster:
Traceback (most recent call last):
  File "cassandra/cluster.py", line 1690, in cassandra.cluster.Cluster.connect
  File "cassandra/cluster.py", line 3488, in cassandra.cluster.ControlConnection.connect
  File "cassandra/cluster.py", line 3533, in cassandra.cluster.ControlConnection._reconnect_internal
cassandra.cluster.NoHostAvailable: ('Unable to connect to any servers', {'127.0.0.1:9042': AuthenticationFailed('Failed to authenticate to 127.0.0.1:9042: Error from server: code=0100 [Bad credentials] message="Provided username cassandra and/or password are incorrect"',)})
02:23:57,419 cassandra.cluster WARNING [control connection] Error connecting to 127.0.0.1:9042:
Traceback (most recent call last):
  File "cassandra/cluster.py", line 3522, in cassandra.cluster.ControlConnection._reconnect_internal
  File "cassandra/cluster.py", line 3544, in cassandra.cluster.ControlConnection._try_connect
  File "cassandra/cluster.py", line 1620, in cassandra.cluster.Cluster.connection_factory
  File "cassandra/connection.py", line 837, in cassandra.connection.Connection.factory
  File "cassandra/connection.py", line 600, in cassandra.connection.defunct_on_error.wrapper
  File "cassandra/connection.py", line 1421, in cassandra.connection.Connection._handle_auth_response
cassandra.AuthenticationFailed: Failed to authenticate to 127.0.0.1:9042: Error from server: code=0100 [Bad credentials] message="Provided username cassandra and/or password are incorrect"
02:23:57,421 cassandra.cluster ERROR Control connection failed to connect, shutting down Cluster:
Traceback (most recent call last):
  File "cassandra/cluster.py", line 1690, in cassandra.cluster.Cluster.connect
  File "cassandra/cluster.py", line 3488, in cassandra.cluster.ControlConnection.connect
  File "cassandra/cluster.py", line 3533, in cassandra.cluster.ControlConnection._reconnect_internal
cassandra.cluster.NoHostAvailable: ('Unable to connect to any servers', {'127.0.0.1:9042': AuthenticationFailed('Failed to authenticate to 127.0.0.1:9042: Error from server: code=0100 [Bad credentials] message="Provided username cassandra and/or password are incorrect"',)})
02:23:57,680 cassandra.cluster WARNING [control connection] Error connecting to 127.0.0.1:9042:
Traceback (most recent call last):
  File "cassandra/cluster.py", line 3522, in cassandra.cluster.ControlConnection._reconnect_internal
  File "cassandra/cluster.py", line 3544, in cassandra.cluster.ControlConnection._try_connect
  File "cassandra/cluster.py", line 1620, in cassandra.cluster.Cluster.connection_factory
  File "cassandra/connection.py", line 837, in cassandra.connection.Connection.factory
  File "cassandra/connection.py", line 600, in cassandra.connection.defunct_on_error.wrapper
  File "cassandra/connection.py", line 1421, in cassandra.connection.Connection._handle_auth_response
cassandra.AuthenticationFailed: Failed to authenticate to 127.0.0.1:9042: Error from server: code=0100 [Bad credentials] message="Provided username cassandra and/or password are incorrect"
02:23:57,681 cassandra.cluster ERROR Control connection failed to connect, shutting down Cluster:
Traceback (most recent call last):
  File "cassandra/cluster.py", line 1690, in cassandra.cluster.Cluster.connect
  File "cassandra/cluster.py", line 3488, in cassandra.cluster.ControlConnection.connect
  File "cassandra/cluster.py", line 3533, in cassandra.cluster.ControlConnection._reconnect_internal
cassandra.cluster.NoHostAvailable: ('Unable to connect to any servers', {'127.0.0.1:9042': AuthenticationFailed('Failed to authenticate to 127.0.0.1:9042: Error from server: code=0100 [Bad credentials] message="Provided username cassandra and/or password are incorrect"',)})
02:23:57,940 cassandra.cluster WARNING [control connection] Error connecting to 127.0.0.1:9042:
Traceback (most recent call last):
  File "cassandra/cluster.py", line 3522, in cassandra.cluster.ControlConnection._reconnect_internal
  File "cassandra/cluster.py", line 3544, in cassandra.cluster.ControlConnection._try_connect
  File "cassandra/cluster.py", line 1620, in cassandra.cluster.Cluster.connection_factory
  File "cassandra/connection.py", line 837, in cassandra.connection.Connection.factory
  File "cassandra/connection.py", line 600, in cassandra.connection.defunct_on_error.wrapper
  File "cassandra/connection.py", line 1421, in cassandra.connection.Connection._handle_auth_response
cassandra.AuthenticationFailed: Failed to authenticate to 127.0.0.1:9042: Error from server: code=0100 [Bad credentials] message="Provided username cassandra and/or password are incorrect"
02:23:57,941 cassandra.cluster ERROR Control connection failed to connect, shutting down Cluster:
Traceback (most recent call last):
  File "cassandra/cluster.py", line 1690, in cassandra.cluster.Cluster.connect
  File "cassandra/cluster.py", line 3488, in cassandra.cluster.ControlConnection.connect
  File "cassandra/cluster.py", line 3533, in cassandra.cluster.ControlConnection._reconnect_internal
cassandra.cluster.NoHostAvailable: ('Unable to connect to any servers', {'127.0.0.1:9042': AuthenticationFailed('Failed to authenticate to 127.0.0.1:9042: Error from server: code=0100 [Bad credentials] message="Provided username cassandra and/or password are incorrect"',)})
02:23:58,199 cassandra.cluster WARNING [control connection] Error connecting to 127.0.0.1:9042:
Traceback (most recent call last):
  File "cassandra/cluster.py", line 3522, in cassandra.cluster.ControlConnection._reconnect_internal
  File "cassandra/cluster.py", line 3544, in cassandra.cluster.ControlConnection._try_connect
  File "cassandra/cluster.py", line 1620, in cassandra.cluster.Cluster.connection_factory
  File "cassandra/connection.py", line 837, in cassandra.connection.Connection.factory
  File "cassandra/connection.py", line 600, in cassandra.connection.defunct_on_error.wrapper
  File "cassandra/connection.py", line 1421, in cassandra.connection.Connection._handle_auth_response
cassandra.AuthenticationFailed: Failed to authenticate to 127.0.0.1:9042: Error from server: code=0100 [Bad credentials] message="Provided username cassandra and/or password are incorrect"
02:23:58,200 cassandra.cluster ERROR Control connection failed to connect, shutting down Cluster:
Traceback (most recent call last):
  File "cassandra/cluster.py", line 1690, in cassandra.cluster.Cluster.connect
  File "cassandra/cluster.py", line 3488, in cassandra.cluster.ControlConnection.connect
  File "cassandra/cluster.py", line 3533, in cassandra.cluster.ControlConnection._reconnect_internal
cassandra.cluster.NoHostAvailable: ('Unable to connect to any servers', {'127.0.0.1:9042': AuthenticationFailed('Failed to authenticate to 127.0.0.1:9042: Error from server: code=0100 [Bad credentials] message="Provided username cassandra and/or password are incorrect"',)})
02:23:58,458 cassandra.cluster WARNING [control connection] Error connecting to 127.0.0.1:9042:
Traceback (most recent call last):
  File "cassandra/cluster.py", line 3522, in cassandra.cluster.ControlConnection._reconnect_internal
  File "cassandra/cluster.py", line 3544, in cassandra.cluster.ControlConnection._try_connect
  File "cassandra/cluster.py", line 1620, in cassandra.cluster.Cluster.connection_factory
  File "cassandra/connection.py", line 837, in cassandra.connection.Connection.factory
  File "cassandra/connection.py", line 600, in cassandra.connection.defunct_on_error.wrapper
  File "cassandra/connection.py", line 1421, in cassandra.connection.Connection._handle_auth_response
cassandra.AuthenticationFailed: Failed to authenticate to 127.0.0.1:9042: Error from server: code=0100 [Bad credentials] message="Provided username cassandra and/or password are incorrect"
02:23:58,459 cassandra.cluster ERROR Control connection failed to connect, shutting down Cluster:
Traceback (most recent call last):
  File "cassandra/cluster.py", line 1690, in cassandra.cluster.Cluster.connect
  File "cassandra/cluster.py", line 3488, in cassandra.cluster.ControlConnection.connect
  File "cassandra/cluster.py", line 3533, in cassandra.cluster.ControlConnection._reconnect_internal
cassandra.cluster.NoHostAvailable: ('Unable to connect to any servers', {'127.0.0.1:9042': AuthenticationFailed('Failed to authenticate to 127.0.0.1:9042: Error from server: code=0100 [Bad credentials] message="Provided username cassandra and/or password are incorrect"',)})
02:23:58,722 cassandra.cluster WARNING [control connection] Error connecting to 127.0.0.1:9042:
Traceback (most recent call last):
  File "cassandra/cluster.py", line 3522, in cassandra.cluster.ControlConnection._reconnect_internal
  File "cassandra/cluster.py", line 3544, in cassandra.cluster.ControlConnection._try_connect
  File "cassandra/cluster.py", line 1620, in cassandra.cluster.Cluster.connection_factory
  File "cassandra/connection.py", line 837, in cassandra.connection.Connection.factory
  File "cassandra/connection.py", line 600, in cassandra.connection.defunct_on_error.wrapper
  File "cassandra/connection.py", line 1421, in cassandra.connection.Connection._handle_auth_response
cassandra.AuthenticationFailed: Failed to authenticate to 127.0.0.1:9042: Error from server: code=0100 [Bad credentials] message="Provided username cassandra and/or password are incorrect"
02:23:58,723 cassandra.cluster ERROR Control connection failed to connect, shutting down Cluster:
Traceback (most recent call last):
  File "cassandra/cluster.py", line 1690, in cassandra.cluster.Cluster.connect
  File "cassandra/cluster.py", line 3488, in cassandra.cluster.ControlConnection.connect
  File "cassandra/cluster.py", line 3533, in cassandra.cluster.ControlConnection._reconnect_internal
cassandra.cluster.NoHostAvailable: ('Unable to connect to any servers', {'127.0.0.1:9042': AuthenticationFailed('Failed to authenticate to 127.0.0.1:9042: Error from server: code=0100 [Bad credentials] message="Provided username cassandra and/or password are incorrect"',)})
02:23:58,988 cassandra.cluster WARNING [control connection] Error connecting to 127.0.0.1:9042:
Traceback (most recent call last):
  File "cassandra/cluster.py", line 3522, in cassandra.cluster.ControlConnection._reconnect_internal
  File "cassandra/cluster.py", line 3544, in cassandra.cluster.ControlConnection._try_connect
  File "cassandra/cluster.py", line 1620, in cassandra.cluster.Cluster.connection_factory
  File "cassandra/connection.py", line 837, in cassandra.connection.Connection.factory
  File "cassandra/connection.py", line 600, in cassandra.connection.defunct_on_error.wrapper
  File "cassandra/connection.py", line 1421, in cassandra.connection.Connection._handle_auth_response
cassandra.AuthenticationFailed: Failed to authenticate to 127.0.0.1:9042: Error from server: code=0100 [Bad credentials] message="Provided username cassandra and/or password are incorrect"
02:23:58,989 cassandra.cluster ERROR Control connection failed to connect, shutting down Cluster:
Traceback (most recent call last):
  File "cassandra/cluster.py", line 1690, in cassandra.cluster.Cluster.connect
  File "cassandra/cluster.py", line 3488, in cassandra.cluster.ControlConnection.connect
  File "cassandra/cluster.py", line 3533, in cassandra.cluster.ControlConnection._reconnect_internal
cassandra.cluster.NoHostAvailable: ('Unable to connect to any servers', {'127.0.0.1:9042': AuthenticationFailed('Failed to authenticate to 127.0.0.1:9042: Error from server: code=0100 [Bad credentials] message="Provided username cassandra and/or password are incorrect"',)})
02:23:59,247 cassandra.cluster WARNING [control connection] Error connecting to 127.0.0.1:9042:
Traceback (most recent call last):
  File "cassandra/cluster.py", line 3522, in cassandra.cluster.ControlConnection._reconnect_internal
  File "cassandra/cluster.py", line 3544, in cassandra.cluster.ControlConnection._try_connect
  File "cassandra/cluster.py", line 1620, in cassandra.cluster.Cluster.connection_factory
  File "cassandra/connection.py", line 837, in cassandra.connection.Connection.factory
  File "cassandra/connection.py", line 600, in cassandra.connection.defunct_on_error.wrapper
  File "cassandra/connection.py", line 1421, in cassandra.connection.Connection._handle_auth_response
cassandra.AuthenticationFailed: Failed to authenticate to 127.0.0.1:9042: Error from server: code=0100 [Bad credentials] message="Provided username cassandra and/or password are incorrect"
02:23:59,248 cassandra.cluster ERROR Control connection failed to connect, shutting down Cluster:
Traceback (most recent call last):
  File "cassandra/cluster.py", line 1690, in cassandra.cluster.Cluster.connect
  File "cassandra/cluster.py", line 3488, in cassandra.cluster.ControlConnection.connect
  File "cassandra/cluster.py", line 3533, in cassandra.cluster.ControlConnection._reconnect_internal
cassandra.cluster.NoHostAvailable: ('Unable to connect to any servers', {'127.0.0.1:9042': AuthenticationFailed('Failed to authenticate to 127.0.0.1:9042: Error from server: code=0100 [Bad credentials] message="Provided username cassandra and/or password are incorrect"',)})
02:23:59,506 cassandra.cluster WARNING [control connection] Error connecting to 127.0.0.1:9042:
Traceback (most recent call last):
  File "cassandra/cluster.py", line 3522, in cassandra.cluster.ControlConnection._reconnect_internal
  File "cassandra/cluster.py", line 3544, in cassandra.cluster.ControlConnection._try_connect
  File "cassandra/cluster.py", line 1620, in cassandra.cluster.Cluster.connection_factory
  File "cassandra/connection.py", line 837, in cassandra.connection.Connection.factory
  File "cassandra/connection.py", line 600, in cassandra.connection.defunct_on_error.wrapper
  File "cassandra/connection.py", line 1421, in cassandra.connection.Connection._handle_auth_response
cassandra.AuthenticationFailed: Failed to authenticate to 127.0.0.1:9042: Error from server: code=0100 [Bad credentials] message="Provided username cassandra and/or password are incorrect"
02:23:59,507 cassandra.cluster ERROR Control connection failed to connect, shutting down Cluster:
Traceback (most recent call last):
  File "cassandra/cluster.py", line 1690, in cassandra.cluster.Cluster.connect
  File "cassandra/cluster.py", line 3488, in cassandra.cluster.ControlConnection.connect
  File "cassandra/cluster.py", line 3533, in cassandra.cluster.ControlConnection._reconnect_internal
cassandra.cluster.NoHostAvailable: ('Unable to connect to any servers', {'127.0.0.1:9042': AuthenticationFailed('Failed to authenticate to 127.0.0.1:9042: Error from server: code=0100 [Bad credentials] message="Provided username cassandra and/or password are incorrect"',)})
02:23:59,765 cassandra.cluster WARNING [control connection] Error connecting to 127.0.0.1:9042:
Traceback (most recent call last):
  File "cassandra/cluster.py", line 3522, in cassandra.cluster.ControlConnection._reconnect_internal
  File "cassandra/cluster.py", line 3544, in cassandra.cluster.ControlConnection._try_connect
  File "cassandra/cluster.py", line 1620, in cassandra.cluster.Cluster.connection_factory
  File "cassandra/connection.py", line 837, in cassandra.connection.Connection.factory
  File "cassandra/connection.py", line 600, in cassandra.connection.defunct_on_error.wrapper
  File "cassandra/connection.py", line 1421, in cassandra.connection.Connection._handle_auth_response
cassandra.AuthenticationFailed: Failed to authenticate to 127.0.0.1:9042: Error from server: code=0100 [Bad credentials] message="Provided username cassandra and/or password are incorrect"
02:23:59,766 cassandra.cluster ERROR Control connection failed to connect, shutting down Cluster:
Traceback (most recent call last):
  File "cassandra/cluster.py", line 1690, in cassandra.cluster.Cluster.connect
  File "cassandra/cluster.py", line 3488, in cassandra.cluster.ControlConnection.connect
  File "cassandra/cluster.py", line 3533, in cassandra.cluster.ControlConnection._reconnect_internal
cassandra.cluster.NoHostAvailable: ('Unable to connect to any servers', {'127.0.0.1:9042': AuthenticationFailed('Failed to authenticate to 127.0.0.1:9042: Error from server: code=0100 [Bad credentials] message="Provided username cassandra and/or password are incorrect"',)})
02:24:00,25 cassandra.cluster WARNING [control connection] Error connecting to 127.0.0.1:9042:
Traceback (most recent call last):
  File "cassandra/cluster.py", line 3522, in cassandra.cluster.ControlConnection._reconnect_internal
  File "cassandra/cluster.py", line 3544, in cassandra.cluster.ControlConnection._try_connect
  File "cassandra/cluster.py", line 1620, in cassandra.cluster.Cluster.connection_factory
  File "cassandra/connection.py", line 837, in cassandra.connection.Connection.factory
  File "cassandra/connection.py", line 600, in cassandra.connection.defunct_on_error.wrapper
  File "cassandra/connection.py", line 1421, in cassandra.connection.Connection._handle_auth_response
cassandra.AuthenticationFailed: Failed to authenticate to 127.0.0.1:9042: Error from server: code=0100 [Bad credentials] message="Provided username cassandra and/or password are incorrect"
02:24:00,26 cassandra.cluster ERROR Control connection failed to connect, shutting down Cluster:
Traceback (most recent call last):
  File "cassandra/cluster.py", line 1690, in cassandra.cluster.Cluster.connect
  File "cassandra/cluster.py", line 3488, in cassandra.cluster.ControlConnection.connect
  File "cassandra/cluster.py", line 3533, in cassandra.cluster.ControlConnection._reconnect_internal
cassandra.cluster.NoHostAvailable: ('Unable to connect to any servers', {'127.0.0.1:9042': AuthenticationFailed('Failed to authenticate to 127.0.0.1:9042: Error from server: code=0100 [Bad credentials] message="Provided username cassandra and/or password are incorrect"',)})
PASSED                                                                   [100%]
===Flaky Test Report===

test_drop_role_revokes_permissions_granted_on_it passed 1 out of the required 1 times. Success!

===End Flaky Test Report===

========================== 1 passed in 20.02 seconds ===========================
[msx] rc = 0
