cassandra refresh_test.py::TestRefresh::test_refresh_deadlock_startup false true
log_dst_dir = /users/masix/vm_images/ZebraConf/app_meta/logs
the_test is refresh_test.py::TestRefresh::test_refresh_deadlock_startup
rm: cannot remove '/tmp/my_log.txt': No such file or directory
============================= test session starts ==============================
platform linux -- Python 3.6.9, pytest-3.6.4, py-1.11.0, pluggy-0.7.1 -- /users/masix/dtest/bin/python3
cachedir: .pytest_cache
rootdir: /users/masix/cassandra-dtest, inifile: pytest.ini
plugins: timeout-1.4.2, repeat-0.9.1, flaky-3.7.0
timeout: 1200.0s
timeout method: signal
timeout func_only: False
collecting ... collected 1 item

refresh_test.py::TestRefresh::test_refresh_deadlock_startup 
-------------------------------- live log call ---------------------------------
00:04:49,244 cassandra.cluster WARNING Host 127.0.0.1:9042 has been marked down
00:04:49,247 cassandra.cluster WARNING [control connection] Error connecting to 127.0.0.1:9042:
Traceback (most recent call last):
  File "cassandra/cluster.py", line 3522, in cassandra.cluster.ControlConnection._reconnect_internal
  File "cassandra/cluster.py", line 3544, in cassandra.cluster.ControlConnection._try_connect
  File "cassandra/cluster.py", line 1620, in cassandra.cluster.Cluster.connection_factory
  File "cassandra/connection.py", line 831, in cassandra.connection.Connection.factory
  File "/users/masix/dtest/src/cassandra-driver/cassandra/io/libevreactor.py", line 267, in __init__
    self._connect_socket()
  File "cassandra/connection.py", line 898, in cassandra.connection.Connection._connect_socket
ConnectionRefusedError: [Errno 111] Tried connecting to [('127.0.0.1', 9042)]. Last error: Connection refused
00:04:50,253 cassandra.pool WARNING Error attempting to reconnect to 127.0.0.1:9042, scheduling retry in 2.22 seconds: [Errno 111] Tried connecting to [('127.0.0.1', 9042)]. Last error: Connection refused
00:04:52,559 cassandra.pool WARNING Error attempting to reconnect to 127.0.0.1:9042, scheduling retry in 3.72 seconds: [Errno 111] Tried connecting to [('127.0.0.1', 9042)]. Last error: Connection refused
00:04:56,369 cassandra.pool WARNING Error attempting to reconnect to 127.0.0.1:9042, scheduling retry in 8.88 seconds: [Errno 111] Tried connecting to [('127.0.0.1', 9042)]. Last error: Connection refused
00:05:05,292 cassandra.pool WARNING Error attempting to reconnect to 127.0.0.1:9042, scheduling retry in 16.16 seconds: [Errno 111] Tried connecting to [('127.0.0.1', 9042)]. Last error: Connection refused
00:05:21,534 cassandra.pool WARNING Error attempting to reconnect to 127.0.0.1:9042, scheduling retry in 34.88 seconds: [Errno 111] Tried connecting to [('127.0.0.1', 9042)]. Last error: Connection refused
00:05:56,422 cassandra.pool WARNING Error attempting to reconnect to 127.0.0.1:9042, scheduling retry in 55.04 seconds: [Errno 111] Tried connecting to [('127.0.0.1', 9042)]. Last error: Connection refused
00:06:51,564 cassandra.pool WARNING Error attempting to reconnect to 127.0.0.1:9042, scheduling retry in 120.32 seconds: [Errno 111] Tried connecting to [('127.0.0.1', 9042)]. Last error: Connection refused
PASSED                                                                   [100%]
===Flaky Test Report===

test_refresh_deadlock_startup passed 1 out of the required 1 times. Success!

===End Flaky Test Report===

========================== 1 passed in 232.18 seconds ==========================
[msx] rc = 0
mv /tmp/my_log.txt /users/masix/vm_images/ZebraConf/app_meta/logs/refresh_test.py::TestRefresh::test_refresh_deadlock_startup-output_1643090893816_3182921218.txt
