cassandra replica_side_filtering_test.py::TestAllowFiltering::test_complementary_deletion_with_limit_on_static_column_with_empty_partitions_and_rows_after false true
log_dst_dir = /users/masix/vm_images/ZebraConf/app_meta/logs
the_test is replica_side_filtering_test.py::TestAllowFiltering::test_complementary_deletion_with_limit_on_static_column_with_empty_partitions_and_rows_after
rm: cannot remove '/tmp/my_log.txt': No such file or directory
============================= test session starts ==============================
platform linux -- Python 3.6.9, pytest-3.6.4, py-1.11.0, pluggy-0.7.1 -- /users/masix/dtest/bin/python3
cachedir: .pytest_cache
rootdir: /users/masix/cassandra-dtest, inifile: pytest.ini
plugins: timeout-1.4.2, repeat-0.9.1, flaky-3.7.0
timeout: 1200.0s
timeout method: signal
timeout func_only: False
collecting ... collected 1 item

replica_side_filtering_test.py::TestAllowFiltering::test_complementary_deletion_with_limit_on_static_column_with_empty_partitions_and_rows_after 
-------------------------------- live log call ---------------------------------
00:06:25,333 cassandra.cluster WARNING Failed to create connection pool for new host 127.0.0.2:9042:
Traceback (most recent call last):
  File "cassandra/cluster.py", line 3175, in cassandra.cluster.Session.add_or_renew_pool.run_add_or_renew_pool
  File "cassandra/pool.py", line 402, in cassandra.pool.HostConnection.__init__
  File "cassandra/cluster.py", line 1620, in cassandra.cluster.Cluster.connection_factory
  File "cassandra/connection.py", line 831, in cassandra.connection.Connection.factory
  File "/users/masix/dtest/src/cassandra-driver/cassandra/io/libevreactor.py", line 267, in __init__
    self._connect_socket()
  File "cassandra/connection.py", line 898, in cassandra.connection.Connection._connect_socket
ConnectionRefusedError: [Errno 111] Tried connecting to [('127.0.0.2', 9042)]. Last error: Connection refused
00:06:25,337 cassandra.cluster WARNING Host 127.0.0.2:9042 has been marked down
00:06:26,447 cassandra.pool WARNING Error attempting to reconnect to 127.0.0.2:9042, scheduling retry in 2.04 seconds: [Errno 111] Tried connecting to [('127.0.0.2', 9042)]. Last error: Connection refused
00:06:28,555 cassandra.pool WARNING Error attempting to reconnect to 127.0.0.2:9042, scheduling retry in 3.72 seconds: [Errno 111] Tried connecting to [('127.0.0.2', 9042)]. Last error: Connection refused
00:06:32,367 cassandra.pool WARNING Error attempting to reconnect to 127.0.0.2:9042, scheduling retry in 8.08 seconds: [Errno 111] Tried connecting to [('127.0.0.2', 9042)]. Last error: Connection refused
00:06:42,446 cassandra.cluster WARNING Failed to create connection pool for new host 127.0.0.1:9042:
Traceback (most recent call last):
  File "cassandra/cluster.py", line 3175, in cassandra.cluster.Session.add_or_renew_pool.run_add_or_renew_pool
  File "cassandra/pool.py", line 402, in cassandra.pool.HostConnection.__init__
  File "cassandra/cluster.py", line 1620, in cassandra.cluster.Cluster.connection_factory
  File "cassandra/connection.py", line 831, in cassandra.connection.Connection.factory
  File "/users/masix/dtest/src/cassandra-driver/cassandra/io/libevreactor.py", line 267, in __init__
    self._connect_socket()
  File "cassandra/connection.py", line 898, in cassandra.connection.Connection._connect_socket
ConnectionRefusedError: [Errno 111] Tried connecting to [('127.0.0.1', 9042)]. Last error: Connection refused
00:06:42,448 cassandra.cluster WARNING Host 127.0.0.1:9042 has been marked down
00:06:43,556 cassandra.pool WARNING Error attempting to reconnect to 127.0.0.1:9042, scheduling retry in 2.02 seconds: [Errno 111] Tried connecting to [('127.0.0.1', 9042)]. Last error: Connection refused
00:06:45,339 cassandra.cluster WARNING Host 127.0.0.1:9042 has been marked down
00:06:45,341 cassandra.cluster WARNING [control connection] Error connecting to 127.0.0.1:9042:
Traceback (most recent call last):
  File "cassandra/cluster.py", line 3522, in cassandra.cluster.ControlConnection._reconnect_internal
  File "cassandra/cluster.py", line 3544, in cassandra.cluster.ControlConnection._try_connect
  File "cassandra/cluster.py", line 1620, in cassandra.cluster.Cluster.connection_factory
  File "cassandra/connection.py", line 831, in cassandra.connection.Connection.factory
  File "/users/masix/dtest/src/cassandra-driver/cassandra/io/libevreactor.py", line 267, in __init__
    self._connect_socket()
  File "cassandra/connection.py", line 898, in cassandra.connection.Connection._connect_socket
ConnectionRefusedError: [Errno 111] Tried connecting to [('127.0.0.1', 9042)]. Last error: Connection refused
00:06:45,665 cassandra.pool WARNING Error attempting to reconnect to 127.0.0.1:9042, scheduling retry in 3.8 seconds: [Errno 111] Tried connecting to [('127.0.0.1', 9042)]. Last error: Connection refused
00:06:46,346 cassandra.pool WARNING Error attempting to reconnect to 127.0.0.1:9042, scheduling retry in 1.76 seconds: [Errno 111] Tried connecting to [('127.0.0.1', 9042)]. Last error: Connection refused
00:06:48,151 cassandra.pool WARNING Error attempting to reconnect to 127.0.0.1:9042, scheduling retry in 4.04 seconds: [Errno 111] Tried connecting to [('127.0.0.1', 9042)]. Last error: Connection refused
00:06:49,477 cassandra.pool WARNING Error attempting to reconnect to 127.0.0.1:9042, scheduling retry in 8.96 seconds: [Errno 111] Tried connecting to [('127.0.0.1', 9042)]. Last error: Connection refused
00:06:52,262 cassandra.pool WARNING Error attempting to reconnect to 127.0.0.1:9042, scheduling retry in 7.04 seconds: [Errno 111] Tried connecting to [('127.0.0.1', 9042)]. Last error: Connection refused
00:06:55,332 cassandra.cluster WARNING Host 127.0.0.1:9042 has been marked down
PASSED                                                                   [100%]
===Flaky Test Report===

test_complementary_deletion_with_limit_on_static_column_with_empty_partitions_and_rows_after passed 1 out of the required 1 times. Success!

===End Flaky Test Report===

========================== 1 passed in 58.33 seconds ===========================
[msx] rc = 0
mv /tmp/my_log.txt /users/masix/vm_images/ZebraConf/app_meta/logs/replica_side_filtering_test.py::TestAllowFiltering::test_complementary_deletion_with_limit_on_static_column_with_empty_partitions_and_rows_after-output_1643090826467_1558618001.txt
