cassandra auth_test.py::TestAuth::test_handle_corrupt_role_data true true
the_test is auth_test.py::TestAuth::test_handle_corrupt_role_data
============================= test session starts ==============================
platform linux -- Python 3.6.9, pytest-3.6.4, py-1.11.0, pluggy-0.7.1 -- /users/masix/dtest/bin/python
cachedir: .pytest_cache
rootdir: /users/masix/cassandra-dtest, inifile: pytest.ini
plugins: timeout-1.4.2, repeat-0.9.1, flaky-3.7.0
timeout: 900.0s
timeout method: signal
timeout func_only: False
collecting ... collected 1 item

auth_test.py::TestAuth::test_handle_corrupt_role_data 
-------------------------------- live log call ---------------------------------
17:49:08,315 ccmlib.node WARNING [msx] ccmlib:copy_config_files.py, conf_dir = /users/masix/cassandra/conf
17:49:08,400 ccmlib.node WARNING [msx] ccmlib:node.py, self.name = node1
17:49:08,400 ccmlib.node WARNING [msx] ccmlib:node.py, sstable_preemptive_open_interval_in_mb = 50
17:49:08,470 ccmlib.node WARNING [msx] ccmlib:node.py, self.name = node1
17:49:08,471 ccmlib.node WARNING [msx] ccmlib:node.py, sstable_preemptive_open_interval_in_mb = 50
17:49:24,938 cassandra.cluster WARNING Host 127.0.0.1:9042 error: Server error.
PASSED                                                                   [100%]
===Flaky Test Report===

test_handle_corrupt_role_data passed 1 out of the required 1 times. Success!

===End Flaky Test Report===

========================== 1 passed in 17.82 seconds ===========================
[msx] rc = 0
