cassandra global_row_key_cache_test.py::TestGlobalRowKeyCache::test_functional true true
the_test is global_row_key_cache_test.py::TestGlobalRowKeyCache::test_functional
============================= test session starts ==============================
platform linux -- Python 3.6.9, pytest-3.6.4, py-1.11.0, pluggy-0.7.1 -- /users/masix/dtest/bin/python
cachedir: .pytest_cache
rootdir: /users/masix/cassandra-dtest, inifile: pytest.ini
plugins: timeout-1.4.2, repeat-0.9.1, flaky-3.7.0
timeout: 900.0s
timeout method: signal
timeout func_only: False
collecting ... collected 1 item

global_row_key_cache_test.py::TestGlobalRowKeyCache::test_functional 
-------------------------------- live log call ---------------------------------
01:18:36,664 ccmlib.node WARNING [msx] ccmlib:copy_config_files.py, conf_dir = /users/masix/cassandra/conf
01:18:36,751 ccmlib.node WARNING [msx] ccmlib:node.py, self.name = node1
01:18:36,752 ccmlib.node WARNING [msx] ccmlib:node.py, sstable_preemptive_open_interval_in_mb = 50
01:18:36,820 ccmlib.node WARNING [msx] ccmlib:node.py, self.name = node1
01:18:36,820 ccmlib.node WARNING [msx] ccmlib:node.py, sstable_preemptive_open_interval_in_mb = 50
01:18:36,911 ccmlib.node WARNING [msx] ccmlib:copy_config_files.py, conf_dir = /users/masix/cassandra/conf
01:18:36,996 ccmlib.node WARNING [msx] ccmlib:node.py, self.name = node2
01:18:36,996 ccmlib.node WARNING [msx] ccmlib:node.py, sstable_preemptive_open_interval_in_mb = 50
01:18:37,62 ccmlib.node WARNING [msx] ccmlib:node.py, self.name = node2
01:18:37,62 ccmlib.node WARNING [msx] ccmlib:node.py, sstable_preemptive_open_interval_in_mb = 50
01:18:37,153 ccmlib.node WARNING [msx] ccmlib:copy_config_files.py, conf_dir = /users/masix/cassandra/conf
01:18:37,238 ccmlib.node WARNING [msx] ccmlib:node.py, self.name = node3
01:18:37,238 ccmlib.node WARNING [msx] ccmlib:node.py, sstable_preemptive_open_interval_in_mb = 50
01:18:37,304 ccmlib.node WARNING [msx] ccmlib:node.py, self.name = node3
01:18:37,304 ccmlib.node WARNING [msx] ccmlib:node.py, sstable_preemptive_open_interval_in_mb = 50
01:18:37,359 ccmlib.node WARNING [msx] ccmlib:copy_config_files.py, conf_dir = /users/masix/cassandra/conf
01:18:37,444 ccmlib.node WARNING [msx] ccmlib:node.py, self.name = node1
01:18:37,444 ccmlib.node WARNING [msx] ccmlib:node.py, sstable_preemptive_open_interval_in_mb = 50
01:18:37,494 ccmlib.node WARNING [msx] ccmlib:copy_config_files.py, conf_dir = /users/masix/cassandra/conf
01:18:37,578 ccmlib.node WARNING [msx] ccmlib:node.py, self.name = node2
01:18:37,578 ccmlib.node WARNING [msx] ccmlib:node.py, sstable_preemptive_open_interval_in_mb = 50
01:18:37,628 ccmlib.node WARNING [msx] ccmlib:copy_config_files.py, conf_dir = /users/masix/cassandra/conf
01:18:37,713 ccmlib.node WARNING [msx] ccmlib:node.py, self.name = node3
01:18:37,713 ccmlib.node WARNING [msx] ccmlib:node.py, sstable_preemptive_open_interval_in_mb = 50
01:19:18,39 cassandra.cluster WARNING Host 127.0.0.1:9042 has been marked down
01:19:19,147 cassandra.pool WARNING Error attempting to reconnect to 127.0.0.1:9042, scheduling retry in 1.74 seconds: [Errno 111] Tried connecting to [('127.0.0.1', 9042)]. Last error: Connection refused
01:19:20,954 cassandra.pool WARNING Error attempting to reconnect to 127.0.0.1:9042, scheduling retry in 3.8 seconds: [Errno 111] Tried connecting to [('127.0.0.1', 9042)]. Last error: Connection refused
01:19:24,765 cassandra.pool WARNING Error attempting to reconnect to 127.0.0.1:9042, scheduling retry in 8.64 seconds: [Errno 111] Tried connecting to [('127.0.0.1', 9042)]. Last error: Connection refused
01:19:25,153 cassandra.cluster WARNING Host 127.0.0.2:9042 has been marked down
01:19:26,170 cassandra.pool WARNING Error attempting to reconnect to 127.0.0.2:9042, scheduling retry in 2.12 seconds: [Errno 111] Tried connecting to [('127.0.0.2', 9042)]. Last error: Connection refused
01:19:28,376 cassandra.pool WARNING Error attempting to reconnect to 127.0.0.2:9042, scheduling retry in 3.84 seconds: [Errno 111] Tried connecting to [('127.0.0.2', 9042)]. Last error: Connection refused
01:19:32,285 cassandra.pool WARNING Error attempting to reconnect to 127.0.0.2:9042, scheduling retry in 8.64 seconds: [Errno 111] Tried connecting to [('127.0.0.2', 9042)]. Last error: Connection refused
01:19:33,488 cassandra.pool WARNING Error attempting to reconnect to 127.0.0.1:9042, scheduling retry in 15.84 seconds: [Errno 111] Tried connecting to [('127.0.0.1', 9042)]. Last error: Connection refused
01:19:40,279 cassandra.cluster WARNING Host 127.0.0.3:9042 has been marked down
01:19:41,7 cassandra.pool WARNING Error attempting to reconnect to 127.0.0.2:9042, scheduling retry in 15.68 seconds: [Errno 111] Tried connecting to [('127.0.0.2', 9042)]. Last error: Connection refused
01:19:41,509 cassandra.pool WARNING Error attempting to reconnect to 127.0.0.3:9042, scheduling retry in 1.92 seconds: [Errno 111] Tried connecting to [('127.0.0.3', 9042)]. Last error: Connection refused
01:19:43,514 cassandra.pool WARNING Error attempting to reconnect to 127.0.0.3:9042, scheduling retry in 4.24 seconds: [Errno 111] Tried connecting to [('127.0.0.3', 9042)]. Last error: Connection refused
01:19:47,825 cassandra.pool WARNING Error attempting to reconnect to 127.0.0.3:9042, scheduling retry in 8.48 seconds: [Errno 111] Tried connecting to [('127.0.0.3', 9042)]. Last error: Connection refused
01:19:49,334 cassandra.pool WARNING Error attempting to reconnect to 127.0.0.1:9042, scheduling retry in 28.16 seconds: [Errno 111] Tried connecting to [('127.0.0.1', 9042)]. Last error: Connection refused
01:19:56,354 cassandra.pool WARNING Error attempting to reconnect to 127.0.0.3:9042, scheduling retry in 16.64 seconds: [Errno 111] Tried connecting to [('127.0.0.3', 9042)]. Last error: Connection refused
01:19:56,755 cassandra.pool WARNING Error attempting to reconnect to 127.0.0.2:9042, scheduling retry in 28.48 seconds: [Errno 111] Tried connecting to [('127.0.0.2', 9042)]. Last error: Connection refused
01:20:17,509 cassandra.pool WARNING Error attempting to reconnect to 127.0.0.1:9042, scheduling retry in 58.88 seconds: [Errno 111] Tried connecting to [('127.0.0.1', 9042)]. Last error: Connection refused
01:20:25,329 cassandra.pool WARNING Error attempting to reconnect to 127.0.0.2:9042, scheduling retry in 57.6 seconds: [Errno 111] Tried connecting to [('127.0.0.2', 9042)]. Last error: Connection refused
01:20:34,276 cassandra.cluster WARNING Host 127.0.0.3:9042 has been marked down
01:20:35,355 cassandra.pool WARNING Error attempting to reconnect to 127.0.0.3:9042, scheduling retry in 2.02 seconds: [Errno 111] Tried connecting to [('127.0.0.3', 9042)]. Last error: Connection refused
01:20:37,460 cassandra.pool WARNING Error attempting to reconnect to 127.0.0.3:9042, scheduling retry in 3.88 seconds: [Errno 111] Tried connecting to [('127.0.0.3', 9042)]. Last error: Connection refused
01:20:41,370 cassandra.pool WARNING Error attempting to reconnect to 127.0.0.3:9042, scheduling retry in 8.72 seconds: [Errno 111] Tried connecting to [('127.0.0.3', 9042)]. Last error: Connection refused
01:20:41,670 cassandra.cluster WARNING Host 127.0.0.1:9042 has been marked down
01:20:41,670 cassandra.cluster WARNING Host 127.0.0.3:9042 has been marked down
01:20:41,672 cassandra.cluster WARNING Host 127.0.0.2:9042 has been marked down
01:20:41,673 cassandra.cluster WARNING [control connection] Error connecting to 127.0.0.2:9042:
Traceback (most recent call last):
  File "cassandra/cluster.py", line 3522, in cassandra.cluster.ControlConnection._reconnect_internal
  File "cassandra/cluster.py", line 3544, in cassandra.cluster.ControlConnection._try_connect
  File "cassandra/cluster.py", line 1620, in cassandra.cluster.Cluster.connection_factory
  File "cassandra/connection.py", line 831, in cassandra.connection.Connection.factory
  File "/users/masix/dtest/src/cassandra-driver/cassandra/io/libevreactor.py", line 267, in __init__
    self._connect_socket()
  File "cassandra/connection.py", line 898, in cassandra.connection.Connection._connect_socket
ConnectionRefusedError: [Errno 111] Tried connecting to [('127.0.0.2', 9042)]. Last error: Connection refused
01:20:42,675 cassandra.pool WARNING Error attempting to reconnect to 127.0.0.1:9042, scheduling retry in 2.02 seconds: [Errno 111] Tried connecting to [('127.0.0.1', 9042)]. Last error: Connection refused
01:20:42,676 cassandra.pool WARNING Error attempting to reconnect to 127.0.0.2:9042, scheduling retry in 1.84 seconds: [Errno 111] Tried connecting to [('127.0.0.2', 9042)]. Last error: Connection refused
01:20:42,776 cassandra.pool WARNING Error attempting to reconnect to 127.0.0.3:9042, scheduling retry in 2.28 seconds: [Errno 111] Tried connecting to [('127.0.0.3', 9042)]. Last error: Connection refused
01:20:44,580 cassandra.pool WARNING Error attempting to reconnect to 127.0.0.2:9042, scheduling retry in 4.28 seconds: [Errno 111] Tried connecting to [('127.0.0.2', 9042)]. Last error: Connection refused
01:20:44,781 cassandra.pool WARNING Error attempting to reconnect to 127.0.0.1:9042, scheduling retry in 3.48 seconds: [Errno 111] Tried connecting to [('127.0.0.1', 9042)]. Last error: Connection refused
01:20:45,82 cassandra.pool WARNING Error attempting to reconnect to 127.0.0.3:9042, scheduling retry in 4.32 seconds: [Errno 111] Tried connecting to [('127.0.0.3', 9042)]. Last error: Connection refused
01:20:48,290 cassandra.pool WARNING Error attempting to reconnect to 127.0.0.1:9042, scheduling retry in 7.36 seconds: [Errno 111] Tried connecting to [('127.0.0.1', 9042)]. Last error: Connection refused
01:20:48,892 cassandra.pool WARNING Error attempting to reconnect to 127.0.0.2:9042, scheduling retry in 9.04 seconds: [Errno 111] Tried connecting to [('127.0.0.2', 9042)]. Last error: Connection refused
01:20:49,402 ccmlib.node WARNING [msx] ccmlib:copy_config_files.py, conf_dir = /users/masix/cassandra/conf
01:20:49,498 ccmlib.node WARNING [msx] ccmlib:node.py, self.name = node1
01:20:49,500 ccmlib.node WARNING [msx] ccmlib:node.py, sstable_preemptive_open_interval_in_mb = 50
01:20:49,500 cassandra.pool WARNING Error attempting to reconnect to 127.0.0.3:9042, scheduling retry in 9.04 seconds: [Errno 111] Tried connecting to [('127.0.0.3', 9042)]. Last error: Connection refused
01:20:49,564 ccmlib.node WARNING [msx] ccmlib:copy_config_files.py, conf_dir = /users/masix/cassandra/conf
01:20:49,649 ccmlib.node WARNING [msx] ccmlib:node.py, self.name = node2
01:20:49,649 ccmlib.node WARNING [msx] ccmlib:node.py, sstable_preemptive_open_interval_in_mb = 50
01:20:49,699 ccmlib.node WARNING [msx] ccmlib:copy_config_files.py, conf_dir = /users/masix/cassandra/conf
01:20:49,784 ccmlib.node WARNING [msx] ccmlib:node.py, self.name = node3
01:20:49,785 ccmlib.node WARNING [msx] ccmlib:node.py, sstable_preemptive_open_interval_in_mb = 50
01:20:50,119 cassandra.pool WARNING Error attempting to reconnect to 127.0.0.3:9042, scheduling retry in 13.92 seconds: [Errno 111] Tried connecting to [('127.0.0.3', 9042)]. Last error: Connection refused
01:20:55,730 cassandra.pool WARNING Error attempting to reconnect to 127.0.0.1:9042, scheduling retry in 16.64 seconds: [Errno 111] Tried connecting to [('127.0.0.1', 9042)]. Last error: Connection refused
01:20:57,935 cassandra.pool WARNING Error attempting to reconnect to 127.0.0.2:9042, scheduling retry in 14.56 seconds: [Errno 111] Tried connecting to [('127.0.0.2', 9042)]. Last error: Connection refused
01:20:58,637 cassandra.pool WARNING Error attempting to reconnect to 127.0.0.3:9042, scheduling retry in 17.92 seconds: [Errno 111] Tried connecting to [('127.0.0.3', 9042)]. Last error: Connection refused
01:21:04,58 cassandra.pool WARNING Error attempting to reconnect to 127.0.0.3:9042, scheduling retry in 28.48 seconds: [Errno 111] Tried connecting to [('127.0.0.3', 9042)]. Last error: Connection refused
01:21:31,840 cassandra.cluster WARNING Host 127.0.0.1:9042 has been marked down
01:21:31,841 cassandra.cluster WARNING Host 127.0.0.1:9042 has been marked down
01:21:32,948 cassandra.pool WARNING Error attempting to reconnect to 127.0.0.1:9042, scheduling retry in 1.86 seconds: [Errno 111] Tried connecting to [('127.0.0.1', 9042)]. Last error: Connection refused
01:21:32,950 cassandra.pool WARNING Error attempting to reconnect to 127.0.0.1:9042, scheduling retry in 1.94 seconds: [Errno 111] Tried connecting to [('127.0.0.1', 9042)]. Last error: Connection refused
01:21:34,855 cassandra.pool WARNING Error attempting to reconnect to 127.0.0.1:9042, scheduling retry in 3.44 seconds: [Errno 111] Tried connecting to [('127.0.0.1', 9042)]. Last error: Connection refused
01:21:34,958 cassandra.pool WARNING Error attempting to reconnect to 127.0.0.1:9042, scheduling retry in 3.4 seconds: [Errno 111] Tried connecting to [('127.0.0.1', 9042)]. Last error: Connection refused
01:21:38,367 cassandra.pool WARNING Error attempting to reconnect to 127.0.0.1:9042, scheduling retry in 6.8 seconds: [Errno 111] Tried connecting to [('127.0.0.1', 9042)]. Last error: Connection refused
01:21:38,369 cassandra.pool WARNING Error attempting to reconnect to 127.0.0.1:9042, scheduling retry in 7.12 seconds: [Errno 111] Tried connecting to [('127.0.0.1', 9042)]. Last error: Connection refused
01:21:38,957 cassandra.cluster WARNING Host 127.0.0.2:9042 has been marked down
01:21:38,958 cassandra.cluster WARNING Host 127.0.0.2:9042 has been marked down
01:21:39,974 cassandra.pool WARNING Error attempting to reconnect to 127.0.0.2:9042, scheduling retry in 2.26 seconds: [Errno 111] Tried connecting to [('127.0.0.2', 9042)]. Last error: Connection refused
01:21:40,75 cassandra.pool WARNING Error attempting to reconnect to 127.0.0.2:9042, scheduling retry in 2.26 seconds: [Errno 111] Tried connecting to [('127.0.0.2', 9042)]. Last error: Connection refused
01:21:41,671 cassandra.cluster WARNING Host 127.0.0.1:9042 has been marked down
01:21:41,672 cassandra.cluster WARNING Host 127.0.0.2:9042 has been marked down
01:21:41,674 cassandra.cluster WARNING [control connection] Error connecting to 127.0.0.2:9042:
Traceback (most recent call last):
  File "cassandra/cluster.py", line 3522, in cassandra.cluster.ControlConnection._reconnect_internal
  File "cassandra/cluster.py", line 3544, in cassandra.cluster.ControlConnection._try_connect
  File "cassandra/cluster.py", line 1620, in cassandra.cluster.Cluster.connection_factory
  File "cassandra/connection.py", line 831, in cassandra.connection.Connection.factory
  File "/users/masix/dtest/src/cassandra-driver/cassandra/io/libevreactor.py", line 267, in __init__
    self._connect_socket()
  File "cassandra/connection.py", line 898, in cassandra.connection.Connection._connect_socket
ConnectionRefusedError: [Errno 111] Tried connecting to [('127.0.0.2', 9042)]. Last error: Connection refused
01:21:42,280 cassandra.pool WARNING Error attempting to reconnect to 127.0.0.2:9042, scheduling retry in 4.08 seconds: [Errno 111] Tried connecting to [('127.0.0.2', 9042)]. Last error: Connection refused
01:21:42,381 cassandra.pool WARNING Error attempting to reconnect to 127.0.0.2:9042, scheduling retry in 3.84 seconds: [Errno 111] Tried connecting to [('127.0.0.2', 9042)]. Last error: Connection refused
01:21:42,677 cassandra.pool WARNING Error attempting to reconnect to 127.0.0.1:9042, scheduling retry in 1.84 seconds: [Errno 111] Tried connecting to [('127.0.0.1', 9042)]. Last error: Connection refused
01:21:42,677 cassandra.pool WARNING Error attempting to reconnect to 127.0.0.2:9042, scheduling retry in 1.74 seconds: [Errno 111] Tried connecting to [('127.0.0.2', 9042)]. Last error: Connection refused
01:21:44,484 cassandra.pool WARNING Error attempting to reconnect to 127.0.0.2:9042, scheduling retry in 4.12 seconds: [Errno 111] Tried connecting to [('127.0.0.2', 9042)]. Last error: Connection refused
01:21:44,584 cassandra.pool WARNING Error attempting to reconnect to 127.0.0.1:9042, scheduling retry in 4.0 seconds: [Errno 111] Tried connecting to [('127.0.0.1', 9042)]. Last error: Connection refused
01:21:45,188 cassandra.pool WARNING Error attempting to reconnect to 127.0.0.1:9042, scheduling retry in 14.88 seconds: [Errno 111] Tried connecting to [('127.0.0.1', 9042)]. Last error: Connection refused
01:21:45,589 cassandra.pool WARNING Error attempting to reconnect to 127.0.0.1:9042, scheduling retry in 18.24 seconds: [Errno 111] Tried connecting to [('127.0.0.1', 9042)]. Last error: Connection refused
01:21:46,292 cassandra.pool WARNING Error attempting to reconnect to 127.0.0.2:9042, scheduling retry in 8.0 seconds: [Errno 111] Tried connecting to [('127.0.0.2', 9042)]. Last error: Connection refused
01:21:46,391 cassandra.pool WARNING Error attempting to reconnect to 127.0.0.2:9042, scheduling retry in 7.28 seconds: [Errno 111] Tried connecting to [('127.0.0.2', 9042)]. Last error: Connection refused
01:21:48,595 cassandra.pool WARNING Error attempting to reconnect to 127.0.0.1:9042, scheduling retry in 9.04 seconds: [Errno 111] Tried connecting to [('127.0.0.1', 9042)]. Last error: Connection refused
01:21:48,695 cassandra.pool WARNING Error attempting to reconnect to 127.0.0.2:9042, scheduling retry in 8.96 seconds: [Errno 111] Tried connecting to [('127.0.0.2', 9042)]. Last error: Connection refused
01:21:53,711 cassandra.pool WARNING Error attempting to reconnect to 127.0.0.2:9042, scheduling retry in 17.44 seconds: [Errno 111] Tried connecting to [('127.0.0.2', 9042)]. Last error: Connection refused
01:21:54,87 cassandra.cluster WARNING Host 127.0.0.3:9042 has been marked down
01:21:54,87 cassandra.cluster WARNING Host 127.0.0.3:9042 has been marked down
01:21:54,312 cassandra.pool WARNING Error attempting to reconnect to 127.0.0.2:9042, scheduling retry in 15.84 seconds: [Errno 111] Tried connecting to [('127.0.0.2', 9042)]. Last error: Connection refused
01:21:55,116 cassandra.pool WARNING Error attempting to reconnect to 127.0.0.3:9042, scheduling retry in 1.86 seconds: [Errno 111] Tried connecting to [('127.0.0.3', 9042)]. Last error: Connection refused
01:21:55,116 cassandra.pool WARNING Error attempting to reconnect to 127.0.0.3:9042, scheduling retry in 1.76 seconds: [Errno 111] Tried connecting to [('127.0.0.3', 9042)]. Last error: Connection refused
01:21:56,919 cassandra.pool WARNING Error attempting to reconnect to 127.0.0.3:9042, scheduling retry in 3.92 seconds: [Errno 111] Tried connecting to [('127.0.0.3', 9042)]. Last error: Connection refused
01:21:57,20 cassandra.pool WARNING Error attempting to reconnect to 127.0.0.3:9042, scheduling retry in 4.32 seconds: [Errno 111] Tried connecting to [('127.0.0.3', 9042)]. Last error: Connection refused
01:21:57,720 cassandra.pool WARNING Error attempting to reconnect to 127.0.0.1:9042, scheduling retry in 13.6 seconds: [Errno 111] Tried connecting to [('127.0.0.1', 9042)]. Last error: Connection refused
01:21:57,720 cassandra.pool WARNING Error attempting to reconnect to 127.0.0.2:9042, scheduling retry in 14.72 seconds: [Errno 111] Tried connecting to [('127.0.0.2', 9042)]. Last error: Connection refused
01:22:00,128 cassandra.pool WARNING Error attempting to reconnect to 127.0.0.1:9042, scheduling retry in 33.6 seconds: [Errno 111] Tried connecting to [('127.0.0.1', 9042)]. Last error: Connection refused
01:22:00,931 cassandra.pool WARNING Error attempting to reconnect to 127.0.0.3:9042, scheduling retry in 7.52 seconds: [Errno 111] Tried connecting to [('127.0.0.3', 9042)]. Last error: Connection refused
01:22:01,432 cassandra.pool WARNING Error attempting to reconnect to 127.0.0.3:9042, scheduling retry in 7.84 seconds: [Errno 111] Tried connecting to [('127.0.0.3', 9042)]. Last error: Connection refused
01:22:03,839 cassandra.pool WARNING Error attempting to reconnect to 127.0.0.1:9042, scheduling retry in 27.84 seconds: [Errno 111] Tried connecting to [('127.0.0.1', 9042)]. Last error: Connection refused
01:22:08,551 cassandra.pool WARNING Error attempting to reconnect to 127.0.0.3:9042, scheduling retry in 14.08 seconds: [Errno 111] Tried connecting to [('127.0.0.3', 9042)]. Last error: Connection refused
01:22:09,353 cassandra.pool WARNING Error attempting to reconnect to 127.0.0.3:9042, scheduling retry in 16.8 seconds: [Errno 111] Tried connecting to [('127.0.0.3', 9042)]. Last error: Connection refused
01:22:10,156 cassandra.pool WARNING Error attempting to reconnect to 127.0.0.2:9042, scheduling retry in 28.16 seconds: [Errno 111] Tried connecting to [('127.0.0.2', 9042)]. Last error: Connection refused
01:22:11,162 cassandra.pool WARNING Error attempting to reconnect to 127.0.0.2:9042, scheduling retry in 28.48 seconds: [Errno 111] Tried connecting to [('127.0.0.2', 9042)]. Last error: Connection refused
01:22:11,365 cassandra.pool WARNING Error attempting to reconnect to 127.0.0.1:9042, scheduling retry in 27.84 seconds: [Errno 111] Tried connecting to [('127.0.0.1', 9042)]. Last error: Connection refused
01:22:11,672 cassandra.cluster WARNING Host 127.0.0.3:9042 has been marked down
01:22:11,674 cassandra.cluster WARNING [control connection] Error connecting to 127.0.0.3:9042:
Traceback (most recent call last):
  File "cassandra/cluster.py", line 3522, in cassandra.cluster.ControlConnection._reconnect_internal
  File "cassandra/cluster.py", line 3544, in cassandra.cluster.ControlConnection._try_connect
  File "cassandra/cluster.py", line 1620, in cassandra.cluster.Cluster.connection_factory
  File "cassandra/connection.py", line 831, in cassandra.connection.Connection.factory
  File "/users/masix/dtest/src/cassandra-driver/cassandra/io/libevreactor.py", line 267, in __init__
    self._connect_socket()
  File "cassandra/connection.py", line 898, in cassandra.connection.Connection._connect_socket
ConnectionRefusedError: [Errno 111] Tried connecting to [('127.0.0.3', 9042)]. Last error: Connection refused
01:22:12,466 cassandra.pool WARNING Error attempting to reconnect to 127.0.0.2:9042, scheduling retry in 28.8 seconds: [Errno 111] Tried connecting to [('127.0.0.2', 9042)]. Last error: Connection refused
01:22:12,767 cassandra.pool WARNING Error attempting to reconnect to 127.0.0.3:9042, scheduling retry in 1.86 seconds: [Errno 111] Tried connecting to [('127.0.0.3', 9042)]. Last error: Connection refused
01:22:14,671 cassandra.pool WARNING Error attempting to reconnect to 127.0.0.3:9042, scheduling retry in 3.56 seconds: [Errno 111] Tried connecting to [('127.0.0.3', 9042)]. Last error: Connection refused
01:22:18,281 cassandra.pool WARNING Error attempting to reconnect to 127.0.0.3:9042, scheduling retry in 8.96 seconds: [Errno 111] Tried connecting to [('127.0.0.3', 9042)]. Last error: Connection refused
01:22:22,693 cassandra.pool WARNING Error attempting to reconnect to 127.0.0.3:9042, scheduling retry in 32.64 seconds: [Errno 111] Tried connecting to [('127.0.0.3', 9042)]. Last error: Connection refused
01:22:26,202 cassandra.pool WARNING Error attempting to reconnect to 127.0.0.3:9042, scheduling retry in 31.04 seconds: [Errno 111] Tried connecting to [('127.0.0.3', 9042)]. Last error: Connection refused
01:22:27,304 cassandra.pool WARNING Error attempting to reconnect to 127.0.0.3:9042, scheduling retry in 15.04 seconds: [Errno 111] Tried connecting to [('127.0.0.3', 9042)]. Last error: Connection refused
01:22:37,332 cassandra.cluster WARNING [control connection] Error connecting to 127.0.0.1:9042:
Traceback (most recent call last):
  File "cassandra/cluster.py", line 3522, in cassandra.cluster.ControlConnection._reconnect_internal
  File "cassandra/cluster.py", line 3544, in cassandra.cluster.ControlConnection._try_connect
  File "cassandra/cluster.py", line 1620, in cassandra.cluster.Cluster.connection_factory
  File "cassandra/connection.py", line 831, in cassandra.connection.Connection.factory
  File "/users/masix/dtest/src/cassandra-driver/cassandra/io/libevreactor.py", line 267, in __init__
    self._connect_socket()
  File "cassandra/connection.py", line 898, in cassandra.connection.Connection._connect_socket
ConnectionRefusedError: [Errno 111] Tried connecting to [('127.0.0.1', 9042)]. Last error: Connection refused
01:22:38,110 cassandra.cluster WARNING [control connection] Error connecting to 127.0.0.1:9042:
Traceback (most recent call last):
  File "cassandra/cluster.py", line 3522, in cassandra.cluster.ControlConnection._reconnect_internal
  File "cassandra/cluster.py", line 3544, in cassandra.cluster.ControlConnection._try_connect
  File "cassandra/cluster.py", line 1620, in cassandra.cluster.Cluster.connection_factory
  File "cassandra/connection.py", line 831, in cassandra.connection.Connection.factory
  File "/users/masix/dtest/src/cassandra-driver/cassandra/io/libevreactor.py", line 267, in __init__
    self._connect_socket()
  File "cassandra/connection.py", line 898, in cassandra.connection.Connection._connect_socket
ConnectionRefusedError: [Errno 111] Tried connecting to [('127.0.0.1', 9042)]. Last error: Connection refused
01:22:39,136 cassandra.cluster WARNING [control connection] Error connecting to 127.0.0.1:9042:
Traceback (most recent call last):
  File "cassandra/cluster.py", line 3522, in cassandra.cluster.ControlConnection._reconnect_internal
  File "cassandra/cluster.py", line 3544, in cassandra.cluster.ControlConnection._try_connect
  File "cassandra/cluster.py", line 1620, in cassandra.cluster.Cluster.connection_factory
  File "cassandra/connection.py", line 831, in cassandra.connection.Connection.factory
  File "/users/masix/dtest/src/cassandra-driver/cassandra/io/libevreactor.py", line 267, in __init__
    self._connect_socket()
  File "cassandra/connection.py", line 898, in cassandra.connection.Connection._connect_socket
ConnectionRefusedError: [Errno 111] Tried connecting to [('127.0.0.1', 9042)]. Last error: Connection refused
01:22:39,235 cassandra.pool WARNING Error attempting to reconnect to 127.0.0.1:9042, scheduling retry in 69.76 seconds: [Errno 111] Tried connecting to [('127.0.0.1', 9042)]. Last error: Connection refused
01:22:56,49 cassandra.cluster WARNING [control connection] Error connecting to 127.0.0.1:9042:
Traceback (most recent call last):
  File "cassandra/cluster.py", line 3522, in cassandra.cluster.ControlConnection._reconnect_internal
  File "cassandra/cluster.py", line 3544, in cassandra.cluster.ControlConnection._try_connect
  File "cassandra/cluster.py", line 1620, in cassandra.cluster.Cluster.connection_factory
  File "cassandra/connection.py", line 831, in cassandra.connection.Connection.factory
  File "/users/masix/dtest/src/cassandra-driver/cassandra/io/libevreactor.py", line 267, in __init__
    self._connect_socket()
  File "cassandra/connection.py", line 898, in cassandra.connection.Connection._connect_socket
ConnectionRefusedError: [Errno 111] Tried connecting to [('127.0.0.1', 9042)]. Last error: Connection refused
01:22:56,51 cassandra.cluster WARNING [control connection] Error connecting to 127.0.0.2:9042:
Traceback (most recent call last):
  File "cassandra/cluster.py", line 3522, in cassandra.cluster.ControlConnection._reconnect_internal
  File "cassandra/cluster.py", line 3544, in cassandra.cluster.ControlConnection._try_connect
  File "cassandra/cluster.py", line 1620, in cassandra.cluster.Cluster.connection_factory
  File "cassandra/connection.py", line 831, in cassandra.connection.Connection.factory
  File "/users/masix/dtest/src/cassandra-driver/cassandra/io/libevreactor.py", line 267, in __init__
    self._connect_socket()
  File "cassandra/connection.py", line 898, in cassandra.connection.Connection._connect_socket
ConnectionRefusedError: [Errno 111] Tried connecting to [('127.0.0.2', 9042)]. Last error: Connection refused
01:22:57,85 cassandra.cluster WARNING [control connection] Error connecting to 127.0.0.2:9042:
Traceback (most recent call last):
  File "cassandra/cluster.py", line 3522, in cassandra.cluster.ControlConnection._reconnect_internal
  File "cassandra/cluster.py", line 3544, in cassandra.cluster.ControlConnection._try_connect
  File "cassandra/cluster.py", line 1620, in cassandra.cluster.Cluster.connection_factory
  File "cassandra/connection.py", line 831, in cassandra.connection.Connection.factory
  File "/users/masix/dtest/src/cassandra-driver/cassandra/io/libevreactor.py", line 267, in __init__
    self._connect_socket()
  File "cassandra/connection.py", line 898, in cassandra.connection.Connection._connect_socket
ConnectionRefusedError: [Errno 111] Tried connecting to [('127.0.0.2', 9042)]. Last error: Connection refused
01:22:57,87 cassandra.cluster WARNING [control connection] Error connecting to 127.0.0.1:9042:
Traceback (most recent call last):
  File "cassandra/cluster.py", line 3522, in cassandra.cluster.ControlConnection._reconnect_internal
  File "cassandra/cluster.py", line 3544, in cassandra.cluster.ControlConnection._try_connect
  File "cassandra/cluster.py", line 1620, in cassandra.cluster.Cluster.connection_factory
  File "cassandra/connection.py", line 831, in cassandra.connection.Connection.factory
  File "/users/masix/dtest/src/cassandra-driver/cassandra/io/libevreactor.py", line 267, in __init__
    self._connect_socket()
  File "cassandra/connection.py", line 898, in cassandra.connection.Connection._connect_socket
ConnectionRefusedError: [Errno 111] Tried connecting to [('127.0.0.1', 9042)]. Last error: Connection refused
01:22:57,285 cassandra.pool WARNING Error attempting to reconnect to 127.0.0.3:9042, scheduling retry in 57.6 seconds: [Errno 111] Tried connecting to [('127.0.0.3', 9042)]. Last error: Connection refused
01:22:59,90 cassandra.cluster WARNING [control connection] Error connecting to 127.0.0.1:9042:
Traceback (most recent call last):
  File "cassandra/cluster.py", line 3522, in cassandra.cluster.ControlConnection._reconnect_internal
  File "cassandra/cluster.py", line 3544, in cassandra.cluster.ControlConnection._try_connect
  File "cassandra/cluster.py", line 1620, in cassandra.cluster.Cluster.connection_factory
  File "cassandra/connection.py", line 831, in cassandra.connection.Connection.factory
  File "/users/masix/dtest/src/cassandra-driver/cassandra/io/libevreactor.py", line 267, in __init__
    self._connect_socket()
  File "cassandra/connection.py", line 898, in cassandra.connection.Connection._connect_socket
ConnectionRefusedError: [Errno 111] Tried connecting to [('127.0.0.1', 9042)]. Last error: Connection refused
01:22:59,92 cassandra.cluster WARNING [control connection] Error connecting to 127.0.0.2:9042:
Traceback (most recent call last):
  File "cassandra/cluster.py", line 3522, in cassandra.cluster.ControlConnection._reconnect_internal
  File "cassandra/cluster.py", line 3544, in cassandra.cluster.ControlConnection._try_connect
  File "cassandra/cluster.py", line 1620, in cassandra.cluster.Cluster.connection_factory
  File "cassandra/connection.py", line 831, in cassandra.connection.Connection.factory
  File "/users/masix/dtest/src/cassandra-driver/cassandra/io/libevreactor.py", line 267, in __init__
    self._connect_socket()
  File "cassandra/connection.py", line 898, in cassandra.connection.Connection._connect_socket
ConnectionRefusedError: [Errno 111] Tried connecting to [('127.0.0.2', 9042)]. Last error: Connection refused
01:23:03,101 cassandra.cluster WARNING [control connection] Error connecting to 127.0.0.2:9042:
Traceback (most recent call last):
  File "cassandra/cluster.py", line 3522, in cassandra.cluster.ControlConnection._reconnect_internal
  File "cassandra/cluster.py", line 3544, in cassandra.cluster.ControlConnection._try_connect
  File "cassandra/cluster.py", line 1620, in cassandra.cluster.Cluster.connection_factory
  File "cassandra/connection.py", line 831, in cassandra.connection.Connection.factory
  File "/users/masix/dtest/src/cassandra-driver/cassandra/io/libevreactor.py", line 267, in __init__
    self._connect_socket()
  File "cassandra/connection.py", line 898, in cassandra.connection.Connection._connect_socket
ConnectionRefusedError: [Errno 111] Tried connecting to [('127.0.0.2', 9042)]. Last error: Connection refused
01:23:03,102 cassandra.cluster WARNING [control connection] Error connecting to 127.0.0.1:9042:
Traceback (most recent call last):
  File "cassandra/cluster.py", line 3522, in cassandra.cluster.ControlConnection._reconnect_internal
  File "cassandra/cluster.py", line 3544, in cassandra.cluster.ControlConnection._try_connect
  File "cassandra/cluster.py", line 1620, in cassandra.cluster.Cluster.connection_factory
  File "cassandra/connection.py", line 831, in cassandra.connection.Connection.factory
  File "/users/masix/dtest/src/cassandra-driver/cassandra/io/libevreactor.py", line 267, in __init__
    self._connect_socket()
  File "cassandra/connection.py", line 898, in cassandra.connection.Connection._connect_socket
ConnectionRefusedError: [Errno 111] Tried connecting to [('127.0.0.1', 9042)]. Last error: Connection refused
01:23:04,405 cassandra.cluster WARNING Host 127.0.0.1:9042 has been marked down
01:23:04,406 cassandra.cluster WARNING Host 127.0.0.3:9042 has been marked down
01:23:04,407 cassandra.cluster WARNING Host 127.0.0.2:9042 has been marked down
01:23:04,410 cassandra.cluster WARNING [control connection] Error connecting to 127.0.0.2:9042:
Traceback (most recent call last):
  File "cassandra/cluster.py", line 3522, in cassandra.cluster.ControlConnection._reconnect_internal
  File "cassandra/cluster.py", line 3544, in cassandra.cluster.ControlConnection._try_connect
  File "cassandra/cluster.py", line 1620, in cassandra.cluster.Cluster.connection_factory
  File "cassandra/connection.py", line 831, in cassandra.connection.Connection.factory
  File "/users/masix/dtest/src/cassandra-driver/cassandra/io/libevreactor.py", line 267, in __init__
    self._connect_socket()
  File "cassandra/connection.py", line 898, in cassandra.connection.Connection._connect_socket
ConnectionRefusedError: [Errno 111] Tried connecting to [('127.0.0.2', 9042)]. Last error: Connection refused
01:23:05,411 cassandra.pool WARNING Error attempting to reconnect to 127.0.0.3:9042, scheduling retry in 2.26 seconds: [Errno 111] Tried connecting to [('127.0.0.3', 9042)]. Last error: Connection refused
01:23:05,512 cassandra.pool WARNING Error attempting to reconnect to 127.0.0.2:9042, scheduling retry in 1.9 seconds: [Errno 111] Tried connecting to [('127.0.0.2', 9042)]. Last error: Connection refused
01:23:05,512 cassandra.pool WARNING Error attempting to reconnect to 127.0.0.1:9042, scheduling retry in 2.08 seconds: [Errno 111] Tried connecting to [('127.0.0.1', 9042)]. Last error: Connection refused
01:23:07,416 cassandra.pool WARNING Error attempting to reconnect to 127.0.0.2:9042, scheduling retry in 3.88 seconds: [Errno 111] Tried connecting to [('127.0.0.2', 9042)]. Last error: Connection refused
01:23:07,617 cassandra.pool WARNING Error attempting to reconnect to 127.0.0.1:9042, scheduling retry in 4.52 seconds: [Errno 111] Tried connecting to [('127.0.0.1', 9042)]. Last error: Connection refused
01:23:07,718 cassandra.pool WARNING Error attempting to reconnect to 127.0.0.3:9042, scheduling retry in 4.08 seconds: [Errno 111] Tried connecting to [('127.0.0.3', 9042)]. Last error: Connection refused
01:23:08,114 cassandra.cluster WARNING [control connection] Error connecting to 127.0.0.2:9042:
Traceback (most recent call last):
  File "cassandra/cluster.py", line 3522, in cassandra.cluster.ControlConnection._reconnect_internal
  File "cassandra/cluster.py", line 3544, in cassandra.cluster.ControlConnection._try_connect
  File "cassandra/cluster.py", line 1620, in cassandra.cluster.Cluster.connection_factory
  File "cassandra/connection.py", line 831, in cassandra.connection.Connection.factory
  File "/users/masix/dtest/src/cassandra-driver/cassandra/io/libevreactor.py", line 267, in __init__
    self._connect_socket()
  File "cassandra/connection.py", line 898, in cassandra.connection.Connection._connect_socket
ConnectionRefusedError: [Errno 111] Tried connecting to [('127.0.0.2', 9042)]. Last error: Connection refused
01:23:08,116 cassandra.cluster WARNING [control connection] Error connecting to 127.0.0.3:9042:
Traceback (most recent call last):
  File "cassandra/cluster.py", line 3522, in cassandra.cluster.ControlConnection._reconnect_internal
  File "cassandra/cluster.py", line 3544, in cassandra.cluster.ControlConnection._try_connect
  File "cassandra/cluster.py", line 1620, in cassandra.cluster.Cluster.connection_factory
  File "cassandra/connection.py", line 831, in cassandra.connection.Connection.factory
  File "/users/masix/dtest/src/cassandra-driver/cassandra/io/libevreactor.py", line 267, in __init__
    self._connect_socket()
  File "cassandra/connection.py", line 898, in cassandra.connection.Connection._connect_socket
ConnectionRefusedError: [Errno 111] Tried connecting to [('127.0.0.3', 9042)]. Last error: Connection refused
01:23:08,117 cassandra.cluster WARNING [control connection] Error connecting to 127.0.0.1:9042:
Traceback (most recent call last):
  File "cassandra/cluster.py", line 3522, in cassandra.cluster.ControlConnection._reconnect_internal
  File "cassandra/cluster.py", line 3544, in cassandra.cluster.ControlConnection._try_connect
  File "cassandra/cluster.py", line 1620, in cassandra.cluster.Cluster.connection_factory
  File "cassandra/connection.py", line 831, in cassandra.connection.Connection.factory
  File "/users/masix/dtest/src/cassandra-driver/cassandra/io/libevreactor.py", line 267, in __init__
    self._connect_socket()
  File "cassandra/connection.py", line 898, in cassandra.connection.Connection._connect_socket
ConnectionRefusedError: [Errno 111] Tried connecting to [('127.0.0.1', 9042)]. Last error: Connection refused
01:23:09,218 cassandra.cluster WARNING [control connection] Error connecting to 127.0.0.3:9042:
Traceback (most recent call last):
  File "cassandra/cluster.py", line 3522, in cassandra.cluster.ControlConnection._reconnect_internal
  File "cassandra/cluster.py", line 3544, in cassandra.cluster.ControlConnection._try_connect
  File "cassandra/cluster.py", line 1620, in cassandra.cluster.Cluster.connection_factory
  File "cassandra/connection.py", line 831, in cassandra.connection.Connection.factory
  File "/users/masix/dtest/src/cassandra-driver/cassandra/io/libevreactor.py", line 267, in __init__
    self._connect_socket()
  File "cassandra/connection.py", line 898, in cassandra.connection.Connection._connect_socket
ConnectionRefusedError: [Errno 111] Tried connecting to [('127.0.0.3', 9042)]. Last error: Connection refused
01:23:09,219 cassandra.cluster WARNING [control connection] Error connecting to 127.0.0.1:9042:
Traceback (most recent call last):
  File "cassandra/cluster.py", line 3522, in cassandra.cluster.ControlConnection._reconnect_internal
  File "cassandra/cluster.py", line 3544, in cassandra.cluster.ControlConnection._try_connect
  File "cassandra/cluster.py", line 1620, in cassandra.cluster.Cluster.connection_factory
  File "cassandra/connection.py", line 831, in cassandra.connection.Connection.factory
  File "/users/masix/dtest/src/cassandra-driver/cassandra/io/libevreactor.py", line 267, in __init__
    self._connect_socket()
  File "cassandra/connection.py", line 898, in cassandra.connection.Connection._connect_socket
ConnectionRefusedError: [Errno 111] Tried connecting to [('127.0.0.1', 9042)]. Last error: Connection refused
01:23:09,220 cassandra.cluster WARNING [control connection] Error connecting to 127.0.0.2:9042:
Traceback (most recent call last):
  File "cassandra/cluster.py", line 3522, in cassandra.cluster.ControlConnection._reconnect_internal
  File "cassandra/cluster.py", line 3544, in cassandra.cluster.ControlConnection._try_connect
  File "cassandra/cluster.py", line 1620, in cassandra.cluster.Cluster.connection_factory
  File "cassandra/connection.py", line 831, in cassandra.connection.Connection.factory
  File "/users/masix/dtest/src/cassandra-driver/cassandra/io/libevreactor.py", line 267, in __init__
    self._connect_socket()
  File "cassandra/connection.py", line 898, in cassandra.connection.Connection._connect_socket
ConnectionRefusedError: [Errno 111] Tried connecting to [('127.0.0.2', 9042)]. Last error: Connection refused
01:23:10,722 cassandra.cluster WARNING [control connection] Error connecting to 127.0.0.1:9042:
Traceback (most recent call last):
  File "cassandra/cluster.py", line 3522, in cassandra.cluster.ControlConnection._reconnect_internal
  File "cassandra/cluster.py", line 3544, in cassandra.cluster.ControlConnection._try_connect
  File "cassandra/cluster.py", line 1620, in cassandra.cluster.Cluster.connection_factory
  File "cassandra/connection.py", line 831, in cassandra.connection.Connection.factory
  File "/users/masix/dtest/src/cassandra-driver/cassandra/io/libevreactor.py", line 267, in __init__
    self._connect_socket()
  File "cassandra/connection.py", line 898, in cassandra.connection.Connection._connect_socket
ConnectionRefusedError: [Errno 111] Tried connecting to [('127.0.0.1', 9042)]. Last error: Connection refused
01:23:10,723 cassandra.cluster WARNING [control connection] Error connecting to 127.0.0.2:9042:
Traceback (most recent call last):
  File "cassandra/cluster.py", line 3522, in cassandra.cluster.ControlConnection._reconnect_internal
  File "cassandra/cluster.py", line 3544, in cassandra.cluster.ControlConnection._try_connect
  File "cassandra/cluster.py", line 1620, in cassandra.cluster.Cluster.connection_factory
  File "cassandra/connection.py", line 831, in cassandra.connection.Connection.factory
  File "/users/masix/dtest/src/cassandra-driver/cassandra/io/libevreactor.py", line 267, in __init__
    self._connect_socket()
  File "cassandra/connection.py", line 898, in cassandra.connection.Connection._connect_socket
ConnectionRefusedError: [Errno 111] Tried connecting to [('127.0.0.2', 9042)]. Last error: Connection refused
01:23:11,22 cassandra.cluster WARNING [control connection] Error connecting to 127.0.0.1:9042:
Traceback (most recent call last):
  File "cassandra/cluster.py", line 3522, in cassandra.cluster.ControlConnection._reconnect_internal
  File "cassandra/cluster.py", line 3544, in cassandra.cluster.ControlConnection._try_connect
  File "cassandra/cluster.py", line 1620, in cassandra.cluster.Cluster.connection_factory
  File "cassandra/connection.py", line 831, in cassandra.connection.Connection.factory
  File "/users/masix/dtest/src/cassandra-driver/cassandra/io/libevreactor.py", line 267, in __init__
    self._connect_socket()
  File "cassandra/connection.py", line 898, in cassandra.connection.Connection._connect_socket
ConnectionRefusedError: [Errno 111] Tried connecting to [('127.0.0.1', 9042)]. Last error: Connection refused
01:23:11,24 cassandra.cluster WARNING [control connection] Error connecting to 127.0.0.2:9042:
Traceback (most recent call last):
  File "cassandra/cluster.py", line 3522, in cassandra.cluster.ControlConnection._reconnect_internal
  File "cassandra/cluster.py", line 3544, in cassandra.cluster.ControlConnection._try_connect
  File "cassandra/cluster.py", line 1620, in cassandra.cluster.Cluster.connection_factory
  File "cassandra/connection.py", line 831, in cassandra.connection.Connection.factory
  File "/users/masix/dtest/src/cassandra-driver/cassandra/io/libevreactor.py", line 267, in __init__
    self._connect_socket()
  File "cassandra/connection.py", line 898, in cassandra.connection.Connection._connect_socket
ConnectionRefusedError: [Errno 111] Tried connecting to [('127.0.0.2', 9042)]. Last error: Connection refused
01:23:11,25 cassandra.cluster WARNING [control connection] Error connecting to 127.0.0.3:9042:
Traceback (most recent call last):
  File "cassandra/cluster.py", line 3522, in cassandra.cluster.ControlConnection._reconnect_internal
  File "cassandra/cluster.py", line 3544, in cassandra.cluster.ControlConnection._try_connect
  File "cassandra/cluster.py", line 1620, in cassandra.cluster.Cluster.connection_factory
  File "cassandra/connection.py", line 831, in cassandra.connection.Connection.factory
  File "/users/masix/dtest/src/cassandra-driver/cassandra/io/libevreactor.py", line 267, in __init__
    self._connect_socket()
  File "cassandra/connection.py", line 898, in cassandra.connection.Connection._connect_socket
ConnectionRefusedError: [Errno 111] Tried connecting to [('127.0.0.3', 9042)]. Last error: Connection refused
01:23:11,327 cassandra.pool WARNING Error attempting to reconnect to 127.0.0.2:9042, scheduling retry in 8.48 seconds: [Errno 111] Tried connecting to [('127.0.0.2', 9042)]. Last error: Connection refused
01:23:11,673 cassandra.cluster WARNING Host 127.0.0.2:9042 has been marked down
01:23:11,673 cassandra.cluster WARNING Host 127.0.0.3:9042 has been marked down
01:23:11,675 cassandra.cluster WARNING [control connection] Error connecting to 127.0.0.3:9042:
Traceback (most recent call last):
  File "cassandra/cluster.py", line 3522, in cassandra.cluster.ControlConnection._reconnect_internal
  File "cassandra/cluster.py", line 3544, in cassandra.cluster.ControlConnection._try_connect
  File "cassandra/cluster.py", line 1620, in cassandra.cluster.Cluster.connection_factory
  File "cassandra/connection.py", line 831, in cassandra.connection.Connection.factory
  File "/users/masix/dtest/src/cassandra-driver/cassandra/io/libevreactor.py", line 267, in __init__
    self._connect_socket()
  File "cassandra/connection.py", line 898, in cassandra.connection.Connection._connect_socket
ConnectionRefusedError: [Errno 111] Tried connecting to [('127.0.0.3', 9042)]. Last error: Connection refused
01:23:11,829 cassandra.pool WARNING Error attempting to reconnect to 127.0.0.3:9042, scheduling retry in 7.36 seconds: [Errno 111] Tried connecting to [('127.0.0.3', 9042)]. Last error: Connection refused
01:23:12,136 ccmlib.node WARNING [msx] ccmlib:copy_config_files.py, conf_dir = /users/masix/cassandra/conf
01:23:12,230 ccmlib.node WARNING [msx] ccmlib:node.py, self.name = node1
01:23:12,231 ccmlib.node WARNING [msx] ccmlib:node.py, sstable_preemptive_open_interval_in_mb = 50
01:23:12,236 cassandra.pool WARNING Error attempting to reconnect to 127.0.0.1:9042, scheduling retry in 6.96 seconds: [Errno 111] Tried connecting to [('127.0.0.1', 9042)]. Last error: Connection refused
01:23:12,284 ccmlib.node WARNING [msx] ccmlib:copy_config_files.py, conf_dir = /users/masix/cassandra/conf
01:23:12,372 ccmlib.node WARNING [msx] ccmlib:node.py, self.name = node2
01:23:12,372 ccmlib.node WARNING [msx] ccmlib:node.py, sstable_preemptive_open_interval_in_mb = 50
01:23:12,423 ccmlib.node WARNING [msx] ccmlib:copy_config_files.py, conf_dir = /users/masix/cassandra/conf
01:23:12,508 ccmlib.node WARNING [msx] ccmlib:node.py, self.name = node3
01:23:12,508 ccmlib.node WARNING [msx] ccmlib:node.py, sstable_preemptive_open_interval_in_mb = 50
01:23:12,752 cassandra.pool WARNING Error attempting to reconnect to 127.0.0.2:9042, scheduling retry in 2.26 seconds: [Errno 111] Tried connecting to [('127.0.0.2', 9042)]. Last error: Connection refused
01:23:12,853 cassandra.pool WARNING Error attempting to reconnect to 127.0.0.3:9042, scheduling retry in 2.18 seconds: [Errno 111] Tried connecting to [('127.0.0.3', 9042)]. Last error: Connection refused
01:23:15,60 cassandra.pool WARNING Error attempting to reconnect to 127.0.0.2:9042, scheduling retry in 3.76 seconds: [Errno 111] Tried connecting to [('127.0.0.2', 9042)]. Last error: Connection refused
01:23:15,60 cassandra.pool WARNING Error attempting to reconnect to 127.0.0.3:9042, scheduling retry in 3.68 seconds: [Errno 111] Tried connecting to [('127.0.0.3', 9042)]. Last error: Connection refused
01:23:15,456 cassandra.cluster WARNING [control connection] Error connecting to 127.0.0.2:9042:
Traceback (most recent call last):
  File "cassandra/cluster.py", line 3522, in cassandra.cluster.ControlConnection._reconnect_internal
  File "cassandra/cluster.py", line 3544, in cassandra.cluster.ControlConnection._try_connect
  File "cassandra/cluster.py", line 1620, in cassandra.cluster.Cluster.connection_factory
  File "cassandra/connection.py", line 831, in cassandra.connection.Connection.factory
  File "/users/masix/dtest/src/cassandra-driver/cassandra/io/libevreactor.py", line 267, in __init__
    self._connect_socket()
  File "cassandra/connection.py", line 898, in cassandra.connection.Connection._connect_socket
ConnectionRefusedError: [Errno 111] Tried connecting to [('127.0.0.2', 9042)]. Last error: Connection refused
01:23:15,457 cassandra.cluster WARNING [control connection] Error connecting to 127.0.0.3:9042:
Traceback (most recent call last):
  File "cassandra/cluster.py", line 3522, in cassandra.cluster.ControlConnection._reconnect_internal
  File "cassandra/cluster.py", line 3544, in cassandra.cluster.ControlConnection._try_connect
  File "cassandra/cluster.py", line 1620, in cassandra.cluster.Cluster.connection_factory
  File "cassandra/connection.py", line 831, in cassandra.connection.Connection.factory
  File "/users/masix/dtest/src/cassandra-driver/cassandra/io/libevreactor.py", line 267, in __init__
    self._connect_socket()
  File "cassandra/connection.py", line 898, in cassandra.connection.Connection._connect_socket
ConnectionRefusedError: [Errno 111] Tried connecting to [('127.0.0.3', 9042)]. Last error: Connection refused
01:23:15,457 cassandra.cluster WARNING [control connection] Error connecting to 127.0.0.1:9042:
Traceback (most recent call last):
  File "cassandra/cluster.py", line 3522, in cassandra.cluster.ControlConnection._reconnect_internal
  File "cassandra/cluster.py", line 3544, in cassandra.cluster.ControlConnection._try_connect
  File "cassandra/cluster.py", line 1620, in cassandra.cluster.Cluster.connection_factory
  File "cassandra/connection.py", line 831, in cassandra.connection.Connection.factory
  File "/users/masix/dtest/src/cassandra-driver/cassandra/io/libevreactor.py", line 267, in __init__
    self._connect_socket()
  File "cassandra/connection.py", line 898, in cassandra.connection.Connection._connect_socket
ConnectionRefusedError: [Errno 111] Tried connecting to [('127.0.0.1', 9042)]. Last error: Connection refused
01:23:18,767 cassandra.pool WARNING Error attempting to reconnect to 127.0.0.3:9042, scheduling retry in 7.76 seconds: [Errno 111] Tried connecting to [('127.0.0.3', 9042)]. Last error: Connection refused
01:23:18,868 cassandra.pool WARNING Error attempting to reconnect to 127.0.0.2:9042, scheduling retry in 8.88 seconds: [Errno 111] Tried connecting to [('127.0.0.2', 9042)]. Last error: Connection refused
01:23:19,270 cassandra.pool WARNING Error attempting to reconnect to 127.0.0.1:9042, scheduling retry in 17.76 seconds: [Errno 111] Tried connecting to [('127.0.0.1', 9042)]. Last error: Connection refused
01:23:19,270 cassandra.pool WARNING Error attempting to reconnect to 127.0.0.3:9042, scheduling retry in 14.72 seconds: [Errno 111] Tried connecting to [('127.0.0.3', 9042)]. Last error: Connection refused
01:23:19,871 cassandra.pool WARNING Error attempting to reconnect to 127.0.0.2:9042, scheduling retry in 16.0 seconds: [Errno 111] Tried connecting to [('127.0.0.2', 9042)]. Last error: Connection refused
01:23:24,179 cassandra.cluster WARNING [control connection] Error connecting to 127.0.0.3:9042:
Traceback (most recent call last):
  File "cassandra/cluster.py", line 3522, in cassandra.cluster.ControlConnection._reconnect_internal
  File "cassandra/cluster.py", line 3544, in cassandra.cluster.ControlConnection._try_connect
  File "cassandra/cluster.py", line 1620, in cassandra.cluster.Cluster.connection_factory
  File "cassandra/connection.py", line 831, in cassandra.connection.Connection.factory
  File "/users/masix/dtest/src/cassandra-driver/cassandra/io/libevreactor.py", line 267, in __init__
    self._connect_socket()
  File "cassandra/connection.py", line 898, in cassandra.connection.Connection._connect_socket
ConnectionRefusedError: [Errno 111] Tried connecting to [('127.0.0.3', 9042)]. Last error: Connection refused
01:23:26,50 cassandra.cluster WARNING [control connection] Error connecting to 127.0.0.2:9042:
Traceback (most recent call last):
  File "cassandra/cluster.py", line 3522, in cassandra.cluster.ControlConnection._reconnect_internal
  File "cassandra/cluster.py", line 3544, in cassandra.cluster.ControlConnection._try_connect
  File "cassandra/cluster.py", line 1620, in cassandra.cluster.Cluster.connection_factory
  File "cassandra/connection.py", line 831, in cassandra.connection.Connection.factory
  File "/users/masix/dtest/src/cassandra-driver/cassandra/io/libevreactor.py", line 267, in __init__
    self._connect_socket()
  File "cassandra/connection.py", line 898, in cassandra.connection.Connection._connect_socket
ConnectionRefusedError: [Errno 111] Tried connecting to [('127.0.0.2', 9042)]. Last error: Connection refused
01:23:26,590 cassandra.pool WARNING Error attempting to reconnect to 127.0.0.3:9042, scheduling retry in 15.68 seconds: [Errno 111] Tried connecting to [('127.0.0.3', 9042)]. Last error: Connection refused
01:23:27,794 cassandra.pool WARNING Error attempting to reconnect to 127.0.0.2:9042, scheduling retry in 15.04 seconds: [Errno 111] Tried connecting to [('127.0.0.2', 9042)]. Last error: Connection refused
01:23:55,659 cassandra.cluster WARNING Host 127.0.0.1:9042 has been marked down
01:23:55,660 cassandra.cluster WARNING Host 127.0.0.1:9042 has been marked down
01:23:55,689 cassandra.cluster WARNING Host 127.0.0.1:9042 has been marked down
01:23:56,50 cassandra.cluster WARNING [control connection] Error connecting to 127.0.0.1:9042:
Traceback (most recent call last):
  File "cassandra/cluster.py", line 3522, in cassandra.cluster.ControlConnection._reconnect_internal
  File "cassandra/cluster.py", line 3544, in cassandra.cluster.ControlConnection._try_connect
  File "cassandra/cluster.py", line 1620, in cassandra.cluster.Cluster.connection_factory
  File "cassandra/connection.py", line 831, in cassandra.connection.Connection.factory
  File "/users/masix/dtest/src/cassandra-driver/cassandra/io/libevreactor.py", line 267, in __init__
    self._connect_socket()
  File "cassandra/connection.py", line 898, in cassandra.connection.Connection._connect_socket
ConnectionRefusedError: [Errno 111] Tried connecting to [('127.0.0.1', 9042)]. Last error: Connection refused
01:23:56,766 cassandra.pool WARNING Error attempting to reconnect to 127.0.0.1:9042, scheduling retry in 2.16 seconds: [Errno 111] Tried connecting to [('127.0.0.1', 9042)]. Last error: Connection refused
01:23:56,770 cassandra.pool WARNING Error attempting to reconnect to 127.0.0.1:9042, scheduling retry in 1.94 seconds: [Errno 111] Tried connecting to [('127.0.0.1', 9042)]. Last error: Connection refused
01:23:56,801 cassandra.pool WARNING Error attempting to reconnect to 127.0.0.1:9042, scheduling retry in 1.86 seconds: [Errno 111] Tried connecting to [('127.0.0.1', 9042)]. Last error: Connection refused
01:23:58,707 cassandra.pool WARNING Error attempting to reconnect to 127.0.0.1:9042, scheduling retry in 3.52 seconds: [Errno 111] Tried connecting to [('127.0.0.1', 9042)]. Last error: Connection refused
01:23:58,776 cassandra.pool WARNING Error attempting to reconnect to 127.0.0.1:9042, scheduling retry in 3.6 seconds: [Errno 111] Tried connecting to [('127.0.0.1', 9042)]. Last error: Connection refused
01:23:58,974 cassandra.pool WARNING Error attempting to reconnect to 127.0.0.1:9042, scheduling retry in 4.44 seconds: [Errno 111] Tried connecting to [('127.0.0.1', 9042)]. Last error: Connection refused
01:24:02,319 cassandra.pool WARNING Error attempting to reconnect to 127.0.0.1:9042, scheduling retry in 7.04 seconds: [Errno 111] Tried connecting to [('127.0.0.1', 9042)]. Last error: Connection refused
01:24:02,387 cassandra.pool WARNING Error attempting to reconnect to 127.0.0.1:9042, scheduling retry in 6.88 seconds: [Errno 111] Tried connecting to [('127.0.0.1', 9042)]. Last error: Connection refused
01:24:02,774 cassandra.cluster WARNING Host 127.0.0.2:9042 has been marked down
01:24:02,775 cassandra.cluster WARNING Host 127.0.0.2:9042 has been marked down
01:24:02,780 cassandra.cluster WARNING [control connection] Error connecting to 127.0.0.1:9042:
Traceback (most recent call last):
  File "cassandra/cluster.py", line 3522, in cassandra.cluster.ControlConnection._reconnect_internal
  File "cassandra/cluster.py", line 3544, in cassandra.cluster.ControlConnection._try_connect
  File "cassandra/cluster.py", line 1620, in cassandra.cluster.Cluster.connection_factory
  File "cassandra/connection.py", line 831, in cassandra.connection.Connection.factory
  File "/users/masix/dtest/src/cassandra-driver/cassandra/io/libevreactor.py", line 267, in __init__
    self._connect_socket()
  File "cassandra/connection.py", line 898, in cassandra.connection.Connection._connect_socket
ConnectionRefusedError: [Errno 111] Tried connecting to [('127.0.0.1', 9042)]. Last error: Connection refused
01:24:02,784 cassandra.cluster WARNING Host 127.0.0.2:9042 has been marked down
01:24:02,785 cassandra.cluster WARNING Host 127.0.0.2:9042 has been marked down
01:24:03,487 cassandra.pool WARNING Error attempting to reconnect to 127.0.0.1:9042, scheduling retry in 8.88 seconds: [Errno 111] Tried connecting to [('127.0.0.1', 9042)]. Last error: Connection refused
01:24:03,925 cassandra.pool WARNING Error attempting to reconnect to 127.0.0.2:9042, scheduling retry in 1.78 seconds: [Errno 111] Tried connecting to [('127.0.0.2', 9042)]. Last error: Connection refused
01:24:03,984 cassandra.pool WARNING Error attempting to reconnect to 127.0.0.2:9042, scheduling retry in 1.8 seconds: [Errno 111] Tried connecting to [('127.0.0.2', 9042)]. Last error: Connection refused
01:24:03,989 cassandra.pool WARNING Error attempting to reconnect to 127.0.0.2:9042, scheduling retry in 2.3 seconds: [Errno 111] Tried connecting to [('127.0.0.2', 9042)]. Last error: Connection refused
01:24:03,993 cassandra.pool WARNING Error attempting to reconnect to 127.0.0.2:9042, scheduling retry in 1.78 seconds: [Errno 111] Tried connecting to [('127.0.0.2', 9042)]. Last error: Connection refused
01:24:05,729 cassandra.pool WARNING Error attempting to reconnect to 127.0.0.2:9042, scheduling retry in 3.68 seconds: [Errno 111] Tried connecting to [('127.0.0.2', 9042)]. Last error: Connection refused
01:24:05,790 cassandra.pool WARNING Error attempting to reconnect to 127.0.0.2:9042, scheduling retry in 3.88 seconds: [Errno 111] Tried connecting to [('127.0.0.2', 9042)]. Last error: Connection refused
01:24:05,798 cassandra.pool WARNING Error attempting to reconnect to 127.0.0.2:9042, scheduling retry in 3.88 seconds: [Errno 111] Tried connecting to [('127.0.0.2', 9042)]. Last error: Connection refused
01:24:06,295 cassandra.pool WARNING Error attempting to reconnect to 127.0.0.2:9042, scheduling retry in 4.24 seconds: [Errno 111] Tried connecting to [('127.0.0.2', 9042)]. Last error: Connection refused
01:24:09,308 cassandra.pool WARNING Error attempting to reconnect to 127.0.0.1:9042, scheduling retry in 17.6 seconds: [Errno 111] Tried connecting to [('127.0.0.1', 9042)]. Last error: Connection refused
01:24:09,440 cassandra.pool WARNING Error attempting to reconnect to 127.0.0.1:9042, scheduling retry in 15.52 seconds: [Errno 111] Tried connecting to [('127.0.0.1', 9042)]. Last error: Connection refused
01:24:09,440 cassandra.pool WARNING Error attempting to reconnect to 127.0.0.2:9042, scheduling retry in 7.68 seconds: [Errno 111] Tried connecting to [('127.0.0.2', 9042)]. Last error: Connection refused
01:24:09,701 cassandra.pool WARNING Error attempting to reconnect to 127.0.0.2:9042, scheduling retry in 6.8 seconds: [Errno 111] Tried connecting to [('127.0.0.2', 9042)]. Last error: Connection refused
01:24:09,709 cassandra.pool WARNING Error attempting to reconnect to 127.0.0.2:9042, scheduling retry in 8.48 seconds: [Errno 111] Tried connecting to [('127.0.0.2', 9042)]. Last error: Connection refused
01:24:10,606 cassandra.pool WARNING Error attempting to reconnect to 127.0.0.2:9042, scheduling retry in 9.2 seconds: [Errno 111] Tried connecting to [('127.0.0.2', 9042)]. Last error: Connection refused
01:24:11,675 cassandra.cluster WARNING Host 127.0.0.2:9042 has been marked down
01:24:11,676 cassandra.cluster WARNING Host 127.0.0.1:9042 has been marked down
01:24:11,678 cassandra.cluster WARNING [control connection] Error connecting to 127.0.0.1:9042:
Traceback (most recent call last):
  File "cassandra/cluster.py", line 3522, in cassandra.cluster.ControlConnection._reconnect_internal
  File "cassandra/cluster.py", line 3544, in cassandra.cluster.ControlConnection._try_connect
  File "cassandra/cluster.py", line 1620, in cassandra.cluster.Cluster.connection_factory
  File "cassandra/connection.py", line 831, in cassandra.connection.Connection.factory
  File "/users/masix/dtest/src/cassandra-driver/cassandra/io/libevreactor.py", line 267, in __init__
    self._connect_socket()
  File "cassandra/connection.py", line 898, in cassandra.connection.Connection._connect_socket
ConnectionRefusedError: [Errno 111] Tried connecting to [('127.0.0.1', 9042)]. Last error: Connection refused
01:24:12,410 cassandra.pool WARNING Error attempting to reconnect to 127.0.0.1:9042, scheduling retry in 18.4 seconds: [Errno 111] Tried connecting to [('127.0.0.1', 9042)]. Last error: Connection refused
01:24:12,680 cassandra.pool WARNING Error attempting to reconnect to 127.0.0.2:9042, scheduling retry in 2.1 seconds: [Errno 111] Tried connecting to [('127.0.0.2', 9042)]. Last error: Connection refused
01:24:12,780 cassandra.pool WARNING Error attempting to reconnect to 127.0.0.1:9042, scheduling retry in 2.24 seconds: [Errno 111] Tried connecting to [('127.0.0.1', 9042)]. Last error: Connection refused
01:24:14,785 cassandra.pool WARNING Error attempting to reconnect to 127.0.0.2:9042, scheduling retry in 3.4 seconds: [Errno 111] Tried connecting to [('127.0.0.2', 9042)]. Last error: Connection refused
01:24:15,86 cassandra.pool WARNING Error attempting to reconnect to 127.0.0.1:9042, scheduling retry in 3.76 seconds: [Errno 111] Tried connecting to [('127.0.0.1', 9042)]. Last error: Connection refused
01:24:16,520 cassandra.pool WARNING Error attempting to reconnect to 127.0.0.2:9042, scheduling retry in 15.52 seconds: [Errno 111] Tried connecting to [('127.0.0.2', 9042)]. Last error: Connection refused
01:24:17,162 cassandra.pool WARNING Error attempting to reconnect to 127.0.0.2:9042, scheduling retry in 13.92 seconds: [Errno 111] Tried connecting to [('127.0.0.2', 9042)]. Last error: Connection refused
01:24:17,899 cassandra.cluster WARNING Host 127.0.0.3:9042 has been marked down
01:24:17,902 cassandra.cluster WARNING Host 127.0.0.3:9042 has been marked down
01:24:17,903 cassandra.cluster WARNING Host 127.0.0.3:9042 has been marked down
01:24:17,907 cassandra.cluster WARNING [control connection] Error connecting to 127.0.0.1:9042:
Traceback (most recent call last):
  File "cassandra/cluster.py", line 3522, in cassandra.cluster.ControlConnection._reconnect_internal
  File "cassandra/cluster.py", line 3544, in cassandra.cluster.ControlConnection._try_connect
  File "cassandra/cluster.py", line 1620, in cassandra.cluster.Cluster.connection_factory
  File "cassandra/connection.py", line 831, in cassandra.connection.Connection.factory
  File "/users/masix/dtest/src/cassandra-driver/cassandra/io/libevreactor.py", line 267, in __init__
    self._connect_socket()
  File "cassandra/connection.py", line 898, in cassandra.connection.Connection._connect_socket
ConnectionRefusedError: [Errno 111] Tried connecting to [('127.0.0.1', 9042)]. Last error: Connection refused
01:24:18,194 cassandra.pool WARNING Error attempting to reconnect to 127.0.0.2:9042, scheduling retry in 7.2 seconds: [Errno 111] Tried connecting to [('127.0.0.2', 9042)]. Last error: Connection refused
01:24:18,231 cassandra.pool WARNING Error attempting to reconnect to 127.0.0.2:9042, scheduling retry in 18.4 seconds: [Errno 111] Tried connecting to [('127.0.0.2', 9042)]. Last error: Connection refused
01:24:18,896 cassandra.pool WARNING Error attempting to reconnect to 127.0.0.1:9042, scheduling retry in 8.8 seconds: [Errno 111] Tried connecting to [('127.0.0.1', 9042)]. Last error: Connection refused
01:24:18,927 cassandra.pool WARNING Error attempting to reconnect to 127.0.0.3:9042, scheduling retry in 1.76 seconds: [Errno 111] Tried connecting to [('127.0.0.3', 9042)]. Last error: Connection refused
01:24:18,929 cassandra.pool WARNING Error attempting to reconnect to 127.0.0.3:9042, scheduling retry in 2.16 seconds: [Errno 111] Tried connecting to [('127.0.0.3', 9042)]. Last error: Connection refused
01:24:18,929 cassandra.cluster WARNING [control connection] Error connecting to 127.0.0.1:9042:
Traceback (most recent call last):
  File "cassandra/cluster.py", line 3522, in cassandra.cluster.ControlConnection._reconnect_internal
  File "cassandra/cluster.py", line 3544, in cassandra.cluster.ControlConnection._try_connect
  File "cassandra/cluster.py", line 1620, in cassandra.cluster.Cluster.connection_factory
  File "cassandra/connection.py", line 831, in cassandra.connection.Connection.factory
  File "/users/masix/dtest/src/cassandra-driver/cassandra/io/libevreactor.py", line 267, in __init__
    self._connect_socket()
  File "cassandra/connection.py", line 898, in cassandra.connection.Connection._connect_socket
ConnectionRefusedError: [Errno 111] Tried connecting to [('127.0.0.1', 9042)]. Last error: Connection refused
01:24:19,33 cassandra.pool WARNING Error attempting to reconnect to 127.0.0.3:9042, scheduling retry in 2.2 seconds: [Errno 111] Tried connecting to [('127.0.0.3', 9042)]. Last error: Connection refused
01:24:19,830 cassandra.pool WARNING Error attempting to reconnect to 127.0.0.2:9042, scheduling retry in 14.88 seconds: [Errno 111] Tried connecting to [('127.0.0.2', 9042)]. Last error: Connection refused
01:24:20,732 cassandra.pool WARNING Error attempting to reconnect to 127.0.0.3:9042, scheduling retry in 3.48 seconds: [Errno 111] Tried connecting to [('127.0.0.3', 9042)]. Last error: Connection refused
01:24:20,933 cassandra.cluster WARNING [control connection] Error connecting to 127.0.0.1:9042:
Traceback (most recent call last):
  File "cassandra/cluster.py", line 3522, in cassandra.cluster.ControlConnection._reconnect_internal
  File "cassandra/cluster.py", line 3544, in cassandra.cluster.ControlConnection._try_connect
  File "cassandra/cluster.py", line 1620, in cassandra.cluster.Cluster.connection_factory
  File "cassandra/connection.py", line 831, in cassandra.connection.Connection.factory
  File "/users/masix/dtest/src/cassandra-driver/cassandra/io/libevreactor.py", line 267, in __init__
    self._connect_socket()
  File "cassandra/connection.py", line 898, in cassandra.connection.Connection._connect_socket
ConnectionRefusedError: [Errno 111] Tried connecting to [('127.0.0.1', 9042)]. Last error: Connection refused
01:24:21,134 cassandra.pool WARNING Error attempting to reconnect to 127.0.0.3:9042, scheduling retry in 3.44 seconds: [Errno 111] Tried connecting to [('127.0.0.3', 9042)]. Last error: Connection refused
01:24:21,239 cassandra.pool WARNING Error attempting to reconnect to 127.0.0.3:9042, scheduling retry in 3.8 seconds: [Errno 111] Tried connecting to [('127.0.0.3', 9042)]. Last error: Connection refused
01:24:24,242 cassandra.pool WARNING Error attempting to reconnect to 127.0.0.3:9042, scheduling retry in 8.96 seconds: [Errno 111] Tried connecting to [('127.0.0.3', 9042)]. Last error: Connection refused
01:24:24,543 cassandra.cluster WARNING [control connection] Error connecting to 127.0.0.1:9042:
Traceback (most recent call last):
  File "cassandra/cluster.py", line 3522, in cassandra.cluster.ControlConnection._reconnect_internal
  File "cassandra/cluster.py", line 3544, in cassandra.cluster.ControlConnection._try_connect
  File "cassandra/cluster.py", line 1620, in cassandra.cluster.Cluster.connection_factory
  File "cassandra/connection.py", line 831, in cassandra.connection.Connection.factory
  File "/users/masix/dtest/src/cassandra-driver/cassandra/io/libevreactor.py", line 267, in __init__
    self._connect_socket()
  File "cassandra/connection.py", line 898, in cassandra.connection.Connection._connect_socket
ConnectionRefusedError: [Errno 111] Tried connecting to [('127.0.0.1', 9042)]. Last error: Connection refused
01:24:24,644 cassandra.pool WARNING Error attempting to reconnect to 127.0.0.3:9042, scheduling retry in 7.36 seconds: [Errno 111] Tried connecting to [('127.0.0.3', 9042)]. Last error: Connection refused
01:24:24,982 cassandra.pool WARNING Error attempting to reconnect to 127.0.0.1:9042, scheduling retry in 29.12 seconds: [Errno 111] Tried connecting to [('127.0.0.1', 9042)]. Last error: Connection refused
01:24:25,49 cassandra.pool WARNING Error attempting to reconnect to 127.0.0.3:9042, scheduling retry in 8.56 seconds: [Errno 111] Tried connecting to [('127.0.0.3', 9042)]. Last error: Connection refused
01:24:25,413 cassandra.pool WARNING Error attempting to reconnect to 127.0.0.2:9042, scheduling retry in 14.4 seconds: [Errno 111] Tried connecting to [('127.0.0.2', 9042)]. Last error: Connection refused
01:24:26,53 cassandra.cluster WARNING [control connection] Error connecting to 127.0.0.1:9042:
Traceback (most recent call last):
  File "cassandra/cluster.py", line 3522, in cassandra.cluster.ControlConnection._reconnect_internal
  File "cassandra/cluster.py", line 3544, in cassandra.cluster.ControlConnection._try_connect
  File "cassandra/cluster.py", line 1620, in cassandra.cluster.Cluster.connection_factory
  File "cassandra/connection.py", line 831, in cassandra.connection.Connection.factory
  File "/users/masix/dtest/src/cassandra-driver/cassandra/io/libevreactor.py", line 267, in __init__
    self._connect_socket()
  File "cassandra/connection.py", line 898, in cassandra.connection.Connection._connect_socket
ConnectionRefusedError: [Errno 111] Tried connecting to [('127.0.0.1', 9042)]. Last error: Connection refused
01:24:26,965 cassandra.pool WARNING Error attempting to reconnect to 127.0.0.1:9042, scheduling retry in 32.96 seconds: [Errno 111] Tried connecting to [('127.0.0.1', 9042)]. Last error: Connection refused
01:24:27,157 cassandra.cluster WARNING [control connection] Error connecting to 127.0.0.1:9042:
Traceback (most recent call last):
  File "cassandra/cluster.py", line 3522, in cassandra.cluster.ControlConnection._reconnect_internal
  File "cassandra/cluster.py", line 3544, in cassandra.cluster.ControlConnection._try_connect
  File "cassandra/cluster.py", line 1620, in cassandra.cluster.Cluster.connection_factory
  File "cassandra/connection.py", line 831, in cassandra.connection.Connection.factory
  File "/users/masix/dtest/src/cassandra-driver/cassandra/io/libevreactor.py", line 267, in __init__
    self._connect_socket()
  File "cassandra/connection.py", line 898, in cassandra.connection.Connection._connect_socket
ConnectionRefusedError: [Errno 111] Tried connecting to [('127.0.0.1', 9042)]. Last error: Connection refused
01:24:27,729 cassandra.pool WARNING Error attempting to reconnect to 127.0.0.1:9042, scheduling retry in 14.88 seconds: [Errno 111] Tried connecting to [('127.0.0.1', 9042)]. Last error: Connection refused
01:24:28,962 cassandra.cluster WARNING [control connection] Error connecting to 127.0.0.1:9042:
Traceback (most recent call last):
  File "cassandra/cluster.py", line 3522, in cassandra.cluster.ControlConnection._reconnect_internal
  File "cassandra/cluster.py", line 3544, in cassandra.cluster.ControlConnection._try_connect
  File "cassandra/cluster.py", line 1620, in cassandra.cluster.Cluster.connection_factory
  File "cassandra/connection.py", line 831, in cassandra.connection.Connection.factory
  File "/users/masix/dtest/src/cassandra-driver/cassandra/io/libevreactor.py", line 267, in __init__
    self._connect_socket()
  File "cassandra/connection.py", line 898, in cassandra.connection.Connection._connect_socket
ConnectionRefusedError: [Errno 111] Tried connecting to [('127.0.0.1', 9042)]. Last error: Connection refused
01:24:30,867 cassandra.pool WARNING Error attempting to reconnect to 127.0.0.1:9042, scheduling retry in 29.12 seconds: [Errno 111] Tried connecting to [('127.0.0.1', 9042)]. Last error: Connection refused
01:24:31,98 cassandra.pool WARNING Error attempting to reconnect to 127.0.0.2:9042, scheduling retry in 27.2 seconds: [Errno 111] Tried connecting to [('127.0.0.2', 9042)]. Last error: Connection refused
01:24:32,70 cassandra.pool WARNING Error attempting to reconnect to 127.0.0.3:9042, scheduling retry in 14.24 seconds: [Errno 111] Tried connecting to [('127.0.0.3', 9042)]. Last error: Connection refused
01:24:32,71 cassandra.pool WARNING Error attempting to reconnect to 127.0.0.2:9042, scheduling retry in 35.2 seconds: [Errno 111] Tried connecting to [('127.0.0.2', 9042)]. Last error: Connection refused
01:24:32,872 cassandra.cluster WARNING [control connection] Error connecting to 127.0.0.1:9042:
Traceback (most recent call last):
  File "cassandra/cluster.py", line 3522, in cassandra.cluster.ControlConnection._reconnect_internal
  File "cassandra/cluster.py", line 3544, in cassandra.cluster.ControlConnection._try_connect
  File "cassandra/cluster.py", line 1620, in cassandra.cluster.Cluster.connection_factory
  File "cassandra/connection.py", line 831, in cassandra.connection.Connection.factory
  File "/users/masix/dtest/src/cassandra-driver/cassandra/io/libevreactor.py", line 267, in __init__
    self._connect_socket()
  File "cassandra/connection.py", line 898, in cassandra.connection.Connection._connect_socket
ConnectionRefusedError: [Errno 111] Tried connecting to [('127.0.0.1', 9042)]. Last error: Connection refused
01:24:33,274 cassandra.pool WARNING Error attempting to reconnect to 127.0.0.3:9042, scheduling retry in 17.44 seconds: [Errno 111] Tried connecting to [('127.0.0.3', 9042)]. Last error: Connection refused
01:24:33,681 cassandra.pool WARNING Error attempting to reconnect to 127.0.0.3:9042, scheduling retry in 13.76 seconds: [Errno 111] Tried connecting to [('127.0.0.3', 9042)]. Last error: Connection refused
01:24:34,407 cassandra.cluster WARNING Host 127.0.0.3:9042 has been marked down
01:24:34,408 cassandra.cluster WARNING [control connection] Error connecting to 127.0.0.3:9042:
Traceback (most recent call last):
  File "cassandra/cluster.py", line 3522, in cassandra.cluster.ControlConnection._reconnect_internal
  File "cassandra/cluster.py", line 3544, in cassandra.cluster.ControlConnection._try_connect
  File "cassandra/cluster.py", line 1620, in cassandra.cluster.Cluster.connection_factory
  File "cassandra/connection.py", line 831, in cassandra.connection.Connection.factory
  File "/users/masix/dtest/src/cassandra-driver/cassandra/io/libevreactor.py", line 267, in __init__
    self._connect_socket()
  File "cassandra/connection.py", line 898, in cassandra.connection.Connection._connect_socket
ConnectionRefusedError: [Errno 111] Tried connecting to [('127.0.0.3', 9042)]. Last error: Connection refused
01:24:34,778 cassandra.pool WARNING Error attempting to reconnect to 127.0.0.2:9042, scheduling retry in 35.52 seconds: [Errno 111] Tried connecting to [('127.0.0.2', 9042)]. Last error: Connection refused
01:24:35,610 cassandra.pool WARNING Error attempting to reconnect to 127.0.0.3:9042, scheduling retry in 2.1 seconds: [Errno 111] Tried connecting to [('127.0.0.3', 9042)]. Last error: Connection refused
01:24:36,689 cassandra.pool WARNING Error attempting to reconnect to 127.0.0.2:9042, scheduling retry in 32.0 seconds: [Errno 111] Tried connecting to [('127.0.0.2', 9042)]. Last error: Connection refused
01:24:37,716 cassandra.pool WARNING Error attempting to reconnect to 127.0.0.3:9042, scheduling retry in 4.28 seconds: [Errno 111] Tried connecting to [('127.0.0.3', 9042)]. Last error: Connection refused
01:24:39,858 cassandra.pool WARNING Error attempting to reconnect to 127.0.0.2:9042, scheduling retry in 33.6 seconds: [Errno 111] Tried connecting to [('127.0.0.2', 9042)]. Last error: Connection refused
01:24:41,676 cassandra.cluster WARNING Host 127.0.0.3:9042 has been marked down
01:24:41,677 cassandra.cluster WARNING [control connection] Error connecting to 127.0.0.3:9042:
Traceback (most recent call last):
  File "cassandra/cluster.py", line 3522, in cassandra.cluster.ControlConnection._reconnect_internal
  File "cassandra/cluster.py", line 3544, in cassandra.cluster.ControlConnection._try_connect
  File "cassandra/cluster.py", line 1620, in cassandra.cluster.Cluster.connection_factory
  File "cassandra/connection.py", line 831, in cassandra.connection.Connection.factory
  File "/users/masix/dtest/src/cassandra-driver/cassandra/io/libevreactor.py", line 267, in __init__
    self._connect_socket()
  File "cassandra/connection.py", line 898, in cassandra.connection.Connection._connect_socket
ConnectionRefusedError: [Errno 111] Tried connecting to [('127.0.0.3', 9042)]. Last error: Connection refused
01:24:42,27 cassandra.pool WARNING Error attempting to reconnect to 127.0.0.3:9042, scheduling retry in 7.12 seconds: [Errno 111] Tried connecting to [('127.0.0.3', 9042)]. Last error: Connection refused
01:24:42,766 cassandra.pool WARNING Error attempting to reconnect to 127.0.0.3:9042, scheduling retry in 1.96 seconds: [Errno 111] Tried connecting to [('127.0.0.3', 9042)]. Last error: Connection refused
01:24:54,165 cassandra.pool WARNING Error attempting to reconnect to 127.0.0.1:9042, scheduling retry in 67.84 seconds: [Errno 111] Tried connecting to [('127.0.0.1', 9042)]. Last error: Connection refused
01:24:56,52 cassandra.cluster WARNING [control connection] Error connecting to 127.0.0.1:9042:
Traceback (most recent call last):
  File "cassandra/cluster.py", line 3522, in cassandra.cluster.ControlConnection._reconnect_internal
  File "cassandra/cluster.py", line 3544, in cassandra.cluster.ControlConnection._try_connect
  File "cassandra/cluster.py", line 1620, in cassandra.cluster.Cluster.connection_factory
  File "cassandra/connection.py", line 831, in cassandra.connection.Connection.factory
  File "/users/masix/dtest/src/cassandra-driver/cassandra/io/libevreactor.py", line 267, in __init__
    self._connect_socket()
  File "cassandra/connection.py", line 898, in cassandra.connection.Connection._connect_socket
ConnectionRefusedError: [Errno 111] Tried connecting to [('127.0.0.1', 9042)]. Last error: Connection refused
01:24:58,379 cassandra.pool WARNING Error attempting to reconnect to 127.0.0.2:9042, scheduling retry in 70.4 seconds: [Errno 111] Tried connecting to [('127.0.0.2', 9042)]. Last error: Connection refused
01:24:59,957 cassandra.pool WARNING Error attempting to reconnect to 127.0.0.1:9042, scheduling retry in 71.04 seconds: [Errno 111] Tried connecting to [('127.0.0.1', 9042)]. Last error: Connection refused
01:25:00,48 cassandra.pool WARNING Error attempting to reconnect to 127.0.0.1:9042, scheduling retry in 60.16 seconds: [Errno 111] Tried connecting to [('127.0.0.1', 9042)]. Last error: Connection refused
01:25:07,274 cassandra.pool WARNING Error attempting to reconnect to 127.0.0.2:9042, scheduling retry in 67.2 seconds: [Errno 111] Tried connecting to [('127.0.0.2', 9042)]. Last error: Connection refused
01:25:08,780 cassandra.pool WARNING Error attempting to reconnect to 127.0.0.2:9042, scheduling retry in 60.8 seconds: [Errno 111] Tried connecting to [('127.0.0.2', 9042)]. Last error: Connection refused
01:25:10,382 cassandra.pool WARNING Error attempting to reconnect to 127.0.0.2:9042, scheduling retry in 58.24 seconds: [Errno 111] Tried connecting to [('127.0.0.2', 9042)]. Last error: Connection refused
01:25:11,677 cassandra.cluster WARNING Host 127.0.0.1:9042 has been marked down
01:25:11,679 cassandra.cluster WARNING [control connection] Error connecting to 127.0.0.1:9042:
Traceback (most recent call last):
  File "cassandra/cluster.py", line 3522, in cassandra.cluster.ControlConnection._reconnect_internal
  File "cassandra/cluster.py", line 3544, in cassandra.cluster.ControlConnection._try_connect
  File "cassandra/cluster.py", line 1620, in cassandra.cluster.Cluster.connection_factory
  File "cassandra/connection.py", line 831, in cassandra.connection.Connection.factory
  File "/users/masix/dtest/src/cassandra-driver/cassandra/io/libevreactor.py", line 267, in __init__
    self._connect_socket()
  File "cassandra/connection.py", line 898, in cassandra.connection.Connection._connect_socket
ConnectionRefusedError: [Errno 111] Tried connecting to [('127.0.0.1', 9042)]. Last error: Connection refused
01:25:12,759 cassandra.pool WARNING Error attempting to reconnect to 127.0.0.1:9042, scheduling retry in 1.98 seconds: [Errno 111] Tried connecting to [('127.0.0.1', 9042)]. Last error: Connection refused
01:25:12,761 cassandra.cluster WARNING Host 127.0.0.3:9042 has been marked down
01:25:12,766 cassandra.cluster WARNING Host 127.0.0.3:9042 has been marked down
01:25:12,771 cassandra.cluster WARNING [control connection] Error connecting to 127.0.0.1:9042:
Traceback (most recent call last):
  File "cassandra/cluster.py", line 3522, in cassandra.cluster.ControlConnection._reconnect_internal
  File "cassandra/cluster.py", line 3544, in cassandra.cluster.ControlConnection._try_connect
  File "cassandra/cluster.py", line 1620, in cassandra.cluster.Cluster.connection_factory
  File "cassandra/connection.py", line 831, in cassandra.connection.Connection.factory
  File "/users/masix/dtest/src/cassandra-driver/cassandra/io/libevreactor.py", line 267, in __init__
    self._connect_socket()
  File "cassandra/connection.py", line 898, in cassandra.connection.Connection._connect_socket
ConnectionRefusedError: [Errno 111] Tried connecting to [('127.0.0.1', 9042)]. Last error: Connection refused
01:25:13,461 cassandra.pool WARNING Error attempting to reconnect to 127.0.0.2:9042, scheduling retry in 71.04 seconds: [Errno 111] Tried connecting to [('127.0.0.2', 9042)]. Last error: Connection refused
01:25:13,794 cassandra.pool WARNING Error attempting to reconnect to 127.0.0.3:9042, scheduling retry in 1.78 seconds: [Errno 111] Tried connecting to [('127.0.0.3', 9042)]. Last error: Connection refused
01:25:13,891 cassandra.cluster WARNING [control connection] Error connecting to 127.0.0.1:9042:
Traceback (most recent call last):
  File "cassandra/cluster.py", line 3522, in cassandra.cluster.ControlConnection._reconnect_internal
  File "cassandra/cluster.py", line 3544, in cassandra.cluster.ControlConnection._try_connect
  File "cassandra/cluster.py", line 1620, in cassandra.cluster.Cluster.connection_factory
  File "cassandra/connection.py", line 831, in cassandra.connection.Connection.factory
  File "/users/masix/dtest/src/cassandra-driver/cassandra/io/libevreactor.py", line 267, in __init__
    self._connect_socket()
  File "cassandra/connection.py", line 898, in cassandra.connection.Connection._connect_socket
ConnectionRefusedError: [Errno 111] Tried connecting to [('127.0.0.1', 9042)]. Last error: Connection refused
01:25:13,991 cassandra.pool WARNING Error attempting to reconnect to 127.0.0.3:9042, scheduling retry in 2.0 seconds: [Errno 111] Tried connecting to [('127.0.0.3', 9042)]. Last error: Connection refused
01:25:14,764 cassandra.pool WARNING Error attempting to reconnect to 127.0.0.1:9042, scheduling retry in 4.48 seconds: [Errno 111] Tried connecting to [('127.0.0.1', 9042)]. Last error: Connection refused
01:25:15,599 cassandra.pool WARNING Error attempting to reconnect to 127.0.0.3:9042, scheduling retry in 4.36 seconds: [Errno 111] Tried connecting to [('127.0.0.3', 9042)]. Last error: Connection refused
01:25:15,696 cassandra.cluster WARNING [control connection] Error connecting to 127.0.0.1:9042:
Traceback (most recent call last):
  File "cassandra/cluster.py", line 3522, in cassandra.cluster.ControlConnection._reconnect_internal
  File "cassandra/cluster.py", line 3544, in cassandra.cluster.ControlConnection._try_connect
  File "cassandra/cluster.py", line 1620, in cassandra.cluster.Cluster.connection_factory
  File "cassandra/connection.py", line 831, in cassandra.connection.Connection.factory
  File "/users/masix/dtest/src/cassandra-driver/cassandra/io/libevreactor.py", line 267, in __init__
    self._connect_socket()
  File "cassandra/connection.py", line 898, in cassandra.connection.Connection._connect_socket
ConnectionRefusedError: [Errno 111] Tried connecting to [('127.0.0.1', 9042)]. Last error: Connection refused
01:25:15,996 cassandra.pool WARNING Error attempting to reconnect to 127.0.0.3:9042, scheduling retry in 4.6 seconds: [Errno 111] Tried connecting to [('127.0.0.3', 9042)]. Last error: Connection refused
01:25:19,276 cassandra.pool WARNING Error attempting to reconnect to 127.0.0.1:9042, scheduling retry in 8.72 seconds: [Errno 111] Tried connecting to [('127.0.0.1', 9042)]. Last error: Connection refused
01:25:20,11 cassandra.pool WARNING Error attempting to reconnect to 127.0.0.3:9042, scheduling retry in 6.88 seconds: [Errno 111] Tried connecting to [('127.0.0.3', 9042)]. Last error: Connection refused
01:25:20,176 cassandra.cluster WARNING Host 127.0.0.1:9042 has been marked down
01:25:20,177 cassandra.cluster WARNING Host 127.0.0.3:9042 has been marked down
01:25:20,178 cassandra.cluster WARNING Host 127.0.0.2:9042 has been marked down
01:25:20,181 cassandra.cluster WARNING [control connection] Error connecting to 127.0.0.2:9042:
Traceback (most recent call last):
  File "cassandra/cluster.py", line 3522, in cassandra.cluster.ControlConnection._reconnect_internal
  File "cassandra/cluster.py", line 3544, in cassandra.cluster.ControlConnection._try_connect
  File "cassandra/cluster.py", line 1620, in cassandra.cluster.Cluster.connection_factory
  File "cassandra/connection.py", line 831, in cassandra.connection.Connection.factory
  File "/users/masix/dtest/src/cassandra-driver/cassandra/io/libevreactor.py", line 267, in __init__
    self._connect_socket()
  File "cassandra/connection.py", line 898, in cassandra.connection.Connection._connect_socket
ConnectionRefusedError: [Errno 111] Tried connecting to [('127.0.0.2', 9042)]. Last error: Connection refused
01:25:20,207 cassandra.cluster WARNING [control connection] Error connecting to 127.0.0.1:9042:
Traceback (most recent call last):
  File "cassandra/cluster.py", line 3522, in cassandra.cluster.ControlConnection._reconnect_internal
  File "cassandra/cluster.py", line 3544, in cassandra.cluster.ControlConnection._try_connect
  File "cassandra/cluster.py", line 1620, in cassandra.cluster.Cluster.connection_factory
  File "cassandra/connection.py", line 831, in cassandra.connection.Connection.factory
  File "/users/masix/dtest/src/cassandra-driver/cassandra/io/libevreactor.py", line 267, in __init__
    self._connect_socket()
  File "cassandra/connection.py", line 898, in cassandra.connection.Connection._connect_socket
ConnectionRefusedError: [Errno 111] Tried connecting to [('127.0.0.1', 9042)]. Last error: Connection refused
01:25:20,608 cassandra.pool WARNING Error attempting to reconnect to 127.0.0.3:9042, scheduling retry in 8.08 seconds: [Errno 111] Tried connecting to [('127.0.0.3', 9042)]. Last error: Connection refused
01:25:21,183 cassandra.pool WARNING Error attempting to reconnect to 127.0.0.3:9042, scheduling retry in 1.96 seconds: [Errno 111] Tried connecting to [('127.0.0.3', 9042)]. Last error: Connection refused
01:25:21,184 cassandra.pool WARNING Error attempting to reconnect to 127.0.0.1:9042, scheduling retry in 1.78 seconds: [Errno 111] Tried connecting to [('127.0.0.1', 9042)]. Last error: Connection refused
01:25:21,185 cassandra.pool WARNING Error attempting to reconnect to 127.0.0.2:9042, scheduling retry in 2.04 seconds: [Errno 111] Tried connecting to [('127.0.0.2', 9042)]. Last error: Connection refused
01:25:22,988 cassandra.pool WARNING Error attempting to reconnect to 127.0.0.1:9042, scheduling retry in 3.56 seconds: [Errno 111] Tried connecting to [('127.0.0.1', 9042)]. Last error: Connection refused
01:25:23,189 cassandra.pool WARNING Error attempting to reconnect to 127.0.0.3:9042, scheduling retry in 4.52 seconds: [Errno 111] Tried connecting to [('127.0.0.3', 9042)]. Last error: Connection refused
01:25:23,289 cassandra.pool WARNING Error attempting to reconnect to 127.0.0.2:9042, scheduling retry in 4.44 seconds: [Errno 111] Tried connecting to [('127.0.0.2', 9042)]. Last error: Connection refused
01:25:26,53 cassandra.cluster WARNING [control connection] Error connecting to 127.0.0.1:9042:
Traceback (most recent call last):
  File "cassandra/cluster.py", line 3522, in cassandra.cluster.ControlConnection._reconnect_internal
  File "cassandra/cluster.py", line 3544, in cassandra.cluster.ControlConnection._try_connect
  File "cassandra/cluster.py", line 1620, in cassandra.cluster.Cluster.connection_factory
  File "cassandra/connection.py", line 831, in cassandra.connection.Connection.factory
  File "/users/masix/dtest/src/cassandra-driver/cassandra/io/libevreactor.py", line 267, in __init__
    self._connect_socket()
  File "cassandra/connection.py", line 898, in cassandra.connection.Connection._connect_socket
ConnectionRefusedError: [Errno 111] Tried connecting to [('127.0.0.1', 9042)]. Last error: Connection refused
01:25:26,598 cassandra.pool WARNING Error attempting to reconnect to 127.0.0.1:9042, scheduling retry in 7.28 seconds: [Errno 111] Tried connecting to [('127.0.0.1', 9042)]. Last error: Connection refused
01:25:26,929 cassandra.pool WARNING Error attempting to reconnect to 127.0.0.3:9042, scheduling retry in 13.6 seconds: [Errno 111] Tried connecting to [('127.0.0.3', 9042)]. Last error: Connection refused
01:25:27,125 cassandra.cluster WARNING [control connection] Error connecting to 127.0.0.1:9042:
Traceback (most recent call last):
  File "cassandra/cluster.py", line 3522, in cassandra.cluster.ControlConnection._reconnect_internal
  File "cassandra/cluster.py", line 3544, in cassandra.cluster.ControlConnection._try_connect
  File "cassandra/cluster.py", line 1620, in cassandra.cluster.Cluster.connection_factory
  File "cassandra/connection.py", line 831, in cassandra.connection.Connection.factory
  File "/users/masix/dtest/src/cassandra-driver/cassandra/io/libevreactor.py", line 267, in __init__
    self._connect_socket()
  File "cassandra/connection.py", line 898, in cassandra.connection.Connection._connect_socket
ConnectionRefusedError: [Errno 111] Tried connecting to [('127.0.0.1', 9042)]. Last error: Connection refused
01:25:27,802 cassandra.pool WARNING Error attempting to reconnect to 127.0.0.3:9042, scheduling retry in 8.08 seconds: [Errno 111] Tried connecting to [('127.0.0.3', 9042)]. Last error: Connection refused
01:25:27,802 cassandra.pool WARNING Error attempting to reconnect to 127.0.0.2:9042, scheduling retry in 8.32 seconds: [Errno 111] Tried connecting to [('127.0.0.2', 9042)]. Last error: Connection refused
01:25:27,884 ccmlib.node WARNING [msx] ccmlib:copy_config_files.py, conf_dir = /users/masix/cassandra/conf
01:25:27,977 ccmlib.node WARNING [msx] ccmlib:node.py, self.name = node1
01:25:27,977 ccmlib.node WARNING [msx] ccmlib:node.py, sstable_preemptive_open_interval_in_mb = 50
01:25:28,7 cassandra.pool WARNING Error attempting to reconnect to 127.0.0.1:9042, scheduling retry in 14.56 seconds: [Errno 111] Tried connecting to [('127.0.0.1', 9042)]. Last error: Connection refused
01:25:28,32 ccmlib.node WARNING [msx] ccmlib:copy_config_files.py, conf_dir = /users/masix/cassandra/conf
01:25:28,119 ccmlib.node WARNING [msx] ccmlib:node.py, self.name = node2
01:25:28,119 ccmlib.node WARNING [msx] ccmlib:node.py, sstable_preemptive_open_interval_in_mb = 50
01:25:28,171 ccmlib.node WARNING [msx] ccmlib:copy_config_files.py, conf_dir = /users/masix/cassandra/conf
01:25:28,257 ccmlib.node WARNING [msx] ccmlib:node.py, self.name = node3
01:25:28,257 ccmlib.node WARNING [msx] ccmlib:node.py, sstable_preemptive_open_interval_in_mb = 50
01:25:28,742 cassandra.pool WARNING Error attempting to reconnect to 127.0.0.3:9042, scheduling retry in 13.92 seconds: [Errno 111] Tried connecting to [('127.0.0.3', 9042)]. Last error: Connection refused
01:25:29,143 cassandra.cluster WARNING [control connection] Error connecting to 127.0.0.1:9042:
Traceback (most recent call last):
  File "cassandra/cluster.py", line 3522, in cassandra.cluster.ControlConnection._reconnect_internal
  File "cassandra/cluster.py", line 3544, in cassandra.cluster.ControlConnection._try_connect
  File "cassandra/cluster.py", line 1620, in cassandra.cluster.Cluster.connection_factory
  File "cassandra/connection.py", line 831, in cassandra.connection.Connection.factory
  File "/users/masix/dtest/src/cassandra-driver/cassandra/io/libevreactor.py", line 267, in __init__
    self._connect_socket()
  File "cassandra/connection.py", line 898, in cassandra.connection.Connection._connect_socket
ConnectionRefusedError: [Errno 111] Tried connecting to [('127.0.0.1', 9042)]. Last error: Connection refused
01:25:30,761 cassandra.cluster WARNING [control connection] Error connecting to 127.0.0.3:9042:
Traceback (most recent call last):
  File "cassandra/cluster.py", line 3522, in cassandra.cluster.ControlConnection._reconnect_internal
  File "cassandra/cluster.py", line 3544, in cassandra.cluster.ControlConnection._try_connect
  File "cassandra/cluster.py", line 1620, in cassandra.cluster.Cluster.connection_factory
  File "cassandra/connection.py", line 831, in cassandra.connection.Connection.factory
  File "/users/masix/dtest/src/cassandra-driver/cassandra/io/libevreactor.py", line 267, in __init__
    self._connect_socket()
  File "cassandra/connection.py", line 898, in cassandra.connection.Connection._connect_socket
ConnectionRefusedError: [Errno 111] Tried connecting to [('127.0.0.3', 9042)]. Last error: Connection refused
01:25:31,851 cassandra.cluster WARNING [control connection] Error connecting to 127.0.0.3:9042:
Traceback (most recent call last):
  File "cassandra/cluster.py", line 3522, in cassandra.cluster.ControlConnection._reconnect_internal
  File "cassandra/cluster.py", line 3544, in cassandra.cluster.ControlConnection._try_connect
  File "cassandra/cluster.py", line 1620, in cassandra.cluster.Cluster.connection_factory
  File "cassandra/connection.py", line 831, in cassandra.connection.Connection.factory
  File "/users/masix/dtest/src/cassandra-driver/cassandra/io/libevreactor.py", line 267, in __init__
    self._connect_socket()
  File "cassandra/connection.py", line 898, in cassandra.connection.Connection._connect_socket
ConnectionRefusedError: [Errno 111] Tried connecting to [('127.0.0.3', 9042)]. Last error: Connection refused
01:25:32,853 cassandra.cluster WARNING [control connection] Error connecting to 127.0.0.1:9042:
Traceback (most recent call last):
  File "cassandra/cluster.py", line 3522, in cassandra.cluster.ControlConnection._reconnect_internal
  File "cassandra/cluster.py", line 3544, in cassandra.cluster.ControlConnection._try_connect
  File "cassandra/cluster.py", line 1620, in cassandra.cluster.Cluster.connection_factory
  File "cassandra/connection.py", line 831, in cassandra.connection.Connection.factory
  File "/users/masix/dtest/src/cassandra-driver/cassandra/io/libevreactor.py", line 267, in __init__
    self._connect_socket()
  File "cassandra/connection.py", line 898, in cassandra.connection.Connection._connect_socket
ConnectionRefusedError: [Errno 111] Tried connecting to [('127.0.0.1', 9042)]. Last error: Connection refused
01:25:33,655 cassandra.cluster WARNING [control connection] Error connecting to 127.0.0.3:9042:
Traceback (most recent call last):
  File "cassandra/cluster.py", line 3522, in cassandra.cluster.ControlConnection._reconnect_internal
  File "cassandra/cluster.py", line 3544, in cassandra.cluster.ControlConnection._try_connect
  File "cassandra/cluster.py", line 1620, in cassandra.cluster.Cluster.connection_factory
  File "cassandra/connection.py", line 831, in cassandra.connection.Connection.factory
  File "/users/masix/dtest/src/cassandra-driver/cassandra/io/libevreactor.py", line 267, in __init__
    self._connect_socket()
  File "cassandra/connection.py", line 898, in cassandra.connection.Connection._connect_socket
ConnectionRefusedError: [Errno 111] Tried connecting to [('127.0.0.3', 9042)]. Last error: Connection refused
01:25:33,937 cassandra.pool WARNING Error attempting to reconnect to 127.0.0.1:9042, scheduling retry in 14.24 seconds: [Errno 111] Tried connecting to [('127.0.0.1', 9042)]. Last error: Connection refused
01:25:34,409 cassandra.cluster WARNING Host 127.0.0.3:9042 has been marked down
01:25:34,411 cassandra.cluster WARNING [control connection] Error connecting to 127.0.0.3:9042:
Traceback (most recent call last):
  File "cassandra/cluster.py", line 3522, in cassandra.cluster.ControlConnection._reconnect_internal
  File "cassandra/cluster.py", line 3544, in cassandra.cluster.ControlConnection._try_connect
  File "cassandra/cluster.py", line 1620, in cassandra.cluster.Cluster.connection_factory
  File "cassandra/connection.py", line 831, in cassandra.connection.Connection.factory
  File "/users/masix/dtest/src/cassandra-driver/cassandra/io/libevreactor.py", line 267, in __init__
    self._connect_socket()
  File "cassandra/connection.py", line 898, in cassandra.connection.Connection._connect_socket
ConnectionRefusedError: [Errno 111] Tried connecting to [('127.0.0.3', 9042)]. Last error: Connection refused
01:25:35,606 cassandra.pool WARNING Error attempting to reconnect to 127.0.0.3:9042, scheduling retry in 2.3 seconds: [Errno 111] Tried connecting to [('127.0.0.3', 9042)]. Last error: Connection refused
01:25:35,943 cassandra.pool WARNING Error attempting to reconnect to 127.0.0.3:9042, scheduling retry in 16.8 seconds: [Errno 111] Tried connecting to [('127.0.0.3', 9042)]. Last error: Connection refused
01:25:36,143 cassandra.pool WARNING Error attempting to reconnect to 127.0.0.2:9042, scheduling retry in 16.8 seconds: [Errno 111] Tried connecting to [('127.0.0.2', 9042)]. Last error: Connection refused
01:25:37,265 cassandra.cluster WARNING [control connection] Error connecting to 127.0.0.3:9042:
Traceback (most recent call last):
  File "cassandra/cluster.py", line 3522, in cassandra.cluster.ControlConnection._reconnect_internal
  File "cassandra/cluster.py", line 3544, in cassandra.cluster.ControlConnection._try_connect
  File "cassandra/cluster.py", line 1620, in cassandra.cluster.Cluster.connection_factory
  File "cassandra/connection.py", line 831, in cassandra.connection.Connection.factory
  File "/users/masix/dtest/src/cassandra-driver/cassandra/io/libevreactor.py", line 267, in __init__
    self._connect_socket()
  File "cassandra/connection.py", line 898, in cassandra.connection.Connection._connect_socket
ConnectionRefusedError: [Errno 111] Tried connecting to [('127.0.0.3', 9042)]. Last error: Connection refused
01:25:37,912 cassandra.pool WARNING Error attempting to reconnect to 127.0.0.3:9042, scheduling retry in 3.96 seconds: [Errno 111] Tried connecting to [('127.0.0.3', 9042)]. Last error: Connection refused
01:25:40,589 cassandra.pool WARNING Error attempting to reconnect to 127.0.0.3:9042, scheduling retry in 28.48 seconds: [Errno 111] Tried connecting to [('127.0.0.3', 9042)]. Last error: Connection refused
01:25:41,678 cassandra.cluster WARNING Host 127.0.0.3:9042 has been marked down
01:25:41,680 cassandra.cluster WARNING [control connection] Error connecting to 127.0.0.3:9042:
Traceback (most recent call last):
  File "cassandra/cluster.py", line 3522, in cassandra.cluster.ControlConnection._reconnect_internal
  File "cassandra/cluster.py", line 3544, in cassandra.cluster.ControlConnection._try_connect
  File "cassandra/cluster.py", line 1620, in cassandra.cluster.Cluster.connection_factory
  File "cassandra/connection.py", line 831, in cassandra.connection.Connection.factory
  File "/users/masix/dtest/src/cassandra-driver/cassandra/io/libevreactor.py", line 267, in __init__
    self._connect_socket()
  File "cassandra/connection.py", line 898, in cassandra.connection.Connection._connect_socket
ConnectionRefusedError: [Errno 111] Tried connecting to [('127.0.0.3', 9042)]. Last error: Connection refused
01:25:41,922 cassandra.pool WARNING Error attempting to reconnect to 127.0.0.3:9042, scheduling retry in 8.08 seconds: [Errno 111] Tried connecting to [('127.0.0.3', 9042)]. Last error: Connection refused
01:25:42,679 cassandra.pool WARNING Error attempting to reconnect to 127.0.0.3:9042, scheduling retry in 36.8 seconds: [Errno 111] Tried connecting to [('127.0.0.3', 9042)]. Last error: Connection refused
01:25:42,764 cassandra.pool WARNING Error attempting to reconnect to 127.0.0.3:9042, scheduling retry in 1.82 seconds: [Errno 111] Tried connecting to [('127.0.0.3', 9042)]. Last error: Connection refused
01:25:44,629 cassandra.pool WARNING Error attempting to reconnect to 127.0.0.3:9042, scheduling retry in 3.84 seconds: [Errno 111] Tried connecting to [('127.0.0.3', 9042)]. Last error: Connection refused
01:25:45,734 cassandra.cluster WARNING [control connection] Error connecting to 127.0.0.3:9042:
Traceback (most recent call last):
  File "cassandra/cluster.py", line 3522, in cassandra.cluster.ControlConnection._reconnect_internal
  File "cassandra/cluster.py", line 3544, in cassandra.cluster.ControlConnection._try_connect
  File "cassandra/cluster.py", line 1620, in cassandra.cluster.Cluster.connection_factory
  File "cassandra/connection.py", line 831, in cassandra.connection.Connection.factory
  File "/users/masix/dtest/src/cassandra-driver/cassandra/io/libevreactor.py", line 267, in __init__
    self._connect_socket()
  File "cassandra/connection.py", line 898, in cassandra.connection.Connection._connect_socket
ConnectionRefusedError: [Errno 111] Tried connecting to [('127.0.0.3', 9042)]. Last error: Connection refused
01:26:10,592 cassandra.cluster WARNING Host 127.0.0.1:9042 has been marked down
01:26:10,594 cassandra.cluster WARNING Host 127.0.0.1:9042 has been marked down
01:26:10,610 cassandra.cluster WARNING Host 127.0.0.1:9042 has been marked down
01:26:11,6 cassandra.pool WARNING Error attempting to reconnect to 127.0.0.1:9042, scheduling retry in 138.24 seconds: [Errno 111] Tried connecting to [('127.0.0.1', 9042)]. Last error: Connection refused
01:26:11,602 cassandra.pool WARNING Error attempting to reconnect to 127.0.0.1:9042, scheduling retry in 2.16 seconds: [Errno 111] Tried connecting to [('127.0.0.1', 9042)]. Last error: Connection refused
01:26:11,614 cassandra.pool WARNING Error attempting to reconnect to 127.0.0.1:9042, scheduling retry in 2.28 seconds: [Errno 111] Tried connecting to [('127.0.0.1', 9042)]. Last error: Connection refused
01:26:11,616 cassandra.pool WARNING Error attempting to reconnect to 127.0.0.1:9042, scheduling retry in 1.86 seconds: [Errno 111] Tried connecting to [('127.0.0.1', 9042)]. Last error: Connection refused
01:26:11,679 cassandra.cluster WARNING Host 127.0.0.1:9042 has been marked down
01:26:12,907 cassandra.pool WARNING Error attempting to reconnect to 127.0.0.1:9042, scheduling retry in 2.18 seconds: [Errno 111] Tried connecting to [('127.0.0.1', 9042)]. Last error: Connection refused
01:26:13,526 cassandra.pool WARNING Error attempting to reconnect to 127.0.0.1:9042, scheduling retry in 4.24 seconds: [Errno 111] Tried connecting to [('127.0.0.1', 9042)]. Last error: Connection refused
01:26:13,810 cassandra.pool WARNING Error attempting to reconnect to 127.0.0.1:9042, scheduling retry in 4.0 seconds: [Errno 111] Tried connecting to [('127.0.0.1', 9042)]. Last error: Connection refused
01:26:13,922 cassandra.pool WARNING Error attempting to reconnect to 127.0.0.1:9042, scheduling retry in 4.56 seconds: [Errno 111] Tried connecting to [('127.0.0.1', 9042)]. Last error: Connection refused
01:26:15,113 cassandra.pool WARNING Error attempting to reconnect to 127.0.0.1:9042, scheduling retry in 4.6 seconds: [Errno 111] Tried connecting to [('127.0.0.1', 9042)]. Last error: Connection refused
01:26:17,709 cassandra.cluster WARNING Host 127.0.0.2:9042 has been marked down
01:26:17,822 cassandra.pool WARNING Error attempting to reconnect to 127.0.0.1:9042, scheduling retry in 7.12 seconds: [Errno 111] Tried connecting to [('127.0.0.1', 9042)]. Last error: Connection refused
01:26:17,840 cassandra.pool WARNING Error attempting to reconnect to 127.0.0.1:9042, scheduling retry in 8.88 seconds: [Errno 111] Tried connecting to [('127.0.0.1', 9042)]. Last error: Connection refused
01:26:18,434 cassandra.cluster WARNING [control connection] Error connecting to 127.0.0.2:9042:
Traceback (most recent call last):
  File "cassandra/cluster.py", line 3522, in cassandra.cluster.ControlConnection._reconnect_internal
  File "cassandra/cluster.py", line 3544, in cassandra.cluster.ControlConnection._try_connect
  File "cassandra/cluster.py", line 1620, in cassandra.cluster.Cluster.connection_factory
  File "cassandra/connection.py", line 831, in cassandra.connection.Connection.factory
  File "/users/masix/dtest/src/cassandra-driver/cassandra/io/libevreactor.py", line 267, in __init__
    self._connect_socket()
  File "cassandra/connection.py", line 898, in cassandra.connection.Connection._connect_socket
ConnectionRefusedError: [Errno 111] Tried connecting to [('127.0.0.2', 9042)]. Last error: Connection refused
01:26:18,534 cassandra.pool WARNING Error attempting to reconnect to 127.0.0.1:9042, scheduling retry in 9.04 seconds: [Errno 111] Tried connecting to [('127.0.0.1', 9042)]. Last error: Connection refused
01:26:18,824 cassandra.pool WARNING Error attempting to reconnect to 127.0.0.2:9042, scheduling retry in 1.94 seconds: [Errno 111] Tried connecting to [('127.0.0.2', 9042)]. Last error: Connection refused
01:26:19,725 cassandra.pool WARNING Error attempting to reconnect to 127.0.0.1:9042, scheduling retry in 7.6 seconds: [Errno 111] Tried connecting to [('127.0.0.1', 9042)]. Last error: Connection refused
01:26:20,177 cassandra.cluster WARNING Host 127.0.0.2:9042 has been marked down
01:26:20,831 cassandra.pool WARNING Error attempting to reconnect to 127.0.0.2:9042, scheduling retry in 4.56 seconds: [Errno 111] Tried connecting to [('127.0.0.2', 9042)]. Last error: Connection refused
01:26:21,254 cassandra.pool WARNING Error attempting to reconnect to 127.0.0.2:9042, scheduling retry in 1.84 seconds: [Errno 111] Tried connecting to [('127.0.0.2', 9042)]. Last error: Connection refused
01:26:23,159 cassandra.pool WARNING Error attempting to reconnect to 127.0.0.2:9042, scheduling retry in 4.24 seconds: [Errno 111] Tried connecting to [('127.0.0.2', 9042)]. Last error: Connection refused
01:26:24,541 cassandra.pool WARNING Error attempting to reconnect to 127.0.0.2:9042, scheduling retry in 131.84 seconds: [Errno 111] Tried connecting to [('127.0.0.2', 9042)]. Last error: Connection refused
01:26:25,42 cassandra.pool WARNING Error attempting to reconnect to 127.0.0.1:9042, scheduling retry in 16.32 seconds: [Errno 111] Tried connecting to [('127.0.0.1', 9042)]. Last error: Connection refused
01:26:25,443 cassandra.pool WARNING Error attempting to reconnect to 127.0.0.2:9042, scheduling retry in 8.4 seconds: [Errno 111] Tried connecting to [('127.0.0.2', 9042)]. Last error: Connection refused
01:26:26,55 cassandra.cluster WARNING [control connection] Error connecting to 127.0.0.2:9042:
Traceback (most recent call last):
  File "cassandra/cluster.py", line 3522, in cassandra.cluster.ControlConnection._reconnect_internal
  File "cassandra/cluster.py", line 3544, in cassandra.cluster.ControlConnection._try_connect
  File "cassandra/cluster.py", line 1620, in cassandra.cluster.Cluster.connection_factory
  File "cassandra/connection.py", line 831, in cassandra.connection.Connection.factory
  File "/users/masix/dtest/src/cassandra-driver/cassandra/io/libevreactor.py", line 267, in __init__
    self._connect_socket()
  File "cassandra/connection.py", line 898, in cassandra.connection.Connection._connect_socket
ConnectionRefusedError: [Errno 111] Tried connecting to [('127.0.0.2', 9042)]. Last error: Connection refused
01:26:26,768 cassandra.pool WARNING Error attempting to reconnect to 127.0.0.1:9042, scheduling retry in 14.08 seconds: [Errno 111] Tried connecting to [('127.0.0.1', 9042)]. Last error: Connection refused
01:26:27,347 cassandra.pool WARNING Error attempting to reconnect to 127.0.0.1:9042, scheduling retry in 17.92 seconds: [Errno 111] Tried connecting to [('127.0.0.1', 9042)]. Last error: Connection refused
01:26:27,470 cassandra.pool WARNING Error attempting to reconnect to 127.0.0.2:9042, scheduling retry in 9.2 seconds: [Errno 111] Tried connecting to [('127.0.0.2', 9042)]. Last error: Connection refused
01:26:27,659 cassandra.pool WARNING Error attempting to reconnect to 127.0.0.1:9042, scheduling retry in 17.44 seconds: [Errno 111] Tried connecting to [('127.0.0.1', 9042)]. Last error: Connection refused
01:26:30,761 cassandra.cluster WARNING [control connection] Error connecting to 127.0.0.1:9042:
Traceback (most recent call last):
  File "cassandra/cluster.py", line 3522, in cassandra.cluster.ControlConnection._reconnect_internal
  File "cassandra/cluster.py", line 3544, in cassandra.cluster.ControlConnection._try_connect
  File "cassandra/cluster.py", line 1620, in cassandra.cluster.Cluster.connection_factory
  File "cassandra/connection.py", line 831, in cassandra.connection.Connection.factory
  File "/users/masix/dtest/src/cassandra-driver/cassandra/io/libevreactor.py", line 267, in __init__
    self._connect_socket()
  File "cassandra/connection.py", line 898, in cassandra.connection.Connection._connect_socket
ConnectionRefusedError: [Errno 111] Tried connecting to [('127.0.0.1', 9042)]. Last error: Connection refused
01:26:32,827 cassandra.cluster WARNING Host 127.0.0.3:9042 has been marked down
01:26:32,828 cassandra.cluster WARNING Host 127.0.0.3:9042 has been marked down
01:26:32,829 cassandra.cluster WARNING Host 127.0.0.3:9042 has been marked down
01:26:32,833 cassandra.cluster WARNING [control connection] Error connecting to 127.0.0.2:9042:
Traceback (most recent call last):
  File "cassandra/cluster.py", line 3522, in cassandra.cluster.ControlConnection._reconnect_internal
  File "cassandra/cluster.py", line 3544, in cassandra.cluster.ControlConnection._try_connect
  File "cassandra/cluster.py", line 1620, in cassandra.cluster.Cluster.connection_factory
  File "cassandra/connection.py", line 831, in cassandra.connection.Connection.factory
  File "/users/masix/dtest/src/cassandra-driver/cassandra/io/libevreactor.py", line 267, in __init__
    self._connect_socket()
  File "cassandra/connection.py", line 898, in cassandra.connection.Connection._connect_socket
ConnectionRefusedError: [Errno 111] Tried connecting to [('127.0.0.2', 9042)]. Last error: Connection refused
01:26:32,836 cassandra.cluster WARNING [control connection] Error connecting to 127.0.0.2:9042:
Traceback (most recent call last):
  File "cassandra/cluster.py", line 3522, in cassandra.cluster.ControlConnection._reconnect_internal
  File "cassandra/cluster.py", line 3544, in cassandra.cluster.ControlConnection._try_connect
  File "cassandra/cluster.py", line 1620, in cassandra.cluster.Cluster.connection_factory
  File "cassandra/connection.py", line 831, in cassandra.connection.Connection.factory
  File "/users/masix/dtest/src/cassandra-driver/cassandra/io/libevreactor.py", line 267, in __init__
    self._connect_socket()
  File "cassandra/connection.py", line 898, in cassandra.connection.Connection._connect_socket
ConnectionRefusedError: [Errno 111] Tried connecting to [('127.0.0.2', 9042)]. Last error: Connection refused
01:26:32,839 cassandra.cluster WARNING [control connection] Error connecting to 127.0.0.1:9042:
Traceback (most recent call last):
  File "cassandra/cluster.py", line 3522, in cassandra.cluster.ControlConnection._reconnect_internal
  File "cassandra/cluster.py", line 3544, in cassandra.cluster.ControlConnection._try_connect
  File "cassandra/cluster.py", line 1620, in cassandra.cluster.Cluster.connection_factory
  File "cassandra/connection.py", line 831, in cassandra.connection.Connection.factory
  File "/users/masix/dtest/src/cassandra-driver/cassandra/io/libevreactor.py", line 267, in __init__
    self._connect_socket()
  File "cassandra/connection.py", line 898, in cassandra.connection.Connection._connect_socket
ConnectionRefusedError: [Errno 111] Tried connecting to [('127.0.0.1', 9042)]. Last error: Connection refused
01:26:33,836 cassandra.pool WARNING Error attempting to reconnect to 127.0.0.3:9042, scheduling retry in 1.9 seconds: [Errno 111] Tried connecting to [('127.0.0.3', 9042)]. Last error: Connection refused
01:26:33,908 cassandra.pool WARNING Error attempting to reconnect to 127.0.0.3:9042, scheduling retry in 2.24 seconds: [Errno 111] Tried connecting to [('127.0.0.3', 9042)]. Last error: Connection refused
01:26:33,911 cassandra.pool WARNING Error attempting to reconnect to 127.0.0.2:9042, scheduling retry in 16.16 seconds: [Errno 111] Tried connecting to [('127.0.0.2', 9042)]. Last error: Connection refused
01:26:33,911 cassandra.pool WARNING Error attempting to reconnect to 127.0.0.3:9042, scheduling retry in 1.86 seconds: [Errno 111] Tried connecting to [('127.0.0.3', 9042)]. Last error: Connection refused
01:26:33,936 cassandra.cluster WARNING [control connection] Error connecting to 127.0.0.1:9042:
Traceback (most recent call last):
  File "cassandra/cluster.py", line 3522, in cassandra.cluster.ControlConnection._reconnect_internal
  File "cassandra/cluster.py", line 3544, in cassandra.cluster.ControlConnection._try_connect
  File "cassandra/cluster.py", line 1620, in cassandra.cluster.Cluster.connection_factory
  File "cassandra/connection.py", line 831, in cassandra.connection.Connection.factory
  File "/users/masix/dtest/src/cassandra-driver/cassandra/io/libevreactor.py", line 267, in __init__
    self._connect_socket()
  File "cassandra/connection.py", line 898, in cassandra.connection.Connection._connect_socket
ConnectionRefusedError: [Errno 111] Tried connecting to [('127.0.0.1', 9042)]. Last error: Connection refused
01:26:33,937 cassandra.cluster WARNING [control connection] Error connecting to 127.0.0.2:9042:
Traceback (most recent call last):
  File "cassandra/cluster.py", line 3522, in cassandra.cluster.ControlConnection._reconnect_internal
  File "cassandra/cluster.py", line 3544, in cassandra.cluster.ControlConnection._try_connect
  File "cassandra/cluster.py", line 1620, in cassandra.cluster.Cluster.connection_factory
  File "cassandra/connection.py", line 831, in cassandra.connection.Connection.factory
  File "/users/masix/dtest/src/cassandra-driver/cassandra/io/libevreactor.py", line 267, in __init__
    self._connect_socket()
  File "cassandra/connection.py", line 898, in cassandra.connection.Connection._connect_socket
ConnectionRefusedError: [Errno 111] Tried connecting to [('127.0.0.2', 9042)]. Last error: Connection refused
01:26:34,9 cassandra.cluster WARNING [control connection] Error connecting to 127.0.0.2:9042:
Traceback (most recent call last):
  File "cassandra/cluster.py", line 3522, in cassandra.cluster.ControlConnection._reconnect_internal
  File "cassandra/cluster.py", line 3544, in cassandra.cluster.ControlConnection._try_connect
  File "cassandra/cluster.py", line 1620, in cassandra.cluster.Cluster.connection_factory
  File "cassandra/connection.py", line 831, in cassandra.connection.Connection.factory
  File "/users/masix/dtest/src/cassandra-driver/cassandra/io/libevreactor.py", line 267, in __init__
    self._connect_socket()
  File "cassandra/connection.py", line 898, in cassandra.connection.Connection._connect_socket
ConnectionRefusedError: [Errno 111] Tried connecting to [('127.0.0.2', 9042)]. Last error: Connection refused
01:26:34,410 cassandra.cluster WARNING Host 127.0.0.3:9042 has been marked down
01:26:34,411 cassandra.cluster WARNING Host 127.0.0.1:9042 has been marked down
01:26:34,412 cassandra.cluster WARNING Host 127.0.0.2:9042 has been marked down
01:26:34,414 cassandra.cluster WARNING [control connection] Error connecting to 127.0.0.2:9042:
Traceback (most recent call last):
  File "cassandra/cluster.py", line 3522, in cassandra.cluster.ControlConnection._reconnect_internal
  File "cassandra/cluster.py", line 3544, in cassandra.cluster.ControlConnection._try_connect
  File "cassandra/cluster.py", line 1620, in cassandra.cluster.Cluster.connection_factory
  File "cassandra/connection.py", line 831, in cassandra.connection.Connection.factory
  File "/users/masix/dtest/src/cassandra-driver/cassandra/io/libevreactor.py", line 267, in __init__
    self._connect_socket()
  File "cassandra/connection.py", line 898, in cassandra.connection.Connection._connect_socket
ConnectionRefusedError: [Errno 111] Tried connecting to [('127.0.0.2', 9042)]. Last error: Connection refused
01:26:35,417 cassandra.pool WARNING Error attempting to reconnect to 127.0.0.3:9042, scheduling retry in 2.02 seconds: [Errno 111] Tried connecting to [('127.0.0.3', 9042)]. Last error: Connection refused
01:26:35,417 cassandra.pool WARNING Error attempting to reconnect to 127.0.0.2:9042, scheduling retry in 1.84 seconds: [Errno 111] Tried connecting to [('127.0.0.2', 9042)]. Last error: Connection refused
01:26:35,617 cassandra.pool WARNING Error attempting to reconnect to 127.0.0.1:9042, scheduling retry in 1.9 seconds: [Errno 111] Tried connecting to [('127.0.0.1', 9042)]. Last error: Connection refused
01:26:35,741 cassandra.pool WARNING Error attempting to reconnect to 127.0.0.3:9042, scheduling retry in 4.32 seconds: [Errno 111] Tried connecting to [('127.0.0.3', 9042)]. Last error: Connection refused
01:26:35,816 cassandra.pool WARNING Error attempting to reconnect to 127.0.0.3:9042, scheduling retry in 4.08 seconds: [Errno 111] Tried connecting to [('127.0.0.3', 9042)]. Last error: Connection refused
01:26:35,914 cassandra.cluster WARNING [control connection] Error connecting to 127.0.0.2:9042:
Traceback (most recent call last):
  File "cassandra/cluster.py", line 3522, in cassandra.cluster.ControlConnection._reconnect_internal
  File "cassandra/cluster.py", line 3544, in cassandra.cluster.ControlConnection._try_connect
  File "cassandra/cluster.py", line 1620, in cassandra.cluster.Cluster.connection_factory
  File "cassandra/connection.py", line 831, in cassandra.connection.Connection.factory
  File "/users/masix/dtest/src/cassandra-driver/cassandra/io/libevreactor.py", line 267, in __init__
    self._connect_socket()
  File "cassandra/connection.py", line 898, in cassandra.connection.Connection._connect_socket
ConnectionRefusedError: [Errno 111] Tried connecting to [('127.0.0.2', 9042)]. Last error: Connection refused
01:26:36,42 cassandra.cluster WARNING [control connection] Error connecting to 127.0.0.2:9042:
Traceback (most recent call last):
  File "cassandra/cluster.py", line 3522, in cassandra.cluster.ControlConnection._reconnect_internal
  File "cassandra/cluster.py", line 3544, in cassandra.cluster.ControlConnection._try_connect
  File "cassandra/cluster.py", line 1620, in cassandra.cluster.Cluster.connection_factory
  File "cassandra/connection.py", line 831, in cassandra.connection.Connection.factory
  File "/users/masix/dtest/src/cassandra-driver/cassandra/io/libevreactor.py", line 267, in __init__
    self._connect_socket()
  File "cassandra/connection.py", line 898, in cassandra.connection.Connection._connect_socket
ConnectionRefusedError: [Errno 111] Tried connecting to [('127.0.0.2', 9042)]. Last error: Connection refused
01:26:36,43 cassandra.cluster WARNING [control connection] Error connecting to 127.0.0.1:9042:
Traceback (most recent call last):
  File "cassandra/cluster.py", line 3522, in cassandra.cluster.ControlConnection._reconnect_internal
  File "cassandra/cluster.py", line 3544, in cassandra.cluster.ControlConnection._try_connect
  File "cassandra/cluster.py", line 1620, in cassandra.cluster.Cluster.connection_factory
  File "cassandra/connection.py", line 831, in cassandra.connection.Connection.factory
  File "/users/masix/dtest/src/cassandra-driver/cassandra/io/libevreactor.py", line 267, in __init__
    self._connect_socket()
  File "cassandra/connection.py", line 898, in cassandra.connection.Connection._connect_socket
ConnectionRefusedError: [Errno 111] Tried connecting to [('127.0.0.1', 9042)]. Last error: Connection refused
01:26:36,215 cassandra.pool WARNING Error attempting to reconnect to 127.0.0.3:9042, scheduling retry in 3.44 seconds: [Errno 111] Tried connecting to [('127.0.0.3', 9042)]. Last error: Connection refused
01:26:36,716 cassandra.pool WARNING Error attempting to reconnect to 127.0.0.2:9042, scheduling retry in 17.6 seconds: [Errno 111] Tried connecting to [('127.0.0.2', 9042)]. Last error: Connection refused
01:26:37,322 cassandra.pool WARNING Error attempting to reconnect to 127.0.0.2:9042, scheduling retry in 3.56 seconds: [Errno 111] Tried connecting to [('127.0.0.2', 9042)]. Last error: Connection refused
01:26:37,523 cassandra.pool WARNING Error attempting to reconnect to 127.0.0.1:9042, scheduling retry in 4.08 seconds: [Errno 111] Tried connecting to [('127.0.0.1', 9042)]. Last error: Connection refused
01:26:37,523 cassandra.pool WARNING Error attempting to reconnect to 127.0.0.3:9042, scheduling retry in 3.56 seconds: [Errno 111] Tried connecting to [('127.0.0.3', 9042)]. Last error: Connection refused
01:26:38,115 cassandra.cluster WARNING [control connection] Error connecting to 127.0.0.2:9042:
Traceback (most recent call last):
  File "cassandra/cluster.py", line 3522, in cassandra.cluster.ControlConnection._reconnect_internal
  File "cassandra/cluster.py", line 3544, in cassandra.cluster.ControlConnection._try_connect
  File "cassandra/cluster.py", line 1620, in cassandra.cluster.Cluster.connection_factory
  File "cassandra/connection.py", line 831, in cassandra.connection.Connection.factory
  File "/users/masix/dtest/src/cassandra-driver/cassandra/io/libevreactor.py", line 267, in __init__
    self._connect_socket()
  File "cassandra/connection.py", line 898, in cassandra.connection.Connection._connect_socket
ConnectionRefusedError: [Errno 111] Tried connecting to [('127.0.0.2', 9042)]. Last error: Connection refused
01:26:38,116 cassandra.cluster WARNING [control connection] Error connecting to 127.0.0.3:9042:
Traceback (most recent call last):
  File "cassandra/cluster.py", line 3522, in cassandra.cluster.ControlConnection._reconnect_internal
  File "cassandra/cluster.py", line 3544, in cassandra.cluster.ControlConnection._try_connect
  File "cassandra/cluster.py", line 1620, in cassandra.cluster.Cluster.connection_factory
  File "cassandra/connection.py", line 831, in cassandra.connection.Connection.factory
  File "/users/masix/dtest/src/cassandra-driver/cassandra/io/libevreactor.py", line 267, in __init__
    self._connect_socket()
  File "cassandra/connection.py", line 898, in cassandra.connection.Connection._connect_socket
ConnectionRefusedError: [Errno 111] Tried connecting to [('127.0.0.3', 9042)]. Last error: Connection refused
01:26:39,124 cassandra.cluster WARNING [control connection] Error connecting to 127.0.0.3:9042:
Traceback (most recent call last):
  File "cassandra/cluster.py", line 3522, in cassandra.cluster.ControlConnection._reconnect_internal
  File "cassandra/cluster.py", line 3544, in cassandra.cluster.ControlConnection._try_connect
  File "cassandra/cluster.py", line 1620, in cassandra.cluster.Cluster.connection_factory
  File "cassandra/connection.py", line 831, in cassandra.connection.Connection.factory
  File "/users/masix/dtest/src/cassandra-driver/cassandra/io/libevreactor.py", line 267, in __init__
    self._connect_socket()
  File "cassandra/connection.py", line 898, in cassandra.connection.Connection._connect_socket
ConnectionRefusedError: [Errno 111] Tried connecting to [('127.0.0.3', 9042)]. Last error: Connection refused
01:26:39,127 cassandra.cluster WARNING [control connection] Error connecting to 127.0.0.2:9042:
Traceback (most recent call last):
  File "cassandra/cluster.py", line 3522, in cassandra.cluster.ControlConnection._reconnect_internal
  File "cassandra/cluster.py", line 3544, in cassandra.cluster.ControlConnection._try_connect
  File "cassandra/cluster.py", line 1620, in cassandra.cluster.Cluster.connection_factory
  File "cassandra/connection.py", line 831, in cassandra.connection.Connection.factory
  File "/users/masix/dtest/src/cassandra-driver/cassandra/io/libevreactor.py", line 267, in __init__
    self._connect_socket()
  File "cassandra/connection.py", line 898, in cassandra.connection.Connection._connect_socket
ConnectionRefusedError: [Errno 111] Tried connecting to [('127.0.0.2', 9042)]. Last error: Connection refused
01:26:39,724 cassandra.pool WARNING Error attempting to reconnect to 127.0.0.3:9042, scheduling retry in 8.16 seconds: [Errno 111] Tried connecting to [('127.0.0.3', 9042)]. Last error: Connection refused
01:26:39,752 cassandra.cluster WARNING [control connection] Error connecting to 127.0.0.1:9042:
Traceback (most recent call last):
  File "cassandra/cluster.py", line 3522, in cassandra.cluster.ControlConnection._reconnect_internal
  File "cassandra/cluster.py", line 3544, in cassandra.cluster.ControlConnection._try_connect
  File "cassandra/cluster.py", line 1620, in cassandra.cluster.Cluster.connection_factory
  File "cassandra/connection.py", line 831, in cassandra.connection.Connection.factory
  File "/users/masix/dtest/src/cassandra-driver/cassandra/io/libevreactor.py", line 267, in __init__
    self._connect_socket()
  File "cassandra/connection.py", line 898, in cassandra.connection.Connection._connect_socket
ConnectionRefusedError: [Errno 111] Tried connecting to [('127.0.0.1', 9042)]. Last error: Connection refused
01:26:39,754 cassandra.cluster WARNING [control connection] Error connecting to 127.0.0.2:9042:
Traceback (most recent call last):
  File "cassandra/cluster.py", line 3522, in cassandra.cluster.ControlConnection._reconnect_internal
  File "cassandra/cluster.py", line 3544, in cassandra.cluster.ControlConnection._try_connect
  File "cassandra/cluster.py", line 1620, in cassandra.cluster.Cluster.connection_factory
  File "cassandra/connection.py", line 831, in cassandra.connection.Connection.factory
  File "/users/masix/dtest/src/cassandra-driver/cassandra/io/libevreactor.py", line 267, in __init__
    self._connect_socket()
  File "cassandra/connection.py", line 898, in cassandra.connection.Connection._connect_socket
ConnectionRefusedError: [Errno 111] Tried connecting to [('127.0.0.2', 9042)]. Last error: Connection refused
01:26:39,824 cassandra.cluster WARNING [control connection] Error connecting to 127.0.0.2:9042:
Traceback (most recent call last):
  File "cassandra/cluster.py", line 3522, in cassandra.cluster.ControlConnection._reconnect_internal
  File "cassandra/cluster.py", line 3544, in cassandra.cluster.ControlConnection._try_connect
  File "cassandra/cluster.py", line 1620, in cassandra.cluster.Cluster.connection_factory
  File "cassandra/connection.py", line 831, in cassandra.connection.Connection.factory
  File "/users/masix/dtest/src/cassandra-driver/cassandra/io/libevreactor.py", line 267, in __init__
    self._connect_socket()
  File "cassandra/connection.py", line 898, in cassandra.connection.Connection._connect_socket
ConnectionRefusedError: [Errno 111] Tried connecting to [('127.0.0.2', 9042)]. Last error: Connection refused
01:26:39,932 cassandra.pool WARNING Error attempting to reconnect to 127.0.0.3:9042, scheduling retry in 8.72 seconds: [Errno 111] Tried connecting to [('127.0.0.3', 9042)]. Last error: Connection refused
01:26:40,153 cassandra.pool WARNING Error attempting to reconnect to 127.0.0.3:9042, scheduling retry in 7.6 seconds: [Errno 111] Tried connecting to [('127.0.0.3', 9042)]. Last error: Connection refused
01:26:40,927 cassandra.pool WARNING Error attempting to reconnect to 127.0.0.1:9042, scheduling retry in 27.52 seconds: [Errno 111] Tried connecting to [('127.0.0.1', 9042)]. Last error: Connection refused
01:26:40,935 cassandra.pool WARNING Error attempting to reconnect to 127.0.0.2:9042, scheduling retry in 8.0 seconds: [Errno 111] Tried connecting to [('127.0.0.2', 9042)]. Last error: Connection refused
01:26:41,133 cassandra.cluster WARNING [control connection] Error connecting to 127.0.0.2:9042:
Traceback (most recent call last):
  File "cassandra/cluster.py", line 3522, in cassandra.cluster.ControlConnection._reconnect_internal
  File "cassandra/cluster.py", line 3544, in cassandra.cluster.ControlConnection._try_connect
  File "cassandra/cluster.py", line 1620, in cassandra.cluster.Cluster.connection_factory
  File "cassandra/connection.py", line 831, in cassandra.connection.Connection.factory
  File "/users/masix/dtest/src/cassandra-driver/cassandra/io/libevreactor.py", line 267, in __init__
    self._connect_socket()
  File "cassandra/connection.py", line 898, in cassandra.connection.Connection._connect_socket
ConnectionRefusedError: [Errno 111] Tried connecting to [('127.0.0.2', 9042)]. Last error: Connection refused
01:26:41,143 cassandra.pool WARNING Error attempting to reconnect to 127.0.0.3:9042, scheduling retry in 7.2 seconds: [Errno 111] Tried connecting to [('127.0.0.3', 9042)]. Last error: Connection refused
01:26:41,146 cassandra.cluster WARNING [control connection] Error connecting to 127.0.0.3:9042:
Traceback (most recent call last):
  File "cassandra/cluster.py", line 3522, in cassandra.cluster.ControlConnection._reconnect_internal
  File "cassandra/cluster.py", line 3544, in cassandra.cluster.ControlConnection._try_connect
  File "cassandra/cluster.py", line 1620, in cassandra.cluster.Cluster.connection_factory
  File "cassandra/connection.py", line 831, in cassandra.connection.Connection.factory
  File "/users/masix/dtest/src/cassandra-driver/cassandra/io/libevreactor.py", line 267, in __init__
    self._connect_socket()
  File "cassandra/connection.py", line 898, in cassandra.connection.Connection._connect_socket
ConnectionRefusedError: [Errno 111] Tried connecting to [('127.0.0.3', 9042)]. Last error: Connection refused
01:26:41,438 cassandra.pool WARNING Error attempting to reconnect to 127.0.0.1:9042, scheduling retry in 27.52 seconds: [Errno 111] Tried connecting to [('127.0.0.1', 9042)]. Last error: Connection refused
01:26:41,641 cassandra.pool WARNING Error attempting to reconnect to 127.0.0.1:9042, scheduling retry in 8.24 seconds: [Errno 111] Tried connecting to [('127.0.0.1', 9042)]. Last error: Connection refused
01:26:41,681 cassandra.cluster WARNING Host 127.0.0.3:9042 has been marked down
01:26:41,683 cassandra.cluster WARNING [control connection] Error connecting to 127.0.0.3:9042:
Traceback (most recent call last):
  File "cassandra/cluster.py", line 3522, in cassandra.cluster.ControlConnection._reconnect_internal
  File "cassandra/cluster.py", line 3544, in cassandra.cluster.ControlConnection._try_connect
  File "cassandra/cluster.py", line 1620, in cassandra.cluster.Cluster.connection_factory
  File "cassandra/connection.py", line 831, in cassandra.connection.Connection.factory
  File "/users/masix/dtest/src/cassandra-driver/cassandra/io/libevreactor.py", line 267, in __init__
    self._connect_socket()
  File "cassandra/connection.py", line 898, in cassandra.connection.Connection._connect_socket
ConnectionRefusedError: [Errno 111] Tried connecting to [('127.0.0.3', 9042)]. Last error: Connection refused
01:26:42,838 cassandra.pool WARNING Error attempting to reconnect to 127.0.0.3:9042, scheduling retry in 1.82 seconds: [Errno 111] Tried connecting to [('127.0.0.3', 9042)]. Last error: Connection refused
01:26:44,740 cassandra.pool WARNING Error attempting to reconnect to 127.0.0.3:9042, scheduling retry in 4.28 seconds: [Errno 111] Tried connecting to [('127.0.0.3', 9042)]. Last error: Connection refused
01:26:45,141 cassandra.pool WARNING Error attempting to reconnect to 127.0.0.1:9042, scheduling retry in 34.88 seconds: [Errno 111] Tried connecting to [('127.0.0.1', 9042)]. Last error: Connection refused
01:26:45,342 cassandra.pool WARNING Error attempting to reconnect to 127.0.0.1:9042, scheduling retry in 32.0 seconds: [Errno 111] Tried connecting to [('127.0.0.1', 9042)]. Last error: Connection refused
01:26:45,444 cassandra.cluster WARNING [control connection] Error connecting to 127.0.0.3:9042:
Traceback (most recent call last):
  File "cassandra/cluster.py", line 3522, in cassandra.cluster.ControlConnection._reconnect_internal
  File "cassandra/cluster.py", line 3544, in cassandra.cluster.ControlConnection._try_connect
  File "cassandra/cluster.py", line 1620, in cassandra.cluster.Cluster.connection_factory
  File "cassandra/connection.py", line 831, in cassandra.connection.Connection.factory
  File "/users/masix/dtest/src/cassandra-driver/cassandra/io/libevreactor.py", line 267, in __init__
    self._connect_socket()
  File "cassandra/connection.py", line 898, in cassandra.connection.Connection._connect_socket
ConnectionRefusedError: [Errno 111] Tried connecting to [('127.0.0.3', 9042)]. Last error: Connection refused
01:26:45,446 cassandra.cluster WARNING [control connection] Error connecting to 127.0.0.2:9042:
Traceback (most recent call last):
  File "cassandra/cluster.py", line 3522, in cassandra.cluster.ControlConnection._reconnect_internal
  File "cassandra/cluster.py", line 3544, in cassandra.cluster.ControlConnection._try_connect
  File "cassandra/cluster.py", line 1620, in cassandra.cluster.Cluster.connection_factory
  File "cassandra/connection.py", line 831, in cassandra.connection.Connection.factory
  File "/users/masix/dtest/src/cassandra-driver/cassandra/io/libevreactor.py", line 267, in __init__
    self._connect_socket()
  File "cassandra/connection.py", line 898, in cassandra.connection.Connection._connect_socket
ConnectionRefusedError: [Errno 111] Tried connecting to [('127.0.0.2', 9042)]. Last error: Connection refused
01:26:47,376 cassandra.cluster WARNING [control connection] Error connecting to 127.0.0.2:9042:
Traceback (most recent call last):
  File "cassandra/cluster.py", line 3522, in cassandra.cluster.ControlConnection._reconnect_internal
  File "cassandra/cluster.py", line 3544, in cassandra.cluster.ControlConnection._try_connect
  File "cassandra/cluster.py", line 1620, in cassandra.cluster.Cluster.connection_factory
  File "cassandra/connection.py", line 831, in cassandra.connection.Connection.factory
  File "/users/masix/dtest/src/cassandra-driver/cassandra/io/libevreactor.py", line 267, in __init__
    self._connect_socket()
  File "cassandra/connection.py", line 898, in cassandra.connection.Connection._connect_socket
ConnectionRefusedError: [Errno 111] Tried connecting to [('127.0.0.2', 9042)]. Last error: Connection refused
01:26:47,377 cassandra.cluster WARNING [control connection] Error connecting to 127.0.0.1:9042:
Traceback (most recent call last):
  File "cassandra/cluster.py", line 3522, in cassandra.cluster.ControlConnection._reconnect_internal
  File "cassandra/cluster.py", line 3544, in cassandra.cluster.ControlConnection._try_connect
  File "cassandra/cluster.py", line 1620, in cassandra.cluster.Cluster.connection_factory
  File "cassandra/connection.py", line 831, in cassandra.connection.Connection.factory
  File "/users/masix/dtest/src/cassandra-driver/cassandra/io/libevreactor.py", line 267, in __init__
    self._connect_socket()
  File "cassandra/connection.py", line 898, in cassandra.connection.Connection._connect_socket
ConnectionRefusedError: [Errno 111] Tried connecting to [('127.0.0.1', 9042)]. Last error: Connection refused
01:26:47,748 cassandra.cluster WARNING [control connection] Error connecting to 127.0.0.2:9042:
Traceback (most recent call last):
  File "cassandra/cluster.py", line 3522, in cassandra.cluster.ControlConnection._reconnect_internal
  File "cassandra/cluster.py", line 3544, in cassandra.cluster.ControlConnection._try_connect
  File "cassandra/cluster.py", line 1620, in cassandra.cluster.Cluster.connection_factory
  File "cassandra/connection.py", line 831, in cassandra.connection.Connection.factory
  File "/users/masix/dtest/src/cassandra-driver/cassandra/io/libevreactor.py", line 267, in __init__
    self._connect_socket()
  File "cassandra/connection.py", line 898, in cassandra.connection.Connection._connect_socket
ConnectionRefusedError: [Errno 111] Tried connecting to [('127.0.0.2', 9042)]. Last error: Connection refused
01:26:47,777 cassandra.pool WARNING Error attempting to reconnect to 127.0.0.3:9042, scheduling retry in 16.16 seconds: [Errno 111] Tried connecting to [('127.0.0.3', 9042)]. Last error: Connection refused
01:26:47,949 cassandra.pool WARNING Error attempting to reconnect to 127.0.0.3:9042, scheduling retry in 17.28 seconds: [Errno 111] Tried connecting to [('127.0.0.3', 9042)]. Last error: Connection refused
01:26:48,358 cassandra.pool WARNING Error attempting to reconnect to 127.0.0.3:9042, scheduling retry in 15.36 seconds: [Errno 111] Tried connecting to [('127.0.0.3', 9042)]. Last error: Connection refused
01:26:48,660 cassandra.pool WARNING Error attempting to reconnect to 127.0.0.3:9042, scheduling retry in 16.32 seconds: [Errno 111] Tried connecting to [('127.0.0.3', 9042)]. Last error: Connection refused
01:26:48,960 cassandra.pool WARNING Error attempting to reconnect to 127.0.0.2:9042, scheduling retry in 18.4 seconds: [Errno 111] Tried connecting to [('127.0.0.2', 9042)]. Last error: Connection refused
01:26:49,51 cassandra.pool WARNING Error attempting to reconnect to 127.0.0.3:9042, scheduling retry in 9.12 seconds: [Errno 111] Tried connecting to [('127.0.0.3', 9042)]. Last error: Connection refused
01:26:49,962 cassandra.pool WARNING Error attempting to reconnect to 127.0.0.1:9042, scheduling retry in 14.88 seconds: [Errno 111] Tried connecting to [('127.0.0.1', 9042)]. Last error: Connection refused
01:26:50,164 cassandra.pool WARNING Error attempting to reconnect to 127.0.0.2:9042, scheduling retry in 36.8 seconds: [Errno 111] Tried connecting to [('127.0.0.2', 9042)]. Last error: Connection refused
01:26:50,178 cassandra.cluster WARNING Host 127.0.0.3:9042 has been marked down
01:26:50,180 cassandra.cluster WARNING [control connection] Error connecting to 127.0.0.3:9042:
Traceback (most recent call last):
  File "cassandra/cluster.py", line 3522, in cassandra.cluster.ControlConnection._reconnect_internal
  File "cassandra/cluster.py", line 3544, in cassandra.cluster.ControlConnection._try_connect
  File "cassandra/cluster.py", line 1620, in cassandra.cluster.Cluster.connection_factory
  File "cassandra/connection.py", line 831, in cassandra.connection.Connection.factory
  File "/users/masix/dtest/src/cassandra-driver/cassandra/io/libevreactor.py", line 267, in __init__
    self._connect_socket()
  File "cassandra/connection.py", line 898, in cassandra.connection.Connection._connect_socket
ConnectionRefusedError: [Errno 111] Tried connecting to [('127.0.0.3', 9042)]. Last error: Connection refused
01:26:51,357 cassandra.pool WARNING Error attempting to reconnect to 127.0.0.3:9042, scheduling retry in 2.12 seconds: [Errno 111] Tried connecting to [('127.0.0.3', 9042)]. Last error: Connection refused
01:26:53,563 cassandra.pool WARNING Error attempting to reconnect to 127.0.0.3:9042, scheduling retry in 3.44 seconds: [Errno 111] Tried connecting to [('127.0.0.3', 9042)]. Last error: Connection refused
01:26:54,65 cassandra.cluster WARNING [control connection] Error connecting to 127.0.0.2:9042:
Traceback (most recent call last):
  File "cassandra/cluster.py", line 3522, in cassandra.cluster.ControlConnection._reconnect_internal
  File "cassandra/cluster.py", line 3544, in cassandra.cluster.ControlConnection._try_connect
  File "cassandra/cluster.py", line 1620, in cassandra.cluster.Cluster.connection_factory
  File "cassandra/connection.py", line 831, in cassandra.connection.Connection.factory
  File "/users/masix/dtest/src/cassandra-driver/cassandra/io/libevreactor.py", line 267, in __init__
    self._connect_socket()
  File "cassandra/connection.py", line 898, in cassandra.connection.Connection._connect_socket
ConnectionRefusedError: [Errno 111] Tried connecting to [('127.0.0.2', 9042)]. Last error: Connection refused
01:26:54,67 cassandra.cluster WARNING [control connection] Error connecting to 127.0.0.3:9042:
Traceback (most recent call last):
  File "cassandra/cluster.py", line 3522, in cassandra.cluster.ControlConnection._reconnect_internal
  File "cassandra/cluster.py", line 3544, in cassandra.cluster.ControlConnection._try_connect
  File "cassandra/cluster.py", line 1620, in cassandra.cluster.Cluster.connection_factory
  File "cassandra/connection.py", line 831, in cassandra.connection.Connection.factory
  File "/users/masix/dtest/src/cassandra-driver/cassandra/io/libevreactor.py", line 267, in __init__
    self._connect_socket()
  File "cassandra/connection.py", line 898, in cassandra.connection.Connection._connect_socket
ConnectionRefusedError: [Errno 111] Tried connecting to [('127.0.0.3', 9042)]. Last error: Connection refused
01:26:54,365 cassandra.pool WARNING Error attempting to reconnect to 127.0.0.2:9042, scheduling retry in 28.48 seconds: [Errno 111] Tried connecting to [('127.0.0.2', 9042)]. Last error: Connection refused
01:26:56,55 cassandra.cluster WARNING [control connection] Error connecting to 127.0.0.2:9042:
Traceback (most recent call last):
  File "cassandra/cluster.py", line 3522, in cassandra.cluster.ControlConnection._reconnect_internal
  File "cassandra/cluster.py", line 3544, in cassandra.cluster.ControlConnection._try_connect
  File "cassandra/cluster.py", line 1620, in cassandra.cluster.Cluster.connection_factory
  File "cassandra/connection.py", line 831, in cassandra.connection.Connection.factory
  File "/users/masix/dtest/src/cassandra-driver/cassandra/io/libevreactor.py", line 267, in __init__
    self._connect_socket()
  File "cassandra/connection.py", line 898, in cassandra.connection.Connection._connect_socket
ConnectionRefusedError: [Errno 111] Tried connecting to [('127.0.0.2', 9042)]. Last error: Connection refused
01:26:57,73 cassandra.pool WARNING Error attempting to reconnect to 127.0.0.3:9042, scheduling retry in 8.88 seconds: [Errno 111] Tried connecting to [('127.0.0.3', 9042)]. Last error: Connection refused
01:26:57,73 cassandra.cluster WARNING [control connection] Error connecting to 127.0.0.2:9042:
Traceback (most recent call last):
  File "cassandra/cluster.py", line 3522, in cassandra.cluster.ControlConnection._reconnect_internal
  File "cassandra/cluster.py", line 3544, in cassandra.cluster.ControlConnection._try_connect
  File "cassandra/cluster.py", line 1620, in cassandra.cluster.Cluster.connection_factory
  File "cassandra/connection.py", line 831, in cassandra.connection.Connection.factory
  File "/users/masix/dtest/src/cassandra-driver/cassandra/io/libevreactor.py", line 267, in __init__
    self._connect_socket()
  File "cassandra/connection.py", line 898, in cassandra.connection.Connection._connect_socket
ConnectionRefusedError: [Errno 111] Tried connecting to [('127.0.0.2', 9042)]. Last error: Connection refused
01:26:58,176 cassandra.pool WARNING Error attempting to reconnect to 127.0.0.3:9042, scheduling retry in 17.44 seconds: [Errno 111] Tried connecting to [('127.0.0.3', 9042)]. Last error: Connection refused
01:26:58,977 cassandra.cluster WARNING [control connection] Error connecting to 127.0.0.2:9042:
Traceback (most recent call last):
  File "cassandra/cluster.py", line 3522, in cassandra.cluster.ControlConnection._reconnect_internal
  File "cassandra/cluster.py", line 3544, in cassandra.cluster.ControlConnection._try_connect
  File "cassandra/cluster.py", line 1620, in cassandra.cluster.Cluster.connection_factory
  File "cassandra/connection.py", line 831, in cassandra.connection.Connection.factory
  File "/users/masix/dtest/src/cassandra-driver/cassandra/io/libevreactor.py", line 267, in __init__
    self._connect_socket()
  File "cassandra/connection.py", line 898, in cassandra.connection.Connection._connect_socket
ConnectionRefusedError: [Errno 111] Tried connecting to [('127.0.0.2', 9042)]. Last error: Connection refused
PASSED                                                                   [100%]
===Flaky Test Report===

test_functional passed 1 out of the required 1 times. Success!

===End Flaky Test Report===

========================== 1 passed in 510.24 seconds ==========================
[msx] rc = 0
