cassandra replace_address_test.py::TestReplaceAddress::test_resume_failed_replace true true
the_test is replace_address_test.py::TestReplaceAddress::test_resume_failed_replace
============================= test session starts ==============================
platform linux -- Python 3.6.9, pytest-3.6.4, py-1.11.0, pluggy-0.7.1 -- /users/masix/dtest/bin/python
cachedir: .pytest_cache
rootdir: /users/masix/cassandra-dtest, inifile: pytest.ini
plugins: timeout-1.4.2, repeat-0.9.1, flaky-3.7.0
timeout: 900.0s
timeout method: signal
timeout func_only: False
collecting ... collected 1 item

replace_address_test.py::TestReplaceAddress::test_resume_failed_replace 
-------------------------------- live log call ---------------------------------
09:43:01,123 ccmlib.node WARNING [msx] ccmlib:copy_config_files.py, conf_dir = /users/masix/cassandra/conf
09:43:01,208 ccmlib.node WARNING [msx] ccmlib:node.py, self.name = node1
09:43:01,208 ccmlib.node WARNING [msx] ccmlib:node.py, sstable_preemptive_open_interval_in_mb = 50
09:43:01,277 ccmlib.node WARNING [msx] ccmlib:node.py, self.name = node1
09:43:01,277 ccmlib.node WARNING [msx] ccmlib:node.py, sstable_preemptive_open_interval_in_mb = 50
09:43:01,370 ccmlib.node WARNING [msx] ccmlib:copy_config_files.py, conf_dir = /users/masix/cassandra/conf
09:43:01,454 ccmlib.node WARNING [msx] ccmlib:node.py, self.name = node2
09:43:01,454 ccmlib.node WARNING [msx] ccmlib:node.py, sstable_preemptive_open_interval_in_mb = 50
09:43:01,520 ccmlib.node WARNING [msx] ccmlib:node.py, self.name = node2
09:43:01,520 ccmlib.node WARNING [msx] ccmlib:node.py, sstable_preemptive_open_interval_in_mb = 50
09:43:01,622 ccmlib.node WARNING [msx] ccmlib:copy_config_files.py, conf_dir = /users/masix/cassandra/conf
09:43:01,706 ccmlib.node WARNING [msx] ccmlib:node.py, self.name = node3
09:43:01,706 ccmlib.node WARNING [msx] ccmlib:node.py, sstable_preemptive_open_interval_in_mb = 50
09:43:01,773 ccmlib.node WARNING [msx] ccmlib:node.py, self.name = node3
09:43:01,773 ccmlib.node WARNING [msx] ccmlib:node.py, sstable_preemptive_open_interval_in_mb = 50
09:43:01,827 ccmlib.node WARNING [msx] ccmlib:copy_config_files.py, conf_dir = /users/masix/cassandra/conf
09:43:01,911 ccmlib.node WARNING [msx] ccmlib:node.py, self.name = node1
09:43:01,911 ccmlib.node WARNING [msx] ccmlib:node.py, sstable_preemptive_open_interval_in_mb = 50
09:43:01,961 ccmlib.node WARNING [msx] ccmlib:copy_config_files.py, conf_dir = /users/masix/cassandra/conf
09:43:02,45 ccmlib.node WARNING [msx] ccmlib:node.py, self.name = node2
09:43:02,45 ccmlib.node WARNING [msx] ccmlib:node.py, sstable_preemptive_open_interval_in_mb = 50
09:43:02,96 ccmlib.node WARNING [msx] ccmlib:copy_config_files.py, conf_dir = /users/masix/cassandra/conf
09:43:02,180 ccmlib.node WARNING [msx] ccmlib:node.py, self.name = node3
09:43:02,180 ccmlib.node WARNING [msx] ccmlib:node.py, sstable_preemptive_open_interval_in_mb = 50
09:43:02,230 ccmlib.node WARNING [msx] ccmlib:copy_config_files.py, conf_dir = /users/masix/cassandra/conf
09:43:02,314 ccmlib.node WARNING [msx] ccmlib:node.py, self.name = node1
09:43:02,314 ccmlib.node WARNING [msx] ccmlib:node.py, sstable_preemptive_open_interval_in_mb = 50
09:43:23,845 cassandra.protocol WARNING Server warning: When increasing replication factor you need to run a full (-full) repair to distribute the data.
09:44:13,873 cassandra.cluster WARNING Host 127.0.0.3:9042 has been marked down
09:44:13,875 cassandra.cluster WARNING Host 127.0.0.3:9042 has been marked down
09:44:14,881 cassandra.pool WARNING Error attempting to reconnect to 127.0.0.3:9042, scheduling retry in 1.76 seconds: [Errno 111] Tried connecting to [('127.0.0.3', 9042)]. Last error: Connection refused
09:44:14,938 cassandra.cluster WARNING Failed to create connection pool for new host 127.0.0.3:9042:
Traceback (most recent call last):
  File "cassandra/cluster.py", line 3175, in cassandra.cluster.Session.add_or_renew_pool.run_add_or_renew_pool
  File "cassandra/pool.py", line 402, in cassandra.pool.HostConnection.__init__
  File "cassandra/cluster.py", line 1620, in cassandra.cluster.Cluster.connection_factory
  File "cassandra/connection.py", line 831, in cassandra.connection.Connection.factory
  File "/users/masix/dtest/src/cassandra-driver/cassandra/io/libevreactor.py", line 267, in __init__
    self._connect_socket()
  File "cassandra/connection.py", line 898, in cassandra.connection.Connection._connect_socket
ConnectionRefusedError: [Errno 111] Tried connecting to [('127.0.0.3', 9042)]. Last error: Connection refused
09:44:14,942 cassandra.cluster WARNING Host 127.0.0.3:9042 has been marked down
09:44:14,984 cassandra.pool WARNING Error attempting to reconnect to 127.0.0.3:9042, scheduling retry in 1.7 seconds: [Errno 111] Tried connecting to [('127.0.0.3', 9042)]. Last error: Connection refused
09:44:15,196 ccmlib.node WARNING [msx] ccmlib:copy_config_files.py, conf_dir = /users/masix/cassandra/conf
09:44:15,282 ccmlib.node WARNING [msx] ccmlib:node.py, self.name = replacement
09:44:15,282 ccmlib.node WARNING [msx] ccmlib:node.py, sstable_preemptive_open_interval_in_mb = 50
09:44:15,352 ccmlib.node WARNING [msx] ccmlib:node.py, self.name = replacement
09:44:15,352 ccmlib.node WARNING [msx] ccmlib:node.py, sstable_preemptive_open_interval_in_mb = 50
09:44:15,967 cassandra.pool WARNING Error attempting to reconnect to 127.0.0.3:9042, scheduling retry in 1.9 seconds: [Errno 111] Tried connecting to [('127.0.0.3', 9042)]. Last error: Connection refused
09:44:16,695 cassandra.pool WARNING Error attempting to reconnect to 127.0.0.3:9042, scheduling retry in 4.52 seconds: [Errno 111] Tried connecting to [('127.0.0.3', 9042)]. Last error: Connection refused
09:44:16,695 cassandra.pool WARNING Error attempting to reconnect to 127.0.0.3:9042, scheduling retry in 3.84 seconds: [Errno 111] Tried connecting to [('127.0.0.3', 9042)]. Last error: Connection refused
09:44:17,875 cassandra.pool WARNING Error attempting to reconnect to 127.0.0.3:9042, scheduling retry in 4.52 seconds: [Errno 111] Tried connecting to [('127.0.0.3', 9042)]. Last error: Connection refused
09:44:20,607 cassandra.pool WARNING Error attempting to reconnect to 127.0.0.3:9042, scheduling retry in 8.16 seconds: [Errno 111] Tried connecting to [('127.0.0.3', 9042)]. Last error: Connection refused
09:44:21,309 cassandra.pool WARNING Error attempting to reconnect to 127.0.0.3:9042, scheduling retry in 7.84 seconds: [Errno 111] Tried connecting to [('127.0.0.3', 9042)]. Last error: Connection refused
09:44:22,489 cassandra.pool WARNING Error attempting to reconnect to 127.0.0.3:9042, scheduling retry in 8.48 seconds: [Errno 111] Tried connecting to [('127.0.0.3', 9042)]. Last error: Connection refused
09:44:28,830 cassandra.pool WARNING Error attempting to reconnect to 127.0.0.3:9042, scheduling retry in 14.4 seconds: [Errno 111] Tried connecting to [('127.0.0.3', 9042)]. Last error: Connection refused
09:44:29,231 cassandra.pool WARNING Error attempting to reconnect to 127.0.0.3:9042, scheduling retry in 15.68 seconds: [Errno 111] Tried connecting to [('127.0.0.3', 9042)]. Last error: Connection refused
09:44:31,13 cassandra.pool WARNING Error attempting to reconnect to 127.0.0.3:9042, scheduling retry in 15.04 seconds: [Errno 111] Tried connecting to [('127.0.0.3', 9042)]. Last error: Connection refused
09:44:43,269 cassandra.pool WARNING Error attempting to reconnect to 127.0.0.3:9042, scheduling retry in 35.84 seconds: [Errno 111] Tried connecting to [('127.0.0.3', 9042)]. Last error: Connection refused
09:44:44,973 cassandra.pool WARNING Error attempting to reconnect to 127.0.0.3:9042, scheduling retry in 28.48 seconds: [Errno 111] Tried connecting to [('127.0.0.3', 9042)]. Last error: Connection refused
09:44:46,153 cassandra.pool WARNING Error attempting to reconnect to 127.0.0.3:9042, scheduling retry in 33.6 seconds: [Errno 111] Tried connecting to [('127.0.0.3', 9042)]. Last error: Connection refused
09:45:01,615 cassandra.cluster WARNING Host 127.0.0.1:9042 has been marked down
09:45:01,617 cassandra.cluster WARNING [control connection] Error connecting to 127.0.0.1:9042:
Traceback (most recent call last):
  File "cassandra/cluster.py", line 3522, in cassandra.cluster.ControlConnection._reconnect_internal
  File "cassandra/cluster.py", line 3544, in cassandra.cluster.ControlConnection._try_connect
  File "cassandra/cluster.py", line 1620, in cassandra.cluster.Cluster.connection_factory
  File "cassandra/connection.py", line 831, in cassandra.connection.Connection.factory
  File "/users/masix/dtest/src/cassandra-driver/cassandra/io/libevreactor.py", line 267, in __init__
    self._connect_socket()
  File "cassandra/connection.py", line 898, in cassandra.connection.Connection._connect_socket
ConnectionRefusedError: [Errno 111] Tried connecting to [('127.0.0.1', 9042)]. Last error: Connection refused
09:45:02,723 cassandra.pool WARNING Error attempting to reconnect to 127.0.0.1:9042, scheduling retry in 2.3 seconds: [Errno 111] Tried connecting to [('127.0.0.1', 9042)]. Last error: Connection refused
09:45:05,29 cassandra.pool WARNING Error attempting to reconnect to 127.0.0.1:9042, scheduling retry in 3.44 seconds: [Errno 111] Tried connecting to [('127.0.0.1', 9042)]. Last error: Connection refused
09:45:08,538 cassandra.pool WARNING Error attempting to reconnect to 127.0.0.1:9042, scheduling retry in 8.32 seconds: [Errno 111] Tried connecting to [('127.0.0.1', 9042)]. Last error: Connection refused
09:45:13,550 cassandra.pool WARNING Error attempting to reconnect to 127.0.0.3:9042, scheduling retry in 73.6 seconds: [Errno 111] Tried connecting to [('127.0.0.3', 9042)]. Last error: Connection refused
09:45:14,937 cassandra.cluster WARNING Host 127.0.0.1:9042 has been marked down
09:45:14,937 cassandra.cluster WARNING Host 127.0.0.2:9042 has been marked down
09:45:14,939 cassandra.cluster WARNING [control connection] Error connecting to 127.0.0.2:9042:
Traceback (most recent call last):
  File "cassandra/cluster.py", line 3522, in cassandra.cluster.ControlConnection._reconnect_internal
  File "cassandra/cluster.py", line 3544, in cassandra.cluster.ControlConnection._try_connect
  File "cassandra/cluster.py", line 1620, in cassandra.cluster.Cluster.connection_factory
  File "cassandra/connection.py", line 831, in cassandra.connection.Connection.factory
  File "/users/masix/dtest/src/cassandra-driver/cassandra/io/libevreactor.py", line 267, in __init__
    self._connect_socket()
  File "cassandra/connection.py", line 898, in cassandra.connection.Connection._connect_socket
ConnectionRefusedError: [Errno 111] Tried connecting to [('127.0.0.2', 9042)]. Last error: Connection refused
09:45:16,137 cassandra.pool WARNING Error attempting to reconnect to 127.0.0.2:9042, scheduling retry in 1.94 seconds: [Errno 111] Tried connecting to [('127.0.0.2', 9042)]. Last error: Connection refused
09:45:16,138 cassandra.pool WARNING Error attempting to reconnect to 127.0.0.1:9042, scheduling retry in 2.0 seconds: [Errno 111] Tried connecting to [('127.0.0.1', 9042)]. Last error: Connection refused
09:45:16,959 cassandra.pool WARNING Error attempting to reconnect to 127.0.0.1:9042, scheduling retry in 15.04 seconds: [Errno 111] Tried connecting to [('127.0.0.1', 9042)]. Last error: Connection refused
09:45:18,143 cassandra.pool WARNING Error attempting to reconnect to 127.0.0.2:9042, scheduling retry in 3.88 seconds: [Errno 111] Tried connecting to [('127.0.0.2', 9042)]. Last error: Connection refused
09:45:18,143 cassandra.pool WARNING Error attempting to reconnect to 127.0.0.1:9042, scheduling retry in 4.44 seconds: [Errno 111] Tried connecting to [('127.0.0.1', 9042)]. Last error: Connection refused
09:45:19,847 cassandra.pool WARNING Error attempting to reconnect to 127.0.0.3:9042, scheduling retry in 56.32 seconds: [Errno 111] Tried connecting to [('127.0.0.3', 9042)]. Last error: Connection refused
PASSED                                                                   [100%]
===Flaky Test Report===

test_resume_failed_replace passed 1 out of the required 1 times. Success!

===End Flaky Test Report===

========================== 1 passed in 140.33 seconds ==========================
[msx] rc = 0
