cassandra auth_test.py::TestAuthRoles::test_disallow_grant_revoke_on_builtin_functions true true
log_dts_dir = /users/masix/vm_images/ZebraConf/app_meta/logs
the_test is auth_test.py::TestAuthRoles::test_disallow_grant_revoke_on_builtin_functions
rm: cannot remove '/tmp/my_log.txt': No such file or directory
============================= test session starts ==============================
platform linux -- Python 3.6.9, pytest-3.6.4, py-1.11.0, pluggy-0.7.1 -- /users/masix/dtest/bin/python
cachedir: .pytest_cache
rootdir: /users/masix/cassandra-dtest, inifile: pytest.ini
plugins: flaky-3.7.0, timeout-1.4.2, repeat-0.9.1
timeout: 900.0s
timeout method: signal
timeout func_only: False
collecting ... collected 1 item

auth_test.py::TestAuthRoles::test_disallow_grant_revoke_on_builtin_functions 
-------------------------------- live log setup --------------------------------
18:41:50,754 ccmlib.node WARNING [msx] ccmlib:node.py:start(), self.name= node1, self.pid= 3693
18:41:50,756 ccmlib.cluster WARNING [msx] ccmlib:cluster.py:start() p.pid= 3597 node.name= node1 node.pid= 3693
18:41:58,511 cassandra.cluster WARNING [control connection] Error connecting to 127.0.0.1:9042:
Traceback (most recent call last):
  File "cassandra/cluster.py", line 3522, in cassandra.cluster.ControlConnection._reconnect_internal
  File "cassandra/cluster.py", line 3544, in cassandra.cluster.ControlConnection._try_connect
  File "cassandra/cluster.py", line 1620, in cassandra.cluster.Cluster.connection_factory
  File "cassandra/connection.py", line 837, in cassandra.connection.Connection.factory
  File "cassandra/connection.py", line 600, in cassandra.connection.defunct_on_error.wrapper
  File "cassandra/connection.py", line 1421, in cassandra.connection.Connection._handle_auth_response
cassandra.AuthenticationFailed: Failed to authenticate to 127.0.0.1:9042: Error from server: code=0100 [Bad credentials] message="Provided username cassandra and/or password are incorrect"
18:41:58,515 cassandra.cluster ERROR Control connection failed to connect, shutting down Cluster:
Traceback (most recent call last):
  File "cassandra/cluster.py", line 1690, in cassandra.cluster.Cluster.connect
  File "cassandra/cluster.py", line 3488, in cassandra.cluster.ControlConnection.connect
  File "cassandra/cluster.py", line 3533, in cassandra.cluster.ControlConnection._reconnect_internal
cassandra.cluster.NoHostAvailable: ('Unable to connect to any servers', {'127.0.0.1:9042': AuthenticationFailed('Failed to authenticate to 127.0.0.1:9042: Error from server: code=0100 [Bad credentials] message="Provided username cassandra and/or password are incorrect"',)})
18:41:58,781 cassandra.cluster WARNING [control connection] Error connecting to 127.0.0.1:9042:
Traceback (most recent call last):
  File "cassandra/cluster.py", line 3522, in cassandra.cluster.ControlConnection._reconnect_internal
  File "cassandra/cluster.py", line 3544, in cassandra.cluster.ControlConnection._try_connect
  File "cassandra/cluster.py", line 1620, in cassandra.cluster.Cluster.connection_factory
  File "cassandra/connection.py", line 837, in cassandra.connection.Connection.factory
  File "cassandra/connection.py", line 600, in cassandra.connection.defunct_on_error.wrapper
  File "cassandra/connection.py", line 1421, in cassandra.connection.Connection._handle_auth_response
cassandra.AuthenticationFailed: Failed to authenticate to 127.0.0.1:9042: Error from server: code=0100 [Bad credentials] message="Provided username cassandra and/or password are incorrect"
18:41:58,782 cassandra.cluster ERROR Control connection failed to connect, shutting down Cluster:
Traceback (most recent call last):
  File "cassandra/cluster.py", line 1690, in cassandra.cluster.Cluster.connect
  File "cassandra/cluster.py", line 3488, in cassandra.cluster.ControlConnection.connect
  File "cassandra/cluster.py", line 3533, in cassandra.cluster.ControlConnection._reconnect_internal
cassandra.cluster.NoHostAvailable: ('Unable to connect to any servers', {'127.0.0.1:9042': AuthenticationFailed('Failed to authenticate to 127.0.0.1:9042: Error from server: code=0100 [Bad credentials] message="Provided username cassandra and/or password are incorrect"',)})
18:41:59,47 cassandra.cluster WARNING [control connection] Error connecting to 127.0.0.1:9042:
Traceback (most recent call last):
  File "cassandra/cluster.py", line 3522, in cassandra.cluster.ControlConnection._reconnect_internal
  File "cassandra/cluster.py", line 3544, in cassandra.cluster.ControlConnection._try_connect
  File "cassandra/cluster.py", line 1620, in cassandra.cluster.Cluster.connection_factory
  File "cassandra/connection.py", line 837, in cassandra.connection.Connection.factory
  File "cassandra/connection.py", line 600, in cassandra.connection.defunct_on_error.wrapper
  File "cassandra/connection.py", line 1421, in cassandra.connection.Connection._handle_auth_response
cassandra.AuthenticationFailed: Failed to authenticate to 127.0.0.1:9042: Error from server: code=0100 [Bad credentials] message="Provided username cassandra and/or password are incorrect"
18:41:59,48 cassandra.cluster ERROR Control connection failed to connect, shutting down Cluster:
Traceback (most recent call last):
  File "cassandra/cluster.py", line 1690, in cassandra.cluster.Cluster.connect
  File "cassandra/cluster.py", line 3488, in cassandra.cluster.ControlConnection.connect
  File "cassandra/cluster.py", line 3533, in cassandra.cluster.ControlConnection._reconnect_internal
cassandra.cluster.NoHostAvailable: ('Unable to connect to any servers', {'127.0.0.1:9042': AuthenticationFailed('Failed to authenticate to 127.0.0.1:9042: Error from server: code=0100 [Bad credentials] message="Provided username cassandra and/or password are incorrect"',)})
18:41:59,312 cassandra.cluster WARNING [control connection] Error connecting to 127.0.0.1:9042:
Traceback (most recent call last):
  File "cassandra/cluster.py", line 3522, in cassandra.cluster.ControlConnection._reconnect_internal
  File "cassandra/cluster.py", line 3544, in cassandra.cluster.ControlConnection._try_connect
  File "cassandra/cluster.py", line 1620, in cassandra.cluster.Cluster.connection_factory
  File "cassandra/connection.py", line 837, in cassandra.connection.Connection.factory
  File "cassandra/connection.py", line 600, in cassandra.connection.defunct_on_error.wrapper
  File "cassandra/connection.py", line 1421, in cassandra.connection.Connection._handle_auth_response
cassandra.AuthenticationFailed: Failed to authenticate to 127.0.0.1:9042: Error from server: code=0100 [Bad credentials] message="Provided username cassandra and/or password are incorrect"
18:41:59,313 cassandra.cluster ERROR Control connection failed to connect, shutting down Cluster:
Traceback (most recent call last):
  File "cassandra/cluster.py", line 1690, in cassandra.cluster.Cluster.connect
  File "cassandra/cluster.py", line 3488, in cassandra.cluster.ControlConnection.connect
  File "cassandra/cluster.py", line 3533, in cassandra.cluster.ControlConnection._reconnect_internal
cassandra.cluster.NoHostAvailable: ('Unable to connect to any servers', {'127.0.0.1:9042': AuthenticationFailed('Failed to authenticate to 127.0.0.1:9042: Error from server: code=0100 [Bad credentials] message="Provided username cassandra and/or password are incorrect"',)})
18:41:59,578 cassandra.cluster WARNING [control connection] Error connecting to 127.0.0.1:9042:
Traceback (most recent call last):
  File "cassandra/cluster.py", line 3522, in cassandra.cluster.ControlConnection._reconnect_internal
  File "cassandra/cluster.py", line 3544, in cassandra.cluster.ControlConnection._try_connect
  File "cassandra/cluster.py", line 1620, in cassandra.cluster.Cluster.connection_factory
  File "cassandra/connection.py", line 837, in cassandra.connection.Connection.factory
  File "cassandra/connection.py", line 600, in cassandra.connection.defunct_on_error.wrapper
  File "cassandra/connection.py", line 1421, in cassandra.connection.Connection._handle_auth_response
cassandra.AuthenticationFailed: Failed to authenticate to 127.0.0.1:9042: Error from server: code=0100 [Bad credentials] message="Provided username cassandra and/or password are incorrect"
18:41:59,579 cassandra.cluster ERROR Control connection failed to connect, shutting down Cluster:
Traceback (most recent call last):
  File "cassandra/cluster.py", line 1690, in cassandra.cluster.Cluster.connect
  File "cassandra/cluster.py", line 3488, in cassandra.cluster.ControlConnection.connect
  File "cassandra/cluster.py", line 3533, in cassandra.cluster.ControlConnection._reconnect_internal
cassandra.cluster.NoHostAvailable: ('Unable to connect to any servers', {'127.0.0.1:9042': AuthenticationFailed('Failed to authenticate to 127.0.0.1:9042: Error from server: code=0100 [Bad credentials] message="Provided username cassandra and/or password are incorrect"',)})
18:41:59,843 cassandra.cluster WARNING [control connection] Error connecting to 127.0.0.1:9042:
Traceback (most recent call last):
  File "cassandra/cluster.py", line 3522, in cassandra.cluster.ControlConnection._reconnect_internal
  File "cassandra/cluster.py", line 3544, in cassandra.cluster.ControlConnection._try_connect
  File "cassandra/cluster.py", line 1620, in cassandra.cluster.Cluster.connection_factory
  File "cassandra/connection.py", line 837, in cassandra.connection.Connection.factory
  File "cassandra/connection.py", line 600, in cassandra.connection.defunct_on_error.wrapper
  File "cassandra/connection.py", line 1421, in cassandra.connection.Connection._handle_auth_response
cassandra.AuthenticationFailed: Failed to authenticate to 127.0.0.1:9042: Error from server: code=0100 [Bad credentials] message="Provided username cassandra and/or password are incorrect"
18:41:59,844 cassandra.cluster ERROR Control connection failed to connect, shutting down Cluster:
Traceback (most recent call last):
  File "cassandra/cluster.py", line 1690, in cassandra.cluster.Cluster.connect
  File "cassandra/cluster.py", line 3488, in cassandra.cluster.ControlConnection.connect
  File "cassandra/cluster.py", line 3533, in cassandra.cluster.ControlConnection._reconnect_internal
cassandra.cluster.NoHostAvailable: ('Unable to connect to any servers', {'127.0.0.1:9042': AuthenticationFailed('Failed to authenticate to 127.0.0.1:9042: Error from server: code=0100 [Bad credentials] message="Provided username cassandra and/or password are incorrect"',)})
18:42:00,107 cassandra.cluster WARNING [control connection] Error connecting to 127.0.0.1:9042:
Traceback (most recent call last):
  File "cassandra/cluster.py", line 3522, in cassandra.cluster.ControlConnection._reconnect_internal
  File "cassandra/cluster.py", line 3544, in cassandra.cluster.ControlConnection._try_connect
  File "cassandra/cluster.py", line 1620, in cassandra.cluster.Cluster.connection_factory
  File "cassandra/connection.py", line 837, in cassandra.connection.Connection.factory
  File "cassandra/connection.py", line 600, in cassandra.connection.defunct_on_error.wrapper
  File "cassandra/connection.py", line 1421, in cassandra.connection.Connection._handle_auth_response
cassandra.AuthenticationFailed: Failed to authenticate to 127.0.0.1:9042: Error from server: code=0100 [Bad credentials] message="Provided username cassandra and/or password are incorrect"
18:42:00,108 cassandra.cluster ERROR Control connection failed to connect, shutting down Cluster:
Traceback (most recent call last):
  File "cassandra/cluster.py", line 1690, in cassandra.cluster.Cluster.connect
  File "cassandra/cluster.py", line 3488, in cassandra.cluster.ControlConnection.connect
  File "cassandra/cluster.py", line 3533, in cassandra.cluster.ControlConnection._reconnect_internal
cassandra.cluster.NoHostAvailable: ('Unable to connect to any servers', {'127.0.0.1:9042': AuthenticationFailed('Failed to authenticate to 127.0.0.1:9042: Error from server: code=0100 [Bad credentials] message="Provided username cassandra and/or password are incorrect"',)})
18:42:00,373 cassandra.cluster WARNING [control connection] Error connecting to 127.0.0.1:9042:
Traceback (most recent call last):
  File "cassandra/cluster.py", line 3522, in cassandra.cluster.ControlConnection._reconnect_internal
  File "cassandra/cluster.py", line 3544, in cassandra.cluster.ControlConnection._try_connect
  File "cassandra/cluster.py", line 1620, in cassandra.cluster.Cluster.connection_factory
  File "cassandra/connection.py", line 837, in cassandra.connection.Connection.factory
  File "cassandra/connection.py", line 600, in cassandra.connection.defunct_on_error.wrapper
  File "cassandra/connection.py", line 1421, in cassandra.connection.Connection._handle_auth_response
cassandra.AuthenticationFailed: Failed to authenticate to 127.0.0.1:9042: Error from server: code=0100 [Bad credentials] message="Provided username cassandra and/or password are incorrect"
18:42:00,374 cassandra.cluster ERROR Control connection failed to connect, shutting down Cluster:
Traceback (most recent call last):
  File "cassandra/cluster.py", line 1690, in cassandra.cluster.Cluster.connect
  File "cassandra/cluster.py", line 3488, in cassandra.cluster.ControlConnection.connect
  File "cassandra/cluster.py", line 3533, in cassandra.cluster.ControlConnection._reconnect_internal
cassandra.cluster.NoHostAvailable: ('Unable to connect to any servers', {'127.0.0.1:9042': AuthenticationFailed('Failed to authenticate to 127.0.0.1:9042: Error from server: code=0100 [Bad credentials] message="Provided username cassandra and/or password are incorrect"',)})
18:42:00,639 cassandra.cluster WARNING [control connection] Error connecting to 127.0.0.1:9042:
Traceback (most recent call last):
  File "cassandra/cluster.py", line 3522, in cassandra.cluster.ControlConnection._reconnect_internal
  File "cassandra/cluster.py", line 3544, in cassandra.cluster.ControlConnection._try_connect
  File "cassandra/cluster.py", line 1620, in cassandra.cluster.Cluster.connection_factory
  File "cassandra/connection.py", line 837, in cassandra.connection.Connection.factory
  File "cassandra/connection.py", line 600, in cassandra.connection.defunct_on_error.wrapper
  File "cassandra/connection.py", line 1421, in cassandra.connection.Connection._handle_auth_response
cassandra.AuthenticationFailed: Failed to authenticate to 127.0.0.1:9042: Error from server: code=0100 [Bad credentials] message="Provided username cassandra and/or password are incorrect"
18:42:00,640 cassandra.cluster ERROR Control connection failed to connect, shutting down Cluster:
Traceback (most recent call last):
  File "cassandra/cluster.py", line 1690, in cassandra.cluster.Cluster.connect
  File "cassandra/cluster.py", line 3488, in cassandra.cluster.ControlConnection.connect
  File "cassandra/cluster.py", line 3533, in cassandra.cluster.ControlConnection._reconnect_internal
cassandra.cluster.NoHostAvailable: ('Unable to connect to any servers', {'127.0.0.1:9042': AuthenticationFailed('Failed to authenticate to 127.0.0.1:9042: Error from server: code=0100 [Bad credentials] message="Provided username cassandra and/or password are incorrect"',)})
18:42:00,904 cassandra.cluster WARNING [control connection] Error connecting to 127.0.0.1:9042:
Traceback (most recent call last):
  File "cassandra/cluster.py", line 3522, in cassandra.cluster.ControlConnection._reconnect_internal
  File "cassandra/cluster.py", line 3544, in cassandra.cluster.ControlConnection._try_connect
  File "cassandra/cluster.py", line 1620, in cassandra.cluster.Cluster.connection_factory
  File "cassandra/connection.py", line 837, in cassandra.connection.Connection.factory
  File "cassandra/connection.py", line 600, in cassandra.connection.defunct_on_error.wrapper
  File "cassandra/connection.py", line 1421, in cassandra.connection.Connection._handle_auth_response
cassandra.AuthenticationFailed: Failed to authenticate to 127.0.0.1:9042: Error from server: code=0100 [Bad credentials] message="Provided username cassandra and/or password are incorrect"
18:42:00,905 cassandra.cluster ERROR Control connection failed to connect, shutting down Cluster:
Traceback (most recent call last):
  File "cassandra/cluster.py", line 1690, in cassandra.cluster.Cluster.connect
  File "cassandra/cluster.py", line 3488, in cassandra.cluster.ControlConnection.connect
  File "cassandra/cluster.py", line 3533, in cassandra.cluster.ControlConnection._reconnect_internal
cassandra.cluster.NoHostAvailable: ('Unable to connect to any servers', {'127.0.0.1:9042': AuthenticationFailed('Failed to authenticate to 127.0.0.1:9042: Error from server: code=0100 [Bad credentials] message="Provided username cassandra and/or password are incorrect"',)})
18:42:01,169 cassandra.cluster WARNING [control connection] Error connecting to 127.0.0.1:9042:
Traceback (most recent call last):
  File "cassandra/cluster.py", line 3522, in cassandra.cluster.ControlConnection._reconnect_internal
  File "cassandra/cluster.py", line 3544, in cassandra.cluster.ControlConnection._try_connect
  File "cassandra/cluster.py", line 1620, in cassandra.cluster.Cluster.connection_factory
  File "cassandra/connection.py", line 837, in cassandra.connection.Connection.factory
  File "cassandra/connection.py", line 600, in cassandra.connection.defunct_on_error.wrapper
  File "cassandra/connection.py", line 1421, in cassandra.connection.Connection._handle_auth_response
cassandra.AuthenticationFailed: Failed to authenticate to 127.0.0.1:9042: Error from server: code=0100 [Bad credentials] message="Provided username cassandra and/or password are incorrect"
18:42:01,170 cassandra.cluster ERROR Control connection failed to connect, shutting down Cluster:
Traceback (most recent call last):
  File "cassandra/cluster.py", line 1690, in cassandra.cluster.Cluster.connect
  File "cassandra/cluster.py", line 3488, in cassandra.cluster.ControlConnection.connect
  File "cassandra/cluster.py", line 3533, in cassandra.cluster.ControlConnection._reconnect_internal
cassandra.cluster.NoHostAvailable: ('Unable to connect to any servers', {'127.0.0.1:9042': AuthenticationFailed('Failed to authenticate to 127.0.0.1:9042: Error from server: code=0100 [Bad credentials] message="Provided username cassandra and/or password are incorrect"',)})
18:42:01,434 cassandra.cluster WARNING [control connection] Error connecting to 127.0.0.1:9042:
Traceback (most recent call last):
  File "cassandra/cluster.py", line 3522, in cassandra.cluster.ControlConnection._reconnect_internal
  File "cassandra/cluster.py", line 3544, in cassandra.cluster.ControlConnection._try_connect
  File "cassandra/cluster.py", line 1620, in cassandra.cluster.Cluster.connection_factory
  File "cassandra/connection.py", line 837, in cassandra.connection.Connection.factory
  File "cassandra/connection.py", line 600, in cassandra.connection.defunct_on_error.wrapper
  File "cassandra/connection.py", line 1421, in cassandra.connection.Connection._handle_auth_response
cassandra.AuthenticationFailed: Failed to authenticate to 127.0.0.1:9042: Error from server: code=0100 [Bad credentials] message="Provided username cassandra and/or password are incorrect"
18:42:01,435 cassandra.cluster ERROR Control connection failed to connect, shutting down Cluster:
Traceback (most recent call last):
  File "cassandra/cluster.py", line 1690, in cassandra.cluster.Cluster.connect
  File "cassandra/cluster.py", line 3488, in cassandra.cluster.ControlConnection.connect
  File "cassandra/cluster.py", line 3533, in cassandra.cluster.ControlConnection._reconnect_internal
cassandra.cluster.NoHostAvailable: ('Unable to connect to any servers', {'127.0.0.1:9042': AuthenticationFailed('Failed to authenticate to 127.0.0.1:9042: Error from server: code=0100 [Bad credentials] message="Provided username cassandra and/or password are incorrect"',)})
18:42:01,719 cassandra.cluster WARNING [control connection] Error connecting to 127.0.0.1:9042:
Traceback (most recent call last):
  File "cassandra/cluster.py", line 3522, in cassandra.cluster.ControlConnection._reconnect_internal
  File "cassandra/cluster.py", line 3544, in cassandra.cluster.ControlConnection._try_connect
  File "cassandra/cluster.py", line 1620, in cassandra.cluster.Cluster.connection_factory
  File "cassandra/connection.py", line 837, in cassandra.connection.Connection.factory
  File "cassandra/connection.py", line 600, in cassandra.connection.defunct_on_error.wrapper
  File "cassandra/connection.py", line 1421, in cassandra.connection.Connection._handle_auth_response
cassandra.AuthenticationFailed: Failed to authenticate to 127.0.0.1:9042: Error from server: code=0100 [Bad credentials] message="Provided username cassandra and/or password are incorrect"
18:42:01,719 cassandra.cluster ERROR Control connection failed to connect, shutting down Cluster:
Traceback (most recent call last):
  File "cassandra/cluster.py", line 1690, in cassandra.cluster.Cluster.connect
  File "cassandra/cluster.py", line 3488, in cassandra.cluster.ControlConnection.connect
  File "cassandra/cluster.py", line 3533, in cassandra.cluster.ControlConnection._reconnect_internal
cassandra.cluster.NoHostAvailable: ('Unable to connect to any servers', {'127.0.0.1:9042': AuthenticationFailed('Failed to authenticate to 127.0.0.1:9042: Error from server: code=0100 [Bad credentials] message="Provided username cassandra and/or password are incorrect"',)})
18:42:01,984 cassandra.cluster WARNING [control connection] Error connecting to 127.0.0.1:9042:
Traceback (most recent call last):
  File "cassandra/cluster.py", line 3522, in cassandra.cluster.ControlConnection._reconnect_internal
  File "cassandra/cluster.py", line 3544, in cassandra.cluster.ControlConnection._try_connect
  File "cassandra/cluster.py", line 1620, in cassandra.cluster.Cluster.connection_factory
  File "cassandra/connection.py", line 837, in cassandra.connection.Connection.factory
  File "cassandra/connection.py", line 600, in cassandra.connection.defunct_on_error.wrapper
  File "cassandra/connection.py", line 1421, in cassandra.connection.Connection._handle_auth_response
cassandra.AuthenticationFailed: Failed to authenticate to 127.0.0.1:9042: Error from server: code=0100 [Bad credentials] message="Provided username cassandra and/or password are incorrect"
18:42:01,985 cassandra.cluster ERROR Control connection failed to connect, shutting down Cluster:
Traceback (most recent call last):
  File "cassandra/cluster.py", line 1690, in cassandra.cluster.Cluster.connect
  File "cassandra/cluster.py", line 3488, in cassandra.cluster.ControlConnection.connect
  File "cassandra/cluster.py", line 3533, in cassandra.cluster.ControlConnection._reconnect_internal
cassandra.cluster.NoHostAvailable: ('Unable to connect to any servers', {'127.0.0.1:9042': AuthenticationFailed('Failed to authenticate to 127.0.0.1:9042: Error from server: code=0100 [Bad credentials] message="Provided username cassandra and/or password are incorrect"',)})
18:42:02,249 cassandra.cluster WARNING [control connection] Error connecting to 127.0.0.1:9042:
Traceback (most recent call last):
  File "cassandra/cluster.py", line 3522, in cassandra.cluster.ControlConnection._reconnect_internal
  File "cassandra/cluster.py", line 3544, in cassandra.cluster.ControlConnection._try_connect
  File "cassandra/cluster.py", line 1620, in cassandra.cluster.Cluster.connection_factory
  File "cassandra/connection.py", line 837, in cassandra.connection.Connection.factory
  File "cassandra/connection.py", line 600, in cassandra.connection.defunct_on_error.wrapper
  File "cassandra/connection.py", line 1421, in cassandra.connection.Connection._handle_auth_response
cassandra.AuthenticationFailed: Failed to authenticate to 127.0.0.1:9042: Error from server: code=0100 [Bad credentials] message="Provided username cassandra and/or password are incorrect"
18:42:02,250 cassandra.cluster ERROR Control connection failed to connect, shutting down Cluster:
Traceback (most recent call last):
  File "cassandra/cluster.py", line 1690, in cassandra.cluster.Cluster.connect
  File "cassandra/cluster.py", line 3488, in cassandra.cluster.ControlConnection.connect
  File "cassandra/cluster.py", line 3533, in cassandra.cluster.ControlConnection._reconnect_internal
cassandra.cluster.NoHostAvailable: ('Unable to connect to any servers', {'127.0.0.1:9042': AuthenticationFailed('Failed to authenticate to 127.0.0.1:9042: Error from server: code=0100 [Bad credentials] message="Provided username cassandra and/or password are incorrect"',)})
18:42:02,514 cassandra.cluster WARNING [control connection] Error connecting to 127.0.0.1:9042:
Traceback (most recent call last):
  File "cassandra/cluster.py", line 3522, in cassandra.cluster.ControlConnection._reconnect_internal
  File "cassandra/cluster.py", line 3544, in cassandra.cluster.ControlConnection._try_connect
  File "cassandra/cluster.py", line 1620, in cassandra.cluster.Cluster.connection_factory
  File "cassandra/connection.py", line 837, in cassandra.connection.Connection.factory
  File "cassandra/connection.py", line 600, in cassandra.connection.defunct_on_error.wrapper
  File "cassandra/connection.py", line 1421, in cassandra.connection.Connection._handle_auth_response
cassandra.AuthenticationFailed: Failed to authenticate to 127.0.0.1:9042: Error from server: code=0100 [Bad credentials] message="Provided username cassandra and/or password are incorrect"
18:42:02,515 cassandra.cluster ERROR Control connection failed to connect, shutting down Cluster:
Traceback (most recent call last):
  File "cassandra/cluster.py", line 1690, in cassandra.cluster.Cluster.connect
  File "cassandra/cluster.py", line 3488, in cassandra.cluster.ControlConnection.connect
  File "cassandra/cluster.py", line 3533, in cassandra.cluster.ControlConnection._reconnect_internal
cassandra.cluster.NoHostAvailable: ('Unable to connect to any servers', {'127.0.0.1:9042': AuthenticationFailed('Failed to authenticate to 127.0.0.1:9042: Error from server: code=0100 [Bad credentials] message="Provided username cassandra and/or password are incorrect"',)})
18:42:02,779 cassandra.cluster WARNING [control connection] Error connecting to 127.0.0.1:9042:
Traceback (most recent call last):
  File "cassandra/cluster.py", line 3522, in cassandra.cluster.ControlConnection._reconnect_internal
  File "cassandra/cluster.py", line 3544, in cassandra.cluster.ControlConnection._try_connect
  File "cassandra/cluster.py", line 1620, in cassandra.cluster.Cluster.connection_factory
  File "cassandra/connection.py", line 837, in cassandra.connection.Connection.factory
  File "cassandra/connection.py", line 600, in cassandra.connection.defunct_on_error.wrapper
  File "cassandra/connection.py", line 1421, in cassandra.connection.Connection._handle_auth_response
cassandra.AuthenticationFailed: Failed to authenticate to 127.0.0.1:9042: Error from server: code=0100 [Bad credentials] message="Provided username cassandra and/or password are incorrect"
18:42:02,780 cassandra.cluster ERROR Control connection failed to connect, shutting down Cluster:
Traceback (most recent call last):
  File "cassandra/cluster.py", line 1690, in cassandra.cluster.Cluster.connect
  File "cassandra/cluster.py", line 3488, in cassandra.cluster.ControlConnection.connect
  File "cassandra/cluster.py", line 3533, in cassandra.cluster.ControlConnection._reconnect_internal
cassandra.cluster.NoHostAvailable: ('Unable to connect to any servers', {'127.0.0.1:9042': AuthenticationFailed('Failed to authenticate to 127.0.0.1:9042: Error from server: code=0100 [Bad credentials] message="Provided username cassandra and/or password are incorrect"',)})
18:42:03,43 cassandra.cluster WARNING [control connection] Error connecting to 127.0.0.1:9042:
Traceback (most recent call last):
  File "cassandra/cluster.py", line 3522, in cassandra.cluster.ControlConnection._reconnect_internal
  File "cassandra/cluster.py", line 3544, in cassandra.cluster.ControlConnection._try_connect
  File "cassandra/cluster.py", line 1620, in cassandra.cluster.Cluster.connection_factory
  File "cassandra/connection.py", line 837, in cassandra.connection.Connection.factory
  File "cassandra/connection.py", line 600, in cassandra.connection.defunct_on_error.wrapper
  File "cassandra/connection.py", line 1421, in cassandra.connection.Connection._handle_auth_response
cassandra.AuthenticationFailed: Failed to authenticate to 127.0.0.1:9042: Error from server: code=0100 [Bad credentials] message="Provided username cassandra and/or password are incorrect"
18:42:03,44 cassandra.cluster ERROR Control connection failed to connect, shutting down Cluster:
Traceback (most recent call last):
  File "cassandra/cluster.py", line 1690, in cassandra.cluster.Cluster.connect
  File "cassandra/cluster.py", line 3488, in cassandra.cluster.ControlConnection.connect
  File "cassandra/cluster.py", line 3533, in cassandra.cluster.ControlConnection._reconnect_internal
cassandra.cluster.NoHostAvailable: ('Unable to connect to any servers', {'127.0.0.1:9042': AuthenticationFailed('Failed to authenticate to 127.0.0.1:9042: Error from server: code=0100 [Bad credentials] message="Provided username cassandra and/or password are incorrect"',)})
18:42:03,308 cassandra.cluster WARNING [control connection] Error connecting to 127.0.0.1:9042:
Traceback (most recent call last):
  File "cassandra/cluster.py", line 3522, in cassandra.cluster.ControlConnection._reconnect_internal
  File "cassandra/cluster.py", line 3544, in cassandra.cluster.ControlConnection._try_connect
  File "cassandra/cluster.py", line 1620, in cassandra.cluster.Cluster.connection_factory
  File "cassandra/connection.py", line 837, in cassandra.connection.Connection.factory
  File "cassandra/connection.py", line 600, in cassandra.connection.defunct_on_error.wrapper
  File "cassandra/connection.py", line 1421, in cassandra.connection.Connection._handle_auth_response
cassandra.AuthenticationFailed: Failed to authenticate to 127.0.0.1:9042: Error from server: code=0100 [Bad credentials] message="Provided username cassandra and/or password are incorrect"
18:42:03,309 cassandra.cluster ERROR Control connection failed to connect, shutting down Cluster:
Traceback (most recent call last):
  File "cassandra/cluster.py", line 1690, in cassandra.cluster.Cluster.connect
  File "cassandra/cluster.py", line 3488, in cassandra.cluster.ControlConnection.connect
  File "cassandra/cluster.py", line 3533, in cassandra.cluster.ControlConnection._reconnect_internal
cassandra.cluster.NoHostAvailable: ('Unable to connect to any servers', {'127.0.0.1:9042': AuthenticationFailed('Failed to authenticate to 127.0.0.1:9042: Error from server: code=0100 [Bad credentials] message="Provided username cassandra and/or password are incorrect"',)})
18:42:03,573 cassandra.cluster WARNING [control connection] Error connecting to 127.0.0.1:9042:
Traceback (most recent call last):
  File "cassandra/cluster.py", line 3522, in cassandra.cluster.ControlConnection._reconnect_internal
  File "cassandra/cluster.py", line 3544, in cassandra.cluster.ControlConnection._try_connect
  File "cassandra/cluster.py", line 1620, in cassandra.cluster.Cluster.connection_factory
  File "cassandra/connection.py", line 837, in cassandra.connection.Connection.factory
  File "cassandra/connection.py", line 600, in cassandra.connection.defunct_on_error.wrapper
  File "cassandra/connection.py", line 1421, in cassandra.connection.Connection._handle_auth_response
cassandra.AuthenticationFailed: Failed to authenticate to 127.0.0.1:9042: Error from server: code=0100 [Bad credentials] message="Provided username cassandra and/or password are incorrect"
18:42:03,574 cassandra.cluster ERROR Control connection failed to connect, shutting down Cluster:
Traceback (most recent call last):
  File "cassandra/cluster.py", line 1690, in cassandra.cluster.Cluster.connect
  File "cassandra/cluster.py", line 3488, in cassandra.cluster.ControlConnection.connect
  File "cassandra/cluster.py", line 3533, in cassandra.cluster.ControlConnection._reconnect_internal
cassandra.cluster.NoHostAvailable: ('Unable to connect to any servers', {'127.0.0.1:9042': AuthenticationFailed('Failed to authenticate to 127.0.0.1:9042: Error from server: code=0100 [Bad credentials] message="Provided username cassandra and/or password are incorrect"',)})
18:42:03,838 cassandra.cluster WARNING [control connection] Error connecting to 127.0.0.1:9042:
Traceback (most recent call last):
  File "cassandra/cluster.py", line 3522, in cassandra.cluster.ControlConnection._reconnect_internal
  File "cassandra/cluster.py", line 3544, in cassandra.cluster.ControlConnection._try_connect
  File "cassandra/cluster.py", line 1620, in cassandra.cluster.Cluster.connection_factory
  File "cassandra/connection.py", line 837, in cassandra.connection.Connection.factory
  File "cassandra/connection.py", line 600, in cassandra.connection.defunct_on_error.wrapper
  File "cassandra/connection.py", line 1421, in cassandra.connection.Connection._handle_auth_response
cassandra.AuthenticationFailed: Failed to authenticate to 127.0.0.1:9042: Error from server: code=0100 [Bad credentials] message="Provided username cassandra and/or password are incorrect"
18:42:03,839 cassandra.cluster ERROR Control connection failed to connect, shutting down Cluster:
Traceback (most recent call last):
  File "cassandra/cluster.py", line 1690, in cassandra.cluster.Cluster.connect
  File "cassandra/cluster.py", line 3488, in cassandra.cluster.ControlConnection.connect
  File "cassandra/cluster.py", line 3533, in cassandra.cluster.ControlConnection._reconnect_internal
cassandra.cluster.NoHostAvailable: ('Unable to connect to any servers', {'127.0.0.1:9042': AuthenticationFailed('Failed to authenticate to 127.0.0.1:9042: Error from server: code=0100 [Bad credentials] message="Provided username cassandra and/or password are incorrect"',)})
18:42:04,101 cassandra.cluster WARNING [control connection] Error connecting to 127.0.0.1:9042:
Traceback (most recent call last):
  File "cassandra/cluster.py", line 3522, in cassandra.cluster.ControlConnection._reconnect_internal
  File "cassandra/cluster.py", line 3544, in cassandra.cluster.ControlConnection._try_connect
  File "cassandra/cluster.py", line 1620, in cassandra.cluster.Cluster.connection_factory
  File "cassandra/connection.py", line 837, in cassandra.connection.Connection.factory
  File "cassandra/connection.py", line 600, in cassandra.connection.defunct_on_error.wrapper
  File "cassandra/connection.py", line 1421, in cassandra.connection.Connection._handle_auth_response
cassandra.AuthenticationFailed: Failed to authenticate to 127.0.0.1:9042: Error from server: code=0100 [Bad credentials] message="Provided username cassandra and/or password are incorrect"
18:42:04,103 cassandra.cluster ERROR Control connection failed to connect, shutting down Cluster:
Traceback (most recent call last):
  File "cassandra/cluster.py", line 1690, in cassandra.cluster.Cluster.connect
  File "cassandra/cluster.py", line 3488, in cassandra.cluster.ControlConnection.connect
  File "cassandra/cluster.py", line 3533, in cassandra.cluster.ControlConnection._reconnect_internal
cassandra.cluster.NoHostAvailable: ('Unable to connect to any servers', {'127.0.0.1:9042': AuthenticationFailed('Failed to authenticate to 127.0.0.1:9042: Error from server: code=0100 [Bad credentials] message="Provided username cassandra and/or password are incorrect"',)})
18:42:04,366 cassandra.cluster WARNING [control connection] Error connecting to 127.0.0.1:9042:
Traceback (most recent call last):
  File "cassandra/cluster.py", line 3522, in cassandra.cluster.ControlConnection._reconnect_internal
  File "cassandra/cluster.py", line 3544, in cassandra.cluster.ControlConnection._try_connect
  File "cassandra/cluster.py", line 1620, in cassandra.cluster.Cluster.connection_factory
  File "cassandra/connection.py", line 837, in cassandra.connection.Connection.factory
  File "cassandra/connection.py", line 600, in cassandra.connection.defunct_on_error.wrapper
  File "cassandra/connection.py", line 1421, in cassandra.connection.Connection._handle_auth_response
cassandra.AuthenticationFailed: Failed to authenticate to 127.0.0.1:9042: Error from server: code=0100 [Bad credentials] message="Provided username cassandra and/or password are incorrect"
18:42:04,367 cassandra.cluster ERROR Control connection failed to connect, shutting down Cluster:
Traceback (most recent call last):
  File "cassandra/cluster.py", line 1690, in cassandra.cluster.Cluster.connect
  File "cassandra/cluster.py", line 3488, in cassandra.cluster.ControlConnection.connect
  File "cassandra/cluster.py", line 3533, in cassandra.cluster.ControlConnection._reconnect_internal
cassandra.cluster.NoHostAvailable: ('Unable to connect to any servers', {'127.0.0.1:9042': AuthenticationFailed('Failed to authenticate to 127.0.0.1:9042: Error from server: code=0100 [Bad credentials] message="Provided username cassandra and/or password are incorrect"',)})
18:42:04,632 cassandra.cluster WARNING [control connection] Error connecting to 127.0.0.1:9042:
Traceback (most recent call last):
  File "cassandra/cluster.py", line 3522, in cassandra.cluster.ControlConnection._reconnect_internal
  File "cassandra/cluster.py", line 3544, in cassandra.cluster.ControlConnection._try_connect
  File "cassandra/cluster.py", line 1620, in cassandra.cluster.Cluster.connection_factory
  File "cassandra/connection.py", line 837, in cassandra.connection.Connection.factory
  File "cassandra/connection.py", line 600, in cassandra.connection.defunct_on_error.wrapper
  File "cassandra/connection.py", line 1421, in cassandra.connection.Connection._handle_auth_response
cassandra.AuthenticationFailed: Failed to authenticate to 127.0.0.1:9042: Error from server: code=0100 [Bad credentials] message="Provided username cassandra and/or password are incorrect"
18:42:04,633 cassandra.cluster ERROR Control connection failed to connect, shutting down Cluster:
Traceback (most recent call last):
  File "cassandra/cluster.py", line 1690, in cassandra.cluster.Cluster.connect
  File "cassandra/cluster.py", line 3488, in cassandra.cluster.ControlConnection.connect
  File "cassandra/cluster.py", line 3533, in cassandra.cluster.ControlConnection._reconnect_internal
cassandra.cluster.NoHostAvailable: ('Unable to connect to any servers', {'127.0.0.1:9042': AuthenticationFailed('Failed to authenticate to 127.0.0.1:9042: Error from server: code=0100 [Bad credentials] message="Provided username cassandra and/or password are incorrect"',)})
18:42:04,898 cassandra.cluster WARNING [control connection] Error connecting to 127.0.0.1:9042:
Traceback (most recent call last):
  File "cassandra/cluster.py", line 3522, in cassandra.cluster.ControlConnection._reconnect_internal
  File "cassandra/cluster.py", line 3544, in cassandra.cluster.ControlConnection._try_connect
  File "cassandra/cluster.py", line 1620, in cassandra.cluster.Cluster.connection_factory
  File "cassandra/connection.py", line 837, in cassandra.connection.Connection.factory
  File "cassandra/connection.py", line 600, in cassandra.connection.defunct_on_error.wrapper
  File "cassandra/connection.py", line 1421, in cassandra.connection.Connection._handle_auth_response
cassandra.AuthenticationFailed: Failed to authenticate to 127.0.0.1:9042: Error from server: code=0100 [Bad credentials] message="Provided username cassandra and/or password are incorrect"
18:42:04,899 cassandra.cluster ERROR Control connection failed to connect, shutting down Cluster:
Traceback (most recent call last):
  File "cassandra/cluster.py", line 1690, in cassandra.cluster.Cluster.connect
  File "cassandra/cluster.py", line 3488, in cassandra.cluster.ControlConnection.connect
  File "cassandra/cluster.py", line 3533, in cassandra.cluster.ControlConnection._reconnect_internal
cassandra.cluster.NoHostAvailable: ('Unable to connect to any servers', {'127.0.0.1:9042': AuthenticationFailed('Failed to authenticate to 127.0.0.1:9042: Error from server: code=0100 [Bad credentials] message="Provided username cassandra and/or password are incorrect"',)})
18:42:05,163 cassandra.cluster WARNING [control connection] Error connecting to 127.0.0.1:9042:
Traceback (most recent call last):
  File "cassandra/cluster.py", line 3522, in cassandra.cluster.ControlConnection._reconnect_internal
  File "cassandra/cluster.py", line 3544, in cassandra.cluster.ControlConnection._try_connect
  File "cassandra/cluster.py", line 1620, in cassandra.cluster.Cluster.connection_factory
  File "cassandra/connection.py", line 837, in cassandra.connection.Connection.factory
  File "cassandra/connection.py", line 600, in cassandra.connection.defunct_on_error.wrapper
  File "cassandra/connection.py", line 1421, in cassandra.connection.Connection._handle_auth_response
cassandra.AuthenticationFailed: Failed to authenticate to 127.0.0.1:9042: Error from server: code=0100 [Bad credentials] message="Provided username cassandra and/or password are incorrect"
18:42:05,164 cassandra.cluster ERROR Control connection failed to connect, shutting down Cluster:
Traceback (most recent call last):
  File "cassandra/cluster.py", line 1690, in cassandra.cluster.Cluster.connect
  File "cassandra/cluster.py", line 3488, in cassandra.cluster.ControlConnection.connect
  File "cassandra/cluster.py", line 3533, in cassandra.cluster.ControlConnection._reconnect_internal
cassandra.cluster.NoHostAvailable: ('Unable to connect to any servers', {'127.0.0.1:9042': AuthenticationFailed('Failed to authenticate to 127.0.0.1:9042: Error from server: code=0100 [Bad credentials] message="Provided username cassandra and/or password are incorrect"',)})
18:42:05,427 cassandra.cluster WARNING [control connection] Error connecting to 127.0.0.1:9042:
Traceback (most recent call last):
  File "cassandra/cluster.py", line 3522, in cassandra.cluster.ControlConnection._reconnect_internal
  File "cassandra/cluster.py", line 3544, in cassandra.cluster.ControlConnection._try_connect
  File "cassandra/cluster.py", line 1620, in cassandra.cluster.Cluster.connection_factory
  File "cassandra/connection.py", line 837, in cassandra.connection.Connection.factory
  File "cassandra/connection.py", line 600, in cassandra.connection.defunct_on_error.wrapper
  File "cassandra/connection.py", line 1421, in cassandra.connection.Connection._handle_auth_response
cassandra.AuthenticationFailed: Failed to authenticate to 127.0.0.1:9042: Error from server: code=0100 [Bad credentials] message="Provided username cassandra and/or password are incorrect"
18:42:05,428 cassandra.cluster ERROR Control connection failed to connect, shutting down Cluster:
Traceback (most recent call last):
  File "cassandra/cluster.py", line 1690, in cassandra.cluster.Cluster.connect
  File "cassandra/cluster.py", line 3488, in cassandra.cluster.ControlConnection.connect
  File "cassandra/cluster.py", line 3533, in cassandra.cluster.ControlConnection._reconnect_internal
cassandra.cluster.NoHostAvailable: ('Unable to connect to any servers', {'127.0.0.1:9042': AuthenticationFailed('Failed to authenticate to 127.0.0.1:9042: Error from server: code=0100 [Bad credentials] message="Provided username cassandra and/or password are incorrect"',)})
18:42:05,692 cassandra.cluster WARNING [control connection] Error connecting to 127.0.0.1:9042:
Traceback (most recent call last):
  File "cassandra/cluster.py", line 3522, in cassandra.cluster.ControlConnection._reconnect_internal
  File "cassandra/cluster.py", line 3544, in cassandra.cluster.ControlConnection._try_connect
  File "cassandra/cluster.py", line 1620, in cassandra.cluster.Cluster.connection_factory
  File "cassandra/connection.py", line 837, in cassandra.connection.Connection.factory
  File "cassandra/connection.py", line 600, in cassandra.connection.defunct_on_error.wrapper
  File "cassandra/connection.py", line 1421, in cassandra.connection.Connection._handle_auth_response
cassandra.AuthenticationFailed: Failed to authenticate to 127.0.0.1:9042: Error from server: code=0100 [Bad credentials] message="Provided username cassandra and/or password are incorrect"
18:42:05,693 cassandra.cluster ERROR Control connection failed to connect, shutting down Cluster:
Traceback (most recent call last):
  File "cassandra/cluster.py", line 1690, in cassandra.cluster.Cluster.connect
  File "cassandra/cluster.py", line 3488, in cassandra.cluster.ControlConnection.connect
  File "cassandra/cluster.py", line 3533, in cassandra.cluster.ControlConnection._reconnect_internal
cassandra.cluster.NoHostAvailable: ('Unable to connect to any servers', {'127.0.0.1:9042': AuthenticationFailed('Failed to authenticate to 127.0.0.1:9042: Error from server: code=0100 [Bad credentials] message="Provided username cassandra and/or password are incorrect"',)})
18:42:05,956 cassandra.cluster WARNING [control connection] Error connecting to 127.0.0.1:9042:
Traceback (most recent call last):
  File "cassandra/cluster.py", line 3522, in cassandra.cluster.ControlConnection._reconnect_internal
  File "cassandra/cluster.py", line 3544, in cassandra.cluster.ControlConnection._try_connect
  File "cassandra/cluster.py", line 1620, in cassandra.cluster.Cluster.connection_factory
  File "cassandra/connection.py", line 837, in cassandra.connection.Connection.factory
  File "cassandra/connection.py", line 600, in cassandra.connection.defunct_on_error.wrapper
  File "cassandra/connection.py", line 1421, in cassandra.connection.Connection._handle_auth_response
cassandra.AuthenticationFailed: Failed to authenticate to 127.0.0.1:9042: Error from server: code=0100 [Bad credentials] message="Provided username cassandra and/or password are incorrect"
18:42:05,956 cassandra.cluster ERROR Control connection failed to connect, shutting down Cluster:
Traceback (most recent call last):
  File "cassandra/cluster.py", line 1690, in cassandra.cluster.Cluster.connect
  File "cassandra/cluster.py", line 3488, in cassandra.cluster.ControlConnection.connect
  File "cassandra/cluster.py", line 3533, in cassandra.cluster.ControlConnection._reconnect_internal
cassandra.cluster.NoHostAvailable: ('Unable to connect to any servers', {'127.0.0.1:9042': AuthenticationFailed('Failed to authenticate to 127.0.0.1:9042: Error from server: code=0100 [Bad credentials] message="Provided username cassandra and/or password are incorrect"',)})
18:42:06,218 cassandra.cluster WARNING [control connection] Error connecting to 127.0.0.1:9042:
Traceback (most recent call last):
  File "cassandra/cluster.py", line 3522, in cassandra.cluster.ControlConnection._reconnect_internal
  File "cassandra/cluster.py", line 3544, in cassandra.cluster.ControlConnection._try_connect
  File "cassandra/cluster.py", line 1620, in cassandra.cluster.Cluster.connection_factory
  File "cassandra/connection.py", line 837, in cassandra.connection.Connection.factory
  File "cassandra/connection.py", line 600, in cassandra.connection.defunct_on_error.wrapper
  File "cassandra/connection.py", line 1421, in cassandra.connection.Connection._handle_auth_response
cassandra.AuthenticationFailed: Failed to authenticate to 127.0.0.1:9042: Error from server: code=0100 [Bad credentials] message="Provided username cassandra and/or password are incorrect"
18:42:06,219 cassandra.cluster ERROR Control connection failed to connect, shutting down Cluster:
Traceback (most recent call last):
  File "cassandra/cluster.py", line 1690, in cassandra.cluster.Cluster.connect
  File "cassandra/cluster.py", line 3488, in cassandra.cluster.ControlConnection.connect
  File "cassandra/cluster.py", line 3533, in cassandra.cluster.ControlConnection._reconnect_internal
cassandra.cluster.NoHostAvailable: ('Unable to connect to any servers', {'127.0.0.1:9042': AuthenticationFailed('Failed to authenticate to 127.0.0.1:9042: Error from server: code=0100 [Bad credentials] message="Provided username cassandra and/or password are incorrect"',)})
18:42:06,483 cassandra.cluster WARNING [control connection] Error connecting to 127.0.0.1:9042:
Traceback (most recent call last):
  File "cassandra/cluster.py", line 3522, in cassandra.cluster.ControlConnection._reconnect_internal
  File "cassandra/cluster.py", line 3544, in cassandra.cluster.ControlConnection._try_connect
  File "cassandra/cluster.py", line 1620, in cassandra.cluster.Cluster.connection_factory
  File "cassandra/connection.py", line 837, in cassandra.connection.Connection.factory
  File "cassandra/connection.py", line 600, in cassandra.connection.defunct_on_error.wrapper
  File "cassandra/connection.py", line 1421, in cassandra.connection.Connection._handle_auth_response
cassandra.AuthenticationFailed: Failed to authenticate to 127.0.0.1:9042: Error from server: code=0100 [Bad credentials] message="Provided username cassandra and/or password are incorrect"
18:42:06,484 cassandra.cluster ERROR Control connection failed to connect, shutting down Cluster:
Traceback (most recent call last):
  File "cassandra/cluster.py", line 1690, in cassandra.cluster.Cluster.connect
  File "cassandra/cluster.py", line 3488, in cassandra.cluster.ControlConnection.connect
  File "cassandra/cluster.py", line 3533, in cassandra.cluster.ControlConnection._reconnect_internal
cassandra.cluster.NoHostAvailable: ('Unable to connect to any servers', {'127.0.0.1:9042': AuthenticationFailed('Failed to authenticate to 127.0.0.1:9042: Error from server: code=0100 [Bad credentials] message="Provided username cassandra and/or password are incorrect"',)})
18:42:06,752 cassandra.cluster WARNING [control connection] Error connecting to 127.0.0.1:9042:
Traceback (most recent call last):
  File "cassandra/cluster.py", line 3522, in cassandra.cluster.ControlConnection._reconnect_internal
  File "cassandra/cluster.py", line 3544, in cassandra.cluster.ControlConnection._try_connect
  File "cassandra/cluster.py", line 1620, in cassandra.cluster.Cluster.connection_factory
  File "cassandra/connection.py", line 837, in cassandra.connection.Connection.factory
  File "cassandra/connection.py", line 600, in cassandra.connection.defunct_on_error.wrapper
  File "cassandra/connection.py", line 1421, in cassandra.connection.Connection._handle_auth_response
cassandra.AuthenticationFailed: Failed to authenticate to 127.0.0.1:9042: Error from server: code=0100 [Bad credentials] message="Provided username cassandra and/or password are incorrect"
18:42:06,753 cassandra.cluster ERROR Control connection failed to connect, shutting down Cluster:
Traceback (most recent call last):
  File "cassandra/cluster.py", line 1690, in cassandra.cluster.Cluster.connect
  File "cassandra/cluster.py", line 3488, in cassandra.cluster.ControlConnection.connect
  File "cassandra/cluster.py", line 3533, in cassandra.cluster.ControlConnection._reconnect_internal
cassandra.cluster.NoHostAvailable: ('Unable to connect to any servers', {'127.0.0.1:9042': AuthenticationFailed('Failed to authenticate to 127.0.0.1:9042: Error from server: code=0100 [Bad credentials] message="Provided username cassandra and/or password are incorrect"',)})
18:42:07,15 cassandra.cluster WARNING [control connection] Error connecting to 127.0.0.1:9042:
Traceback (most recent call last):
  File "cassandra/cluster.py", line 3522, in cassandra.cluster.ControlConnection._reconnect_internal
  File "cassandra/cluster.py", line 3544, in cassandra.cluster.ControlConnection._try_connect
  File "cassandra/cluster.py", line 1620, in cassandra.cluster.Cluster.connection_factory
  File "cassandra/connection.py", line 837, in cassandra.connection.Connection.factory
  File "cassandra/connection.py", line 600, in cassandra.connection.defunct_on_error.wrapper
  File "cassandra/connection.py", line 1421, in cassandra.connection.Connection._handle_auth_response
cassandra.AuthenticationFailed: Failed to authenticate to 127.0.0.1:9042: Error from server: code=0100 [Bad credentials] message="Provided username cassandra and/or password are incorrect"
18:42:07,16 cassandra.cluster ERROR Control connection failed to connect, shutting down Cluster:
Traceback (most recent call last):
  File "cassandra/cluster.py", line 1690, in cassandra.cluster.Cluster.connect
  File "cassandra/cluster.py", line 3488, in cassandra.cluster.ControlConnection.connect
  File "cassandra/cluster.py", line 3533, in cassandra.cluster.ControlConnection._reconnect_internal
cassandra.cluster.NoHostAvailable: ('Unable to connect to any servers', {'127.0.0.1:9042': AuthenticationFailed('Failed to authenticate to 127.0.0.1:9042: Error from server: code=0100 [Bad credentials] message="Provided username cassandra and/or password are incorrect"',)})
18:42:07,284 cassandra.cluster WARNING [control connection] Error connecting to 127.0.0.1:9042:
Traceback (most recent call last):
  File "cassandra/cluster.py", line 3522, in cassandra.cluster.ControlConnection._reconnect_internal
  File "cassandra/cluster.py", line 3544, in cassandra.cluster.ControlConnection._try_connect
  File "cassandra/cluster.py", line 1620, in cassandra.cluster.Cluster.connection_factory
  File "cassandra/connection.py", line 837, in cassandra.connection.Connection.factory
  File "cassandra/connection.py", line 600, in cassandra.connection.defunct_on_error.wrapper
  File "cassandra/connection.py", line 1421, in cassandra.connection.Connection._handle_auth_response
cassandra.AuthenticationFailed: Failed to authenticate to 127.0.0.1:9042: Error from server: code=0100 [Bad credentials] message="Provided username cassandra and/or password are incorrect"
18:42:07,285 cassandra.cluster ERROR Control connection failed to connect, shutting down Cluster:
Traceback (most recent call last):
  File "cassandra/cluster.py", line 1690, in cassandra.cluster.Cluster.connect
  File "cassandra/cluster.py", line 3488, in cassandra.cluster.ControlConnection.connect
  File "cassandra/cluster.py", line 3533, in cassandra.cluster.ControlConnection._reconnect_internal
cassandra.cluster.NoHostAvailable: ('Unable to connect to any servers', {'127.0.0.1:9042': AuthenticationFailed('Failed to authenticate to 127.0.0.1:9042: Error from server: code=0100 [Bad credentials] message="Provided username cassandra and/or password are incorrect"',)})
18:42:07,548 cassandra.cluster WARNING [control connection] Error connecting to 127.0.0.1:9042:
Traceback (most recent call last):
  File "cassandra/cluster.py", line 3522, in cassandra.cluster.ControlConnection._reconnect_internal
  File "cassandra/cluster.py", line 3544, in cassandra.cluster.ControlConnection._try_connect
  File "cassandra/cluster.py", line 1620, in cassandra.cluster.Cluster.connection_factory
  File "cassandra/connection.py", line 837, in cassandra.connection.Connection.factory
  File "cassandra/connection.py", line 600, in cassandra.connection.defunct_on_error.wrapper
  File "cassandra/connection.py", line 1421, in cassandra.connection.Connection._handle_auth_response
cassandra.AuthenticationFailed: Failed to authenticate to 127.0.0.1:9042: Error from server: code=0100 [Bad credentials] message="Provided username cassandra and/or password are incorrect"
18:42:07,549 cassandra.cluster ERROR Control connection failed to connect, shutting down Cluster:
Traceback (most recent call last):
  File "cassandra/cluster.py", line 1690, in cassandra.cluster.Cluster.connect
  File "cassandra/cluster.py", line 3488, in cassandra.cluster.ControlConnection.connect
  File "cassandra/cluster.py", line 3533, in cassandra.cluster.ControlConnection._reconnect_internal
cassandra.cluster.NoHostAvailable: ('Unable to connect to any servers', {'127.0.0.1:9042': AuthenticationFailed('Failed to authenticate to 127.0.0.1:9042: Error from server: code=0100 [Bad credentials] message="Provided username cassandra and/or password are incorrect"',)})
18:42:07,812 cassandra.cluster WARNING [control connection] Error connecting to 127.0.0.1:9042:
Traceback (most recent call last):
  File "cassandra/cluster.py", line 3522, in cassandra.cluster.ControlConnection._reconnect_internal
  File "cassandra/cluster.py", line 3544, in cassandra.cluster.ControlConnection._try_connect
  File "cassandra/cluster.py", line 1620, in cassandra.cluster.Cluster.connection_factory
  File "cassandra/connection.py", line 837, in cassandra.connection.Connection.factory
  File "cassandra/connection.py", line 600, in cassandra.connection.defunct_on_error.wrapper
  File "cassandra/connection.py", line 1421, in cassandra.connection.Connection._handle_auth_response
cassandra.AuthenticationFailed: Failed to authenticate to 127.0.0.1:9042: Error from server: code=0100 [Bad credentials] message="Provided username cassandra and/or password are incorrect"
18:42:07,813 cassandra.cluster ERROR Control connection failed to connect, shutting down Cluster:
Traceback (most recent call last):
  File "cassandra/cluster.py", line 1690, in cassandra.cluster.Cluster.connect
  File "cassandra/cluster.py", line 3488, in cassandra.cluster.ControlConnection.connect
  File "cassandra/cluster.py", line 3533, in cassandra.cluster.ControlConnection._reconnect_internal
cassandra.cluster.NoHostAvailable: ('Unable to connect to any servers', {'127.0.0.1:9042': AuthenticationFailed('Failed to authenticate to 127.0.0.1:9042: Error from server: code=0100 [Bad credentials] message="Provided username cassandra and/or password are incorrect"',)})
18:42:08,78 cassandra.cluster WARNING [control connection] Error connecting to 127.0.0.1:9042:
Traceback (most recent call last):
  File "cassandra/cluster.py", line 3522, in cassandra.cluster.ControlConnection._reconnect_internal
  File "cassandra/cluster.py", line 3544, in cassandra.cluster.ControlConnection._try_connect
  File "cassandra/cluster.py", line 1620, in cassandra.cluster.Cluster.connection_factory
  File "cassandra/connection.py", line 837, in cassandra.connection.Connection.factory
  File "cassandra/connection.py", line 600, in cassandra.connection.defunct_on_error.wrapper
  File "cassandra/connection.py", line 1421, in cassandra.connection.Connection._handle_auth_response
cassandra.AuthenticationFailed: Failed to authenticate to 127.0.0.1:9042: Error from server: code=0100 [Bad credentials] message="Provided username cassandra and/or password are incorrect"
18:42:08,79 cassandra.cluster ERROR Control connection failed to connect, shutting down Cluster:
Traceback (most recent call last):
  File "cassandra/cluster.py", line 1690, in cassandra.cluster.Cluster.connect
  File "cassandra/cluster.py", line 3488, in cassandra.cluster.ControlConnection.connect
  File "cassandra/cluster.py", line 3533, in cassandra.cluster.ControlConnection._reconnect_internal
cassandra.cluster.NoHostAvailable: ('Unable to connect to any servers', {'127.0.0.1:9042': AuthenticationFailed('Failed to authenticate to 127.0.0.1:9042: Error from server: code=0100 [Bad credentials] message="Provided username cassandra and/or password are incorrect"',)})
18:42:08,340 cassandra.cluster WARNING [control connection] Error connecting to 127.0.0.1:9042:
Traceback (most recent call last):
  File "cassandra/cluster.py", line 3522, in cassandra.cluster.ControlConnection._reconnect_internal
  File "cassandra/cluster.py", line 3544, in cassandra.cluster.ControlConnection._try_connect
  File "cassandra/cluster.py", line 1620, in cassandra.cluster.Cluster.connection_factory
  File "cassandra/connection.py", line 837, in cassandra.connection.Connection.factory
  File "cassandra/connection.py", line 600, in cassandra.connection.defunct_on_error.wrapper
  File "cassandra/connection.py", line 1421, in cassandra.connection.Connection._handle_auth_response
cassandra.AuthenticationFailed: Failed to authenticate to 127.0.0.1:9042: Error from server: code=0100 [Bad credentials] message="Provided username cassandra and/or password are incorrect"
18:42:08,340 cassandra.cluster ERROR Control connection failed to connect, shutting down Cluster:
Traceback (most recent call last):
  File "cassandra/cluster.py", line 1690, in cassandra.cluster.Cluster.connect
  File "cassandra/cluster.py", line 3488, in cassandra.cluster.ControlConnection.connect
  File "cassandra/cluster.py", line 3533, in cassandra.cluster.ControlConnection._reconnect_internal
cassandra.cluster.NoHostAvailable: ('Unable to connect to any servers', {'127.0.0.1:9042': AuthenticationFailed('Failed to authenticate to 127.0.0.1:9042: Error from server: code=0100 [Bad credentials] message="Provided username cassandra and/or password are incorrect"',)})
PASSED                                                                   [100%]
===Flaky Test Report===

test_disallow_grant_revoke_on_builtin_functions passed 1 out of the required 1 times. Success!

===End Flaky Test Report===

========================== 1 passed in 21.29 seconds ===========================
[msx] rc = 0
