cassandra sslnodetonode_test.py::TestNodeToNodeSSLEncryption::test_optional_outbound_tls true true
log_dts_dir = /users/masix/vm_images/ZebraConf/app_meta/logs
the_test is sslnodetonode_test.py::TestNodeToNodeSSLEncryption::test_optional_outbound_tls
rm: cannot remove '/tmp/my_log.txt': No such file or directory
============================= test session starts ==============================
platform linux -- Python 3.6.9, pytest-3.6.4, py-1.11.0, pluggy-0.7.1 -- /users/masix/dtest/bin/python
cachedir: .pytest_cache
rootdir: /users/masix/cassandra-dtest, inifile: pytest.ini
plugins: flaky-3.7.0, timeout-1.4.2, repeat-0.9.1
timeout: 900.0s
timeout method: signal
timeout func_only: False
collecting ... collected 1 item

sslnodetonode_test.py::TestNodeToNodeSSLEncryption::test_optional_outbound_tls 
-------------------------------- live log call ---------------------------------
19:24:54,842 ccmlib.node WARNING [msx] ccmlib:node.py:start(), self.name= node1, self.pid= 9696
19:24:54,844 ccmlib.cluster WARNING [msx] ccmlib:cluster.py:start() p.pid= 9599 node.name= node1 node.pid= 9696
19:25:04,815 ccmlib.node WARNING [msx] ccmlib:node.py:start(), self.name= node2, self.pid= 10160
19:25:04,816 ccmlib.cluster WARNING [msx] ccmlib:cluster.py:start() p.pid= 10064 node.name= node2 node.pid= 10160
19:25:32,370 ccmlib.node WARNING [msx] ccmlib:node.py:start(), self.name= node1, self.pid= 10877
19:25:47,123 cassandra.cluster WARNING Host 127.0.0.1:9042 has been marked down
19:25:47,124 cassandra.cluster WARNING Host 127.0.0.2:9042 has been marked down
19:25:47,126 cassandra.cluster WARNING [control connection] Error connecting to 127.0.0.2:9042:
Traceback (most recent call last):
  File "cassandra/cluster.py", line 3522, in cassandra.cluster.ControlConnection._reconnect_internal
  File "cassandra/cluster.py", line 3544, in cassandra.cluster.ControlConnection._try_connect
  File "cassandra/cluster.py", line 1620, in cassandra.cluster.Cluster.connection_factory
  File "cassandra/connection.py", line 831, in cassandra.connection.Connection.factory
  File "/users/masix/dtest/src/cassandra-driver/cassandra/io/libevreactor.py", line 267, in __init__
    self._connect_socket()
  File "cassandra/connection.py", line 898, in cassandra.connection.Connection._connect_socket
ConnectionRefusedError: [Errno 111] Tried connecting to [('127.0.0.2', 9042)]. Last error: Connection refused
19:25:48,229 cassandra.pool WARNING Error attempting to reconnect to 127.0.0.2:9042, scheduling retry in 1.9 seconds: [Errno 111] Tried connecting to [('127.0.0.2', 9042)]. Last error: Connection refused
19:25:50,135 cassandra.pool WARNING Error attempting to reconnect to 127.0.0.2:9042, scheduling retry in 3.56 seconds: [Errno 111] Tried connecting to [('127.0.0.2', 9042)]. Last error: Connection refused
19:25:53,744 cassandra.pool WARNING Error attempting to reconnect to 127.0.0.2:9042, scheduling retry in 8.64 seconds: [Errno 111] Tried connecting to [('127.0.0.2', 9042)]. Last error: Connection refused
19:25:55,576 ccmlib.node WARNING [msx] ccmlib:node.py:start(), self.name= node2, self.pid= 11464
19:26:17,124 cassandra.cluster WARNING Host 127.0.0.1:9042 has been marked down
19:26:17,125 cassandra.cluster WARNING [control connection] Error connecting to 127.0.0.1:9042:
Traceback (most recent call last):
  File "cassandra/cluster.py", line 3522, in cassandra.cluster.ControlConnection._reconnect_internal
  File "cassandra/cluster.py", line 3544, in cassandra.cluster.ControlConnection._try_connect
  File "cassandra/cluster.py", line 1620, in cassandra.cluster.Cluster.connection_factory
  File "cassandra/connection.py", line 831, in cassandra.connection.Connection.factory
  File "/users/masix/dtest/src/cassandra-driver/cassandra/io/libevreactor.py", line 267, in __init__
    self._connect_socket()
  File "cassandra/connection.py", line 898, in cassandra.connection.Connection._connect_socket
ConnectionRefusedError: [Errno 111] Tried connecting to [('127.0.0.1', 9042)]. Last error: Connection refused
19:26:18,229 cassandra.pool WARNING Error attempting to reconnect to 127.0.0.1:9042, scheduling retry in 1.76 seconds: [Errno 111] Tried connecting to [('127.0.0.1', 9042)]. Last error: Connection refused
19:26:19,776 ccmlib.node WARNING [msx] ccmlib:node.py:start(), self.name= node1, self.pid= 12093
19:26:47,125 cassandra.cluster WARNING Host 127.0.0.2:9042 has been marked down
19:26:48,131 cassandra.pool WARNING Error attempting to reconnect to 127.0.0.2:9042, scheduling retry in 2.2 seconds: [Errno 111] Tried connecting to [('127.0.0.2', 9042)]. Last error: Connection refused
19:26:50,337 cassandra.pool WARNING Error attempting to reconnect to 127.0.0.2:9042, scheduling retry in 3.96 seconds: [Errno 111] Tried connecting to [('127.0.0.2', 9042)]. Last error: Connection refused
19:26:50,976 ccmlib.node WARNING [msx] ccmlib:node.py:start(), self.name= node2, self.pid= 12735
19:27:17,125 cassandra.cluster WARNING Host 127.0.0.1:9042 has been marked down
19:27:17,126 cassandra.cluster WARNING Host 127.0.0.2:9042 has been marked down
19:27:17,128 cassandra.cluster WARNING [control connection] Error connecting to 127.0.0.2:9042:
Traceback (most recent call last):
  File "cassandra/cluster.py", line 3522, in cassandra.cluster.ControlConnection._reconnect_internal
  File "cassandra/cluster.py", line 3544, in cassandra.cluster.ControlConnection._try_connect
  File "cassandra/cluster.py", line 1620, in cassandra.cluster.Cluster.connection_factory
  File "cassandra/connection.py", line 831, in cassandra.connection.Connection.factory
  File "/users/masix/dtest/src/cassandra-driver/cassandra/io/libevreactor.py", line 267, in __init__
    self._connect_socket()
  File "cassandra/connection.py", line 898, in cassandra.connection.Connection._connect_socket
ConnectionRefusedError: [Errno 111] Tried connecting to [('127.0.0.2', 9042)]. Last error: Connection refused
19:27:18,131 cassandra.pool WARNING Error attempting to reconnect to 127.0.0.1:9042, scheduling retry in 2.18 seconds: [Errno 111] Tried connecting to [('127.0.0.1', 9042)]. Last error: Connection refused
19:27:18,131 cassandra.pool WARNING Error attempting to reconnect to 127.0.0.2:9042, scheduling retry in 1.96 seconds: [Errno 111] Tried connecting to [('127.0.0.2', 9042)]. Last error: Connection refused
19:27:20,135 cassandra.pool WARNING Error attempting to reconnect to 127.0.0.2:9042, scheduling retry in 4.16 seconds: [Errno 111] Tried connecting to [('127.0.0.2', 9042)]. Last error: Connection refused
19:27:20,336 cassandra.pool WARNING Error attempting to reconnect to 127.0.0.1:9042, scheduling retry in 4.6 seconds: [Errno 111] Tried connecting to [('127.0.0.1', 9042)]. Last error: Connection refused
PASSED                                                                   [100%]
===Flaky Test Report===

test_optional_outbound_tls passed 1 out of the required 1 times. Success!

===End Flaky Test Report===

========================== 1 passed in 155.38 seconds ==========================
[msx] rc = 0
