cassandra sstable_generation_loading_test.py::TestSSTableGenerationAndLoading::test_sstableloader_with_mv false true
log_dst_dir = /users/masix/vm_images/ZebraConf/app_meta/logs
the_test is sstable_generation_loading_test.py::TestSSTableGenerationAndLoading::test_sstableloader_with_mv
rm: cannot remove '/tmp/my_log.txt': No such file or directory
============================= test session starts ==============================
platform linux -- Python 3.6.9, pytest-3.6.4, py-1.11.0, pluggy-0.7.1 -- /users/masix/dtest/bin/python3
cachedir: .pytest_cache
rootdir: /users/masix/cassandra-dtest, inifile: pytest.ini
plugins: timeout-1.4.2, repeat-0.9.1, flaky-3.7.0
timeout: 1200.0s
timeout method: signal
timeout func_only: False
collecting ... collected 1 item

sstable_generation_loading_test.py::TestSSTableGenerationAndLoading::test_sstableloader_with_mv 
-------------------------------- live log call ---------------------------------
22:29:36,796 cassandra.cluster WARNING Host 127.0.0.1:9042 has been marked down
22:29:36,797 cassandra.cluster WARNING Host 127.0.0.2:9042 has been marked down
22:29:36,802 cassandra.cluster WARNING [control connection] Error connecting to 127.0.0.2:9042:
Traceback (most recent call last):
  File "cassandra/cluster.py", line 3522, in cassandra.cluster.ControlConnection._reconnect_internal
  File "cassandra/cluster.py", line 3544, in cassandra.cluster.ControlConnection._try_connect
  File "cassandra/cluster.py", line 1620, in cassandra.cluster.Cluster.connection_factory
  File "cassandra/connection.py", line 831, in cassandra.connection.Connection.factory
  File "/users/masix/dtest/src/cassandra-driver/cassandra/io/libevreactor.py", line 267, in __init__
    self._connect_socket()
  File "cassandra/connection.py", line 898, in cassandra.connection.Connection._connect_socket
ConnectionRefusedError: [Errno 111] Tried connecting to [('127.0.0.2', 9042)]. Last error: Connection refused
22:29:37,805 cassandra.pool WARNING Error attempting to reconnect to 127.0.0.2:9042, scheduling retry in 1.7 seconds: [Errno 111] Tried connecting to [('127.0.0.2', 9042)]. Last error: Connection refused
22:29:38,18 cassandra.cluster WARNING Failed to create connection pool for new host 127.0.0.1:9042:
Traceback (most recent call last):
  File "cassandra/connection.py", line 1439, in cassandra.connection.Connection.set_keyspace_blocking
  File "cassandra/connection.py", line 1029, in cassandra.connection.Connection.wait_for_response
  File "cassandra/connection.py", line 1076, in cassandra.connection.Connection.wait_for_responses
  File "cassandra/connection.py", line 1071, in cassandra.connection.Connection.wait_for_responses
  File "cassandra/connection.py", line 1570, in cassandra.connection.ResponseWaiter.deliver
cassandra.InvalidRequest: Error from server: code=2200 [Invalid query] message="Keyspace 'Keyspace1' does not exist"

During handling of the above exception, another exception occurred:

Traceback (most recent call last):
  File "cassandra/cluster.py", line 3175, in cassandra.cluster.Session.add_or_renew_pool.run_add_or_renew_pool
  File "cassandra/pool.py", line 405, in cassandra.pool.HostConnection.__init__
  File "cassandra/connection.py", line 1447, in cassandra.connection.Connection.set_keyspace_blocking
cassandra.connection.ConnectionException: Problem while setting keyspace: InvalidRequest('Error from server: code=2200 [Invalid query] message="Keyspace \'Keyspace1\' does not exist"',)
22:29:39,126 cassandra.cluster WARNING Failed to create connection pool for new host 127.0.0.1:9042:
Traceback (most recent call last):
  File "cassandra/connection.py", line 1439, in cassandra.connection.Connection.set_keyspace_blocking
  File "cassandra/connection.py", line 1029, in cassandra.connection.Connection.wait_for_response
  File "cassandra/connection.py", line 1076, in cassandra.connection.Connection.wait_for_responses
  File "cassandra/connection.py", line 1071, in cassandra.connection.Connection.wait_for_responses
  File "cassandra/connection.py", line 1570, in cassandra.connection.ResponseWaiter.deliver
cassandra.InvalidRequest: Error from server: code=2200 [Invalid query] message="Keyspace 'Keyspace1' does not exist"

During handling of the above exception, another exception occurred:

Traceback (most recent call last):
  File "cassandra/cluster.py", line 3175, in cassandra.cluster.Session.add_or_renew_pool.run_add_or_renew_pool
  File "cassandra/pool.py", line 405, in cassandra.pool.HostConnection.__init__
  File "cassandra/connection.py", line 1447, in cassandra.connection.Connection.set_keyspace_blocking
cassandra.connection.ConnectionException: Problem while setting keyspace: InvalidRequest('Error from server: code=2200 [Invalid query] message="Keyspace \'Keyspace1\' does not exist"',)
22:29:39,510 cassandra.pool WARNING Error attempting to reconnect to 127.0.0.2:9042, scheduling retry in 3.48 seconds: [Errno 111] Tried connecting to [('127.0.0.2', 9042)]. Last error: Connection refused
22:29:40,227 cassandra.cluster WARNING Failed to create connection pool for new host 127.0.0.1:9042:
Traceback (most recent call last):
  File "cassandra/connection.py", line 1439, in cassandra.connection.Connection.set_keyspace_blocking
  File "cassandra/connection.py", line 1029, in cassandra.connection.Connection.wait_for_response
  File "cassandra/connection.py", line 1076, in cassandra.connection.Connection.wait_for_responses
  File "cassandra/connection.py", line 1071, in cassandra.connection.Connection.wait_for_responses
  File "cassandra/connection.py", line 1570, in cassandra.connection.ResponseWaiter.deliver
cassandra.InvalidRequest: Error from server: code=2200 [Invalid query] message="Keyspace 'Keyspace1' does not exist"

During handling of the above exception, another exception occurred:

Traceback (most recent call last):
  File "cassandra/cluster.py", line 3175, in cassandra.cluster.Session.add_or_renew_pool.run_add_or_renew_pool
  File "cassandra/pool.py", line 405, in cassandra.pool.HostConnection.__init__
  File "cassandra/connection.py", line 1447, in cassandra.connection.Connection.set_keyspace_blocking
cassandra.connection.ConnectionException: Problem while setting keyspace: InvalidRequest('Error from server: code=2200 [Invalid query] message="Keyspace \'Keyspace1\' does not exist"',)
22:29:41,329 cassandra.cluster WARNING Failed to create connection pool for new host 127.0.0.1:9042:
Traceback (most recent call last):
  File "cassandra/connection.py", line 1439, in cassandra.connection.Connection.set_keyspace_blocking
  File "cassandra/connection.py", line 1029, in cassandra.connection.Connection.wait_for_response
  File "cassandra/connection.py", line 1076, in cassandra.connection.Connection.wait_for_responses
  File "cassandra/connection.py", line 1071, in cassandra.connection.Connection.wait_for_responses
  File "cassandra/connection.py", line 1570, in cassandra.connection.ResponseWaiter.deliver
cassandra.InvalidRequest: Error from server: code=2200 [Invalid query] message="Keyspace 'Keyspace1' does not exist"

During handling of the above exception, another exception occurred:

Traceback (most recent call last):
  File "cassandra/cluster.py", line 3175, in cassandra.cluster.Session.add_or_renew_pool.run_add_or_renew_pool
  File "cassandra/pool.py", line 405, in cassandra.pool.HostConnection.__init__
  File "cassandra/connection.py", line 1447, in cassandra.connection.Connection.set_keyspace_blocking
cassandra.connection.ConnectionException: Problem while setting keyspace: InvalidRequest('Error from server: code=2200 [Invalid query] message="Keyspace \'Keyspace1\' does not exist"',)
22:29:42,431 cassandra.cluster WARNING Failed to create connection pool for new host 127.0.0.1:9042:
Traceback (most recent call last):
  File "cassandra/connection.py", line 1439, in cassandra.connection.Connection.set_keyspace_blocking
  File "cassandra/connection.py", line 1029, in cassandra.connection.Connection.wait_for_response
  File "cassandra/connection.py", line 1076, in cassandra.connection.Connection.wait_for_responses
  File "cassandra/connection.py", line 1071, in cassandra.connection.Connection.wait_for_responses
  File "cassandra/connection.py", line 1570, in cassandra.connection.ResponseWaiter.deliver
cassandra.InvalidRequest: Error from server: code=2200 [Invalid query] message="Keyspace 'Keyspace1' does not exist"

During handling of the above exception, another exception occurred:

Traceback (most recent call last):
  File "cassandra/cluster.py", line 3175, in cassandra.cluster.Session.add_or_renew_pool.run_add_or_renew_pool
  File "cassandra/pool.py", line 405, in cassandra.pool.HostConnection.__init__
  File "cassandra/connection.py", line 1447, in cassandra.connection.Connection.set_keyspace_blocking
cassandra.connection.ConnectionException: Problem while setting keyspace: InvalidRequest('Error from server: code=2200 [Invalid query] message="Keyspace \'Keyspace1\' does not exist"',)
22:29:43,19 cassandra.pool WARNING Error attempting to reconnect to 127.0.0.2:9042, scheduling retry in 8.48 seconds: [Errno 111] Tried connecting to [('127.0.0.2', 9042)]. Last error: Connection refused
22:29:43,635 cassandra.cluster WARNING Failed to create connection pool for new host 127.0.0.1:9042:
Traceback (most recent call last):
  File "cassandra/connection.py", line 1439, in cassandra.connection.Connection.set_keyspace_blocking
  File "cassandra/connection.py", line 1029, in cassandra.connection.Connection.wait_for_response
  File "cassandra/connection.py", line 1076, in cassandra.connection.Connection.wait_for_responses
  File "cassandra/connection.py", line 1071, in cassandra.connection.Connection.wait_for_responses
  File "cassandra/connection.py", line 1570, in cassandra.connection.ResponseWaiter.deliver
cassandra.InvalidRequest: Error from server: code=2200 [Invalid query] message="Keyspace 'Keyspace1' does not exist"

During handling of the above exception, another exception occurred:

Traceback (most recent call last):
  File "cassandra/cluster.py", line 3175, in cassandra.cluster.Session.add_or_renew_pool.run_add_or_renew_pool
  File "cassandra/pool.py", line 405, in cassandra.pool.HostConnection.__init__
  File "cassandra/connection.py", line 1447, in cassandra.connection.Connection.set_keyspace_blocking
cassandra.connection.ConnectionException: Problem while setting keyspace: InvalidRequest('Error from server: code=2200 [Invalid query] message="Keyspace \'Keyspace1\' does not exist"',)
22:29:44,866 cassandra.cluster WARNING Failed to create connection pool for new host 127.0.0.1:9042:
Traceback (most recent call last):
  File "cassandra/connection.py", line 1439, in cassandra.connection.Connection.set_keyspace_blocking
  File "cassandra/connection.py", line 1029, in cassandra.connection.Connection.wait_for_response
  File "cassandra/connection.py", line 1076, in cassandra.connection.Connection.wait_for_responses
  File "cassandra/connection.py", line 1071, in cassandra.connection.Connection.wait_for_responses
  File "cassandra/connection.py", line 1570, in cassandra.connection.ResponseWaiter.deliver
cassandra.InvalidRequest: Error from server: code=2200 [Invalid query] message="Keyspace 'Keyspace1' does not exist"

During handling of the above exception, another exception occurred:

Traceback (most recent call last):
  File "cassandra/cluster.py", line 3175, in cassandra.cluster.Session.add_or_renew_pool.run_add_or_renew_pool
  File "cassandra/pool.py", line 405, in cassandra.pool.HostConnection.__init__
  File "cassandra/connection.py", line 1447, in cassandra.connection.Connection.set_keyspace_blocking
cassandra.connection.ConnectionException: Problem while setting keyspace: InvalidRequest('Error from server: code=2200 [Invalid query] message="Keyspace \'Keyspace1\' does not exist"',)
22:29:45,942 cassandra.cluster WARNING Failed to create connection pool for new host 127.0.0.1:9042:
Traceback (most recent call last):
  File "cassandra/connection.py", line 1439, in cassandra.connection.Connection.set_keyspace_blocking
  File "cassandra/connection.py", line 1029, in cassandra.connection.Connection.wait_for_response
  File "cassandra/connection.py", line 1076, in cassandra.connection.Connection.wait_for_responses
  File "cassandra/connection.py", line 1071, in cassandra.connection.Connection.wait_for_responses
  File "cassandra/connection.py", line 1570, in cassandra.connection.ResponseWaiter.deliver
cassandra.InvalidRequest: Error from server: code=2200 [Invalid query] message="Keyspace 'Keyspace1' does not exist"

During handling of the above exception, another exception occurred:

Traceback (most recent call last):
  File "cassandra/cluster.py", line 3175, in cassandra.cluster.Session.add_or_renew_pool.run_add_or_renew_pool
  File "cassandra/pool.py", line 405, in cassandra.pool.HostConnection.__init__
  File "cassandra/connection.py", line 1447, in cassandra.connection.Connection.set_keyspace_blocking
cassandra.connection.ConnectionException: Problem while setting keyspace: InvalidRequest('Error from server: code=2200 [Invalid query] message="Keyspace \'Keyspace1\' does not exist"',)
22:29:47,45 cassandra.cluster WARNING Failed to create connection pool for new host 127.0.0.1:9042:
Traceback (most recent call last):
  File "cassandra/connection.py", line 1439, in cassandra.connection.Connection.set_keyspace_blocking
  File "cassandra/connection.py", line 1029, in cassandra.connection.Connection.wait_for_response
  File "cassandra/connection.py", line 1076, in cassandra.connection.Connection.wait_for_responses
  File "cassandra/connection.py", line 1071, in cassandra.connection.Connection.wait_for_responses
  File "cassandra/connection.py", line 1570, in cassandra.connection.ResponseWaiter.deliver
cassandra.InvalidRequest: Error from server: code=2200 [Invalid query] message="Keyspace 'Keyspace1' does not exist"

During handling of the above exception, another exception occurred:

Traceback (most recent call last):
  File "cassandra/cluster.py", line 3175, in cassandra.cluster.Session.add_or_renew_pool.run_add_or_renew_pool
  File "cassandra/pool.py", line 405, in cassandra.pool.HostConnection.__init__
  File "cassandra/connection.py", line 1447, in cassandra.connection.Connection.set_keyspace_blocking
cassandra.connection.ConnectionException: Problem while setting keyspace: InvalidRequest('Error from server: code=2200 [Invalid query] message="Keyspace \'Keyspace1\' does not exist"',)
22:29:48,149 cassandra.cluster WARNING Failed to create connection pool for new host 127.0.0.1:9042:
Traceback (most recent call last):
  File "cassandra/connection.py", line 1439, in cassandra.connection.Connection.set_keyspace_blocking
  File "cassandra/connection.py", line 1029, in cassandra.connection.Connection.wait_for_response
  File "cassandra/connection.py", line 1076, in cassandra.connection.Connection.wait_for_responses
  File "cassandra/connection.py", line 1071, in cassandra.connection.Connection.wait_for_responses
  File "cassandra/connection.py", line 1570, in cassandra.connection.ResponseWaiter.deliver
cassandra.InvalidRequest: Error from server: code=2200 [Invalid query] message="Keyspace 'Keyspace1' does not exist"

During handling of the above exception, another exception occurred:

Traceback (most recent call last):
  File "cassandra/cluster.py", line 3175, in cassandra.cluster.Session.add_or_renew_pool.run_add_or_renew_pool
  File "cassandra/pool.py", line 405, in cassandra.pool.HostConnection.__init__
  File "cassandra/connection.py", line 1447, in cassandra.connection.Connection.set_keyspace_blocking
cassandra.connection.ConnectionException: Problem while setting keyspace: InvalidRequest('Error from server: code=2200 [Invalid query] message="Keyspace \'Keyspace1\' does not exist"',)
22:29:49,250 cassandra.cluster WARNING Failed to create connection pool for new host 127.0.0.1:9042:
Traceback (most recent call last):
  File "cassandra/connection.py", line 1439, in cassandra.connection.Connection.set_keyspace_blocking
  File "cassandra/connection.py", line 1029, in cassandra.connection.Connection.wait_for_response
  File "cassandra/connection.py", line 1076, in cassandra.connection.Connection.wait_for_responses
  File "cassandra/connection.py", line 1071, in cassandra.connection.Connection.wait_for_responses
  File "cassandra/connection.py", line 1570, in cassandra.connection.ResponseWaiter.deliver
cassandra.InvalidRequest: Error from server: code=2200 [Invalid query] message="Keyspace 'Keyspace1' does not exist"

During handling of the above exception, another exception occurred:

Traceback (most recent call last):
  File "cassandra/cluster.py", line 3175, in cassandra.cluster.Session.add_or_renew_pool.run_add_or_renew_pool
  File "cassandra/pool.py", line 405, in cassandra.pool.HostConnection.__init__
  File "cassandra/connection.py", line 1447, in cassandra.connection.Connection.set_keyspace_blocking
cassandra.connection.ConnectionException: Problem while setting keyspace: InvalidRequest('Error from server: code=2200 [Invalid query] message="Keyspace \'Keyspace1\' does not exist"',)
22:29:50,353 cassandra.cluster WARNING Failed to create connection pool for new host 127.0.0.1:9042:
Traceback (most recent call last):
  File "cassandra/connection.py", line 1439, in cassandra.connection.Connection.set_keyspace_blocking
  File "cassandra/connection.py", line 1029, in cassandra.connection.Connection.wait_for_response
  File "cassandra/connection.py", line 1076, in cassandra.connection.Connection.wait_for_responses
  File "cassandra/connection.py", line 1071, in cassandra.connection.Connection.wait_for_responses
  File "cassandra/connection.py", line 1570, in cassandra.connection.ResponseWaiter.deliver
cassandra.InvalidRequest: Error from server: code=2200 [Invalid query] message="Keyspace 'Keyspace1' does not exist"

During handling of the above exception, another exception occurred:

Traceback (most recent call last):
  File "cassandra/cluster.py", line 3175, in cassandra.cluster.Session.add_or_renew_pool.run_add_or_renew_pool
  File "cassandra/pool.py", line 405, in cassandra.pool.HostConnection.__init__
  File "cassandra/connection.py", line 1447, in cassandra.connection.Connection.set_keyspace_blocking
cassandra.connection.ConnectionException: Problem while setting keyspace: InvalidRequest('Error from server: code=2200 [Invalid query] message="Keyspace \'Keyspace1\' does not exist"',)
22:29:51,455 cassandra.cluster WARNING Failed to create connection pool for new host 127.0.0.1:9042:
Traceback (most recent call last):
  File "cassandra/connection.py", line 1439, in cassandra.connection.Connection.set_keyspace_blocking
  File "cassandra/connection.py", line 1029, in cassandra.connection.Connection.wait_for_response
  File "cassandra/connection.py", line 1076, in cassandra.connection.Connection.wait_for_responses
  File "cassandra/connection.py", line 1071, in cassandra.connection.Connection.wait_for_responses
  File "cassandra/connection.py", line 1570, in cassandra.connection.ResponseWaiter.deliver
cassandra.InvalidRequest: Error from server: code=2200 [Invalid query] message="Keyspace 'Keyspace1' does not exist"

During handling of the above exception, another exception occurred:

Traceback (most recent call last):
  File "cassandra/cluster.py", line 3175, in cassandra.cluster.Session.add_or_renew_pool.run_add_or_renew_pool
  File "cassandra/pool.py", line 405, in cassandra.pool.HostConnection.__init__
  File "cassandra/connection.py", line 1447, in cassandra.connection.Connection.set_keyspace_blocking
cassandra.connection.ConnectionException: Problem while setting keyspace: InvalidRequest('Error from server: code=2200 [Invalid query] message="Keyspace \'Keyspace1\' does not exist"',)
22:29:51,657 cassandra.cluster WARNING Failed to create connection pool for new host 127.0.0.2:9042:
Traceback (most recent call last):
  File "cassandra/connection.py", line 1439, in cassandra.connection.Connection.set_keyspace_blocking
  File "cassandra/connection.py", line 1029, in cassandra.connection.Connection.wait_for_response
  File "cassandra/connection.py", line 1076, in cassandra.connection.Connection.wait_for_responses
  File "cassandra/connection.py", line 1071, in cassandra.connection.Connection.wait_for_responses
  File "cassandra/connection.py", line 1570, in cassandra.connection.ResponseWaiter.deliver
cassandra.InvalidRequest: Error from server: code=2200 [Invalid query] message="Keyspace 'Keyspace1' does not exist"

During handling of the above exception, another exception occurred:

Traceback (most recent call last):
  File "cassandra/cluster.py", line 3175, in cassandra.cluster.Session.add_or_renew_pool.run_add_or_renew_pool
  File "cassandra/pool.py", line 405, in cassandra.pool.HostConnection.__init__
  File "cassandra/connection.py", line 1447, in cassandra.connection.Connection.set_keyspace_blocking
cassandra.connection.ConnectionException: Problem while setting keyspace: InvalidRequest('Error from server: code=2200 [Invalid query] message="Keyspace \'Keyspace1\' does not exist"',)
PASSED                                                                   [100%]
===Flaky Test Report===

test_sstableloader_with_mv passed 1 out of the required 1 times. Success!

===End Flaky Test Report===

========================== 1 passed in 148.97 seconds ==========================
[msx] rc = 0
mv /tmp/my_log.txt /users/masix/vm_images/ZebraConf/app_meta/logs/sstable_generation_loading_test.py::TestSSTableGenerationAndLoading::test_sstableloader_with_mv-output_1643171488014_108751176.txt
