cassandra consistency_test.py::TestAvailability::test_simple_strategy true true
the_test is consistency_test.py::TestAvailability::test_simple_strategy
============================= test session starts ==============================
platform linux -- Python 3.6.9, pytest-3.6.4, py-1.11.0, pluggy-0.7.1 -- /users/masix/dtest/bin/python
cachedir: .pytest_cache
rootdir: /users/masix/cassandra-dtest, inifile: pytest.ini
plugins: timeout-1.4.2, repeat-0.9.1, flaky-3.7.0
timeout: 900.0s
timeout method: signal
timeout func_only: False
collecting ... collected 1 item

consistency_test.py::TestAvailability::test_simple_strategy 
-------------------------------- live log call ---------------------------------
02:01:12,474 ccmlib.node WARNING [msx] ccmlib:copy_config_files.py, conf_dir = /users/masix/cassandra/conf
02:01:12,560 ccmlib.node WARNING [msx] ccmlib:node.py, self.name = node1
02:01:12,629 ccmlib.node WARNING [msx] ccmlib:node.py, self.name = node1
02:01:12,721 ccmlib.node WARNING [msx] ccmlib:copy_config_files.py, conf_dir = /users/masix/cassandra/conf
02:01:12,805 ccmlib.node WARNING [msx] ccmlib:node.py, self.name = node2
02:01:12,871 ccmlib.node WARNING [msx] ccmlib:node.py, self.name = node2
02:01:12,963 ccmlib.node WARNING [msx] ccmlib:copy_config_files.py, conf_dir = /users/masix/cassandra/conf
02:01:13,48 ccmlib.node WARNING [msx] ccmlib:node.py, self.name = node3
02:01:13,115 ccmlib.node WARNING [msx] ccmlib:node.py, self.name = node3
02:02:00,7 cassandra.cluster WARNING Host 127.0.0.1:9042 has been marked down
02:02:00,12 cassandra.cluster WARNING [control connection] Error connecting to 127.0.0.1:9042:
Traceback (most recent call last):
  File "cassandra/cluster.py", line 3522, in cassandra.cluster.ControlConnection._reconnect_internal
  File "cassandra/cluster.py", line 3544, in cassandra.cluster.ControlConnection._try_connect
  File "cassandra/cluster.py", line 1620, in cassandra.cluster.Cluster.connection_factory
  File "cassandra/connection.py", line 831, in cassandra.connection.Connection.factory
  File "/users/masix/dtest/src/cassandra-driver/cassandra/io/libevreactor.py", line 267, in __init__
    self._connect_socket()
  File "cassandra/connection.py", line 898, in cassandra.connection.Connection._connect_socket
ConnectionRefusedError: [Errno 111] Tried connecting to [('127.0.0.1', 9042)]. Last error: Connection refused
02:02:01,24 cassandra.pool WARNING Error attempting to reconnect to 127.0.0.1:9042, scheduling retry in 2.26 seconds: [Errno 111] Tried connecting to [('127.0.0.1', 9042)]. Last error: Connection refused
02:02:03,343 cassandra.pool WARNING Error attempting to reconnect to 127.0.0.1:9042, scheduling retry in 3.68 seconds: [Errno 111] Tried connecting to [('127.0.0.1', 9042)]. Last error: Connection refused
02:02:03,615 cassandra.cluster WARNING Host 127.0.0.1:9042 has been marked down
02:02:03,619 cassandra.cluster WARNING [control connection] Error connecting to 127.0.0.1:9042:
Traceback (most recent call last):
  File "cassandra/cluster.py", line 3522, in cassandra.cluster.ControlConnection._reconnect_internal
  File "cassandra/cluster.py", line 3544, in cassandra.cluster.ControlConnection._try_connect
  File "cassandra/cluster.py", line 1620, in cassandra.cluster.Cluster.connection_factory
  File "cassandra/connection.py", line 831, in cassandra.connection.Connection.factory
  File "/users/masix/dtest/src/cassandra-driver/cassandra/io/libevreactor.py", line 267, in __init__
    self._connect_socket()
  File "cassandra/connection.py", line 898, in cassandra.connection.Connection._connect_socket
ConnectionRefusedError: [Errno 111] Tried connecting to [('127.0.0.1', 9042)]. Last error: Connection refused
02:02:04,634 cassandra.pool WARNING Error attempting to reconnect to 127.0.0.1:9042, scheduling retry in 1.76 seconds: [Errno 111] Tried connecting to [('127.0.0.1', 9042)]. Last error: Connection refused
02:02:06,454 cassandra.pool WARNING Error attempting to reconnect to 127.0.0.1:9042, scheduling retry in 4.0 seconds: [Errno 111] Tried connecting to [('127.0.0.1', 9042)]. Last error: Connection refused
02:02:07,80 cassandra.pool WARNING Error attempting to reconnect to 127.0.0.1:9042, scheduling retry in 7.36 seconds: [Errno 111] Tried connecting to [('127.0.0.1', 9042)]. Last error: Connection refused
02:02:10,469 cassandra.pool WARNING Error attempting to reconnect to 127.0.0.1:9042, scheduling retry in 8.24 seconds: [Errno 111] Tried connecting to [('127.0.0.1', 9042)]. Last error: Connection refused
02:02:14,496 cassandra.pool WARNING Error attempting to reconnect to 127.0.0.1:9042, scheduling retry in 14.56 seconds: [Errno 111] Tried connecting to [('127.0.0.1', 9042)]. Last error: Connection refused
02:02:18,790 cassandra.pool WARNING Error attempting to reconnect to 127.0.0.1:9042, scheduling retry in 15.68 seconds: [Errno 111] Tried connecting to [('127.0.0.1', 9042)]. Last error: Connection refused
02:02:25,718 cassandra.cluster WARNING Host 127.0.0.2:9042 has been marked down
02:02:25,720 cassandra.cluster WARNING [control connection] Error connecting to 127.0.0.2:9042:
Traceback (most recent call last):
  File "cassandra/cluster.py", line 3522, in cassandra.cluster.ControlConnection._reconnect_internal
  File "cassandra/cluster.py", line 3544, in cassandra.cluster.ControlConnection._try_connect
  File "cassandra/cluster.py", line 1620, in cassandra.cluster.Cluster.connection_factory
  File "cassandra/connection.py", line 831, in cassandra.connection.Connection.factory
  File "/users/masix/dtest/src/cassandra-driver/cassandra/io/libevreactor.py", line 267, in __init__
    self._connect_socket()
  File "cassandra/connection.py", line 898, in cassandra.connection.Connection._connect_socket
ConnectionRefusedError: [Errno 111] Tried connecting to [('127.0.0.2', 9042)]. Last error: Connection refused
02:02:26,726 cassandra.pool WARNING Error attempting to reconnect to 127.0.0.2:9042, scheduling retry in 1.86 seconds: [Errno 111] Tried connecting to [('127.0.0.2', 9042)]. Last error: Connection refused
02:02:28,631 cassandra.pool WARNING Error attempting to reconnect to 127.0.0.2:9042, scheduling retry in 3.72 seconds: [Errno 111] Tried connecting to [('127.0.0.2', 9042)]. Last error: Connection refused
02:02:29,149 cassandra.pool WARNING Error attempting to reconnect to 127.0.0.1:9042, scheduling retry in 29.12 seconds: [Errno 111] Tried connecting to [('127.0.0.1', 9042)]. Last error: Connection refused
02:02:32,441 cassandra.pool WARNING Error attempting to reconnect to 127.0.0.2:9042, scheduling retry in 8.96 seconds: [Errno 111] Tried connecting to [('127.0.0.2', 9042)]. Last error: Connection refused
02:02:34,540 cassandra.pool WARNING Error attempting to reconnect to 127.0.0.1:9042, scheduling retry in 28.48 seconds: [Errno 111] Tried connecting to [('127.0.0.1', 9042)]. Last error: Connection refused
PASSED                                                                   [100%]
===Flaky Test Report===

test_simple_strategy passed 1 out of the required 1 times. Success!

===End Flaky Test Report===

========================== 1 passed in 89.16 seconds ===========================
[msx] rc = 0
