cassandra global_row_key_cache_test.py::TestGlobalRowKeyCache::test_functional true true
the_test is global_row_key_cache_test.py::TestGlobalRowKeyCache::test_functional
============================= test session starts ==============================
platform linux -- Python 3.6.9, pytest-3.6.4, py-1.11.0, pluggy-0.7.1 -- /users/masix/dtest/bin/python
cachedir: .pytest_cache
rootdir: /users/masix/cassandra-dtest, inifile: pytest.ini
plugins: timeout-1.4.2, repeat-0.9.1, flaky-3.7.0
timeout: 900.0s
timeout method: signal
timeout func_only: False
collecting ... collected 1 item

global_row_key_cache_test.py::TestGlobalRowKeyCache::test_functional 
-------------------------------- live log call ---------------------------------
03:56:59,505 ccmlib.node WARNING [msx] ccmlib:copy_config_files.py, conf_dir = /users/masix/cassandra/conf
03:56:59,592 ccmlib.node WARNING [msx] ccmlib:node.py, self.name = node1
03:56:59,660 ccmlib.node WARNING [msx] ccmlib:node.py, self.name = node1
03:56:59,751 ccmlib.node WARNING [msx] ccmlib:copy_config_files.py, conf_dir = /users/masix/cassandra/conf
03:56:59,834 ccmlib.node WARNING [msx] ccmlib:node.py, self.name = node2
03:56:59,899 ccmlib.node WARNING [msx] ccmlib:node.py, self.name = node2
03:56:59,990 ccmlib.node WARNING [msx] ccmlib:copy_config_files.py, conf_dir = /users/masix/cassandra/conf
03:57:00,74 ccmlib.node WARNING [msx] ccmlib:node.py, self.name = node3
03:57:00,140 ccmlib.node WARNING [msx] ccmlib:node.py, self.name = node3
03:57:00,195 ccmlib.node WARNING [msx] ccmlib:copy_config_files.py, conf_dir = /users/masix/cassandra/conf
03:57:00,278 ccmlib.node WARNING [msx] ccmlib:node.py, self.name = node1
03:57:00,328 ccmlib.node WARNING [msx] ccmlib:copy_config_files.py, conf_dir = /users/masix/cassandra/conf
03:57:00,410 ccmlib.node WARNING [msx] ccmlib:node.py, self.name = node2
03:57:00,460 ccmlib.node WARNING [msx] ccmlib:copy_config_files.py, conf_dir = /users/masix/cassandra/conf
03:57:00,544 ccmlib.node WARNING [msx] ccmlib:node.py, self.name = node3
03:57:44,459 cassandra.cluster WARNING Host 127.0.0.1:9042 has been marked down
03:57:45,468 cassandra.pool WARNING Error attempting to reconnect to 127.0.0.1:9042, scheduling retry in 1.94 seconds: [Errno 111] Tried connecting to [('127.0.0.1', 9042)]. Last error: Connection refused
03:57:47,475 cassandra.pool WARNING Error attempting to reconnect to 127.0.0.1:9042, scheduling retry in 3.4 seconds: [Errno 111] Tried connecting to [('127.0.0.1', 9042)]. Last error: Connection refused
03:57:50,885 cassandra.pool WARNING Error attempting to reconnect to 127.0.0.1:9042, scheduling retry in 6.8 seconds: [Errno 111] Tried connecting to [('127.0.0.1', 9042)]. Last error: Connection refused
03:57:51,570 cassandra.cluster WARNING Host 127.0.0.2:9042 has been marked down
03:57:52,594 cassandra.pool WARNING Error attempting to reconnect to 127.0.0.2:9042, scheduling retry in 2.06 seconds: [Errno 111] Tried connecting to [('127.0.0.2', 9042)]. Last error: Connection refused
03:57:54,700 cassandra.pool WARNING Error attempting to reconnect to 127.0.0.2:9042, scheduling retry in 4.12 seconds: [Errno 111] Tried connecting to [('127.0.0.2', 9042)]. Last error: Connection refused
03:57:57,708 cassandra.pool WARNING Error attempting to reconnect to 127.0.0.1:9042, scheduling retry in 18.08 seconds: [Errno 111] Tried connecting to [('127.0.0.1', 9042)]. Last error: Connection refused
03:57:58,911 cassandra.pool WARNING Error attempting to reconnect to 127.0.0.2:9042, scheduling retry in 8.56 seconds: [Errno 111] Tried connecting to [('127.0.0.2', 9042)]. Last error: Connection refused
03:58:06,693 cassandra.cluster WARNING Host 127.0.0.3:9042 has been marked down
03:58:07,533 cassandra.pool WARNING Error attempting to reconnect to 127.0.0.2:9042, scheduling retry in 16.16 seconds: [Errno 111] Tried connecting to [('127.0.0.2', 9042)]. Last error: Connection refused
03:58:07,734 cassandra.pool WARNING Error attempting to reconnect to 127.0.0.3:9042, scheduling retry in 1.86 seconds: [Errno 111] Tried connecting to [('127.0.0.3', 9042)]. Last error: Connection refused
03:58:09,639 cassandra.pool WARNING Error attempting to reconnect to 127.0.0.3:9042, scheduling retry in 3.56 seconds: [Errno 111] Tried connecting to [('127.0.0.3', 9042)]. Last error: Connection refused
03:58:13,249 cassandra.pool WARNING Error attempting to reconnect to 127.0.0.3:9042, scheduling retry in 8.88 seconds: [Errno 111] Tried connecting to [('127.0.0.3', 9042)]. Last error: Connection refused
03:58:15,860 cassandra.pool WARNING Error attempting to reconnect to 127.0.0.1:9042, scheduling retry in 31.68 seconds: [Errno 111] Tried connecting to [('127.0.0.1', 9042)]. Last error: Connection refused
03:58:22,179 cassandra.pool WARNING Error attempting to reconnect to 127.0.0.3:9042, scheduling retry in 16.32 seconds: [Errno 111] Tried connecting to [('127.0.0.3', 9042)]. Last error: Connection refused
03:58:23,783 cassandra.pool WARNING Error attempting to reconnect to 127.0.0.2:9042, scheduling retry in 35.52 seconds: [Errno 111] Tried connecting to [('127.0.0.2', 9042)]. Last error: Connection refused
03:58:47,545 cassandra.pool WARNING Error attempting to reconnect to 127.0.0.1:9042, scheduling retry in 64.0 seconds: [Errno 111] Tried connecting to [('127.0.0.1', 9042)]. Last error: Connection refused
03:58:59,377 cassandra.pool WARNING Error attempting to reconnect to 127.0.0.2:9042, scheduling retry in 71.04 seconds: [Errno 111] Tried connecting to [('127.0.0.2', 9042)]. Last error: Connection refused
03:59:08,700 cassandra.cluster WARNING Host 127.0.0.1:9042 has been marked down
03:59:08,701 cassandra.cluster WARNING Host 127.0.0.3:9042 has been marked down
03:59:08,702 cassandra.cluster WARNING Host 127.0.0.2:9042 has been marked down
03:59:08,704 cassandra.cluster WARNING [control connection] Error connecting to 127.0.0.2:9042:
Traceback (most recent call last):
  File "cassandra/cluster.py", line 3522, in cassandra.cluster.ControlConnection._reconnect_internal
  File "cassandra/cluster.py", line 3544, in cassandra.cluster.ControlConnection._try_connect
  File "cassandra/cluster.py", line 1620, in cassandra.cluster.Cluster.connection_factory
  File "cassandra/connection.py", line 831, in cassandra.connection.Connection.factory
  File "/users/masix/dtest/src/cassandra-driver/cassandra/io/libevreactor.py", line 267, in __init__
    self._connect_socket()
  File "cassandra/connection.py", line 898, in cassandra.connection.Connection._connect_socket
ConnectionRefusedError: [Errno 111] Tried connecting to [('127.0.0.2', 9042)]. Last error: Connection refused
03:59:09,706 cassandra.pool WARNING Error attempting to reconnect to 127.0.0.1:9042, scheduling retry in 1.8 seconds: [Errno 111] Tried connecting to [('127.0.0.1', 9042)]. Last error: Connection refused
03:59:09,807 cassandra.pool WARNING Error attempting to reconnect to 127.0.0.2:9042, scheduling retry in 2.0 seconds: [Errno 111] Tried connecting to [('127.0.0.2', 9042)]. Last error: Connection refused
03:59:09,807 cassandra.pool WARNING Error attempting to reconnect to 127.0.0.3:9042, scheduling retry in 2.22 seconds: [Errno 111] Tried connecting to [('127.0.0.3', 9042)]. Last error: Connection refused
03:59:11,511 cassandra.pool WARNING Error attempting to reconnect to 127.0.0.1:9042, scheduling retry in 4.04 seconds: [Errno 111] Tried connecting to [('127.0.0.1', 9042)]. Last error: Connection refused
03:59:11,812 cassandra.pool WARNING Error attempting to reconnect to 127.0.0.2:9042, scheduling retry in 4.36 seconds: [Errno 111] Tried connecting to [('127.0.0.2', 9042)]. Last error: Connection refused
03:59:12,113 cassandra.pool WARNING Error attempting to reconnect to 127.0.0.3:9042, scheduling retry in 4.24 seconds: [Errno 111] Tried connecting to [('127.0.0.3', 9042)]. Last error: Connection refused
03:59:15,622 cassandra.pool WARNING Error attempting to reconnect to 127.0.0.1:9042, scheduling retry in 8.16 seconds: [Errno 111] Tried connecting to [('127.0.0.1', 9042)]. Last error: Connection refused
03:59:16,224 cassandra.pool WARNING Error attempting to reconnect to 127.0.0.2:9042, scheduling retry in 8.32 seconds: [Errno 111] Tried connecting to [('127.0.0.2', 9042)]. Last error: Connection refused
03:59:16,424 cassandra.pool WARNING Error attempting to reconnect to 127.0.0.3:9042, scheduling retry in 8.4 seconds: [Errno 111] Tried connecting to [('127.0.0.3', 9042)]. Last error: Connection refused
03:59:16,454 ccmlib.node WARNING [msx] ccmlib:copy_config_files.py, conf_dir = /users/masix/cassandra/conf
03:59:16,549 ccmlib.node WARNING [msx] ccmlib:node.py, self.name = node1
03:59:16,601 ccmlib.node WARNING [msx] ccmlib:copy_config_files.py, conf_dir = /users/masix/cassandra/conf
03:59:16,684 ccmlib.node WARNING [msx] ccmlib:node.py, self.name = node2
03:59:16,735 ccmlib.node WARNING [msx] ccmlib:copy_config_files.py, conf_dir = /users/masix/cassandra/conf
03:59:16,818 ccmlib.node WARNING [msx] ccmlib:node.py, self.name = node3
03:59:19,502 cassandra.cluster WARNING [control connection] Error connecting to 127.0.0.3:9042:
Traceback (most recent call last):
  File "cassandra/cluster.py", line 3522, in cassandra.cluster.ControlConnection._reconnect_internal
  File "cassandra/cluster.py", line 3544, in cassandra.cluster.ControlConnection._try_connect
  File "cassandra/cluster.py", line 1620, in cassandra.cluster.Cluster.connection_factory
  File "cassandra/connection.py", line 831, in cassandra.connection.Connection.factory
  File "/users/masix/dtest/src/cassandra-driver/cassandra/io/libevreactor.py", line 267, in __init__
    self._connect_socket()
  File "cassandra/connection.py", line 898, in cassandra.connection.Connection._connect_socket
ConnectionRefusedError: [Errno 111] Tried connecting to [('127.0.0.3', 9042)]. Last error: Connection refused
03:59:20,551 cassandra.cluster WARNING [control connection] Error connecting to 127.0.0.3:9042:
Traceback (most recent call last):
  File "cassandra/cluster.py", line 3522, in cassandra.cluster.ControlConnection._reconnect_internal
  File "cassandra/cluster.py", line 3544, in cassandra.cluster.ControlConnection._try_connect
  File "cassandra/cluster.py", line 1620, in cassandra.cluster.Cluster.connection_factory
  File "cassandra/connection.py", line 831, in cassandra.connection.Connection.factory
  File "/users/masix/dtest/src/cassandra-driver/cassandra/io/libevreactor.py", line 267, in __init__
    self._connect_socket()
  File "cassandra/connection.py", line 898, in cassandra.connection.Connection._connect_socket
ConnectionRefusedError: [Errno 111] Tried connecting to [('127.0.0.3', 9042)]. Last error: Connection refused
03:59:22,355 cassandra.cluster WARNING [control connection] Error connecting to 127.0.0.3:9042:
Traceback (most recent call last):
  File "cassandra/cluster.py", line 3522, in cassandra.cluster.ControlConnection._reconnect_internal
  File "cassandra/cluster.py", line 3544, in cassandra.cluster.ControlConnection._try_connect
  File "cassandra/cluster.py", line 1620, in cassandra.cluster.Cluster.connection_factory
  File "cassandra/connection.py", line 831, in cassandra.connection.Connection.factory
  File "/users/masix/dtest/src/cassandra-driver/cassandra/io/libevreactor.py", line 267, in __init__
    self._connect_socket()
  File "cassandra/connection.py", line 898, in cassandra.connection.Connection._connect_socket
ConnectionRefusedError: [Errno 111] Tried connecting to [('127.0.0.3', 9042)]. Last error: Connection refused
03:59:23,881 cassandra.pool WARNING Error attempting to reconnect to 127.0.0.1:9042, scheduling retry in 18.4 seconds: [Errno 111] Tried connecting to [('127.0.0.1', 9042)]. Last error: Connection refused
03:59:24,583 cassandra.pool WARNING Error attempting to reconnect to 127.0.0.2:9042, scheduling retry in 14.88 seconds: [Errno 111] Tried connecting to [('127.0.0.2', 9042)]. Last error: Connection refused
03:59:24,884 cassandra.pool WARNING Error attempting to reconnect to 127.0.0.3:9042, scheduling retry in 18.4 seconds: [Errno 111] Tried connecting to [('127.0.0.3', 9042)]. Last error: Connection refused
03:59:26,166 cassandra.cluster WARNING [control connection] Error connecting to 127.0.0.3:9042:
Traceback (most recent call last):
  File "cassandra/cluster.py", line 3522, in cassandra.cluster.ControlConnection._reconnect_internal
  File "cassandra/cluster.py", line 3544, in cassandra.cluster.ControlConnection._try_connect
  File "cassandra/cluster.py", line 1620, in cassandra.cluster.Cluster.connection_factory
  File "cassandra/connection.py", line 831, in cassandra.connection.Connection.factory
  File "/users/masix/dtest/src/cassandra-driver/cassandra/io/libevreactor.py", line 267, in __init__
    self._connect_socket()
  File "cassandra/connection.py", line 898, in cassandra.connection.Connection._connect_socket
ConnectionRefusedError: [Errno 111] Tried connecting to [('127.0.0.3', 9042)]. Last error: Connection refused
03:59:59,613 cassandra.cluster WARNING Host 127.0.0.1:9042 has been marked down
03:59:59,631 cassandra.cluster WARNING Host 127.0.0.1:9042 has been marked down
04:00:00,619 cassandra.pool WARNING Error attempting to reconnect to 127.0.0.1:9042, scheduling retry in 2.02 seconds: [Errno 111] Tried connecting to [('127.0.0.1', 9042)]. Last error: Connection refused
04:00:00,779 cassandra.pool WARNING Error attempting to reconnect to 127.0.0.1:9042, scheduling retry in 1.9 seconds: [Errno 111] Tried connecting to [('127.0.0.1', 9042)]. Last error: Connection refused
04:00:02,684 cassandra.pool WARNING Error attempting to reconnect to 127.0.0.1:9042, scheduling retry in 4.16 seconds: [Errno 111] Tried connecting to [('127.0.0.1', 9042)]. Last error: Connection refused
04:00:02,726 cassandra.pool WARNING Error attempting to reconnect to 127.0.0.1:9042, scheduling retry in 4.52 seconds: [Errno 111] Tried connecting to [('127.0.0.1', 9042)]. Last error: Connection refused
04:00:06,733 cassandra.cluster WARNING Host 127.0.0.2:9042 has been marked down
04:00:06,899 cassandra.pool WARNING Error attempting to reconnect to 127.0.0.1:9042, scheduling retry in 9.12 seconds: [Errno 111] Tried connecting to [('127.0.0.1', 9042)]. Last error: Connection refused
04:00:07,339 cassandra.pool WARNING Error attempting to reconnect to 127.0.0.1:9042, scheduling retry in 7.84 seconds: [Errno 111] Tried connecting to [('127.0.0.1', 9042)]. Last error: Connection refused
04:00:07,840 cassandra.pool WARNING Error attempting to reconnect to 127.0.0.2:9042, scheduling retry in 2.12 seconds: [Errno 111] Tried connecting to [('127.0.0.2', 9042)]. Last error: Connection refused
04:00:08,703 cassandra.cluster WARNING Host 127.0.0.2:9042 has been marked down
04:00:08,704 cassandra.cluster WARNING Host 127.0.0.1:9042 has been marked down
04:00:09,864 cassandra.pool WARNING Error attempting to reconnect to 127.0.0.2:9042, scheduling retry in 2.1 seconds: [Errno 111] Tried connecting to [('127.0.0.2', 9042)]. Last error: Connection refused
04:00:09,865 cassandra.pool WARNING Error attempting to reconnect to 127.0.0.1:9042, scheduling retry in 2.02 seconds: [Errno 111] Tried connecting to [('127.0.0.1', 9042)]. Last error: Connection refused
04:00:10,46 cassandra.pool WARNING Error attempting to reconnect to 127.0.0.2:9042, scheduling retry in 4.16 seconds: [Errno 111] Tried connecting to [('127.0.0.2', 9042)]. Last error: Connection refused
04:00:10,508 cassandra.pool WARNING Error attempting to reconnect to 127.0.0.2:9042, scheduling retry in 124.16 seconds: [Errno 111] Tried connecting to [('127.0.0.2', 9042)]. Last error: Connection refused
04:00:11,970 cassandra.pool WARNING Error attempting to reconnect to 127.0.0.1:9042, scheduling retry in 4.24 seconds: [Errno 111] Tried connecting to [('127.0.0.1', 9042)]. Last error: Connection refused
04:00:11,970 cassandra.pool WARNING Error attempting to reconnect to 127.0.0.2:9042, scheduling retry in 4.16 seconds: [Errno 111] Tried connecting to [('127.0.0.2', 9042)]. Last error: Connection refused
04:00:14,258 cassandra.pool WARNING Error attempting to reconnect to 127.0.0.2:9042, scheduling retry in 8.72 seconds: [Errno 111] Tried connecting to [('127.0.0.2', 9042)]. Last error: Connection refused
04:00:15,260 cassandra.pool WARNING Error attempting to reconnect to 127.0.0.1:9042, scheduling retry in 17.12 seconds: [Errno 111] Tried connecting to [('127.0.0.1', 9042)]. Last error: Connection refused
04:00:16,22 cassandra.pool WARNING Error attempting to reconnect to 127.0.0.1:9042, scheduling retry in 14.24 seconds: [Errno 111] Tried connecting to [('127.0.0.1', 9042)]. Last error: Connection refused
04:00:16,181 cassandra.pool WARNING Error attempting to reconnect to 127.0.0.2:9042, scheduling retry in 8.8 seconds: [Errno 111] Tried connecting to [('127.0.0.2', 9042)]. Last error: Connection refused
04:00:16,281 cassandra.pool WARNING Error attempting to reconnect to 127.0.0.1:9042, scheduling retry in 7.92 seconds: [Errno 111] Tried connecting to [('127.0.0.1', 9042)]. Last error: Connection refused
04:00:21,853 cassandra.cluster WARNING Host 127.0.0.3:9042 has been marked down
04:00:21,854 cassandra.cluster WARNING Host 127.0.0.3:9042 has been marked down
04:00:22,940 cassandra.pool WARNING Error attempting to reconnect to 127.0.0.3:9042, scheduling retry in 2.24 seconds: [Errno 111] Tried connecting to [('127.0.0.3', 9042)]. Last error: Connection refused
04:00:22,981 cassandra.pool WARNING Error attempting to reconnect to 127.0.0.3:9042, scheduling retry in 2.16 seconds: [Errno 111] Tried connecting to [('127.0.0.3', 9042)]. Last error: Connection refused
04:00:22,981 cassandra.pool WARNING Error attempting to reconnect to 127.0.0.2:9042, scheduling retry in 15.84 seconds: [Errno 111] Tried connecting to [('127.0.0.2', 9042)]. Last error: Connection refused
04:00:24,302 cassandra.pool WARNING Error attempting to reconnect to 127.0.0.1:9042, scheduling retry in 13.6 seconds: [Errno 111] Tried connecting to [('127.0.0.1', 9042)]. Last error: Connection refused
04:00:25,4 cassandra.pool WARNING Error attempting to reconnect to 127.0.0.2:9042, scheduling retry in 15.84 seconds: [Errno 111] Tried connecting to [('127.0.0.2', 9042)]. Last error: Connection refused
04:00:25,187 cassandra.pool WARNING Error attempting to reconnect to 127.0.0.3:9042, scheduling retry in 3.88 seconds: [Errno 111] Tried connecting to [('127.0.0.3', 9042)]. Last error: Connection refused
04:00:25,246 cassandra.pool WARNING Error attempting to reconnect to 127.0.0.3:9042, scheduling retry in 4.6 seconds: [Errno 111] Tried connecting to [('127.0.0.3', 9042)]. Last error: Connection refused
04:00:29,97 cassandra.pool WARNING Error attempting to reconnect to 127.0.0.3:9042, scheduling retry in 8.8 seconds: [Errno 111] Tried connecting to [('127.0.0.3', 9042)]. Last error: Connection refused
04:00:29,858 cassandra.pool WARNING Error attempting to reconnect to 127.0.0.3:9042, scheduling retry in 8.0 seconds: [Errno 111] Tried connecting to [('127.0.0.3', 9042)]. Last error: Connection refused
04:00:30,359 cassandra.pool WARNING Error attempting to reconnect to 127.0.0.1:9042, scheduling retry in 30.08 seconds: [Errno 111] Tried connecting to [('127.0.0.1', 9042)]. Last error: Connection refused
04:00:32,406 cassandra.pool WARNING Error attempting to reconnect to 127.0.0.1:9042, scheduling retry in 33.28 seconds: [Errno 111] Tried connecting to [('127.0.0.1', 9042)]. Last error: Connection refused
04:00:37,879 cassandra.pool WARNING Error attempting to reconnect to 127.0.0.3:9042, scheduling retry in 15.52 seconds: [Errno 111] Tried connecting to [('127.0.0.3', 9042)]. Last error: Connection refused
04:00:37,921 cassandra.pool WARNING Error attempting to reconnect to 127.0.0.3:9042, scheduling retry in 17.6 seconds: [Errno 111] Tried connecting to [('127.0.0.3', 9042)]. Last error: Connection refused
04:00:37,938 cassandra.pool WARNING Error attempting to reconnect to 127.0.0.1:9042, scheduling retry in 31.04 seconds: [Errno 111] Tried connecting to [('127.0.0.1', 9042)]. Last error: Connection refused
04:00:38,705 cassandra.cluster WARNING Host 127.0.0.3:9042 has been marked down
04:00:38,707 cassandra.cluster WARNING [control connection] Error connecting to 127.0.0.3:9042:
Traceback (most recent call last):
  File "cassandra/cluster.py", line 3522, in cassandra.cluster.ControlConnection._reconnect_internal
  File "cassandra/cluster.py", line 3544, in cassandra.cluster.ControlConnection._try_connect
  File "cassandra/cluster.py", line 1620, in cassandra.cluster.Cluster.connection_factory
  File "cassandra/connection.py", line 831, in cassandra.connection.Connection.factory
  File "/users/masix/dtest/src/cassandra-driver/cassandra/io/libevreactor.py", line 267, in __init__
    self._connect_socket()
  File "cassandra/connection.py", line 898, in cassandra.connection.Connection._connect_socket
ConnectionRefusedError: [Errno 111] Tried connecting to [('127.0.0.3', 9042)]. Last error: Connection refused
04:00:38,827 cassandra.pool WARNING Error attempting to reconnect to 127.0.0.2:9042, scheduling retry in 36.8 seconds: [Errno 111] Tried connecting to [('127.0.0.2', 9042)]. Last error: Connection refused
04:00:39,746 cassandra.pool WARNING Error attempting to reconnect to 127.0.0.3:9042, scheduling retry in 1.82 seconds: [Errno 111] Tried connecting to [('127.0.0.3', 9042)]. Last error: Connection refused
04:00:40,849 cassandra.pool WARNING Error attempting to reconnect to 127.0.0.2:9042, scheduling retry in 29.76 seconds: [Errno 111] Tried connecting to [('127.0.0.2', 9042)]. Last error: Connection refused
04:00:41,651 cassandra.pool WARNING Error attempting to reconnect to 127.0.0.3:9042, scheduling retry in 4.28 seconds: [Errno 111] Tried connecting to [('127.0.0.3', 9042)]. Last error: Connection refused
04:00:45,962 cassandra.pool WARNING Error attempting to reconnect to 127.0.0.3:9042, scheduling retry in 8.4 seconds: [Errno 111] Tried connecting to [('127.0.0.3', 9042)]. Last error: Connection refused
04:00:53,422 cassandra.pool WARNING Error attempting to reconnect to 127.0.0.3:9042, scheduling retry in 34.88 seconds: [Errno 111] Tried connecting to [('127.0.0.3', 9042)]. Last error: Connection refused
04:00:54,383 cassandra.pool WARNING Error attempting to reconnect to 127.0.0.3:9042, scheduling retry in 15.04 seconds: [Errno 111] Tried connecting to [('127.0.0.3', 9042)]. Last error: Connection refused
04:00:55,571 cassandra.pool WARNING Error attempting to reconnect to 127.0.0.3:9042, scheduling retry in 29.12 seconds: [Errno 111] Tried connecting to [('127.0.0.3', 9042)]. Last error: Connection refused
04:01:05,453 cassandra.cluster WARNING [control connection] Error connecting to 127.0.0.1:9042:
Traceback (most recent call last):
  File "cassandra/cluster.py", line 3522, in cassandra.cluster.ControlConnection._reconnect_internal
  File "cassandra/cluster.py", line 3544, in cassandra.cluster.ControlConnection._try_connect
  File "cassandra/cluster.py", line 1620, in cassandra.cluster.Cluster.connection_factory
  File "cassandra/connection.py", line 831, in cassandra.connection.Connection.factory
  File "/users/masix/dtest/src/cassandra-driver/cassandra/io/libevreactor.py", line 267, in __init__
    self._connect_socket()
  File "cassandra/connection.py", line 898, in cassandra.connection.Connection._connect_socket
ConnectionRefusedError: [Errno 111] Tried connecting to [('127.0.0.1', 9042)]. Last error: Connection refused
04:01:05,698 cassandra.pool WARNING Error attempting to reconnect to 127.0.0.1:9042, scheduling retry in 71.04 seconds: [Errno 111] Tried connecting to [('127.0.0.1', 9042)]. Last error: Connection refused
04:01:09,26 cassandra.pool WARNING Error attempting to reconnect to 127.0.0.1:9042, scheduling retry in 67.2 seconds: [Errno 111] Tried connecting to [('127.0.0.1', 9042)]. Last error: Connection refused
04:01:10,630 cassandra.pool WARNING Error attempting to reconnect to 127.0.0.2:9042, scheduling retry in 62.08 seconds: [Errno 111] Tried connecting to [('127.0.0.2', 9042)]. Last error: Connection refused
04:01:15,634 cassandra.pool WARNING Error attempting to reconnect to 127.0.0.2:9042, scheduling retry in 68.48 seconds: [Errno 111] Tried connecting to [('127.0.0.2', 9042)]. Last error: Connection refused
04:01:19,502 cassandra.cluster WARNING [control connection] Error connecting to 127.0.0.1:9042:
Traceback (most recent call last):
  File "cassandra/cluster.py", line 3522, in cassandra.cluster.ControlConnection._reconnect_internal
  File "cassandra/cluster.py", line 3544, in cassandra.cluster.ControlConnection._try_connect
  File "cassandra/cluster.py", line 1620, in cassandra.cluster.Cluster.connection_factory
  File "cassandra/connection.py", line 831, in cassandra.connection.Connection.factory
  File "/users/masix/dtest/src/cassandra-driver/cassandra/io/libevreactor.py", line 267, in __init__
    self._connect_socket()
  File "cassandra/connection.py", line 898, in cassandra.connection.Connection._connect_socket
ConnectionRefusedError: [Errno 111] Tried connecting to [('127.0.0.1', 9042)]. Last error: Connection refused
04:01:20,691 cassandra.cluster WARNING [control connection] Error connecting to 127.0.0.1:9042:
Traceback (most recent call last):
  File "cassandra/cluster.py", line 3522, in cassandra.cluster.ControlConnection._reconnect_internal
  File "cassandra/cluster.py", line 3544, in cassandra.cluster.ControlConnection._try_connect
  File "cassandra/cluster.py", line 1620, in cassandra.cluster.Cluster.connection_factory
  File "cassandra/connection.py", line 831, in cassandra.connection.Connection.factory
  File "/users/masix/dtest/src/cassandra-driver/cassandra/io/libevreactor.py", line 267, in __init__
    self._connect_socket()
  File "cassandra/connection.py", line 898, in cassandra.connection.Connection._connect_socket
ConnectionRefusedError: [Errno 111] Tried connecting to [('127.0.0.1', 9042)]. Last error: Connection refused
04:01:22,596 cassandra.cluster WARNING [control connection] Error connecting to 127.0.0.1:9042:
Traceback (most recent call last):
  File "cassandra/cluster.py", line 3522, in cassandra.cluster.ControlConnection._reconnect_internal
  File "cassandra/cluster.py", line 3544, in cassandra.cluster.ControlConnection._try_connect
  File "cassandra/cluster.py", line 1620, in cassandra.cluster.Cluster.connection_factory
  File "cassandra/connection.py", line 831, in cassandra.connection.Connection.factory
  File "/users/masix/dtest/src/cassandra-driver/cassandra/io/libevreactor.py", line 267, in __init__
    self._connect_socket()
  File "cassandra/connection.py", line 898, in cassandra.connection.Connection._connect_socket
ConnectionRefusedError: [Errno 111] Tried connecting to [('127.0.0.1', 9042)]. Last error: Connection refused
04:01:24,758 cassandra.pool WARNING Error attempting to reconnect to 127.0.0.3:9042, scheduling retry in 61.44 seconds: [Errno 111] Tried connecting to [('127.0.0.3', 9042)]. Last error: Connection refused
04:01:26,306 cassandra.cluster WARNING [control connection] Error connecting to 127.0.0.1:9042:
Traceback (most recent call last):
  File "cassandra/cluster.py", line 3522, in cassandra.cluster.ControlConnection._reconnect_internal
  File "cassandra/cluster.py", line 3544, in cassandra.cluster.ControlConnection._try_connect
  File "cassandra/cluster.py", line 1620, in cassandra.cluster.Cluster.connection_factory
  File "cassandra/connection.py", line 831, in cassandra.connection.Connection.factory
  File "/users/masix/dtest/src/cassandra-driver/cassandra/io/libevreactor.py", line 267, in __init__
    self._connect_socket()
  File "cassandra/connection.py", line 898, in cassandra.connection.Connection._connect_socket
ConnectionRefusedError: [Errno 111] Tried connecting to [('127.0.0.1', 9042)]. Last error: Connection refused
04:01:28,311 cassandra.pool WARNING Error attempting to reconnect to 127.0.0.3:9042, scheduling retry in 66.56 seconds: [Errno 111] Tried connecting to [('127.0.0.3', 9042)]. Last error: Connection refused
04:01:31,544 ccmlib.node WARNING [msx] ccmlib:copy_config_files.py, conf_dir = /users/masix/cassandra/conf
04:01:31,645 ccmlib.node WARNING [msx] ccmlib:node.py, self.name = node1
04:01:31,705 ccmlib.node WARNING [msx] ccmlib:copy_config_files.py, conf_dir = /users/masix/cassandra/conf
04:01:31,801 ccmlib.node WARNING [msx] ccmlib:node.py, self.name = node2
04:01:31,812 cassandra.cluster WARNING Host 127.0.0.1:9042 has been marked down
04:01:31,812 cassandra.cluster WARNING Host 127.0.0.3:9042 has been marked down
04:01:31,814 cassandra.cluster WARNING Host 127.0.0.2:9042 has been marked down
04:01:31,817 cassandra.cluster WARNING [control connection] Error connecting to 127.0.0.2:9042:
Traceback (most recent call last):
  File "cassandra/cluster.py", line 3522, in cassandra.cluster.ControlConnection._reconnect_internal
  File "cassandra/cluster.py", line 3544, in cassandra.cluster.ControlConnection._try_connect
  File "cassandra/cluster.py", line 1620, in cassandra.cluster.Cluster.connection_factory
  File "cassandra/connection.py", line 831, in cassandra.connection.Connection.factory
  File "/users/masix/dtest/src/cassandra-driver/cassandra/io/libevreactor.py", line 267, in __init__
    self._connect_socket()
  File "cassandra/connection.py", line 898, in cassandra.connection.Connection._connect_socket
ConnectionRefusedError: [Errno 111] Tried connecting to [('127.0.0.2', 9042)]. Last error: Connection refused
04:01:31,868 ccmlib.node WARNING [msx] ccmlib:copy_config_files.py, conf_dir = /users/masix/cassandra/conf
04:01:31,964 ccmlib.node WARNING [msx] ccmlib:node.py, self.name = node3
04:01:32,826 cassandra.pool WARNING Error attempting to reconnect to 127.0.0.3:9042, scheduling retry in 1.86 seconds: [Errno 111] Tried connecting to [('127.0.0.3', 9042)]. Last error: Connection refused
04:01:32,827 cassandra.pool WARNING Error attempting to reconnect to 127.0.0.2:9042, scheduling retry in 2.1 seconds: [Errno 111] Tried connecting to [('127.0.0.2', 9042)]. Last error: Connection refused
04:01:33,27 cassandra.pool WARNING Error attempting to reconnect to 127.0.0.1:9042, scheduling retry in 1.74 seconds: [Errno 111] Tried connecting to [('127.0.0.1', 9042)]. Last error: Connection refused
04:01:33,340 cassandra.cluster WARNING [control connection] Error connecting to 127.0.0.1:9042:
Traceback (most recent call last):
  File "cassandra/cluster.py", line 3522, in cassandra.cluster.ControlConnection._reconnect_internal
  File "cassandra/cluster.py", line 3544, in cassandra.cluster.ControlConnection._try_connect
  File "cassandra/cluster.py", line 1620, in cassandra.cluster.Cluster.connection_factory
  File "cassandra/connection.py", line 831, in cassandra.connection.Connection.factory
  File "/users/masix/dtest/src/cassandra-driver/cassandra/io/libevreactor.py", line 267, in __init__
    self._connect_socket()
  File "cassandra/connection.py", line 898, in cassandra.connection.Connection._connect_socket
ConnectionRefusedError: [Errno 111] Tried connecting to [('127.0.0.1', 9042)]. Last error: Connection refused
04:01:34,732 cassandra.pool WARNING Error attempting to reconnect to 127.0.0.3:9042, scheduling retry in 3.76 seconds: [Errno 111] Tried connecting to [('127.0.0.3', 9042)]. Last error: Connection refused
04:01:34,832 cassandra.pool WARNING Error attempting to reconnect to 127.0.0.1:9042, scheduling retry in 4.56 seconds: [Errno 111] Tried connecting to [('127.0.0.1', 9042)]. Last error: Connection refused
04:01:34,932 cassandra.pool WARNING Error attempting to reconnect to 127.0.0.2:9042, scheduling retry in 3.68 seconds: [Errno 111] Tried connecting to [('127.0.0.2', 9042)]. Last error: Connection refused
04:01:38,541 cassandra.pool WARNING Error attempting to reconnect to 127.0.0.3:9042, scheduling retry in 7.04 seconds: [Errno 111] Tried connecting to [('127.0.0.3', 9042)]. Last error: Connection refused
04:01:38,641 cassandra.pool WARNING Error attempting to reconnect to 127.0.0.2:9042, scheduling retry in 7.52 seconds: [Errno 111] Tried connecting to [('127.0.0.2', 9042)]. Last error: Connection refused
04:01:38,706 cassandra.cluster WARNING Host 127.0.0.3:9042 has been marked down
04:01:38,707 cassandra.cluster WARNING [control connection] Error connecting to 127.0.0.3:9042:
Traceback (most recent call last):
  File "cassandra/cluster.py", line 3522, in cassandra.cluster.ControlConnection._reconnect_internal
  File "cassandra/cluster.py", line 3544, in cassandra.cluster.ControlConnection._try_connect
  File "cassandra/cluster.py", line 1620, in cassandra.cluster.Cluster.connection_factory
  File "cassandra/connection.py", line 831, in cassandra.connection.Connection.factory
  File "/users/masix/dtest/src/cassandra-driver/cassandra/io/libevreactor.py", line 267, in __init__
    self._connect_socket()
  File "cassandra/connection.py", line 898, in cassandra.connection.Connection._connect_socket
ConnectionRefusedError: [Errno 111] Tried connecting to [('127.0.0.3', 9042)]. Last error: Connection refused
04:01:39,443 cassandra.pool WARNING Error attempting to reconnect to 127.0.0.1:9042, scheduling retry in 8.24 seconds: [Errno 111] Tried connecting to [('127.0.0.1', 9042)]. Last error: Connection refused
04:01:39,724 cassandra.pool WARNING Error attempting to reconnect to 127.0.0.3:9042, scheduling retry in 1.84 seconds: [Errno 111] Tried connecting to [('127.0.0.3', 9042)]. Last error: Connection refused
04:01:41,629 cassandra.pool WARNING Error attempting to reconnect to 127.0.0.3:9042, scheduling retry in 4.56 seconds: [Errno 111] Tried connecting to [('127.0.0.3', 9042)]. Last error: Connection refused
04:01:45,659 cassandra.pool WARNING Error attempting to reconnect to 127.0.0.3:9042, scheduling retry in 14.4 seconds: [Errno 111] Tried connecting to [('127.0.0.3', 9042)]. Last error: Connection refused
04:01:46,241 cassandra.pool WARNING Error attempting to reconnect to 127.0.0.3:9042, scheduling retry in 8.8 seconds: [Errno 111] Tried connecting to [('127.0.0.3', 9042)]. Last error: Connection refused
04:01:46,261 cassandra.pool WARNING Error attempting to reconnect to 127.0.0.2:9042, scheduling retry in 16.48 seconds: [Errno 111] Tried connecting to [('127.0.0.2', 9042)]. Last error: Connection refused
04:02:14,700 cassandra.cluster WARNING Host 127.0.0.1:9042 has been marked down
04:02:15,806 cassandra.pool WARNING Error attempting to reconnect to 127.0.0.1:9042, scheduling retry in 1.8 seconds: [Errno 111] Tried connecting to [('127.0.0.1', 9042)]. Last error: Connection refused
04:02:16,239 cassandra.pool WARNING Error attempting to reconnect to 127.0.0.1:9042, scheduling retry in 119.04 seconds: [Errno 111] Tried connecting to [('127.0.0.1', 9042)]. Last error: Connection refused
04:02:16,740 cassandra.pool WARNING Error attempting to reconnect to 127.0.0.1:9042, scheduling retry in 119.04 seconds: [Errno 111] Tried connecting to [('127.0.0.1', 9042)]. Last error: Connection refused
04:02:17,613 cassandra.pool WARNING Error attempting to reconnect to 127.0.0.1:9042, scheduling retry in 3.76 seconds: [Errno 111] Tried connecting to [('127.0.0.1', 9042)]. Last error: Connection refused
04:02:19,504 cassandra.cluster WARNING [control connection] Error connecting to 127.0.0.1:9042:
Traceback (most recent call last):
  File "cassandra/cluster.py", line 3522, in cassandra.cluster.ControlConnection._reconnect_internal
  File "cassandra/cluster.py", line 3544, in cassandra.cluster.ControlConnection._try_connect
  File "cassandra/cluster.py", line 1620, in cassandra.cluster.Cluster.connection_factory
  File "cassandra/connection.py", line 831, in cassandra.connection.Connection.factory
  File "/users/masix/dtest/src/cassandra-driver/cassandra/io/libevreactor.py", line 267, in __init__
    self._connect_socket()
  File "cassandra/connection.py", line 898, in cassandra.connection.Connection._connect_socket
ConnectionRefusedError: [Errno 111] Tried connecting to [('127.0.0.1', 9042)]. Last error: Connection refused
04:02:21,425 cassandra.pool WARNING Error attempting to reconnect to 127.0.0.1:9042, scheduling retry in 6.88 seconds: [Errno 111] Tried connecting to [('127.0.0.1', 9042)]. Last error: Connection refused
04:02:21,814 cassandra.cluster WARNING Host 127.0.0.2:9042 has been marked down
04:02:21,815 cassandra.cluster WARNING Host 127.0.0.2:9042 has been marked down
04:02:21,818 cassandra.cluster WARNING [control connection] Error connecting to 127.0.0.1:9042:
Traceback (most recent call last):
  File "cassandra/cluster.py", line 3522, in cassandra.cluster.ControlConnection._reconnect_internal
  File "cassandra/cluster.py", line 3544, in cassandra.cluster.ControlConnection._try_connect
  File "cassandra/cluster.py", line 1620, in cassandra.cluster.Cluster.connection_factory
  File "cassandra/connection.py", line 831, in cassandra.connection.Connection.factory
  File "/users/masix/dtest/src/cassandra-driver/cassandra/io/libevreactor.py", line 267, in __init__
    self._connect_socket()
  File "cassandra/connection.py", line 898, in cassandra.connection.Connection._connect_socket
ConnectionRefusedError: [Errno 111] Tried connecting to [('127.0.0.1', 9042)]. Last error: Connection refused
04:02:22,931 cassandra.pool WARNING Error attempting to reconnect to 127.0.0.2:9042, scheduling retry in 2.04 seconds: [Errno 111] Tried connecting to [('127.0.0.2', 9042)]. Last error: Connection refused
04:02:22,971 cassandra.cluster WARNING [control connection] Error connecting to 127.0.0.1:9042:
Traceback (most recent call last):
  File "cassandra/cluster.py", line 3522, in cassandra.cluster.ControlConnection._reconnect_internal
  File "cassandra/cluster.py", line 3544, in cassandra.cluster.ControlConnection._try_connect
  File "cassandra/cluster.py", line 1620, in cassandra.cluster.Cluster.connection_factory
  File "cassandra/connection.py", line 831, in cassandra.connection.Connection.factory
  File "/users/masix/dtest/src/cassandra-driver/cassandra/io/libevreactor.py", line 267, in __init__
    self._connect_socket()
  File "cassandra/connection.py", line 898, in cassandra.connection.Connection._connect_socket
ConnectionRefusedError: [Errno 111] Tried connecting to [('127.0.0.1', 9042)]. Last error: Connection refused
04:02:22,971 cassandra.pool WARNING Error attempting to reconnect to 127.0.0.2:9042, scheduling retry in 2.24 seconds: [Errno 111] Tried connecting to [('127.0.0.2', 9042)]. Last error: Connection refused
04:02:24,164 cassandra.pool WARNING Error attempting to reconnect to 127.0.0.2:9042, scheduling retry in 144.64 seconds: [Errno 111] Tried connecting to [('127.0.0.2', 9042)]. Last error: Connection refused
04:02:25,36 cassandra.pool WARNING Error attempting to reconnect to 127.0.0.2:9042, scheduling retry in 3.8 seconds: [Errno 111] Tried connecting to [('127.0.0.2', 9042)]. Last error: Connection refused
04:02:25,177 cassandra.cluster WARNING [control connection] Error connecting to 127.0.0.1:9042:
Traceback (most recent call last):
  File "cassandra/cluster.py", line 3522, in cassandra.cluster.ControlConnection._reconnect_internal
  File "cassandra/cluster.py", line 3544, in cassandra.cluster.ControlConnection._try_connect
  File "cassandra/cluster.py", line 1620, in cassandra.cluster.Cluster.connection_factory
  File "cassandra/connection.py", line 831, in cassandra.connection.Connection.factory
  File "/users/masix/dtest/src/cassandra-driver/cassandra/io/libevreactor.py", line 267, in __init__
    self._connect_socket()
  File "cassandra/connection.py", line 898, in cassandra.connection.Connection._connect_socket
ConnectionRefusedError: [Errno 111] Tried connecting to [('127.0.0.1', 9042)]. Last error: Connection refused
04:02:25,277 cassandra.pool WARNING Error attempting to reconnect to 127.0.0.2:9042, scheduling retry in 3.6 seconds: [Errno 111] Tried connecting to [('127.0.0.2', 9042)]. Last error: Connection refused
04:02:28,345 cassandra.pool WARNING Error attempting to reconnect to 127.0.0.1:9042, scheduling retry in 13.6 seconds: [Errno 111] Tried connecting to [('127.0.0.1', 9042)]. Last error: Connection refused
04:02:28,846 cassandra.pool WARNING Error attempting to reconnect to 127.0.0.2:9042, scheduling retry in 6.88 seconds: [Errno 111] Tried connecting to [('127.0.0.2', 9042)]. Last error: Connection refused
04:02:28,886 cassandra.pool WARNING Error attempting to reconnect to 127.0.0.2:9042, scheduling retry in 8.8 seconds: [Errno 111] Tried connecting to [('127.0.0.2', 9042)]. Last error: Connection refused
04:02:28,887 cassandra.cluster WARNING [control connection] Error connecting to 127.0.0.1:9042:
Traceback (most recent call last):
  File "cassandra/cluster.py", line 3522, in cassandra.cluster.ControlConnection._reconnect_internal
  File "cassandra/cluster.py", line 3544, in cassandra.cluster.ControlConnection._try_connect
  File "cassandra/cluster.py", line 1620, in cassandra.cluster.Cluster.connection_factory
  File "cassandra/connection.py", line 831, in cassandra.connection.Connection.factory
  File "/users/masix/dtest/src/cassandra-driver/cassandra/io/libevreactor.py", line 267, in __init__
    self._connect_socket()
  File "cassandra/connection.py", line 898, in cassandra.connection.Connection._connect_socket
ConnectionRefusedError: [Errno 111] Tried connecting to [('127.0.0.1', 9042)]. Last error: Connection refused
04:02:31,814 cassandra.cluster WARNING Host 127.0.0.1:9042 has been marked down
04:02:31,815 cassandra.cluster WARNING Host 127.0.0.2:9042 has been marked down
04:02:32,866 cassandra.pool WARNING Error attempting to reconnect to 127.0.0.2:9042, scheduling retry in 2.08 seconds: [Errno 111] Tried connecting to [('127.0.0.2', 9042)]. Last error: Connection refused
04:02:32,867 cassandra.pool WARNING Error attempting to reconnect to 127.0.0.1:9042, scheduling retry in 1.74 seconds: [Errno 111] Tried connecting to [('127.0.0.1', 9042)]. Last error: Connection refused
04:02:34,673 cassandra.pool WARNING Error attempting to reconnect to 127.0.0.1:9042, scheduling retry in 4.2 seconds: [Errno 111] Tried connecting to [('127.0.0.1', 9042)]. Last error: Connection refused
04:02:34,974 cassandra.pool WARNING Error attempting to reconnect to 127.0.0.2:9042, scheduling retry in 4.6 seconds: [Errno 111] Tried connecting to [('127.0.0.2', 9042)]. Last error: Connection refused
04:02:35,772 cassandra.pool WARNING Error attempting to reconnect to 127.0.0.2:9042, scheduling retry in 15.52 seconds: [Errno 111] Tried connecting to [('127.0.0.2', 9042)]. Last error: Connection refused
04:02:36,944 cassandra.cluster WARNING Host 127.0.0.3:9042 has been marked down
04:02:36,945 cassandra.cluster WARNING Host 127.0.0.3:9042 has been marked down
04:02:37,778 cassandra.pool WARNING Error attempting to reconnect to 127.0.0.2:9042, scheduling retry in 16.48 seconds: [Errno 111] Tried connecting to [('127.0.0.2', 9042)]. Last error: Connection refused
04:02:37,978 cassandra.pool WARNING Error attempting to reconnect to 127.0.0.3:9042, scheduling retry in 2.08 seconds: [Errno 111] Tried connecting to [('127.0.0.3', 9042)]. Last error: Connection refused
04:02:38,102 cassandra.pool WARNING Error attempting to reconnect to 127.0.0.3:9042, scheduling retry in 1.72 seconds: [Errno 111] Tried connecting to [('127.0.0.3', 9042)]. Last error: Connection refused
04:02:38,708 cassandra.cluster WARNING Host 127.0.0.3:9042 has been marked down
04:02:38,708 cassandra.cluster WARNING Host 127.0.0.2:9042 has been marked down
04:02:38,710 cassandra.cluster WARNING [control connection] Error connecting to 127.0.0.2:9042:
Traceback (most recent call last):
  File "cassandra/cluster.py", line 3522, in cassandra.cluster.ControlConnection._reconnect_internal
  File "cassandra/cluster.py", line 3544, in cassandra.cluster.ControlConnection._try_connect
  File "cassandra/cluster.py", line 1620, in cassandra.cluster.Cluster.connection_factory
  File "cassandra/connection.py", line 831, in cassandra.connection.Connection.factory
  File "/users/masix/dtest/src/cassandra-driver/cassandra/io/libevreactor.py", line 267, in __init__
    self._connect_socket()
  File "cassandra/connection.py", line 898, in cassandra.connection.Connection._connect_socket
ConnectionRefusedError: [Errno 111] Tried connecting to [('127.0.0.2', 9042)]. Last error: Connection refused
04:02:38,885 cassandra.pool WARNING Error attempting to reconnect to 127.0.0.1:9042, scheduling retry in 7.2 seconds: [Errno 111] Tried connecting to [('127.0.0.1', 9042)]. Last error: Connection refused
04:02:39,587 cassandra.pool WARNING Error attempting to reconnect to 127.0.0.2:9042, scheduling retry in 6.8 seconds: [Errno 111] Tried connecting to [('127.0.0.2', 9042)]. Last error: Connection refused
04:02:39,805 cassandra.pool WARNING Error attempting to reconnect to 127.0.0.2:9042, scheduling retry in 2.28 seconds: [Errno 111] Tried connecting to [('127.0.0.2', 9042)]. Last error: Connection refused
04:02:39,806 cassandra.pool WARNING Error attempting to reconnect to 127.0.0.3:9042, scheduling retry in 1.82 seconds: [Errno 111] Tried connecting to [('127.0.0.3', 9042)]. Last error: Connection refused
04:02:39,907 cassandra.pool WARNING Error attempting to reconnect to 127.0.0.3:9042, scheduling retry in 3.48 seconds: [Errno 111] Tried connecting to [('127.0.0.3', 9042)]. Last error: Connection refused
04:02:40,84 cassandra.pool WARNING Error attempting to reconnect to 127.0.0.3:9042, scheduling retry in 3.8 seconds: [Errno 111] Tried connecting to [('127.0.0.3', 9042)]. Last error: Connection refused
04:02:41,710 cassandra.pool WARNING Error attempting to reconnect to 127.0.0.3:9042, scheduling retry in 3.92 seconds: [Errno 111] Tried connecting to [('127.0.0.3', 9042)]. Last error: Connection refused
04:02:41,990 cassandra.pool WARNING Error attempting to reconnect to 127.0.0.1:9042, scheduling retry in 33.28 seconds: [Errno 111] Tried connecting to [('127.0.0.1', 9042)]. Last error: Connection refused
04:02:42,111 cassandra.pool WARNING Error attempting to reconnect to 127.0.0.2:9042, scheduling retry in 4.2 seconds: [Errno 111] Tried connecting to [('127.0.0.2', 9042)]. Last error: Connection refused
04:02:43,416 cassandra.pool WARNING Error attempting to reconnect to 127.0.0.3:9042, scheduling retry in 7.84 seconds: [Errno 111] Tried connecting to [('127.0.0.3', 9042)]. Last error: Connection refused
04:02:43,895 cassandra.pool WARNING Error attempting to reconnect to 127.0.0.3:9042, scheduling retry in 6.88 seconds: [Errno 111] Tried connecting to [('127.0.0.3', 9042)]. Last error: Connection refused
04:02:45,724 cassandra.pool WARNING Error attempting to reconnect to 127.0.0.3:9042, scheduling retry in 6.96 seconds: [Errno 111] Tried connecting to [('127.0.0.3', 9042)]. Last error: Connection refused
04:02:46,105 cassandra.pool WARNING Error attempting to reconnect to 127.0.0.1:9042, scheduling retry in 18.24 seconds: [Errno 111] Tried connecting to [('127.0.0.1', 9042)]. Last error: Connection refused
04:02:46,327 cassandra.pool WARNING Error attempting to reconnect to 127.0.0.2:9042, scheduling retry in 7.36 seconds: [Errno 111] Tried connecting to [('127.0.0.2', 9042)]. Last error: Connection refused
04:02:46,406 cassandra.pool WARNING Error attempting to reconnect to 127.0.0.2:9042, scheduling retry in 18.4 seconds: [Errno 111] Tried connecting to [('127.0.0.2', 9042)]. Last error: Connection refused
04:02:49,504 cassandra.cluster WARNING [control connection] Error connecting to 127.0.0.1:9042:
Traceback (most recent call last):
  File "cassandra/cluster.py", line 3522, in cassandra.cluster.ControlConnection._reconnect_internal
  File "cassandra/cluster.py", line 3544, in cassandra.cluster.ControlConnection._try_connect
  File "cassandra/cluster.py", line 1620, in cassandra.cluster.Cluster.connection_factory
  File "cassandra/connection.py", line 831, in cassandra.connection.Connection.factory
  File "/users/masix/dtest/src/cassandra-driver/cassandra/io/libevreactor.py", line 267, in __init__
    self._connect_socket()
  File "cassandra/connection.py", line 898, in cassandra.connection.Connection._connect_socket
ConnectionRefusedError: [Errno 111] Tried connecting to [('127.0.0.1', 9042)]. Last error: Connection refused
04:02:49,505 cassandra.cluster WARNING [control connection] Error connecting to 127.0.0.3:9042:
Traceback (most recent call last):
  File "cassandra/cluster.py", line 3522, in cassandra.cluster.ControlConnection._reconnect_internal
  File "cassandra/cluster.py", line 3544, in cassandra.cluster.ControlConnection._try_connect
  File "cassandra/cluster.py", line 1620, in cassandra.cluster.Cluster.connection_factory
  File "cassandra/connection.py", line 831, in cassandra.connection.Connection.factory
  File "/users/masix/dtest/src/cassandra-driver/cassandra/io/libevreactor.py", line 267, in __init__
    self._connect_socket()
  File "cassandra/connection.py", line 898, in cassandra.connection.Connection._connect_socket
ConnectionRefusedError: [Errno 111] Tried connecting to [('127.0.0.3', 9042)]. Last error: Connection refused
04:02:50,618 cassandra.cluster WARNING [control connection] Error connecting to 127.0.0.3:9042:
Traceback (most recent call last):
  File "cassandra/cluster.py", line 3522, in cassandra.cluster.ControlConnection._reconnect_internal
  File "cassandra/cluster.py", line 3544, in cassandra.cluster.ControlConnection._try_connect
  File "cassandra/cluster.py", line 1620, in cassandra.cluster.Cluster.connection_factory
  File "cassandra/connection.py", line 831, in cassandra.connection.Connection.factory
  File "/users/masix/dtest/src/cassandra-driver/cassandra/io/libevreactor.py", line 267, in __init__
    self._connect_socket()
  File "cassandra/connection.py", line 898, in cassandra.connection.Connection._connect_socket
ConnectionRefusedError: [Errno 111] Tried connecting to [('127.0.0.3', 9042)]. Last error: Connection refused
04:02:50,619 cassandra.cluster WARNING [control connection] Error connecting to 127.0.0.1:9042:
Traceback (most recent call last):
  File "cassandra/cluster.py", line 3522, in cassandra.cluster.ControlConnection._reconnect_internal
  File "cassandra/cluster.py", line 3544, in cassandra.cluster.ControlConnection._try_connect
  File "cassandra/cluster.py", line 1620, in cassandra.cluster.Cluster.connection_factory
  File "cassandra/connection.py", line 831, in cassandra.connection.Connection.factory
  File "/users/masix/dtest/src/cassandra-driver/cassandra/io/libevreactor.py", line 267, in __init__
    self._connect_socket()
  File "cassandra/connection.py", line 898, in cassandra.connection.Connection._connect_socket
ConnectionRefusedError: [Errno 111] Tried connecting to [('127.0.0.1', 9042)]. Last error: Connection refused
04:02:50,819 cassandra.pool WARNING Error attempting to reconnect to 127.0.0.3:9042, scheduling retry in 16.16 seconds: [Errno 111] Tried connecting to [('127.0.0.3', 9042)]. Last error: Connection refused
04:02:51,320 cassandra.pool WARNING Error attempting to reconnect to 127.0.0.2:9042, scheduling retry in 32.64 seconds: [Errno 111] Tried connecting to [('127.0.0.2', 9042)]. Last error: Connection refused
04:02:51,342 cassandra.pool WARNING Error attempting to reconnect to 127.0.0.3:9042, scheduling retry in 17.44 seconds: [Errno 111] Tried connecting to [('127.0.0.3', 9042)]. Last error: Connection refused
04:02:52,423 cassandra.cluster WARNING [control connection] Error connecting to 127.0.0.1:9042:
Traceback (most recent call last):
  File "cassandra/cluster.py", line 3522, in cassandra.cluster.ControlConnection._reconnect_internal
  File "cassandra/cluster.py", line 3544, in cassandra.cluster.ControlConnection._try_connect
  File "cassandra/cluster.py", line 1620, in cassandra.cluster.Cluster.connection_factory
  File "cassandra/connection.py", line 831, in cassandra.connection.Connection.factory
  File "/users/masix/dtest/src/cassandra-driver/cassandra/io/libevreactor.py", line 267, in __init__
    self._connect_socket()
  File "cassandra/connection.py", line 898, in cassandra.connection.Connection._connect_socket
ConnectionRefusedError: [Errno 111] Tried connecting to [('127.0.0.1', 9042)]. Last error: Connection refused
04:02:52,425 cassandra.cluster WARNING [control connection] Error connecting to 127.0.0.3:9042:
Traceback (most recent call last):
  File "cassandra/cluster.py", line 3522, in cassandra.cluster.ControlConnection._reconnect_internal
  File "cassandra/cluster.py", line 3544, in cassandra.cluster.ControlConnection._try_connect
  File "cassandra/cluster.py", line 1620, in cassandra.cluster.Cluster.connection_factory
  File "cassandra/connection.py", line 831, in cassandra.connection.Connection.factory
  File "/users/masix/dtest/src/cassandra-driver/cassandra/io/libevreactor.py", line 267, in __init__
    self._connect_socket()
  File "cassandra/connection.py", line 898, in cassandra.connection.Connection._connect_socket
ConnectionRefusedError: [Errno 111] Tried connecting to [('127.0.0.3', 9042)]. Last error: Connection refused
04:02:52,746 cassandra.pool WARNING Error attempting to reconnect to 127.0.0.3:9042, scheduling retry in 17.76 seconds: [Errno 111] Tried connecting to [('127.0.0.3', 9042)]. Last error: Connection refused
04:02:53,749 cassandra.pool WARNING Error attempting to reconnect to 127.0.0.2:9042, scheduling retry in 17.28 seconds: [Errno 111] Tried connecting to [('127.0.0.2', 9042)]. Last error: Connection refused
04:02:54,329 cassandra.pool WARNING Error attempting to reconnect to 127.0.0.2:9042, scheduling retry in 33.92 seconds: [Errno 111] Tried connecting to [('127.0.0.2', 9042)]. Last error: Connection refused
04:02:56,434 cassandra.cluster WARNING [control connection] Error connecting to 127.0.0.3:9042:
Traceback (most recent call last):
  File "cassandra/cluster.py", line 3522, in cassandra.cluster.ControlConnection._reconnect_internal
  File "cassandra/cluster.py", line 3544, in cassandra.cluster.ControlConnection._try_connect
  File "cassandra/cluster.py", line 1620, in cassandra.cluster.Cluster.connection_factory
  File "cassandra/connection.py", line 831, in cassandra.connection.Connection.factory
  File "/users/masix/dtest/src/cassandra-driver/cassandra/io/libevreactor.py", line 267, in __init__
    self._connect_socket()
  File "cassandra/connection.py", line 898, in cassandra.connection.Connection._connect_socket
ConnectionRefusedError: [Errno 111] Tried connecting to [('127.0.0.3', 9042)]. Last error: Connection refused
04:03:01,815 cassandra.cluster WARNING Host 127.0.0.3:9042 has been marked down
04:03:01,816 cassandra.cluster WARNING [control connection] Error connecting to 127.0.0.3:9042:
Traceback (most recent call last):
  File "cassandra/cluster.py", line 3522, in cassandra.cluster.ControlConnection._reconnect_internal
  File "cassandra/cluster.py", line 3544, in cassandra.cluster.ControlConnection._try_connect
  File "cassandra/cluster.py", line 1620, in cassandra.cluster.Cluster.connection_factory
  File "cassandra/connection.py", line 831, in cassandra.connection.Connection.factory
  File "/users/masix/dtest/src/cassandra-driver/cassandra/io/libevreactor.py", line 267, in __init__
    self._connect_socket()
  File "cassandra/connection.py", line 898, in cassandra.connection.Connection._connect_socket
ConnectionRefusedError: [Errno 111] Tried connecting to [('127.0.0.3', 9042)]. Last error: Connection refused
04:03:02,962 cassandra.pool WARNING Error attempting to reconnect to 127.0.0.3:9042, scheduling retry in 1.9 seconds: [Errno 111] Tried connecting to [('127.0.0.3', 9042)]. Last error: Connection refused
04:03:15,296 cassandra.pool WARNING Error attempting to reconnect to 127.0.0.1:9042, scheduling retry in 58.24 seconds: [Errno 111] Tried connecting to [('127.0.0.1', 9042)]. Last error: Connection refused
04:03:19,504 cassandra.cluster WARNING [control connection] Error connecting to 127.0.0.1:9042:
Traceback (most recent call last):
  File "cassandra/cluster.py", line 3522, in cassandra.cluster.ControlConnection._reconnect_internal
  File "cassandra/cluster.py", line 3544, in cassandra.cluster.ControlConnection._try_connect
  File "cassandra/cluster.py", line 1620, in cassandra.cluster.Cluster.connection_factory
  File "cassandra/connection.py", line 831, in cassandra.connection.Connection.factory
  File "/users/masix/dtest/src/cassandra-driver/cassandra/io/libevreactor.py", line 267, in __init__
    self._connect_socket()
  File "cassandra/connection.py", line 898, in cassandra.connection.Connection._connect_socket
ConnectionRefusedError: [Errno 111] Tried connecting to [('127.0.0.1', 9042)]. Last error: Connection refused
04:03:23,377 cassandra.cluster WARNING Host 127.0.0.3:9042 has been marked down
04:03:23,378 cassandra.cluster WARNING Host 127.0.0.3:9042 has been marked down
04:03:23,380 cassandra.cluster WARNING [control connection] Error connecting to 127.0.0.1:9042:
Traceback (most recent call last):
  File "cassandra/cluster.py", line 3522, in cassandra.cluster.ControlConnection._reconnect_internal
  File "cassandra/cluster.py", line 3544, in cassandra.cluster.ControlConnection._try_connect
  File "cassandra/cluster.py", line 1620, in cassandra.cluster.Cluster.connection_factory
  File "cassandra/connection.py", line 831, in cassandra.connection.Connection.factory
  File "/users/masix/dtest/src/cassandra-driver/cassandra/io/libevreactor.py", line 267, in __init__
    self._connect_socket()
  File "cassandra/connection.py", line 898, in cassandra.connection.Connection._connect_socket
ConnectionRefusedError: [Errno 111] Tried connecting to [('127.0.0.1', 9042)]. Last error: Connection refused
04:03:24,18 cassandra.pool WARNING Error attempting to reconnect to 127.0.0.2:9042, scheduling retry in 60.8 seconds: [Errno 111] Tried connecting to [('127.0.0.2', 9042)]. Last error: Connection refused
04:03:24,420 cassandra.cluster WARNING [control connection] Error connecting to 127.0.0.1:9042:
Traceback (most recent call last):
  File "cassandra/cluster.py", line 3522, in cassandra.cluster.ControlConnection._reconnect_internal
  File "cassandra/cluster.py", line 3544, in cassandra.cluster.ControlConnection._try_connect
  File "cassandra/cluster.py", line 1620, in cassandra.cluster.Cluster.connection_factory
  File "cassandra/connection.py", line 831, in cassandra.connection.Connection.factory
  File "/users/masix/dtest/src/cassandra-driver/cassandra/io/libevreactor.py", line 267, in __init__
    self._connect_socket()
  File "cassandra/connection.py", line 898, in cassandra.connection.Connection._connect_socket
ConnectionRefusedError: [Errno 111] Tried connecting to [('127.0.0.1', 9042)]. Last error: Connection refused
04:03:24,520 cassandra.pool WARNING Error attempting to reconnect to 127.0.0.3:9042, scheduling retry in 2.04 seconds: [Errno 111] Tried connecting to [('127.0.0.3', 9042)]. Last error: Connection refused
04:03:24,520 cassandra.pool WARNING Error attempting to reconnect to 127.0.0.3:9042, scheduling retry in 2.06 seconds: [Errno 111] Tried connecting to [('127.0.0.3', 9042)]. Last error: Connection refused
04:03:26,224 cassandra.cluster WARNING [control connection] Error connecting to 127.0.0.1:9042:
Traceback (most recent call last):
  File "cassandra/cluster.py", line 3522, in cassandra.cluster.ControlConnection._reconnect_internal
  File "cassandra/cluster.py", line 3544, in cassandra.cluster.ControlConnection._try_connect
  File "cassandra/cluster.py", line 1620, in cassandra.cluster.Cluster.connection_factory
  File "cassandra/connection.py", line 831, in cassandra.connection.Connection.factory
  File "/users/masix/dtest/src/cassandra-driver/cassandra/io/libevreactor.py", line 267, in __init__
    self._connect_socket()
  File "cassandra/connection.py", line 898, in cassandra.connection.Connection._connect_socket
ConnectionRefusedError: [Errno 111] Tried connecting to [('127.0.0.1', 9042)]. Last error: Connection refused
04:03:26,625 cassandra.pool WARNING Error attempting to reconnect to 127.0.0.3:9042, scheduling retry in 4.32 seconds: [Errno 111] Tried connecting to [('127.0.0.3', 9042)]. Last error: Connection refused
04:03:26,626 cassandra.pool WARNING Error attempting to reconnect to 127.0.0.3:9042, scheduling retry in 3.88 seconds: [Errno 111] Tried connecting to [('127.0.0.3', 9042)]. Last error: Connection refused
04:03:28,330 cassandra.pool WARNING Error attempting to reconnect to 127.0.0.2:9042, scheduling retry in 71.04 seconds: [Errno 111] Tried connecting to [('127.0.0.2', 9042)]. Last error: Connection refused
04:03:30,493 ccmlib.node WARNING [msx] ccmlib:copy_config_files.py, conf_dir = /users/masix/cassandra/conf
04:03:30,587 ccmlib.node WARNING [msx] ccmlib:node.py, self.name = node1
04:03:30,587 cassandra.pool WARNING Error attempting to reconnect to 127.0.0.3:9042, scheduling retry in 7.36 seconds: [Errno 111] Tried connecting to [('127.0.0.3', 9042)]. Last error: Connection refused
04:03:30,640 ccmlib.node WARNING [msx] ccmlib:copy_config_files.py, conf_dir = /users/masix/cassandra/conf
04:03:30,723 ccmlib.node WARNING [msx] ccmlib:node.py, self.name = node2
04:03:30,748 cassandra.cluster WARNING [control connection] Error connecting to 127.0.0.1:9042:
Traceback (most recent call last):
  File "cassandra/cluster.py", line 3522, in cassandra.cluster.ControlConnection._reconnect_internal
  File "cassandra/cluster.py", line 3544, in cassandra.cluster.ControlConnection._try_connect
  File "cassandra/cluster.py", line 1620, in cassandra.cluster.Cluster.connection_factory
  File "cassandra/connection.py", line 831, in cassandra.connection.Connection.factory
  File "/users/masix/dtest/src/cassandra-driver/cassandra/io/libevreactor.py", line 267, in __init__
    self._connect_socket()
  File "cassandra/connection.py", line 898, in cassandra.connection.Connection._connect_socket
ConnectionRefusedError: [Errno 111] Tried connecting to [('127.0.0.1', 9042)]. Last error: Connection refused
04:03:30,778 ccmlib.node WARNING [msx] ccmlib:copy_config_files.py, conf_dir = /users/masix/cassandra/conf
04:03:30,861 ccmlib.node WARNING [msx] ccmlib:node.py, self.name = node3
04:03:30,955 cassandra.pool WARNING Error attempting to reconnect to 127.0.0.3:9042, scheduling retry in 7.2 seconds: [Errno 111] Tried connecting to [('127.0.0.3', 9042)]. Last error: Connection refused
04:03:31,817 cassandra.cluster WARNING Host 127.0.0.1:9042 has been marked down
04:03:31,817 cassandra.cluster WARNING Host 127.0.0.2:9042 has been marked down
04:03:31,819 cassandra.cluster WARNING Host 127.0.0.3:9042 has been marked down
04:03:31,821 cassandra.cluster WARNING [control connection] Error connecting to 127.0.0.3:9042:
Traceback (most recent call last):
  File "cassandra/cluster.py", line 3522, in cassandra.cluster.ControlConnection._reconnect_internal
  File "cassandra/cluster.py", line 3544, in cassandra.cluster.ControlConnection._try_connect
  File "cassandra/cluster.py", line 1620, in cassandra.cluster.Cluster.connection_factory
  File "cassandra/connection.py", line 831, in cassandra.connection.Connection.factory
  File "/users/masix/dtest/src/cassandra-driver/cassandra/io/libevreactor.py", line 267, in __init__
    self._connect_socket()
  File "cassandra/connection.py", line 898, in cassandra.connection.Connection._connect_socket
ConnectionRefusedError: [Errno 111] Tried connecting to [('127.0.0.3', 9042)]. Last error: Connection refused
04:03:32,827 cassandra.pool WARNING Error attempting to reconnect to 127.0.0.1:9042, scheduling retry in 1.78 seconds: [Errno 111] Tried connecting to [('127.0.0.1', 9042)]. Last error: Connection refused
04:03:32,828 cassandra.pool WARNING Error attempting to reconnect to 127.0.0.3:9042, scheduling retry in 2.08 seconds: [Errno 111] Tried connecting to [('127.0.0.3', 9042)]. Last error: Connection refused
04:03:33,26 cassandra.pool WARNING Error attempting to reconnect to 127.0.0.2:9042, scheduling retry in 2.14 seconds: [Errno 111] Tried connecting to [('127.0.0.2', 9042)]. Last error: Connection refused
04:03:34,631 cassandra.pool WARNING Error attempting to reconnect to 127.0.0.1:9042, scheduling retry in 3.52 seconds: [Errno 111] Tried connecting to [('127.0.0.1', 9042)]. Last error: Connection refused
04:03:34,931 cassandra.pool WARNING Error attempting to reconnect to 127.0.0.3:9042, scheduling retry in 3.56 seconds: [Errno 111] Tried connecting to [('127.0.0.3', 9042)]. Last error: Connection refused
04:03:35,232 cassandra.pool WARNING Error attempting to reconnect to 127.0.0.2:9042, scheduling retry in 4.6 seconds: [Errno 111] Tried connecting to [('127.0.0.2', 9042)]. Last error: Connection refused
04:03:35,777 cassandra.cluster WARNING [control connection] Error connecting to 127.0.0.3:9042:
Traceback (most recent call last):
  File "cassandra/cluster.py", line 3522, in cassandra.cluster.ControlConnection._reconnect_internal
  File "cassandra/cluster.py", line 3544, in cassandra.cluster.ControlConnection._try_connect
  File "cassandra/cluster.py", line 1620, in cassandra.cluster.Cluster.connection_factory
  File "cassandra/connection.py", line 831, in cassandra.connection.Connection.factory
  File "/users/masix/dtest/src/cassandra-driver/cassandra/io/libevreactor.py", line 267, in __init__
    self._connect_socket()
  File "cassandra/connection.py", line 898, in cassandra.connection.Connection._connect_socket
ConnectionRefusedError: [Errno 111] Tried connecting to [('127.0.0.3', 9042)]. Last error: Connection refused
04:03:36,784 cassandra.cluster WARNING [control connection] Error connecting to 127.0.0.3:9042:
Traceback (most recent call last):
  File "cassandra/cluster.py", line 3522, in cassandra.cluster.ControlConnection._reconnect_internal
  File "cassandra/cluster.py", line 3544, in cassandra.cluster.ControlConnection._try_connect
  File "cassandra/cluster.py", line 1620, in cassandra.cluster.Cluster.connection_factory
  File "cassandra/connection.py", line 831, in cassandra.connection.Connection.factory
  File "/users/masix/dtest/src/cassandra-driver/cassandra/io/libevreactor.py", line 267, in __init__
    self._connect_socket()
  File "cassandra/connection.py", line 898, in cassandra.connection.Connection._connect_socket
ConnectionRefusedError: [Errno 111] Tried connecting to [('127.0.0.3', 9042)]. Last error: Connection refused
04:03:37,977 cassandra.pool WARNING Error attempting to reconnect to 127.0.0.3:9042, scheduling retry in 14.24 seconds: [Errno 111] Tried connecting to [('127.0.0.3', 9042)]. Last error: Connection refused
04:03:38,177 cassandra.pool WARNING Error attempting to reconnect to 127.0.0.3:9042, scheduling retry in 15.52 seconds: [Errno 111] Tried connecting to [('127.0.0.3', 9042)]. Last error: Connection refused
04:03:38,239 cassandra.pool WARNING Error attempting to reconnect to 127.0.0.1:9042, scheduling retry in 7.12 seconds: [Errno 111] Tried connecting to [('127.0.0.1', 9042)]. Last error: Connection refused
04:03:38,540 cassandra.pool WARNING Error attempting to reconnect to 127.0.0.3:9042, scheduling retry in 8.4 seconds: [Errno 111] Tried connecting to [('127.0.0.3', 9042)]. Last error: Connection refused
04:03:38,709 cassandra.cluster WARNING Host 127.0.0.3:9042 has been marked down
04:03:38,710 cassandra.cluster WARNING Host 127.0.0.2:9042 has been marked down
04:03:38,715 cassandra.cluster WARNING [control connection] Error connecting to 127.0.0.2:9042:
Traceback (most recent call last):
  File "cassandra/cluster.py", line 3522, in cassandra.cluster.ControlConnection._reconnect_internal
  File "cassandra/cluster.py", line 3544, in cassandra.cluster.ControlConnection._try_connect
  File "cassandra/cluster.py", line 1620, in cassandra.cluster.Cluster.connection_factory
  File "cassandra/connection.py", line 831, in cassandra.connection.Connection.factory
  File "/users/masix/dtest/src/cassandra-driver/cassandra/io/libevreactor.py", line 267, in __init__
    self._connect_socket()
  File "cassandra/connection.py", line 898, in cassandra.connection.Connection._connect_socket
ConnectionRefusedError: [Errno 111] Tried connecting to [('127.0.0.2', 9042)]. Last error: Connection refused
04:03:38,866 cassandra.cluster WARNING Host 127.0.0.3:9042 has been marked down
04:03:38,866 cassandra.cluster WARNING Host 127.0.0.1:9042 has been marked down
04:03:38,867 cassandra.cluster WARNING Host 127.0.0.2:9042 has been marked down
04:03:38,870 cassandra.cluster WARNING [control connection] Error connecting to 127.0.0.2:9042:
Traceback (most recent call last):
  File "cassandra/cluster.py", line 3522, in cassandra.cluster.ControlConnection._reconnect_internal
  File "cassandra/cluster.py", line 3544, in cassandra.cluster.ControlConnection._try_connect
  File "cassandra/cluster.py", line 1620, in cassandra.cluster.Cluster.connection_factory
  File "cassandra/connection.py", line 831, in cassandra.connection.Connection.factory
  File "/users/masix/dtest/src/cassandra-driver/cassandra/io/libevreactor.py", line 267, in __init__
    self._connect_socket()
  File "cassandra/connection.py", line 898, in cassandra.connection.Connection._connect_socket
ConnectionRefusedError: [Errno 111] Tried connecting to [('127.0.0.2', 9042)]. Last error: Connection refused
04:03:38,990 cassandra.cluster WARNING [control connection] Error connecting to 127.0.0.3:9042:
Traceback (most recent call last):
  File "cassandra/cluster.py", line 3522, in cassandra.cluster.ControlConnection._reconnect_internal
  File "cassandra/cluster.py", line 3544, in cassandra.cluster.ControlConnection._try_connect
  File "cassandra/cluster.py", line 1620, in cassandra.cluster.Cluster.connection_factory
  File "cassandra/connection.py", line 831, in cassandra.connection.Connection.factory
  File "/users/masix/dtest/src/cassandra-driver/cassandra/io/libevreactor.py", line 267, in __init__
    self._connect_socket()
  File "cassandra/connection.py", line 898, in cassandra.connection.Connection._connect_socket
ConnectionRefusedError: [Errno 111] Tried connecting to [('127.0.0.3', 9042)]. Last error: Connection refused
04:03:39,80 cassandra.cluster WARNING [control connection] Error connecting to 127.0.0.1:9042:
Traceback (most recent call last):
  File "cassandra/cluster.py", line 3522, in cassandra.cluster.ControlConnection._reconnect_internal
  File "cassandra/cluster.py", line 3544, in cassandra.cluster.ControlConnection._try_connect
  File "cassandra/cluster.py", line 1620, in cassandra.cluster.Cluster.connection_factory
  File "cassandra/connection.py", line 831, in cassandra.connection.Connection.factory
  File "/users/masix/dtest/src/cassandra-driver/cassandra/io/libevreactor.py", line 267, in __init__
    self._connect_socket()
  File "cassandra/connection.py", line 898, in cassandra.connection.Connection._connect_socket
ConnectionRefusedError: [Errno 111] Tried connecting to [('127.0.0.1', 9042)]. Last error: Connection refused
04:03:39,793 cassandra.pool WARNING Error attempting to reconnect to 127.0.0.2:9042, scheduling retry in 2.12 seconds: [Errno 111] Tried connecting to [('127.0.0.2', 9042)]. Last error: Connection refused
04:03:39,794 cassandra.pool WARNING Error attempting to reconnect to 127.0.0.3:9042, scheduling retry in 2.0 seconds: [Errno 111] Tried connecting to [('127.0.0.3', 9042)]. Last error: Connection refused
04:03:39,843 cassandra.pool WARNING Error attempting to reconnect to 127.0.0.2:9042, scheduling retry in 8.8 seconds: [Errno 111] Tried connecting to [('127.0.0.2', 9042)]. Last error: Connection refused
04:03:39,872 cassandra.pool WARNING Error attempting to reconnect to 127.0.0.3:9042, scheduling retry in 1.82 seconds: [Errno 111] Tried connecting to [('127.0.0.3', 9042)]. Last error: Connection refused
04:03:39,872 cassandra.pool WARNING Error attempting to reconnect to 127.0.0.1:9042, scheduling retry in 1.88 seconds: [Errno 111] Tried connecting to [('127.0.0.1', 9042)]. Last error: Connection refused
04:03:39,873 cassandra.pool WARNING Error attempting to reconnect to 127.0.0.2:9042, scheduling retry in 2.16 seconds: [Errno 111] Tried connecting to [('127.0.0.2', 9042)]. Last error: Connection refused
04:03:41,778 cassandra.pool WARNING Error attempting to reconnect to 127.0.0.3:9042, scheduling retry in 4.52 seconds: [Errno 111] Tried connecting to [('127.0.0.3', 9042)]. Last error: Connection refused
04:03:41,798 cassandra.pool WARNING Error attempting to reconnect to 127.0.0.3:9042, scheduling retry in 4.24 seconds: [Errno 111] Tried connecting to [('127.0.0.3', 9042)]. Last error: Connection refused
04:03:41,999 cassandra.pool WARNING Error attempting to reconnect to 127.0.0.2:9042, scheduling retry in 3.76 seconds: [Errno 111] Tried connecting to [('127.0.0.2', 9042)]. Last error: Connection refused
04:03:42,78 cassandra.pool WARNING Error attempting to reconnect to 127.0.0.2:9042, scheduling retry in 3.64 seconds: [Errno 111] Tried connecting to [('127.0.0.2', 9042)]. Last error: Connection refused
04:03:43,507 cassandra.cluster WARNING [control connection] Error connecting to 127.0.0.3:9042:
Traceback (most recent call last):
  File "cassandra/cluster.py", line 3522, in cassandra.cluster.ControlConnection._reconnect_internal
  File "cassandra/cluster.py", line 3544, in cassandra.cluster.ControlConnection._try_connect
  File "cassandra/cluster.py", line 1620, in cassandra.cluster.Cluster.connection_factory
  File "cassandra/connection.py", line 831, in cassandra.connection.Connection.factory
  File "/users/masix/dtest/src/cassandra-driver/cassandra/io/libevreactor.py", line 267, in __init__
    self._connect_socket()
  File "cassandra/connection.py", line 898, in cassandra.connection.Connection._connect_socket
ConnectionRefusedError: [Errno 111] Tried connecting to [('127.0.0.3', 9042)]. Last error: Connection refused
04:03:45,788 cassandra.pool WARNING Error attempting to reconnect to 127.0.0.2:9042, scheduling retry in 8.96 seconds: [Errno 111] Tried connecting to [('127.0.0.2', 9042)]. Last error: Connection refused
04:03:45,813 cassandra.pool WARNING Error attempting to reconnect to 127.0.0.2:9042, scheduling retry in 7.12 seconds: [Errno 111] Tried connecting to [('127.0.0.2', 9042)]. Last error: Connection refused
04:03:46,113 cassandra.pool WARNING Error attempting to reconnect to 127.0.0.3:9042, scheduling retry in 8.32 seconds: [Errno 111] Tried connecting to [('127.0.0.3', 9042)]. Last error: Connection refused
04:03:46,390 cassandra.pool WARNING Error attempting to reconnect to 127.0.0.3:9042, scheduling retry in 8.0 seconds: [Errno 111] Tried connecting to [('127.0.0.3', 9042)]. Last error: Connection refused
04:03:46,962 cassandra.pool WARNING Error attempting to reconnect to 127.0.0.3:9042, scheduling retry in 14.4 seconds: [Errno 111] Tried connecting to [('127.0.0.3', 9042)]. Last error: Connection refused
04:03:48,667 cassandra.pool WARNING Error attempting to reconnect to 127.0.0.2:9042, scheduling retry in 16.48 seconds: [Errno 111] Tried connecting to [('127.0.0.2', 9042)]. Last error: Connection refused
04:04:14,701 cassandra.cluster WARNING Host 127.0.0.1:9042 has been marked down
04:04:14,717 cassandra.cluster WARNING Host 127.0.0.1:9042 has been marked down
04:04:14,720 cassandra.cluster WARNING Host 127.0.0.1:9042 has been marked down
04:04:15,321 cassandra.pool WARNING Error attempting to reconnect to 127.0.0.1:9042, scheduling retry in 294.4 seconds: [Errno 111] Tried connecting to [('127.0.0.1', 9042)]. Last error: Connection refused
04:04:15,808 cassandra.pool WARNING Error attempting to reconnect to 127.0.0.1:9042, scheduling retry in 1.9 seconds: [Errno 111] Tried connecting to [('127.0.0.1', 9042)]. Last error: Connection refused
04:04:15,825 cassandra.pool WARNING Error attempting to reconnect to 127.0.0.1:9042, scheduling retry in 240.64 seconds: [Errno 111] Tried connecting to [('127.0.0.1', 9042)]. Last error: Connection refused
04:04:15,832 cassandra.pool WARNING Error attempting to reconnect to 127.0.0.1:9042, scheduling retry in 2.04 seconds: [Errno 111] Tried connecting to [('127.0.0.1', 9042)]. Last error: Connection refused
04:04:15,931 cassandra.pool WARNING Error attempting to reconnect to 127.0.0.1:9042, scheduling retry in 1.74 seconds: [Errno 111] Tried connecting to [('127.0.0.1', 9042)]. Last error: Connection refused
04:04:17,715 cassandra.pool WARNING Error attempting to reconnect to 127.0.0.1:9042, scheduling retry in 4.04 seconds: [Errno 111] Tried connecting to [('127.0.0.1', 9042)]. Last error: Connection refused
04:04:17,737 cassandra.pool WARNING Error attempting to reconnect to 127.0.0.1:9042, scheduling retry in 3.44 seconds: [Errno 111] Tried connecting to [('127.0.0.1', 9042)]. Last error: Connection refused
04:04:17,940 cassandra.pool WARNING Error attempting to reconnect to 127.0.0.1:9042, scheduling retry in 4.24 seconds: [Errno 111] Tried connecting to [('127.0.0.1', 9042)]. Last error: Connection refused
04:04:21,250 cassandra.pool WARNING Error attempting to reconnect to 127.0.0.1:9042, scheduling retry in 7.2 seconds: [Errno 111] Tried connecting to [('127.0.0.1', 9042)]. Last error: Connection refused
04:04:21,816 cassandra.cluster WARNING Host 127.0.0.2:9042 has been marked down
04:04:21,818 cassandra.cluster WARNING Host 127.0.0.2:9042 has been marked down
04:04:21,828 cassandra.cluster WARNING Host 127.0.0.2:9042 has been marked down
04:04:21,829 cassandra.pool WARNING Error attempting to reconnect to 127.0.0.1:9042, scheduling retry in 7.36 seconds: [Errno 111] Tried connecting to [('127.0.0.1', 9042)]. Last error: Connection refused
04:04:22,255 cassandra.pool WARNING Error attempting to reconnect to 127.0.0.1:9042, scheduling retry in 7.76 seconds: [Errno 111] Tried connecting to [('127.0.0.1', 9042)]. Last error: Connection refused
04:04:22,857 cassandra.pool WARNING Error attempting to reconnect to 127.0.0.2:9042, scheduling retry in 1.92 seconds: [Errno 111] Tried connecting to [('127.0.0.2', 9042)]. Last error: Connection refused
04:04:22,930 cassandra.pool WARNING Error attempting to reconnect to 127.0.0.2:9042, scheduling retry in 1.78 seconds: [Errno 111] Tried connecting to [('127.0.0.2', 9042)]. Last error: Connection refused
04:04:22,947 cassandra.pool WARNING Error attempting to reconnect to 127.0.0.2:9042, scheduling retry in 2.16 seconds: [Errno 111] Tried connecting to [('127.0.0.2', 9042)]. Last error: Connection refused
04:04:24,735 cassandra.pool WARNING Error attempting to reconnect to 127.0.0.2:9042, scheduling retry in 4.56 seconds: [Errno 111] Tried connecting to [('127.0.0.2', 9042)]. Last error: Connection refused
04:04:24,851 cassandra.pool WARNING Error attempting to reconnect to 127.0.0.2:9042, scheduling retry in 111.36 seconds: [Errno 111] Tried connecting to [('127.0.0.2', 9042)]. Last error: Connection refused
04:04:24,862 cassandra.pool WARNING Error attempting to reconnect to 127.0.0.2:9042, scheduling retry in 4.4 seconds: [Errno 111] Tried connecting to [('127.0.0.2', 9042)]. Last error: Connection refused
04:04:25,151 cassandra.pool WARNING Error attempting to reconnect to 127.0.0.2:9042, scheduling retry in 4.08 seconds: [Errno 111] Tried connecting to [('127.0.0.2', 9042)]. Last error: Connection refused
04:04:28,472 cassandra.pool WARNING Error attempting to reconnect to 127.0.0.1:9042, scheduling retry in 16.96 seconds: [Errno 111] Tried connecting to [('127.0.0.1', 9042)]. Last error: Connection refused
04:04:29,247 cassandra.pool WARNING Error attempting to reconnect to 127.0.0.1:9042, scheduling retry in 14.88 seconds: [Errno 111] Tried connecting to [('127.0.0.1', 9042)]. Last error: Connection refused
04:04:29,261 cassandra.pool WARNING Error attempting to reconnect to 127.0.0.2:9042, scheduling retry in 8.96 seconds: [Errno 111] Tried connecting to [('127.0.0.2', 9042)]. Last error: Connection refused
04:04:29,274 cassandra.pool WARNING Error attempting to reconnect to 127.0.0.2:9042, scheduling retry in 7.04 seconds: [Errno 111] Tried connecting to [('127.0.0.2', 9042)]. Last error: Connection refused
04:04:29,347 cassandra.pool WARNING Error attempting to reconnect to 127.0.0.2:9042, scheduling retry in 8.64 seconds: [Errno 111] Tried connecting to [('127.0.0.2', 9042)]. Last error: Connection refused
04:04:30,76 cassandra.pool WARNING Error attempting to reconnect to 127.0.0.1:9042, scheduling retry in 18.08 seconds: [Errno 111] Tried connecting to [('127.0.0.1', 9042)]. Last error: Connection refused
04:04:36,393 cassandra.pool WARNING Error attempting to reconnect to 127.0.0.2:9042, scheduling retry in 16.96 seconds: [Errno 111] Tried connecting to [('127.0.0.2', 9042)]. Last error: Connection refused
04:04:36,943 cassandra.cluster WARNING Host 127.0.0.3:9042 has been marked down
04:04:36,945 cassandra.cluster WARNING Host 127.0.0.3:9042 has been marked down
04:04:36,945 cassandra.cluster WARNING Host 127.0.0.3:9042 has been marked down
04:04:36,946 cassandra.cluster WARNING Host 127.0.0.3:9042 has been marked down
04:04:36,948 cassandra.cluster WARNING [control connection] Error connecting to 127.0.0.1:9042:
Traceback (most recent call last):
  File "cassandra/cluster.py", line 3522, in cassandra.cluster.ControlConnection._reconnect_internal
  File "cassandra/cluster.py", line 3544, in cassandra.cluster.ControlConnection._try_connect
  File "cassandra/cluster.py", line 1620, in cassandra.cluster.Cluster.connection_factory
  File "cassandra/connection.py", line 831, in cassandra.connection.Connection.factory
  File "/users/masix/dtest/src/cassandra-driver/cassandra/io/libevreactor.py", line 267, in __init__
    self._connect_socket()
  File "cassandra/connection.py", line 898, in cassandra.connection.Connection._connect_socket
ConnectionRefusedError: [Errno 111] Tried connecting to [('127.0.0.1', 9042)]. Last error: Connection refused
04:04:36,951 cassandra.cluster WARNING [control connection] Error connecting to 127.0.0.1:9042:
Traceback (most recent call last):
  File "cassandra/cluster.py", line 3522, in cassandra.cluster.ControlConnection._reconnect_internal
  File "cassandra/cluster.py", line 3544, in cassandra.cluster.ControlConnection._try_connect
  File "cassandra/cluster.py", line 1620, in cassandra.cluster.Cluster.connection_factory
  File "cassandra/connection.py", line 831, in cassandra.connection.Connection.factory
  File "/users/masix/dtest/src/cassandra-driver/cassandra/io/libevreactor.py", line 267, in __init__
    self._connect_socket()
  File "cassandra/connection.py", line 898, in cassandra.connection.Connection._connect_socket
ConnectionRefusedError: [Errno 111] Tried connecting to [('127.0.0.1', 9042)]. Last error: Connection refused
04:04:37,984 cassandra.cluster WARNING [control connection] Error connecting to 127.0.0.1:9042:
Traceback (most recent call last):
  File "cassandra/cluster.py", line 3522, in cassandra.cluster.ControlConnection._reconnect_internal
  File "cassandra/cluster.py", line 3544, in cassandra.cluster.ControlConnection._try_connect
  File "cassandra/cluster.py", line 1620, in cassandra.cluster.Cluster.connection_factory
  File "cassandra/connection.py", line 831, in cassandra.connection.Connection.factory
  File "/users/masix/dtest/src/cassandra-driver/cassandra/io/libevreactor.py", line 267, in __init__
    self._connect_socket()
  File "cassandra/connection.py", line 898, in cassandra.connection.Connection._connect_socket
ConnectionRefusedError: [Errno 111] Tried connecting to [('127.0.0.1', 9042)]. Last error: Connection refused
04:04:37,987 cassandra.pool WARNING Error attempting to reconnect to 127.0.0.3:9042, scheduling retry in 2.26 seconds: [Errno 111] Tried connecting to [('127.0.0.3', 9042)]. Last error: Connection refused
04:04:38,71 cassandra.pool WARNING Error attempting to reconnect to 127.0.0.3:9042, scheduling retry in 2.1 seconds: [Errno 111] Tried connecting to [('127.0.0.3', 9042)]. Last error: Connection refused
04:04:38,71 cassandra.pool WARNING Error attempting to reconnect to 127.0.0.2:9042, scheduling retry in 13.6 seconds: [Errno 111] Tried connecting to [('127.0.0.2', 9042)]. Last error: Connection refused
04:04:38,84 cassandra.pool WARNING Error attempting to reconnect to 127.0.0.3:9042, scheduling retry in 2.24 seconds: [Errno 111] Tried connecting to [('127.0.0.3', 9042)]. Last error: Connection refused
04:04:38,87 cassandra.cluster WARNING [control connection] Error connecting to 127.0.0.1:9042:
Traceback (most recent call last):
  File "cassandra/cluster.py", line 3522, in cassandra.cluster.ControlConnection._reconnect_internal
  File "cassandra/cluster.py", line 3544, in cassandra.cluster.ControlConnection._try_connect
  File "cassandra/cluster.py", line 1620, in cassandra.cluster.Cluster.connection_factory
  File "cassandra/connection.py", line 831, in cassandra.connection.Connection.factory
  File "/users/masix/dtest/src/cassandra-driver/cassandra/io/libevreactor.py", line 267, in __init__
    self._connect_socket()
  File "cassandra/connection.py", line 898, in cassandra.connection.Connection._connect_socket
ConnectionRefusedError: [Errno 111] Tried connecting to [('127.0.0.1', 9042)]. Last error: Connection refused
04:04:38,187 cassandra.pool WARNING Error attempting to reconnect to 127.0.0.3:9042, scheduling retry in 2.14 seconds: [Errno 111] Tried connecting to [('127.0.0.3', 9042)]. Last error: Connection refused
04:04:38,285 cassandra.pool WARNING Error attempting to reconnect to 127.0.0.2:9042, scheduling retry in 15.2 seconds: [Errno 111] Tried connecting to [('127.0.0.2', 9042)]. Last error: Connection refused
04:04:38,710 cassandra.cluster WARNING Host 127.0.0.2:9042 has been marked down
04:04:38,711 cassandra.cluster WARNING Host 127.0.0.3:9042 has been marked down
04:04:38,713 cassandra.cluster WARNING [control connection] Error connecting to 127.0.0.3:9042:
Traceback (most recent call last):
  File "cassandra/cluster.py", line 3522, in cassandra.cluster.ControlConnection._reconnect_internal
  File "cassandra/cluster.py", line 3544, in cassandra.cluster.ControlConnection._try_connect
  File "cassandra/cluster.py", line 1620, in cassandra.cluster.Cluster.connection_factory
  File "cassandra/connection.py", line 831, in cassandra.connection.Connection.factory
  File "/users/masix/dtest/src/cassandra-driver/cassandra/io/libevreactor.py", line 267, in __init__
    self._connect_socket()
  File "cassandra/connection.py", line 898, in cassandra.connection.Connection._connect_socket
ConnectionRefusedError: [Errno 111] Tried connecting to [('127.0.0.3', 9042)]. Last error: Connection refused
04:04:38,867 cassandra.cluster WARNING Host 127.0.0.3:9042 has been marked down
04:04:38,868 cassandra.cluster WARNING Host 127.0.0.2:9042 has been marked down
04:04:38,869 cassandra.cluster WARNING [control connection] Error connecting to 127.0.0.2:9042:
Traceback (most recent call last):
  File "cassandra/cluster.py", line 3522, in cassandra.cluster.ControlConnection._reconnect_internal
  File "cassandra/cluster.py", line 3544, in cassandra.cluster.ControlConnection._try_connect
  File "cassandra/cluster.py", line 1620, in cassandra.cluster.Cluster.connection_factory
  File "cassandra/connection.py", line 831, in cassandra.connection.Connection.factory
  File "/users/masix/dtest/src/cassandra-driver/cassandra/io/libevreactor.py", line 267, in __init__
    self._connect_socket()
  File "cassandra/connection.py", line 898, in cassandra.connection.Connection._connect_socket
ConnectionRefusedError: [Errno 111] Tried connecting to [('127.0.0.2', 9042)]. Last error: Connection refused
04:04:39,791 cassandra.pool WARNING Error attempting to reconnect to 127.0.0.3:9042, scheduling retry in 1.7 seconds: [Errno 111] Tried connecting to [('127.0.0.3', 9042)]. Last error: Connection refused
04:04:39,791 cassandra.pool WARNING Error attempting to reconnect to 127.0.0.2:9042, scheduling retry in 2.2 seconds: [Errno 111] Tried connecting to [('127.0.0.2', 9042)]. Last error: Connection refused
04:04:39,903 cassandra.pool WARNING Error attempting to reconnect to 127.0.0.3:9042, scheduling retry in 1.84 seconds: [Errno 111] Tried connecting to [('127.0.0.3', 9042)]. Last error: Connection refused
04:04:40,3 cassandra.pool WARNING Error attempting to reconnect to 127.0.0.2:9042, scheduling retry in 1.86 seconds: [Errno 111] Tried connecting to [('127.0.0.2', 9042)]. Last error: Connection refused
04:04:40,176 cassandra.pool WARNING Error attempting to reconnect to 127.0.0.3:9042, scheduling retry in 3.72 seconds: [Errno 111] Tried connecting to [('127.0.0.3', 9042)]. Last error: Connection refused
04:04:40,190 cassandra.cluster WARNING [control connection] Error connecting to 127.0.0.1:9042:
Traceback (most recent call last):
  File "cassandra/cluster.py", line 3522, in cassandra.cluster.ControlConnection._reconnect_internal
  File "cassandra/cluster.py", line 3544, in cassandra.cluster.ControlConnection._try_connect
  File "cassandra/cluster.py", line 1620, in cassandra.cluster.Cluster.connection_factory
  File "cassandra/connection.py", line 831, in cassandra.connection.Connection.factory
  File "/users/masix/dtest/src/cassandra-driver/cassandra/io/libevreactor.py", line 267, in __init__
    self._connect_socket()
  File "cassandra/connection.py", line 898, in cassandra.connection.Connection._connect_socket
ConnectionRefusedError: [Errno 111] Tried connecting to [('127.0.0.1', 9042)]. Last error: Connection refused
04:04:40,294 cassandra.pool WARNING Error attempting to reconnect to 127.0.0.3:9042, scheduling retry in 4.04 seconds: [Errno 111] Tried connecting to [('127.0.0.3', 9042)]. Last error: Connection refused
04:04:40,390 cassandra.pool WARNING Error attempting to reconnect to 127.0.0.3:9042, scheduling retry in 3.88 seconds: [Errno 111] Tried connecting to [('127.0.0.3', 9042)]. Last error: Connection refused
04:04:40,394 cassandra.pool WARNING Error attempting to reconnect to 127.0.0.3:9042, scheduling retry in 3.4 seconds: [Errno 111] Tried connecting to [('127.0.0.3', 9042)]. Last error: Connection refused
04:04:40,394 cassandra.cluster WARNING [control connection] Error connecting to 127.0.0.1:9042:
Traceback (most recent call last):
  File "cassandra/cluster.py", line 3522, in cassandra.cluster.ControlConnection._reconnect_internal
  File "cassandra/cluster.py", line 3544, in cassandra.cluster.ControlConnection._try_connect
  File "cassandra/cluster.py", line 1620, in cassandra.cluster.Cluster.connection_factory
  File "cassandra/connection.py", line 831, in cassandra.connection.Connection.factory
  File "/users/masix/dtest/src/cassandra-driver/cassandra/io/libevreactor.py", line 267, in __init__
    self._connect_socket()
  File "cassandra/connection.py", line 898, in cassandra.connection.Connection._connect_socket
ConnectionRefusedError: [Errno 111] Tried connecting to [('127.0.0.1', 9042)]. Last error: Connection refused
04:04:41,495 cassandra.pool WARNING Error attempting to reconnect to 127.0.0.3:9042, scheduling retry in 3.92 seconds: [Errno 111] Tried connecting to [('127.0.0.3', 9042)]. Last error: Connection refused
04:04:41,808 cassandra.pool WARNING Error attempting to reconnect to 127.0.0.3:9042, scheduling retry in 4.24 seconds: [Errno 111] Tried connecting to [('127.0.0.3', 9042)]. Last error: Connection refused
04:04:41,908 cassandra.pool WARNING Error attempting to reconnect to 127.0.0.2:9042, scheduling retry in 3.56 seconds: [Errno 111] Tried connecting to [('127.0.0.2', 9042)]. Last error: Connection refused
04:04:41,997 cassandra.pool WARNING Error attempting to reconnect to 127.0.0.2:9042, scheduling retry in 4.0 seconds: [Errno 111] Tried connecting to [('127.0.0.2', 9042)]. Last error: Connection refused
04:04:43,803 cassandra.pool WARNING Error attempting to reconnect to 127.0.0.3:9042, scheduling retry in 7.2 seconds: [Errno 111] Tried connecting to [('127.0.0.3', 9042)]. Last error: Connection refused
04:04:43,987 cassandra.pool WARNING Error attempting to reconnect to 127.0.0.3:9042, scheduling retry in 8.24 seconds: [Errno 111] Tried connecting to [('127.0.0.3', 9042)]. Last error: Connection refused
04:04:44,108 cassandra.cluster WARNING [control connection] Error connecting to 127.0.0.1:9042:
Traceback (most recent call last):
  File "cassandra/cluster.py", line 3522, in cassandra.cluster.ControlConnection._reconnect_internal
  File "cassandra/cluster.py", line 3544, in cassandra.cluster.ControlConnection._try_connect
  File "cassandra/cluster.py", line 1620, in cassandra.cluster.Cluster.connection_factory
  File "cassandra/connection.py", line 831, in cassandra.connection.Connection.factory
  File "/users/masix/dtest/src/cassandra-driver/cassandra/io/libevreactor.py", line 267, in __init__
    self._connect_socket()
  File "cassandra/connection.py", line 898, in cassandra.connection.Connection._connect_socket
ConnectionRefusedError: [Errno 111] Tried connecting to [('127.0.0.1', 9042)]. Last error: Connection refused
04:04:44,187 cassandra.pool WARNING Error attempting to reconnect to 127.0.0.1:9042, scheduling retry in 34.56 seconds: [Errno 111] Tried connecting to [('127.0.0.1', 9042)]. Last error: Connection refused
04:04:44,304 cassandra.cluster WARNING [control connection] Error connecting to 127.0.0.1:9042:
Traceback (most recent call last):
  File "cassandra/cluster.py", line 3522, in cassandra.cluster.ControlConnection._reconnect_internal
  File "cassandra/cluster.py", line 3544, in cassandra.cluster.ControlConnection._try_connect
  File "cassandra/cluster.py", line 1620, in cassandra.cluster.Cluster.connection_factory
  File "cassandra/connection.py", line 831, in cassandra.connection.Connection.factory
  File "/users/masix/dtest/src/cassandra-driver/cassandra/io/libevreactor.py", line 267, in __init__
    self._connect_socket()
  File "cassandra/connection.py", line 898, in cassandra.connection.Connection._connect_socket
ConnectionRefusedError: [Errno 111] Tried connecting to [('127.0.0.1', 9042)]. Last error: Connection refused
04:04:44,309 cassandra.pool WARNING Error attempting to reconnect to 127.0.0.3:9042, scheduling retry in 7.6 seconds: [Errno 111] Tried connecting to [('127.0.0.3', 9042)]. Last error: Connection refused
04:04:44,405 cassandra.pool WARNING Error attempting to reconnect to 127.0.0.3:9042, scheduling retry in 7.92 seconds: [Errno 111] Tried connecting to [('127.0.0.3', 9042)]. Last error: Connection refused
04:04:45,506 cassandra.pool WARNING Error attempting to reconnect to 127.0.0.3:9042, scheduling retry in 7.04 seconds: [Errno 111] Tried connecting to [('127.0.0.3', 9042)]. Last error: Connection refused
04:04:45,518 cassandra.pool WARNING Error attempting to reconnect to 127.0.0.2:9042, scheduling retry in 7.84 seconds: [Errno 111] Tried connecting to [('127.0.0.2', 9042)]. Last error: Connection refused
04:04:45,519 cassandra.pool WARNING Error attempting to reconnect to 127.0.0.1:9042, scheduling retry in 31.36 seconds: [Errno 111] Tried connecting to [('127.0.0.1', 9042)]. Last error: Connection refused
04:04:46,7 cassandra.pool WARNING Error attempting to reconnect to 127.0.0.2:9042, scheduling retry in 7.52 seconds: [Errno 111] Tried connecting to [('127.0.0.2', 9042)]. Last error: Connection refused
04:04:46,119 cassandra.pool WARNING Error attempting to reconnect to 127.0.0.3:9042, scheduling retry in 8.48 seconds: [Errno 111] Tried connecting to [('127.0.0.3', 9042)]. Last error: Connection refused
04:04:48,224 cassandra.pool WARNING Error attempting to reconnect to 127.0.0.1:9042, scheduling retry in 35.84 seconds: [Errno 111] Tried connecting to [('127.0.0.1', 9042)]. Last error: Connection refused
04:04:48,817 cassandra.pool WARNING Error attempting to reconnect to 127.0.0.2:9042, scheduling retry in 253.44 seconds: [Errno 111] Tried connecting to [('127.0.0.2', 9042)]. Last error: Connection refused
04:04:49,506 cassandra.cluster WARNING [control connection] Error connecting to 127.0.0.1:9042:
Traceback (most recent call last):
  File "cassandra/cluster.py", line 3522, in cassandra.cluster.ControlConnection._reconnect_internal
  File "cassandra/cluster.py", line 3544, in cassandra.cluster.ControlConnection._try_connect
  File "cassandra/cluster.py", line 1620, in cassandra.cluster.Cluster.connection_factory
  File "cassandra/connection.py", line 831, in cassandra.connection.Connection.factory
  File "/users/masix/dtest/src/cassandra-driver/cassandra/io/libevreactor.py", line 267, in __init__
    self._connect_socket()
  File "cassandra/connection.py", line 898, in cassandra.connection.Connection._connect_socket
ConnectionRefusedError: [Errno 111] Tried connecting to [('127.0.0.1', 9042)]. Last error: Connection refused
04:04:50,726 cassandra.cluster WARNING [control connection] Error connecting to 127.0.0.1:9042:
Traceback (most recent call last):
  File "cassandra/cluster.py", line 3522, in cassandra.cluster.ControlConnection._reconnect_internal
  File "cassandra/cluster.py", line 3544, in cassandra.cluster.ControlConnection._try_connect
  File "cassandra/cluster.py", line 1620, in cassandra.cluster.Cluster.connection_factory
  File "cassandra/connection.py", line 831, in cassandra.connection.Connection.factory
  File "/users/masix/dtest/src/cassandra-driver/cassandra/io/libevreactor.py", line 267, in __init__
    self._connect_socket()
  File "cassandra/connection.py", line 898, in cassandra.connection.Connection._connect_socket
ConnectionRefusedError: [Errno 111] Tried connecting to [('127.0.0.1', 9042)]. Last error: Connection refused
04:04:50,762 cassandra.cluster WARNING [control connection] Error connecting to 127.0.0.1:9042:
Traceback (most recent call last):
  File "cassandra/cluster.py", line 3522, in cassandra.cluster.ControlConnection._reconnect_internal
  File "cassandra/cluster.py", line 3544, in cassandra.cluster.ControlConnection._try_connect
  File "cassandra/cluster.py", line 1620, in cassandra.cluster.Cluster.connection_factory
  File "cassandra/connection.py", line 831, in cassandra.connection.Connection.factory
  File "/users/masix/dtest/src/cassandra-driver/cassandra/io/libevreactor.py", line 267, in __init__
    self._connect_socket()
  File "cassandra/connection.py", line 898, in cassandra.connection.Connection._connect_socket
ConnectionRefusedError: [Errno 111] Tried connecting to [('127.0.0.1', 9042)]. Last error: Connection refused
04:04:51,21 cassandra.pool WARNING Error attempting to reconnect to 127.0.0.3:9042, scheduling retry in 14.56 seconds: [Errno 111] Tried connecting to [('127.0.0.3', 9042)]. Last error: Connection refused
04:04:51,707 cassandra.pool WARNING Error attempting to reconnect to 127.0.0.2:9042, scheduling retry in 36.48 seconds: [Errno 111] Tried connecting to [('127.0.0.2', 9042)]. Last error: Connection refused
04:04:51,924 cassandra.cluster WARNING [control connection] Error connecting to 127.0.0.1:9042:
Traceback (most recent call last):
  File "cassandra/cluster.py", line 3522, in cassandra.cluster.ControlConnection._reconnect_internal
  File "cassandra/cluster.py", line 3544, in cassandra.cluster.ControlConnection._try_connect
  File "cassandra/cluster.py", line 1620, in cassandra.cluster.Cluster.connection_factory
  File "cassandra/connection.py", line 831, in cassandra.connection.Connection.factory
  File "/users/masix/dtest/src/cassandra-driver/cassandra/io/libevreactor.py", line 267, in __init__
    self._connect_socket()
  File "cassandra/connection.py", line 898, in cassandra.connection.Connection._connect_socket
ConnectionRefusedError: [Errno 111] Tried connecting to [('127.0.0.1', 9042)]. Last error: Connection refused
04:04:51,929 cassandra.pool WARNING Error attempting to reconnect to 127.0.0.3:9042, scheduling retry in 17.28 seconds: [Errno 111] Tried connecting to [('127.0.0.3', 9042)]. Last error: Connection refused
04:04:52,309 cassandra.pool WARNING Error attempting to reconnect to 127.0.0.3:9042, scheduling retry in 17.92 seconds: [Errno 111] Tried connecting to [('127.0.0.3', 9042)]. Last error: Connection refused
04:04:52,426 cassandra.pool WARNING Error attempting to reconnect to 127.0.0.3:9042, scheduling retry in 13.6 seconds: [Errno 111] Tried connecting to [('127.0.0.3', 9042)]. Last error: Connection refused
04:04:52,530 cassandra.cluster WARNING [control connection] Error connecting to 127.0.0.1:9042:
Traceback (most recent call last):
  File "cassandra/cluster.py", line 3522, in cassandra.cluster.ControlConnection._reconnect_internal
  File "cassandra/cluster.py", line 3544, in cassandra.cluster.ControlConnection._try_connect
  File "cassandra/cluster.py", line 1620, in cassandra.cluster.Cluster.connection_factory
  File "cassandra/connection.py", line 831, in cassandra.connection.Connection.factory
  File "/users/masix/dtest/src/cassandra-driver/cassandra/io/libevreactor.py", line 267, in __init__
    self._connect_socket()
  File "cassandra/connection.py", line 898, in cassandra.connection.Connection._connect_socket
ConnectionRefusedError: [Errno 111] Tried connecting to [('127.0.0.1', 9042)]. Last error: Connection refused
04:04:52,624 cassandra.pool WARNING Error attempting to reconnect to 127.0.0.3:9042, scheduling retry in 14.24 seconds: [Errno 111] Tried connecting to [('127.0.0.3', 9042)]. Last error: Connection refused
04:04:53,442 cassandra.pool WARNING Error attempting to reconnect to 127.0.0.2:9042, scheduling retry in 36.16 seconds: [Errno 111] Tried connecting to [('127.0.0.2', 9042)]. Last error: Connection refused
04:04:53,443 cassandra.pool WARNING Error attempting to reconnect to 127.0.0.2:9042, scheduling retry in 14.56 seconds: [Errno 111] Tried connecting to [('127.0.0.2', 9042)]. Last error: Connection refused
04:04:53,534 cassandra.pool WARNING Error attempting to reconnect to 127.0.0.2:9042, scheduling retry in 30.4 seconds: [Errno 111] Tried connecting to [('127.0.0.2', 9042)]. Last error: Connection refused
04:04:53,630 cassandra.pool WARNING Error attempting to reconnect to 127.0.0.2:9042, scheduling retry in 14.72 seconds: [Errno 111] Tried connecting to [('127.0.0.2', 9042)]. Last error: Connection refused
04:04:53,830 cassandra.cluster WARNING [control connection] Error connecting to 127.0.0.1:9042:
Traceback (most recent call last):
  File "cassandra/cluster.py", line 3522, in cassandra.cluster.ControlConnection._reconnect_internal
  File "cassandra/cluster.py", line 3544, in cassandra.cluster.ControlConnection._try_connect
  File "cassandra/cluster.py", line 1620, in cassandra.cluster.Cluster.connection_factory
  File "cassandra/connection.py", line 831, in cassandra.connection.Connection.factory
  File "/users/masix/dtest/src/cassandra-driver/cassandra/io/libevreactor.py", line 267, in __init__
    self._connect_socket()
  File "cassandra/connection.py", line 898, in cassandra.connection.Connection._connect_socket
ConnectionRefusedError: [Errno 111] Tried connecting to [('127.0.0.1', 9042)]. Last error: Connection refused
04:04:54,647 cassandra.pool WARNING Error attempting to reconnect to 127.0.0.3:9042, scheduling retry in 14.08 seconds: [Errno 111] Tried connecting to [('127.0.0.3', 9042)]. Last error: Connection refused
04:04:57,143 cassandra.cluster WARNING [control connection] Error connecting to 127.0.0.1:9042:
Traceback (most recent call last):
  File "cassandra/cluster.py", line 3522, in cassandra.cluster.ControlConnection._reconnect_internal
  File "cassandra/cluster.py", line 3544, in cassandra.cluster.ControlConnection._try_connect
  File "cassandra/cluster.py", line 1620, in cassandra.cluster.Cluster.connection_factory
  File "cassandra/connection.py", line 831, in cassandra.connection.Connection.factory
  File "/users/masix/dtest/src/cassandra-driver/cassandra/io/libevreactor.py", line 267, in __init__
    self._connect_socket()
  File "cassandra/connection.py", line 898, in cassandra.connection.Connection._connect_socket
ConnectionRefusedError: [Errno 111] Tried connecting to [('127.0.0.1', 9042)]. Last error: Connection refused
04:04:57,642 cassandra.cluster WARNING [control connection] Error connecting to 127.0.0.1:9042:
Traceback (most recent call last):
  File "cassandra/cluster.py", line 3522, in cassandra.cluster.ControlConnection._reconnect_internal
  File "cassandra/cluster.py", line 3544, in cassandra.cluster.ControlConnection._try_connect
  File "cassandra/cluster.py", line 1620, in cassandra.cluster.Cluster.connection_factory
  File "cassandra/connection.py", line 831, in cassandra.connection.Connection.factory
  File "/users/masix/dtest/src/cassandra-driver/cassandra/io/libevreactor.py", line 267, in __init__
    self._connect_socket()
  File "cassandra/connection.py", line 898, in cassandra.connection.Connection._connect_socket
ConnectionRefusedError: [Errno 111] Tried connecting to [('127.0.0.1', 9042)]. Last error: Connection refused
04:05:01,819 cassandra.cluster WARNING Host 127.0.0.3:9042 has been marked down
04:05:01,821 cassandra.cluster WARNING [control connection] Error connecting to 127.0.0.3:9042:
Traceback (most recent call last):
  File "cassandra/cluster.py", line 3522, in cassandra.cluster.ControlConnection._reconnect_internal
  File "cassandra/cluster.py", line 3544, in cassandra.cluster.ControlConnection._try_connect
  File "cassandra/cluster.py", line 1620, in cassandra.cluster.Cluster.connection_factory
  File "cassandra/connection.py", line 831, in cassandra.connection.Connection.factory
  File "/users/masix/dtest/src/cassandra-driver/cassandra/io/libevreactor.py", line 267, in __init__
    self._connect_socket()
  File "cassandra/connection.py", line 898, in cassandra.connection.Connection._connect_socket
ConnectionRefusedError: [Errno 111] Tried connecting to [('127.0.0.3', 9042)]. Last error: Connection refused
04:05:02,968 cassandra.pool WARNING Error attempting to reconnect to 127.0.0.3:9042, scheduling retry in 1.7 seconds: [Errno 111] Tried connecting to [('127.0.0.3', 9042)]. Last error: Connection refused
04:05:04,673 cassandra.pool WARNING Error attempting to reconnect to 127.0.0.3:9042, scheduling retry in 4.48 seconds: [Errno 111] Tried connecting to [('127.0.0.3', 9042)]. Last error: Connection refused
04:05:05,662 cassandra.pool WARNING Error attempting to reconnect to 127.0.0.3:9042, scheduling retry in 35.52 seconds: [Errno 111] Tried connecting to [('127.0.0.3', 9042)]. Last error: Connection refused
04:05:06,62 cassandra.pool WARNING Error attempting to reconnect to 127.0.0.3:9042, scheduling retry in 32.0 seconds: [Errno 111] Tried connecting to [('127.0.0.3', 9042)]. Last error: Connection refused
04:05:06,966 cassandra.pool WARNING Error attempting to reconnect to 127.0.0.3:9042, scheduling retry in 30.4 seconds: [Errno 111] Tried connecting to [('127.0.0.3', 9042)]. Last error: Connection refused
04:05:08,81 cassandra.pool WARNING Error attempting to reconnect to 127.0.0.2:9042, scheduling retry in 35.52 seconds: [Errno 111] Tried connecting to [('127.0.0.2', 9042)]. Last error: Connection refused
04:05:08,369 cassandra.pool WARNING Error attempting to reconnect to 127.0.0.2:9042, scheduling retry in 27.52 seconds: [Errno 111] Tried connecting to [('127.0.0.2', 9042)]. Last error: Connection refused
04:05:08,783 cassandra.pool WARNING Error attempting to reconnect to 127.0.0.3:9042, scheduling retry in 35.84 seconds: [Errno 111] Tried connecting to [('127.0.0.3', 9042)]. Last error: Connection refused
04:05:09,185 cassandra.pool WARNING Error attempting to reconnect to 127.0.0.3:9042, scheduling retry in 7.12 seconds: [Errno 111] Tried connecting to [('127.0.0.3', 9042)]. Last error: Connection refused
04:05:09,272 cassandra.pool WARNING Error attempting to reconnect to 127.0.0.3:9042, scheduling retry in 32.32 seconds: [Errno 111] Tried connecting to [('127.0.0.3', 9042)]. Last error: Connection refused
04:05:10,263 cassandra.pool WARNING Error attempting to reconnect to 127.0.0.3:9042, scheduling retry in 34.88 seconds: [Errno 111] Tried connecting to [('127.0.0.3', 9042)]. Last error: Connection refused
PASSED                                                                   [100%]
===Flaky Test Report===

test_functional passed 1 out of the required 1 times. Success!

===End Flaky Test Report===

========================== 1 passed in 500.41 seconds ==========================
[msx] rc = 0
