cassandra replica_side_filtering_test.py::TestSecondaryIndexes::test_partition_deletion_on_wide_table true true
the_test is replica_side_filtering_test.py::TestSecondaryIndexes::test_partition_deletion_on_wide_table
============================= test session starts ==============================
platform linux -- Python 3.6.9, pytest-3.6.4, py-1.11.0, pluggy-0.7.1 -- /users/masix/dtest/bin/python
cachedir: .pytest_cache
rootdir: /users/masix/cassandra-dtest, inifile: pytest.ini
plugins: timeout-1.4.2, repeat-0.9.1, flaky-3.7.0
timeout: 900.0s
timeout method: signal
timeout func_only: False
collecting ... collected 1 item

replica_side_filtering_test.py::TestSecondaryIndexes::test_partition_deletion_on_wide_table 
-------------------------------- live log call ---------------------------------
10:24:30,706 ccmlib.node WARNING [msx] ccmlib:copy_config_files.py, conf_dir = /users/masix/cassandra/conf
10:24:30,793 ccmlib.node WARNING [msx] ccmlib:node.py, self.name = node1
10:24:30,862 ccmlib.node WARNING [msx] ccmlib:node.py, self.name = node1
10:24:30,953 ccmlib.node WARNING [msx] ccmlib:copy_config_files.py, conf_dir = /users/masix/cassandra/conf
10:24:31,39 ccmlib.node WARNING [msx] ccmlib:node.py, self.name = node2
10:24:31,105 ccmlib.node WARNING [msx] ccmlib:node.py, self.name = node2
10:24:59,132 cassandra.cluster WARNING Failed to create connection pool for new host 127.0.0.2:9042:
Traceback (most recent call last):
  File "cassandra/cluster.py", line 3175, in cassandra.cluster.Session.add_or_renew_pool.run_add_or_renew_pool
  File "cassandra/pool.py", line 402, in cassandra.pool.HostConnection.__init__
  File "cassandra/cluster.py", line 1620, in cassandra.cluster.Cluster.connection_factory
  File "cassandra/connection.py", line 831, in cassandra.connection.Connection.factory
  File "/users/masix/dtest/src/cassandra-driver/cassandra/io/libevreactor.py", line 267, in __init__
    self._connect_socket()
  File "cassandra/connection.py", line 898, in cassandra.connection.Connection._connect_socket
ConnectionRefusedError: [Errno 111] Tried connecting to [('127.0.0.2', 9042)]. Last error: Connection refused
10:24:59,135 cassandra.cluster WARNING Host 127.0.0.2:9042 has been marked down
10:25:00,243 cassandra.pool WARNING Error attempting to reconnect to 127.0.0.2:9042, scheduling retry in 2.22 seconds: [Errno 111] Tried connecting to [('127.0.0.2', 9042)]. Last error: Connection refused
10:25:02,552 cassandra.pool WARNING Error attempting to reconnect to 127.0.0.2:9042, scheduling retry in 4.28 seconds: [Errno 111] Tried connecting to [('127.0.0.2', 9042)]. Last error: Connection refused
10:25:06,866 cassandra.pool WARNING Error attempting to reconnect to 127.0.0.2:9042, scheduling retry in 8.08 seconds: [Errno 111] Tried connecting to [('127.0.0.2', 9042)]. Last error: Connection refused
10:25:16,481 cassandra.cluster WARNING Failed to create connection pool for new host 127.0.0.1:9042:
Traceback (most recent call last):
  File "cassandra/cluster.py", line 3175, in cassandra.cluster.Session.add_or_renew_pool.run_add_or_renew_pool
  File "cassandra/pool.py", line 402, in cassandra.pool.HostConnection.__init__
  File "cassandra/cluster.py", line 1620, in cassandra.cluster.Cluster.connection_factory
  File "cassandra/connection.py", line 831, in cassandra.connection.Connection.factory
  File "/users/masix/dtest/src/cassandra-driver/cassandra/io/libevreactor.py", line 267, in __init__
    self._connect_socket()
  File "cassandra/connection.py", line 898, in cassandra.connection.Connection._connect_socket
ConnectionRefusedError: [Errno 111] Tried connecting to [('127.0.0.1', 9042)]. Last error: Connection refused
10:25:16,483 cassandra.cluster WARNING Host 127.0.0.1:9042 has been marked down
10:25:17,491 cassandra.pool WARNING Error attempting to reconnect to 127.0.0.1:9042, scheduling retry in 2.06 seconds: [Errno 111] Tried connecting to [('127.0.0.1', 9042)]. Last error: Connection refused
10:25:17,806 cassandra.cluster WARNING Host 127.0.0.1:9042 has been marked down
10:25:17,807 cassandra.cluster WARNING [control connection] Error connecting to 127.0.0.1:9042:
Traceback (most recent call last):
  File "cassandra/cluster.py", line 3522, in cassandra.cluster.ControlConnection._reconnect_internal
  File "cassandra/cluster.py", line 3544, in cassandra.cluster.ControlConnection._try_connect
  File "cassandra/cluster.py", line 1620, in cassandra.cluster.Cluster.connection_factory
  File "cassandra/connection.py", line 831, in cassandra.connection.Connection.factory
  File "/users/masix/dtest/src/cassandra-driver/cassandra/io/libevreactor.py", line 267, in __init__
    self._connect_socket()
  File "cassandra/connection.py", line 898, in cassandra.connection.Connection._connect_socket
ConnectionRefusedError: [Errno 111] Tried connecting to [('127.0.0.1', 9042)]. Last error: Connection refused
10:25:18,813 cassandra.pool WARNING Error attempting to reconnect to 127.0.0.1:9042, scheduling retry in 2.06 seconds: [Errno 111] Tried connecting to [('127.0.0.1', 9042)]. Last error: Connection refused
10:25:19,599 cassandra.pool WARNING Error attempting to reconnect to 127.0.0.1:9042, scheduling retry in 4.16 seconds: [Errno 111] Tried connecting to [('127.0.0.1', 9042)]. Last error: Connection refused
10:25:20,919 cassandra.pool WARNING Error attempting to reconnect to 127.0.0.1:9042, scheduling retry in 4.4 seconds: [Errno 111] Tried connecting to [('127.0.0.1', 9042)]. Last error: Connection refused
10:25:23,813 cassandra.pool WARNING Error attempting to reconnect to 127.0.0.1:9042, scheduling retry in 8.08 seconds: [Errno 111] Tried connecting to [('127.0.0.1', 9042)]. Last error: Connection refused
10:25:25,330 cassandra.pool WARNING Error attempting to reconnect to 127.0.0.1:9042, scheduling retry in 7.68 seconds: [Errno 111] Tried connecting to [('127.0.0.1', 9042)]. Last error: Connection refused
10:25:29,130 cassandra.cluster WARNING Host 127.0.0.1:9042 has been marked down
PASSED                                                                   [100%]
===Flaky Test Report===

test_partition_deletion_on_wide_table passed 1 out of the required 1 times. Success!

===End Flaky Test Report===

========================== 1 passed in 60.59 seconds ===========================
[msx] rc = 0
