cassandra replica_side_filtering_test.py::TestAllowFiltering::test_complementary_deletion_with_limit_on_partition_key_column_with_empty_partitions true true
the_test is replica_side_filtering_test.py::TestAllowFiltering::test_complementary_deletion_with_limit_on_partition_key_column_with_empty_partitions
============================= test session starts ==============================
platform linux -- Python 3.6.9, pytest-3.6.4, py-1.11.0, pluggy-0.7.1 -- /users/masix/dtest/bin/python
cachedir: .pytest_cache
rootdir: /users/masix/cassandra-dtest, inifile: pytest.ini
plugins: timeout-1.4.2, repeat-0.9.1, flaky-3.7.0
timeout: 900.0s
timeout method: signal
timeout func_only: False
collecting ... collected 1 item

replica_side_filtering_test.py::TestAllowFiltering::test_complementary_deletion_with_limit_on_partition_key_column_with_empty_partitions 
-------------------------------- live log call ---------------------------------
10:40:26,396 ccmlib.node WARNING [msx] ccmlib:copy_config_files.py, conf_dir = /users/masix/cassandra/conf
10:40:26,482 ccmlib.node WARNING [msx] ccmlib:node.py, self.name = node1
10:40:26,552 ccmlib.node WARNING [msx] ccmlib:node.py, self.name = node1
10:40:26,643 ccmlib.node WARNING [msx] ccmlib:copy_config_files.py, conf_dir = /users/masix/cassandra/conf
10:40:26,728 ccmlib.node WARNING [msx] ccmlib:node.py, self.name = node2
10:40:26,795 ccmlib.node WARNING [msx] ccmlib:node.py, self.name = node2
10:40:53,860 cassandra.cluster WARNING Failed to create connection pool for new host 127.0.0.2:9042:
Traceback (most recent call last):
  File "cassandra/cluster.py", line 3175, in cassandra.cluster.Session.add_or_renew_pool.run_add_or_renew_pool
  File "cassandra/pool.py", line 402, in cassandra.pool.HostConnection.__init__
  File "cassandra/cluster.py", line 1620, in cassandra.cluster.Cluster.connection_factory
  File "cassandra/connection.py", line 831, in cassandra.connection.Connection.factory
  File "/users/masix/dtest/src/cassandra-driver/cassandra/io/libevreactor.py", line 267, in __init__
    self._connect_socket()
  File "cassandra/connection.py", line 898, in cassandra.connection.Connection._connect_socket
ConnectionRefusedError: [Errno 111] Tried connecting to [('127.0.0.2', 9042)]. Last error: Connection refused
10:40:53,864 cassandra.cluster WARNING Host 127.0.0.2:9042 has been marked down
10:40:54,973 cassandra.pool WARNING Error attempting to reconnect to 127.0.0.2:9042, scheduling retry in 1.9 seconds: [Errno 111] Tried connecting to [('127.0.0.2', 9042)]. Last error: Connection refused
10:40:56,880 cassandra.pool WARNING Error attempting to reconnect to 127.0.0.2:9042, scheduling retry in 3.44 seconds: [Errno 111] Tried connecting to [('127.0.0.2', 9042)]. Last error: Connection refused
10:41:00,391 cassandra.pool WARNING Error attempting to reconnect to 127.0.0.2:9042, scheduling retry in 7.92 seconds: [Errno 111] Tried connecting to [('127.0.0.2', 9042)]. Last error: Connection refused
10:41:08,315 cassandra.pool WARNING Error attempting to reconnect to 127.0.0.2:9042, scheduling retry in 14.88 seconds: [Errno 111] Tried connecting to [('127.0.0.2', 9042)]. Last error: Connection refused
10:41:10,307 cassandra.cluster WARNING Failed to create connection pool for new host 127.0.0.1:9042:
Traceback (most recent call last):
  File "cassandra/cluster.py", line 3175, in cassandra.cluster.Session.add_or_renew_pool.run_add_or_renew_pool
  File "cassandra/pool.py", line 402, in cassandra.pool.HostConnection.__init__
  File "cassandra/cluster.py", line 1620, in cassandra.cluster.Cluster.connection_factory
  File "cassandra/connection.py", line 831, in cassandra.connection.Connection.factory
  File "/users/masix/dtest/src/cassandra-driver/cassandra/io/libevreactor.py", line 267, in __init__
    self._connect_socket()
  File "cassandra/connection.py", line 898, in cassandra.connection.Connection._connect_socket
ConnectionRefusedError: [Errno 111] Tried connecting to [('127.0.0.1', 9042)]. Last error: Connection refused
10:41:10,309 cassandra.cluster WARNING Host 127.0.0.1:9042 has been marked down
10:41:11,317 cassandra.pool WARNING Error attempting to reconnect to 127.0.0.1:9042, scheduling retry in 1.76 seconds: [Errno 111] Tried connecting to [('127.0.0.1', 9042)]. Last error: Connection refused
10:41:13,124 cassandra.pool WARNING Error attempting to reconnect to 127.0.0.1:9042, scheduling retry in 3.88 seconds: [Errno 111] Tried connecting to [('127.0.0.1', 9042)]. Last error: Connection refused
10:41:13,503 cassandra.cluster WARNING Host 127.0.0.1:9042 has been marked down
10:41:13,505 cassandra.cluster WARNING [control connection] Error connecting to 127.0.0.1:9042:
Traceback (most recent call last):
  File "cassandra/cluster.py", line 3522, in cassandra.cluster.ControlConnection._reconnect_internal
  File "cassandra/cluster.py", line 3544, in cassandra.cluster.ControlConnection._try_connect
  File "cassandra/cluster.py", line 1620, in cassandra.cluster.Cluster.connection_factory
  File "cassandra/connection.py", line 831, in cassandra.connection.Connection.factory
  File "/users/masix/dtest/src/cassandra-driver/cassandra/io/libevreactor.py", line 267, in __init__
    self._connect_socket()
  File "cassandra/connection.py", line 898, in cassandra.connection.Connection._connect_socket
ConnectionRefusedError: [Errno 111] Tried connecting to [('127.0.0.1', 9042)]. Last error: Connection refused
10:41:14,610 cassandra.pool WARNING Error attempting to reconnect to 127.0.0.1:9042, scheduling retry in 1.92 seconds: [Errno 111] Tried connecting to [('127.0.0.1', 9042)]. Last error: Connection refused
10:41:16,616 cassandra.pool WARNING Error attempting to reconnect to 127.0.0.1:9042, scheduling retry in 3.6 seconds: [Errno 111] Tried connecting to [('127.0.0.1', 9042)]. Last error: Connection refused
10:41:17,35 cassandra.pool WARNING Error attempting to reconnect to 127.0.0.1:9042, scheduling retry in 7.84 seconds: [Errno 111] Tried connecting to [('127.0.0.1', 9042)]. Last error: Connection refused
10:41:20,225 cassandra.pool WARNING Error attempting to reconnect to 127.0.0.1:9042, scheduling retry in 8.16 seconds: [Errno 111] Tried connecting to [('127.0.0.1', 9042)]. Last error: Connection refused
PASSED                                                                   [100%]
===Flaky Test Report===

test_complementary_deletion_with_limit_on_partition_key_column_with_empty_partitions passed 1 out of the required 1 times. Success!

===End Flaky Test Report===

========================== 1 passed in 57.60 seconds ===========================
[msx] rc = 0
