cassandra snapshot_test.py::TestArchiveCommitlog::test_archive_commitlog_point_in_time true true
the_test is snapshot_test.py::TestArchiveCommitlog::test_archive_commitlog_point_in_time
============================= test session starts ==============================
platform linux -- Python 3.6.9, pytest-3.6.4, py-1.11.0, pluggy-0.7.1 -- /users/masix/dtest/bin/python
cachedir: .pytest_cache
rootdir: /users/masix/cassandra-dtest, inifile: pytest.ini
plugins: timeout-1.4.2, repeat-0.9.1, flaky-3.7.0
timeout: 900.0s
timeout method: signal
timeout func_only: False
collecting ... collected 1 item

snapshot_test.py::TestArchiveCommitlog::test_archive_commitlog_point_in_time 
-------------------------------- live log call ---------------------------------
12:41:20,293 ccmlib.node WARNING [msx] ccmlib:copy_config_files.py, conf_dir = /users/masix/cassandra/conf
12:41:20,379 ccmlib.node WARNING [msx] ccmlib:node.py, self.name = node1
12:41:20,448 ccmlib.node WARNING [msx] ccmlib:node.py, self.name = node1
12:42:49,566 cassandra.protocol WARNING Server warning: Aggregation query used without partition key
12:42:56,502 cassandra.cluster WARNING Host 127.0.0.1:9042 has been marked down
12:42:56,506 cassandra.cluster WARNING [control connection] Error connecting to 127.0.0.1:9042:
Traceback (most recent call last):
  File "cassandra/cluster.py", line 3522, in cassandra.cluster.ControlConnection._reconnect_internal
  File "cassandra/cluster.py", line 3544, in cassandra.cluster.ControlConnection._try_connect
  File "cassandra/cluster.py", line 1620, in cassandra.cluster.Cluster.connection_factory
  File "cassandra/connection.py", line 831, in cassandra.connection.Connection.factory
  File "/users/masix/dtest/src/cassandra-driver/cassandra/io/libevreactor.py", line 267, in __init__
    self._connect_socket()
  File "cassandra/connection.py", line 898, in cassandra.connection.Connection._connect_socket
ConnectionRefusedError: [Errno 111] Tried connecting to [('127.0.0.1', 9042)]. Last error: Connection refused
12:42:57,613 cassandra.pool WARNING Error attempting to reconnect to 127.0.0.1:9042, scheduling retry in 2.06 seconds: [Errno 111] Tried connecting to [('127.0.0.1', 9042)]. Last error: Connection refused
12:42:59,719 cassandra.pool WARNING Error attempting to reconnect to 127.0.0.1:9042, scheduling retry in 3.56 seconds: [Errno 111] Tried connecting to [('127.0.0.1', 9042)]. Last error: Connection refused
12:43:01,77 ccmlib.node WARNING [msx] ccmlib:copy_config_files.py, conf_dir = /users/masix/cassandra/conf
12:43:01,163 ccmlib.node WARNING [msx] ccmlib:node.py, self.name = node1
12:43:01,230 ccmlib.node WARNING [msx] ccmlib:node.py, self.name = node1
12:43:09,513 cassandra.protocol WARNING Server warning: Aggregation query used without partition key
12:43:29,763 cassandra.protocol WARNING Server warning: Aggregation query used without partition key
PASSED                                                                   [100%]
===Flaky Test Report===

test_archive_commitlog_point_in_time passed 1 out of the required 1 times. Success!

===End Flaky Test Report===

========================== 1 passed in 130.33 seconds ==========================
[msx] rc = 0
