cassandra auth_test.py::TestAuthRoles::test_creator_of_db_resource_granted_all_permissions false true
log_dst_dir = /users/masix/vm_images/ZebraConf/app_meta/logs
the_test is auth_test.py::TestAuthRoles::test_creator_of_db_resource_granted_all_permissions
rm: cannot remove '/tmp/my_log.txt': No such file or directory
============================= test session starts ==============================
platform linux -- Python 3.6.9, pytest-3.6.4, py-1.11.0, pluggy-0.7.1 -- /users/masix/dtest/bin/python3
cachedir: .pytest_cache
rootdir: /users/masix/cassandra-dtest, inifile: pytest.ini
plugins: timeout-1.4.2, repeat-0.9.1, flaky-3.7.0
timeout: 1200.0s
timeout method: signal
timeout func_only: False
collecting ... collected 1 item

auth_test.py::TestAuthRoles::test_creator_of_db_resource_granted_all_permissions 
-------------------------------- live log setup --------------------------------
22:13:39,885 cassandra.cluster WARNING [control connection] Error connecting to 127.0.0.1:9042:
Traceback (most recent call last):
  File "cassandra/cluster.py", line 3522, in cassandra.cluster.ControlConnection._reconnect_internal
  File "cassandra/cluster.py", line 3544, in cassandra.cluster.ControlConnection._try_connect
  File "cassandra/cluster.py", line 1620, in cassandra.cluster.Cluster.connection_factory
  File "cassandra/connection.py", line 837, in cassandra.connection.Connection.factory
  File "cassandra/connection.py", line 600, in cassandra.connection.defunct_on_error.wrapper
  File "cassandra/connection.py", line 1421, in cassandra.connection.Connection._handle_auth_response
cassandra.AuthenticationFailed: Failed to authenticate to 127.0.0.1:9042: Error from server: code=0100 [Bad credentials] message="Provided username cassandra and/or password are incorrect"
22:13:39,889 cassandra.cluster ERROR Control connection failed to connect, shutting down Cluster:
Traceback (most recent call last):
  File "cassandra/cluster.py", line 1690, in cassandra.cluster.Cluster.connect
  File "cassandra/cluster.py", line 3488, in cassandra.cluster.ControlConnection.connect
  File "cassandra/cluster.py", line 3533, in cassandra.cluster.ControlConnection._reconnect_internal
cassandra.cluster.NoHostAvailable: ('Unable to connect to any servers', {'127.0.0.1:9042': AuthenticationFailed('Failed to authenticate to 127.0.0.1:9042: Error from server: code=0100 [Bad credentials] message="Provided username cassandra and/or password are incorrect"',)})
22:13:40,154 cassandra.cluster WARNING [control connection] Error connecting to 127.0.0.1:9042:
Traceback (most recent call last):
  File "cassandra/cluster.py", line 3522, in cassandra.cluster.ControlConnection._reconnect_internal
  File "cassandra/cluster.py", line 3544, in cassandra.cluster.ControlConnection._try_connect
  File "cassandra/cluster.py", line 1620, in cassandra.cluster.Cluster.connection_factory
  File "cassandra/connection.py", line 837, in cassandra.connection.Connection.factory
  File "cassandra/connection.py", line 600, in cassandra.connection.defunct_on_error.wrapper
  File "cassandra/connection.py", line 1421, in cassandra.connection.Connection._handle_auth_response
cassandra.AuthenticationFailed: Failed to authenticate to 127.0.0.1:9042: Error from server: code=0100 [Bad credentials] message="Provided username cassandra and/or password are incorrect"
22:13:40,155 cassandra.cluster ERROR Control connection failed to connect, shutting down Cluster:
Traceback (most recent call last):
  File "cassandra/cluster.py", line 1690, in cassandra.cluster.Cluster.connect
  File "cassandra/cluster.py", line 3488, in cassandra.cluster.ControlConnection.connect
  File "cassandra/cluster.py", line 3533, in cassandra.cluster.ControlConnection._reconnect_internal
cassandra.cluster.NoHostAvailable: ('Unable to connect to any servers', {'127.0.0.1:9042': AuthenticationFailed('Failed to authenticate to 127.0.0.1:9042: Error from server: code=0100 [Bad credentials] message="Provided username cassandra and/or password are incorrect"',)})
22:13:40,419 cassandra.cluster WARNING [control connection] Error connecting to 127.0.0.1:9042:
Traceback (most recent call last):
  File "cassandra/cluster.py", line 3522, in cassandra.cluster.ControlConnection._reconnect_internal
  File "cassandra/cluster.py", line 3544, in cassandra.cluster.ControlConnection._try_connect
  File "cassandra/cluster.py", line 1620, in cassandra.cluster.Cluster.connection_factory
  File "cassandra/connection.py", line 837, in cassandra.connection.Connection.factory
  File "cassandra/connection.py", line 600, in cassandra.connection.defunct_on_error.wrapper
  File "cassandra/connection.py", line 1421, in cassandra.connection.Connection._handle_auth_response
cassandra.AuthenticationFailed: Failed to authenticate to 127.0.0.1:9042: Error from server: code=0100 [Bad credentials] message="Provided username cassandra and/or password are incorrect"
22:13:40,420 cassandra.cluster ERROR Control connection failed to connect, shutting down Cluster:
Traceback (most recent call last):
  File "cassandra/cluster.py", line 1690, in cassandra.cluster.Cluster.connect
  File "cassandra/cluster.py", line 3488, in cassandra.cluster.ControlConnection.connect
  File "cassandra/cluster.py", line 3533, in cassandra.cluster.ControlConnection._reconnect_internal
cassandra.cluster.NoHostAvailable: ('Unable to connect to any servers', {'127.0.0.1:9042': AuthenticationFailed('Failed to authenticate to 127.0.0.1:9042: Error from server: code=0100 [Bad credentials] message="Provided username cassandra and/or password are incorrect"',)})
22:13:40,682 cassandra.cluster WARNING [control connection] Error connecting to 127.0.0.1:9042:
Traceback (most recent call last):
  File "cassandra/cluster.py", line 3522, in cassandra.cluster.ControlConnection._reconnect_internal
  File "cassandra/cluster.py", line 3544, in cassandra.cluster.ControlConnection._try_connect
  File "cassandra/cluster.py", line 1620, in cassandra.cluster.Cluster.connection_factory
  File "cassandra/connection.py", line 837, in cassandra.connection.Connection.factory
  File "cassandra/connection.py", line 600, in cassandra.connection.defunct_on_error.wrapper
  File "cassandra/connection.py", line 1421, in cassandra.connection.Connection._handle_auth_response
cassandra.AuthenticationFailed: Failed to authenticate to 127.0.0.1:9042: Error from server: code=0100 [Bad credentials] message="Provided username cassandra and/or password are incorrect"
22:13:40,684 cassandra.cluster ERROR Control connection failed to connect, shutting down Cluster:
Traceback (most recent call last):
  File "cassandra/cluster.py", line 1690, in cassandra.cluster.Cluster.connect
  File "cassandra/cluster.py", line 3488, in cassandra.cluster.ControlConnection.connect
  File "cassandra/cluster.py", line 3533, in cassandra.cluster.ControlConnection._reconnect_internal
cassandra.cluster.NoHostAvailable: ('Unable to connect to any servers', {'127.0.0.1:9042': AuthenticationFailed('Failed to authenticate to 127.0.0.1:9042: Error from server: code=0100 [Bad credentials] message="Provided username cassandra and/or password are incorrect"',)})
22:13:40,946 cassandra.cluster WARNING [control connection] Error connecting to 127.0.0.1:9042:
Traceback (most recent call last):
  File "cassandra/cluster.py", line 3522, in cassandra.cluster.ControlConnection._reconnect_internal
  File "cassandra/cluster.py", line 3544, in cassandra.cluster.ControlConnection._try_connect
  File "cassandra/cluster.py", line 1620, in cassandra.cluster.Cluster.connection_factory
  File "cassandra/connection.py", line 837, in cassandra.connection.Connection.factory
  File "cassandra/connection.py", line 600, in cassandra.connection.defunct_on_error.wrapper
  File "cassandra/connection.py", line 1421, in cassandra.connection.Connection._handle_auth_response
cassandra.AuthenticationFailed: Failed to authenticate to 127.0.0.1:9042: Error from server: code=0100 [Bad credentials] message="Provided username cassandra and/or password are incorrect"
22:13:40,947 cassandra.cluster ERROR Control connection failed to connect, shutting down Cluster:
Traceback (most recent call last):
  File "cassandra/cluster.py", line 1690, in cassandra.cluster.Cluster.connect
  File "cassandra/cluster.py", line 3488, in cassandra.cluster.ControlConnection.connect
  File "cassandra/cluster.py", line 3533, in cassandra.cluster.ControlConnection._reconnect_internal
cassandra.cluster.NoHostAvailable: ('Unable to connect to any servers', {'127.0.0.1:9042': AuthenticationFailed('Failed to authenticate to 127.0.0.1:9042: Error from server: code=0100 [Bad credentials] message="Provided username cassandra and/or password are incorrect"',)})
22:13:41,229 cassandra.cluster WARNING [control connection] Error connecting to 127.0.0.1:9042:
Traceback (most recent call last):
  File "cassandra/cluster.py", line 3522, in cassandra.cluster.ControlConnection._reconnect_internal
  File "cassandra/cluster.py", line 3544, in cassandra.cluster.ControlConnection._try_connect
  File "cassandra/cluster.py", line 1620, in cassandra.cluster.Cluster.connection_factory
  File "cassandra/connection.py", line 837, in cassandra.connection.Connection.factory
  File "cassandra/connection.py", line 600, in cassandra.connection.defunct_on_error.wrapper
  File "cassandra/connection.py", line 1421, in cassandra.connection.Connection._handle_auth_response
cassandra.AuthenticationFailed: Failed to authenticate to 127.0.0.1:9042: Error from server: code=0100 [Bad credentials] message="Provided username cassandra and/or password are incorrect"
22:13:41,230 cassandra.cluster ERROR Control connection failed to connect, shutting down Cluster:
Traceback (most recent call last):
  File "cassandra/cluster.py", line 1690, in cassandra.cluster.Cluster.connect
  File "cassandra/cluster.py", line 3488, in cassandra.cluster.ControlConnection.connect
  File "cassandra/cluster.py", line 3533, in cassandra.cluster.ControlConnection._reconnect_internal
cassandra.cluster.NoHostAvailable: ('Unable to connect to any servers', {'127.0.0.1:9042': AuthenticationFailed('Failed to authenticate to 127.0.0.1:9042: Error from server: code=0100 [Bad credentials] message="Provided username cassandra and/or password are incorrect"',)})
22:13:41,502 cassandra.cluster WARNING [control connection] Error connecting to 127.0.0.1:9042:
Traceback (most recent call last):
  File "cassandra/cluster.py", line 3522, in cassandra.cluster.ControlConnection._reconnect_internal
  File "cassandra/cluster.py", line 3544, in cassandra.cluster.ControlConnection._try_connect
  File "cassandra/cluster.py", line 1620, in cassandra.cluster.Cluster.connection_factory
  File "cassandra/connection.py", line 837, in cassandra.connection.Connection.factory
  File "cassandra/connection.py", line 600, in cassandra.connection.defunct_on_error.wrapper
  File "cassandra/connection.py", line 1421, in cassandra.connection.Connection._handle_auth_response
cassandra.AuthenticationFailed: Failed to authenticate to 127.0.0.1:9042: Error from server: code=0100 [Bad credentials] message="Provided username cassandra and/or password are incorrect"
22:13:41,504 cassandra.cluster ERROR Control connection failed to connect, shutting down Cluster:
Traceback (most recent call last):
  File "cassandra/cluster.py", line 1690, in cassandra.cluster.Cluster.connect
  File "cassandra/cluster.py", line 3488, in cassandra.cluster.ControlConnection.connect
  File "cassandra/cluster.py", line 3533, in cassandra.cluster.ControlConnection._reconnect_internal
cassandra.cluster.NoHostAvailable: ('Unable to connect to any servers', {'127.0.0.1:9042': AuthenticationFailed('Failed to authenticate to 127.0.0.1:9042: Error from server: code=0100 [Bad credentials] message="Provided username cassandra and/or password are incorrect"',)})
22:13:41,766 cassandra.cluster WARNING [control connection] Error connecting to 127.0.0.1:9042:
Traceback (most recent call last):
  File "cassandra/cluster.py", line 3522, in cassandra.cluster.ControlConnection._reconnect_internal
  File "cassandra/cluster.py", line 3544, in cassandra.cluster.ControlConnection._try_connect
  File "cassandra/cluster.py", line 1620, in cassandra.cluster.Cluster.connection_factory
  File "cassandra/connection.py", line 837, in cassandra.connection.Connection.factory
  File "cassandra/connection.py", line 600, in cassandra.connection.defunct_on_error.wrapper
  File "cassandra/connection.py", line 1421, in cassandra.connection.Connection._handle_auth_response
cassandra.AuthenticationFailed: Failed to authenticate to 127.0.0.1:9042: Error from server: code=0100 [Bad credentials] message="Provided username cassandra and/or password are incorrect"
22:13:41,768 cassandra.cluster ERROR Control connection failed to connect, shutting down Cluster:
Traceback (most recent call last):
  File "cassandra/cluster.py", line 1690, in cassandra.cluster.Cluster.connect
  File "cassandra/cluster.py", line 3488, in cassandra.cluster.ControlConnection.connect
  File "cassandra/cluster.py", line 3533, in cassandra.cluster.ControlConnection._reconnect_internal
cassandra.cluster.NoHostAvailable: ('Unable to connect to any servers', {'127.0.0.1:9042': AuthenticationFailed('Failed to authenticate to 127.0.0.1:9042: Error from server: code=0100 [Bad credentials] message="Provided username cassandra and/or password are incorrect"',)})
22:13:42,30 cassandra.cluster WARNING [control connection] Error connecting to 127.0.0.1:9042:
Traceback (most recent call last):
  File "cassandra/cluster.py", line 3522, in cassandra.cluster.ControlConnection._reconnect_internal
  File "cassandra/cluster.py", line 3544, in cassandra.cluster.ControlConnection._try_connect
  File "cassandra/cluster.py", line 1620, in cassandra.cluster.Cluster.connection_factory
  File "cassandra/connection.py", line 837, in cassandra.connection.Connection.factory
  File "cassandra/connection.py", line 600, in cassandra.connection.defunct_on_error.wrapper
  File "cassandra/connection.py", line 1421, in cassandra.connection.Connection._handle_auth_response
cassandra.AuthenticationFailed: Failed to authenticate to 127.0.0.1:9042: Error from server: code=0100 [Bad credentials] message="Provided username cassandra and/or password are incorrect"
22:13:42,31 cassandra.cluster ERROR Control connection failed to connect, shutting down Cluster:
Traceback (most recent call last):
  File "cassandra/cluster.py", line 1690, in cassandra.cluster.Cluster.connect
  File "cassandra/cluster.py", line 3488, in cassandra.cluster.ControlConnection.connect
  File "cassandra/cluster.py", line 3533, in cassandra.cluster.ControlConnection._reconnect_internal
cassandra.cluster.NoHostAvailable: ('Unable to connect to any servers', {'127.0.0.1:9042': AuthenticationFailed('Failed to authenticate to 127.0.0.1:9042: Error from server: code=0100 [Bad credentials] message="Provided username cassandra and/or password are incorrect"',)})
22:13:42,293 cassandra.cluster WARNING [control connection] Error connecting to 127.0.0.1:9042:
Traceback (most recent call last):
  File "cassandra/cluster.py", line 3522, in cassandra.cluster.ControlConnection._reconnect_internal
  File "cassandra/cluster.py", line 3544, in cassandra.cluster.ControlConnection._try_connect
  File "cassandra/cluster.py", line 1620, in cassandra.cluster.Cluster.connection_factory
  File "cassandra/connection.py", line 837, in cassandra.connection.Connection.factory
  File "cassandra/connection.py", line 600, in cassandra.connection.defunct_on_error.wrapper
  File "cassandra/connection.py", line 1421, in cassandra.connection.Connection._handle_auth_response
cassandra.AuthenticationFailed: Failed to authenticate to 127.0.0.1:9042: Error from server: code=0100 [Bad credentials] message="Provided username cassandra and/or password are incorrect"
22:13:42,294 cassandra.cluster ERROR Control connection failed to connect, shutting down Cluster:
Traceback (most recent call last):
  File "cassandra/cluster.py", line 1690, in cassandra.cluster.Cluster.connect
  File "cassandra/cluster.py", line 3488, in cassandra.cluster.ControlConnection.connect
  File "cassandra/cluster.py", line 3533, in cassandra.cluster.ControlConnection._reconnect_internal
cassandra.cluster.NoHostAvailable: ('Unable to connect to any servers', {'127.0.0.1:9042': AuthenticationFailed('Failed to authenticate to 127.0.0.1:9042: Error from server: code=0100 [Bad credentials] message="Provided username cassandra and/or password are incorrect"',)})
22:13:42,556 cassandra.cluster WARNING [control connection] Error connecting to 127.0.0.1:9042:
Traceback (most recent call last):
  File "cassandra/cluster.py", line 3522, in cassandra.cluster.ControlConnection._reconnect_internal
  File "cassandra/cluster.py", line 3544, in cassandra.cluster.ControlConnection._try_connect
  File "cassandra/cluster.py", line 1620, in cassandra.cluster.Cluster.connection_factory
  File "cassandra/connection.py", line 837, in cassandra.connection.Connection.factory
  File "cassandra/connection.py", line 600, in cassandra.connection.defunct_on_error.wrapper
  File "cassandra/connection.py", line 1421, in cassandra.connection.Connection._handle_auth_response
cassandra.AuthenticationFailed: Failed to authenticate to 127.0.0.1:9042: Error from server: code=0100 [Bad credentials] message="Provided username cassandra and/or password are incorrect"
22:13:42,557 cassandra.cluster ERROR Control connection failed to connect, shutting down Cluster:
Traceback (most recent call last):
  File "cassandra/cluster.py", line 1690, in cassandra.cluster.Cluster.connect
  File "cassandra/cluster.py", line 3488, in cassandra.cluster.ControlConnection.connect
  File "cassandra/cluster.py", line 3533, in cassandra.cluster.ControlConnection._reconnect_internal
cassandra.cluster.NoHostAvailable: ('Unable to connect to any servers', {'127.0.0.1:9042': AuthenticationFailed('Failed to authenticate to 127.0.0.1:9042: Error from server: code=0100 [Bad credentials] message="Provided username cassandra and/or password are incorrect"',)})
22:13:42,819 cassandra.cluster WARNING [control connection] Error connecting to 127.0.0.1:9042:
Traceback (most recent call last):
  File "cassandra/cluster.py", line 3522, in cassandra.cluster.ControlConnection._reconnect_internal
  File "cassandra/cluster.py", line 3544, in cassandra.cluster.ControlConnection._try_connect
  File "cassandra/cluster.py", line 1620, in cassandra.cluster.Cluster.connection_factory
  File "cassandra/connection.py", line 837, in cassandra.connection.Connection.factory
  File "cassandra/connection.py", line 600, in cassandra.connection.defunct_on_error.wrapper
  File "cassandra/connection.py", line 1421, in cassandra.connection.Connection._handle_auth_response
cassandra.AuthenticationFailed: Failed to authenticate to 127.0.0.1:9042: Error from server: code=0100 [Bad credentials] message="Provided username cassandra and/or password are incorrect"
22:13:42,820 cassandra.cluster ERROR Control connection failed to connect, shutting down Cluster:
Traceback (most recent call last):
  File "cassandra/cluster.py", line 1690, in cassandra.cluster.Cluster.connect
  File "cassandra/cluster.py", line 3488, in cassandra.cluster.ControlConnection.connect
  File "cassandra/cluster.py", line 3533, in cassandra.cluster.ControlConnection._reconnect_internal
cassandra.cluster.NoHostAvailable: ('Unable to connect to any servers', {'127.0.0.1:9042': AuthenticationFailed('Failed to authenticate to 127.0.0.1:9042: Error from server: code=0100 [Bad credentials] message="Provided username cassandra and/or password are incorrect"',)})
22:13:43,81 cassandra.cluster WARNING [control connection] Error connecting to 127.0.0.1:9042:
Traceback (most recent call last):
  File "cassandra/cluster.py", line 3522, in cassandra.cluster.ControlConnection._reconnect_internal
  File "cassandra/cluster.py", line 3544, in cassandra.cluster.ControlConnection._try_connect
  File "cassandra/cluster.py", line 1620, in cassandra.cluster.Cluster.connection_factory
  File "cassandra/connection.py", line 837, in cassandra.connection.Connection.factory
  File "cassandra/connection.py", line 600, in cassandra.connection.defunct_on_error.wrapper
  File "cassandra/connection.py", line 1421, in cassandra.connection.Connection._handle_auth_response
cassandra.AuthenticationFailed: Failed to authenticate to 127.0.0.1:9042: Error from server: code=0100 [Bad credentials] message="Provided username cassandra and/or password are incorrect"
22:13:43,83 cassandra.cluster ERROR Control connection failed to connect, shutting down Cluster:
Traceback (most recent call last):
  File "cassandra/cluster.py", line 1690, in cassandra.cluster.Cluster.connect
  File "cassandra/cluster.py", line 3488, in cassandra.cluster.ControlConnection.connect
  File "cassandra/cluster.py", line 3533, in cassandra.cluster.ControlConnection._reconnect_internal
cassandra.cluster.NoHostAvailable: ('Unable to connect to any servers', {'127.0.0.1:9042': AuthenticationFailed('Failed to authenticate to 127.0.0.1:9042: Error from server: code=0100 [Bad credentials] message="Provided username cassandra and/or password are incorrect"',)})
22:13:43,345 cassandra.cluster WARNING [control connection] Error connecting to 127.0.0.1:9042:
Traceback (most recent call last):
  File "cassandra/cluster.py", line 3522, in cassandra.cluster.ControlConnection._reconnect_internal
  File "cassandra/cluster.py", line 3544, in cassandra.cluster.ControlConnection._try_connect
  File "cassandra/cluster.py", line 1620, in cassandra.cluster.Cluster.connection_factory
  File "cassandra/connection.py", line 837, in cassandra.connection.Connection.factory
  File "cassandra/connection.py", line 600, in cassandra.connection.defunct_on_error.wrapper
  File "cassandra/connection.py", line 1421, in cassandra.connection.Connection._handle_auth_response
cassandra.AuthenticationFailed: Failed to authenticate to 127.0.0.1:9042: Error from server: code=0100 [Bad credentials] message="Provided username cassandra and/or password are incorrect"
22:13:43,347 cassandra.cluster ERROR Control connection failed to connect, shutting down Cluster:
Traceback (most recent call last):
  File "cassandra/cluster.py", line 1690, in cassandra.cluster.Cluster.connect
  File "cassandra/cluster.py", line 3488, in cassandra.cluster.ControlConnection.connect
  File "cassandra/cluster.py", line 3533, in cassandra.cluster.ControlConnection._reconnect_internal
cassandra.cluster.NoHostAvailable: ('Unable to connect to any servers', {'127.0.0.1:9042': AuthenticationFailed('Failed to authenticate to 127.0.0.1:9042: Error from server: code=0100 [Bad credentials] message="Provided username cassandra and/or password are incorrect"',)})
22:13:43,608 cassandra.cluster WARNING [control connection] Error connecting to 127.0.0.1:9042:
Traceback (most recent call last):
  File "cassandra/cluster.py", line 3522, in cassandra.cluster.ControlConnection._reconnect_internal
  File "cassandra/cluster.py", line 3544, in cassandra.cluster.ControlConnection._try_connect
  File "cassandra/cluster.py", line 1620, in cassandra.cluster.Cluster.connection_factory
  File "cassandra/connection.py", line 837, in cassandra.connection.Connection.factory
  File "cassandra/connection.py", line 600, in cassandra.connection.defunct_on_error.wrapper
  File "cassandra/connection.py", line 1421, in cassandra.connection.Connection._handle_auth_response
cassandra.AuthenticationFailed: Failed to authenticate to 127.0.0.1:9042: Error from server: code=0100 [Bad credentials] message="Provided username cassandra and/or password are incorrect"
22:13:43,610 cassandra.cluster ERROR Control connection failed to connect, shutting down Cluster:
Traceback (most recent call last):
  File "cassandra/cluster.py", line 1690, in cassandra.cluster.Cluster.connect
  File "cassandra/cluster.py", line 3488, in cassandra.cluster.ControlConnection.connect
  File "cassandra/cluster.py", line 3533, in cassandra.cluster.ControlConnection._reconnect_internal
cassandra.cluster.NoHostAvailable: ('Unable to connect to any servers', {'127.0.0.1:9042': AuthenticationFailed('Failed to authenticate to 127.0.0.1:9042: Error from server: code=0100 [Bad credentials] message="Provided username cassandra and/or password are incorrect"',)})
22:13:43,872 cassandra.cluster WARNING [control connection] Error connecting to 127.0.0.1:9042:
Traceback (most recent call last):
  File "cassandra/cluster.py", line 3522, in cassandra.cluster.ControlConnection._reconnect_internal
  File "cassandra/cluster.py", line 3544, in cassandra.cluster.ControlConnection._try_connect
  File "cassandra/cluster.py", line 1620, in cassandra.cluster.Cluster.connection_factory
  File "cassandra/connection.py", line 837, in cassandra.connection.Connection.factory
  File "cassandra/connection.py", line 600, in cassandra.connection.defunct_on_error.wrapper
  File "cassandra/connection.py", line 1421, in cassandra.connection.Connection._handle_auth_response
cassandra.AuthenticationFailed: Failed to authenticate to 127.0.0.1:9042: Error from server: code=0100 [Bad credentials] message="Provided username cassandra and/or password are incorrect"
22:13:43,874 cassandra.cluster ERROR Control connection failed to connect, shutting down Cluster:
Traceback (most recent call last):
  File "cassandra/cluster.py", line 1690, in cassandra.cluster.Cluster.connect
  File "cassandra/cluster.py", line 3488, in cassandra.cluster.ControlConnection.connect
  File "cassandra/cluster.py", line 3533, in cassandra.cluster.ControlConnection._reconnect_internal
cassandra.cluster.NoHostAvailable: ('Unable to connect to any servers', {'127.0.0.1:9042': AuthenticationFailed('Failed to authenticate to 127.0.0.1:9042: Error from server: code=0100 [Bad credentials] message="Provided username cassandra and/or password are incorrect"',)})
22:13:44,136 cassandra.cluster WARNING [control connection] Error connecting to 127.0.0.1:9042:
Traceback (most recent call last):
  File "cassandra/cluster.py", line 3522, in cassandra.cluster.ControlConnection._reconnect_internal
  File "cassandra/cluster.py", line 3544, in cassandra.cluster.ControlConnection._try_connect
  File "cassandra/cluster.py", line 1620, in cassandra.cluster.Cluster.connection_factory
  File "cassandra/connection.py", line 837, in cassandra.connection.Connection.factory
  File "cassandra/connection.py", line 600, in cassandra.connection.defunct_on_error.wrapper
  File "cassandra/connection.py", line 1421, in cassandra.connection.Connection._handle_auth_response
cassandra.AuthenticationFailed: Failed to authenticate to 127.0.0.1:9042: Error from server: code=0100 [Bad credentials] message="Provided username cassandra and/or password are incorrect"
22:13:44,137 cassandra.cluster ERROR Control connection failed to connect, shutting down Cluster:
Traceback (most recent call last):
  File "cassandra/cluster.py", line 1690, in cassandra.cluster.Cluster.connect
  File "cassandra/cluster.py", line 3488, in cassandra.cluster.ControlConnection.connect
  File "cassandra/cluster.py", line 3533, in cassandra.cluster.ControlConnection._reconnect_internal
cassandra.cluster.NoHostAvailable: ('Unable to connect to any servers', {'127.0.0.1:9042': AuthenticationFailed('Failed to authenticate to 127.0.0.1:9042: Error from server: code=0100 [Bad credentials] message="Provided username cassandra and/or password are incorrect"',)})
22:13:44,398 cassandra.cluster WARNING [control connection] Error connecting to 127.0.0.1:9042:
Traceback (most recent call last):
  File "cassandra/cluster.py", line 3522, in cassandra.cluster.ControlConnection._reconnect_internal
  File "cassandra/cluster.py", line 3544, in cassandra.cluster.ControlConnection._try_connect
  File "cassandra/cluster.py", line 1620, in cassandra.cluster.Cluster.connection_factory
  File "cassandra/connection.py", line 837, in cassandra.connection.Connection.factory
  File "cassandra/connection.py", line 600, in cassandra.connection.defunct_on_error.wrapper
  File "cassandra/connection.py", line 1421, in cassandra.connection.Connection._handle_auth_response
cassandra.AuthenticationFailed: Failed to authenticate to 127.0.0.1:9042: Error from server: code=0100 [Bad credentials] message="Provided username cassandra and/or password are incorrect"
22:13:44,399 cassandra.cluster ERROR Control connection failed to connect, shutting down Cluster:
Traceback (most recent call last):
  File "cassandra/cluster.py", line 1690, in cassandra.cluster.Cluster.connect
  File "cassandra/cluster.py", line 3488, in cassandra.cluster.ControlConnection.connect
  File "cassandra/cluster.py", line 3533, in cassandra.cluster.ControlConnection._reconnect_internal
cassandra.cluster.NoHostAvailable: ('Unable to connect to any servers', {'127.0.0.1:9042': AuthenticationFailed('Failed to authenticate to 127.0.0.1:9042: Error from server: code=0100 [Bad credentials] message="Provided username cassandra and/or password are incorrect"',)})
22:13:44,660 cassandra.cluster WARNING [control connection] Error connecting to 127.0.0.1:9042:
Traceback (most recent call last):
  File "cassandra/cluster.py", line 3522, in cassandra.cluster.ControlConnection._reconnect_internal
  File "cassandra/cluster.py", line 3544, in cassandra.cluster.ControlConnection._try_connect
  File "cassandra/cluster.py", line 1620, in cassandra.cluster.Cluster.connection_factory
  File "cassandra/connection.py", line 837, in cassandra.connection.Connection.factory
  File "cassandra/connection.py", line 600, in cassandra.connection.defunct_on_error.wrapper
  File "cassandra/connection.py", line 1421, in cassandra.connection.Connection._handle_auth_response
cassandra.AuthenticationFailed: Failed to authenticate to 127.0.0.1:9042: Error from server: code=0100 [Bad credentials] message="Provided username cassandra and/or password are incorrect"
22:13:44,662 cassandra.cluster ERROR Control connection failed to connect, shutting down Cluster:
Traceback (most recent call last):
  File "cassandra/cluster.py", line 1690, in cassandra.cluster.Cluster.connect
  File "cassandra/cluster.py", line 3488, in cassandra.cluster.ControlConnection.connect
  File "cassandra/cluster.py", line 3533, in cassandra.cluster.ControlConnection._reconnect_internal
cassandra.cluster.NoHostAvailable: ('Unable to connect to any servers', {'127.0.0.1:9042': AuthenticationFailed('Failed to authenticate to 127.0.0.1:9042: Error from server: code=0100 [Bad credentials] message="Provided username cassandra and/or password are incorrect"',)})
22:13:44,923 cassandra.cluster WARNING [control connection] Error connecting to 127.0.0.1:9042:
Traceback (most recent call last):
  File "cassandra/cluster.py", line 3522, in cassandra.cluster.ControlConnection._reconnect_internal
  File "cassandra/cluster.py", line 3544, in cassandra.cluster.ControlConnection._try_connect
  File "cassandra/cluster.py", line 1620, in cassandra.cluster.Cluster.connection_factory
  File "cassandra/connection.py", line 837, in cassandra.connection.Connection.factory
  File "cassandra/connection.py", line 600, in cassandra.connection.defunct_on_error.wrapper
  File "cassandra/connection.py", line 1421, in cassandra.connection.Connection._handle_auth_response
cassandra.AuthenticationFailed: Failed to authenticate to 127.0.0.1:9042: Error from server: code=0100 [Bad credentials] message="Provided username cassandra and/or password are incorrect"
22:13:44,924 cassandra.cluster ERROR Control connection failed to connect, shutting down Cluster:
Traceback (most recent call last):
  File "cassandra/cluster.py", line 1690, in cassandra.cluster.Cluster.connect
  File "cassandra/cluster.py", line 3488, in cassandra.cluster.ControlConnection.connect
  File "cassandra/cluster.py", line 3533, in cassandra.cluster.ControlConnection._reconnect_internal
cassandra.cluster.NoHostAvailable: ('Unable to connect to any servers', {'127.0.0.1:9042': AuthenticationFailed('Failed to authenticate to 127.0.0.1:9042: Error from server: code=0100 [Bad credentials] message="Provided username cassandra and/or password are incorrect"',)})
22:13:45,185 cassandra.cluster WARNING [control connection] Error connecting to 127.0.0.1:9042:
Traceback (most recent call last):
  File "cassandra/cluster.py", line 3522, in cassandra.cluster.ControlConnection._reconnect_internal
  File "cassandra/cluster.py", line 3544, in cassandra.cluster.ControlConnection._try_connect
  File "cassandra/cluster.py", line 1620, in cassandra.cluster.Cluster.connection_factory
  File "cassandra/connection.py", line 837, in cassandra.connection.Connection.factory
  File "cassandra/connection.py", line 600, in cassandra.connection.defunct_on_error.wrapper
  File "cassandra/connection.py", line 1421, in cassandra.connection.Connection._handle_auth_response
cassandra.AuthenticationFailed: Failed to authenticate to 127.0.0.1:9042: Error from server: code=0100 [Bad credentials] message="Provided username cassandra and/or password are incorrect"
22:13:45,186 cassandra.cluster ERROR Control connection failed to connect, shutting down Cluster:
Traceback (most recent call last):
  File "cassandra/cluster.py", line 1690, in cassandra.cluster.Cluster.connect
  File "cassandra/cluster.py", line 3488, in cassandra.cluster.ControlConnection.connect
  File "cassandra/cluster.py", line 3533, in cassandra.cluster.ControlConnection._reconnect_internal
cassandra.cluster.NoHostAvailable: ('Unable to connect to any servers', {'127.0.0.1:9042': AuthenticationFailed('Failed to authenticate to 127.0.0.1:9042: Error from server: code=0100 [Bad credentials] message="Provided username cassandra and/or password are incorrect"',)})
22:13:45,447 cassandra.cluster WARNING [control connection] Error connecting to 127.0.0.1:9042:
Traceback (most recent call last):
  File "cassandra/cluster.py", line 3522, in cassandra.cluster.ControlConnection._reconnect_internal
  File "cassandra/cluster.py", line 3544, in cassandra.cluster.ControlConnection._try_connect
  File "cassandra/cluster.py", line 1620, in cassandra.cluster.Cluster.connection_factory
  File "cassandra/connection.py", line 837, in cassandra.connection.Connection.factory
  File "cassandra/connection.py", line 600, in cassandra.connection.defunct_on_error.wrapper
  File "cassandra/connection.py", line 1421, in cassandra.connection.Connection._handle_auth_response
cassandra.AuthenticationFailed: Failed to authenticate to 127.0.0.1:9042: Error from server: code=0100 [Bad credentials] message="Provided username cassandra and/or password are incorrect"
22:13:45,448 cassandra.cluster ERROR Control connection failed to connect, shutting down Cluster:
Traceback (most recent call last):
  File "cassandra/cluster.py", line 1690, in cassandra.cluster.Cluster.connect
  File "cassandra/cluster.py", line 3488, in cassandra.cluster.ControlConnection.connect
  File "cassandra/cluster.py", line 3533, in cassandra.cluster.ControlConnection._reconnect_internal
cassandra.cluster.NoHostAvailable: ('Unable to connect to any servers', {'127.0.0.1:9042': AuthenticationFailed('Failed to authenticate to 127.0.0.1:9042: Error from server: code=0100 [Bad credentials] message="Provided username cassandra and/or password are incorrect"',)})
22:13:45,710 cassandra.cluster WARNING [control connection] Error connecting to 127.0.0.1:9042:
Traceback (most recent call last):
  File "cassandra/cluster.py", line 3522, in cassandra.cluster.ControlConnection._reconnect_internal
  File "cassandra/cluster.py", line 3544, in cassandra.cluster.ControlConnection._try_connect
  File "cassandra/cluster.py", line 1620, in cassandra.cluster.Cluster.connection_factory
  File "cassandra/connection.py", line 837, in cassandra.connection.Connection.factory
  File "cassandra/connection.py", line 600, in cassandra.connection.defunct_on_error.wrapper
  File "cassandra/connection.py", line 1421, in cassandra.connection.Connection._handle_auth_response
cassandra.AuthenticationFailed: Failed to authenticate to 127.0.0.1:9042: Error from server: code=0100 [Bad credentials] message="Provided username cassandra and/or password are incorrect"
22:13:45,711 cassandra.cluster ERROR Control connection failed to connect, shutting down Cluster:
Traceback (most recent call last):
  File "cassandra/cluster.py", line 1690, in cassandra.cluster.Cluster.connect
  File "cassandra/cluster.py", line 3488, in cassandra.cluster.ControlConnection.connect
  File "cassandra/cluster.py", line 3533, in cassandra.cluster.ControlConnection._reconnect_internal
cassandra.cluster.NoHostAvailable: ('Unable to connect to any servers', {'127.0.0.1:9042': AuthenticationFailed('Failed to authenticate to 127.0.0.1:9042: Error from server: code=0100 [Bad credentials] message="Provided username cassandra and/or password are incorrect"',)})
22:13:45,972 cassandra.cluster WARNING [control connection] Error connecting to 127.0.0.1:9042:
Traceback (most recent call last):
  File "cassandra/cluster.py", line 3522, in cassandra.cluster.ControlConnection._reconnect_internal
  File "cassandra/cluster.py", line 3544, in cassandra.cluster.ControlConnection._try_connect
  File "cassandra/cluster.py", line 1620, in cassandra.cluster.Cluster.connection_factory
  File "cassandra/connection.py", line 837, in cassandra.connection.Connection.factory
  File "cassandra/connection.py", line 600, in cassandra.connection.defunct_on_error.wrapper
  File "cassandra/connection.py", line 1421, in cassandra.connection.Connection._handle_auth_response
cassandra.AuthenticationFailed: Failed to authenticate to 127.0.0.1:9042: Error from server: code=0100 [Bad credentials] message="Provided username cassandra and/or password are incorrect"
22:13:45,974 cassandra.cluster ERROR Control connection failed to connect, shutting down Cluster:
Traceback (most recent call last):
  File "cassandra/cluster.py", line 1690, in cassandra.cluster.Cluster.connect
  File "cassandra/cluster.py", line 3488, in cassandra.cluster.ControlConnection.connect
  File "cassandra/cluster.py", line 3533, in cassandra.cluster.ControlConnection._reconnect_internal
cassandra.cluster.NoHostAvailable: ('Unable to connect to any servers', {'127.0.0.1:9042': AuthenticationFailed('Failed to authenticate to 127.0.0.1:9042: Error from server: code=0100 [Bad credentials] message="Provided username cassandra and/or password are incorrect"',)})
22:13:46,235 cassandra.cluster WARNING [control connection] Error connecting to 127.0.0.1:9042:
Traceback (most recent call last):
  File "cassandra/cluster.py", line 3522, in cassandra.cluster.ControlConnection._reconnect_internal
  File "cassandra/cluster.py", line 3544, in cassandra.cluster.ControlConnection._try_connect
  File "cassandra/cluster.py", line 1620, in cassandra.cluster.Cluster.connection_factory
  File "cassandra/connection.py", line 837, in cassandra.connection.Connection.factory
  File "cassandra/connection.py", line 600, in cassandra.connection.defunct_on_error.wrapper
  File "cassandra/connection.py", line 1421, in cassandra.connection.Connection._handle_auth_response
cassandra.AuthenticationFailed: Failed to authenticate to 127.0.0.1:9042: Error from server: code=0100 [Bad credentials] message="Provided username cassandra and/or password are incorrect"
22:13:46,236 cassandra.cluster ERROR Control connection failed to connect, shutting down Cluster:
Traceback (most recent call last):
  File "cassandra/cluster.py", line 1690, in cassandra.cluster.Cluster.connect
  File "cassandra/cluster.py", line 3488, in cassandra.cluster.ControlConnection.connect
  File "cassandra/cluster.py", line 3533, in cassandra.cluster.ControlConnection._reconnect_internal
cassandra.cluster.NoHostAvailable: ('Unable to connect to any servers', {'127.0.0.1:9042': AuthenticationFailed('Failed to authenticate to 127.0.0.1:9042: Error from server: code=0100 [Bad credentials] message="Provided username cassandra and/or password are incorrect"',)})
22:13:46,498 cassandra.cluster WARNING [control connection] Error connecting to 127.0.0.1:9042:
Traceback (most recent call last):
  File "cassandra/cluster.py", line 3522, in cassandra.cluster.ControlConnection._reconnect_internal
  File "cassandra/cluster.py", line 3544, in cassandra.cluster.ControlConnection._try_connect
  File "cassandra/cluster.py", line 1620, in cassandra.cluster.Cluster.connection_factory
  File "cassandra/connection.py", line 837, in cassandra.connection.Connection.factory
  File "cassandra/connection.py", line 600, in cassandra.connection.defunct_on_error.wrapper
  File "cassandra/connection.py", line 1421, in cassandra.connection.Connection._handle_auth_response
cassandra.AuthenticationFailed: Failed to authenticate to 127.0.0.1:9042: Error from server: code=0100 [Bad credentials] message="Provided username cassandra and/or password are incorrect"
22:13:46,499 cassandra.cluster ERROR Control connection failed to connect, shutting down Cluster:
Traceback (most recent call last):
  File "cassandra/cluster.py", line 1690, in cassandra.cluster.Cluster.connect
  File "cassandra/cluster.py", line 3488, in cassandra.cluster.ControlConnection.connect
  File "cassandra/cluster.py", line 3533, in cassandra.cluster.ControlConnection._reconnect_internal
cassandra.cluster.NoHostAvailable: ('Unable to connect to any servers', {'127.0.0.1:9042': AuthenticationFailed('Failed to authenticate to 127.0.0.1:9042: Error from server: code=0100 [Bad credentials] message="Provided username cassandra and/or password are incorrect"',)})
22:13:46,761 cassandra.cluster WARNING [control connection] Error connecting to 127.0.0.1:9042:
Traceback (most recent call last):
  File "cassandra/cluster.py", line 3522, in cassandra.cluster.ControlConnection._reconnect_internal
  File "cassandra/cluster.py", line 3544, in cassandra.cluster.ControlConnection._try_connect
  File "cassandra/cluster.py", line 1620, in cassandra.cluster.Cluster.connection_factory
  File "cassandra/connection.py", line 837, in cassandra.connection.Connection.factory
  File "cassandra/connection.py", line 600, in cassandra.connection.defunct_on_error.wrapper
  File "cassandra/connection.py", line 1421, in cassandra.connection.Connection._handle_auth_response
cassandra.AuthenticationFailed: Failed to authenticate to 127.0.0.1:9042: Error from server: code=0100 [Bad credentials] message="Provided username cassandra and/or password are incorrect"
22:13:46,762 cassandra.cluster ERROR Control connection failed to connect, shutting down Cluster:
Traceback (most recent call last):
  File "cassandra/cluster.py", line 1690, in cassandra.cluster.Cluster.connect
  File "cassandra/cluster.py", line 3488, in cassandra.cluster.ControlConnection.connect
  File "cassandra/cluster.py", line 3533, in cassandra.cluster.ControlConnection._reconnect_internal
cassandra.cluster.NoHostAvailable: ('Unable to connect to any servers', {'127.0.0.1:9042': AuthenticationFailed('Failed to authenticate to 127.0.0.1:9042: Error from server: code=0100 [Bad credentials] message="Provided username cassandra and/or password are incorrect"',)})
22:13:47,23 cassandra.cluster WARNING [control connection] Error connecting to 127.0.0.1:9042:
Traceback (most recent call last):
  File "cassandra/cluster.py", line 3522, in cassandra.cluster.ControlConnection._reconnect_internal
  File "cassandra/cluster.py", line 3544, in cassandra.cluster.ControlConnection._try_connect
  File "cassandra/cluster.py", line 1620, in cassandra.cluster.Cluster.connection_factory
  File "cassandra/connection.py", line 837, in cassandra.connection.Connection.factory
  File "cassandra/connection.py", line 600, in cassandra.connection.defunct_on_error.wrapper
  File "cassandra/connection.py", line 1421, in cassandra.connection.Connection._handle_auth_response
cassandra.AuthenticationFailed: Failed to authenticate to 127.0.0.1:9042: Error from server: code=0100 [Bad credentials] message="Provided username cassandra and/or password are incorrect"
22:13:47,25 cassandra.cluster ERROR Control connection failed to connect, shutting down Cluster:
Traceback (most recent call last):
  File "cassandra/cluster.py", line 1690, in cassandra.cluster.Cluster.connect
  File "cassandra/cluster.py", line 3488, in cassandra.cluster.ControlConnection.connect
  File "cassandra/cluster.py", line 3533, in cassandra.cluster.ControlConnection._reconnect_internal
cassandra.cluster.NoHostAvailable: ('Unable to connect to any servers', {'127.0.0.1:9042': AuthenticationFailed('Failed to authenticate to 127.0.0.1:9042: Error from server: code=0100 [Bad credentials] message="Provided username cassandra and/or password are incorrect"',)})
22:13:47,287 cassandra.cluster WARNING [control connection] Error connecting to 127.0.0.1:9042:
Traceback (most recent call last):
  File "cassandra/cluster.py", line 3522, in cassandra.cluster.ControlConnection._reconnect_internal
  File "cassandra/cluster.py", line 3544, in cassandra.cluster.ControlConnection._try_connect
  File "cassandra/cluster.py", line 1620, in cassandra.cluster.Cluster.connection_factory
  File "cassandra/connection.py", line 837, in cassandra.connection.Connection.factory
  File "cassandra/connection.py", line 600, in cassandra.connection.defunct_on_error.wrapper
  File "cassandra/connection.py", line 1421, in cassandra.connection.Connection._handle_auth_response
cassandra.AuthenticationFailed: Failed to authenticate to 127.0.0.1:9042: Error from server: code=0100 [Bad credentials] message="Provided username cassandra and/or password are incorrect"
22:13:47,289 cassandra.cluster ERROR Control connection failed to connect, shutting down Cluster:
Traceback (most recent call last):
  File "cassandra/cluster.py", line 1690, in cassandra.cluster.Cluster.connect
  File "cassandra/cluster.py", line 3488, in cassandra.cluster.ControlConnection.connect
  File "cassandra/cluster.py", line 3533, in cassandra.cluster.ControlConnection._reconnect_internal
cassandra.cluster.NoHostAvailable: ('Unable to connect to any servers', {'127.0.0.1:9042': AuthenticationFailed('Failed to authenticate to 127.0.0.1:9042: Error from server: code=0100 [Bad credentials] message="Provided username cassandra and/or password are incorrect"',)})
22:13:47,550 cassandra.cluster WARNING [control connection] Error connecting to 127.0.0.1:9042:
Traceback (most recent call last):
  File "cassandra/cluster.py", line 3522, in cassandra.cluster.ControlConnection._reconnect_internal
  File "cassandra/cluster.py", line 3544, in cassandra.cluster.ControlConnection._try_connect
  File "cassandra/cluster.py", line 1620, in cassandra.cluster.Cluster.connection_factory
  File "cassandra/connection.py", line 837, in cassandra.connection.Connection.factory
  File "cassandra/connection.py", line 600, in cassandra.connection.defunct_on_error.wrapper
  File "cassandra/connection.py", line 1421, in cassandra.connection.Connection._handle_auth_response
cassandra.AuthenticationFailed: Failed to authenticate to 127.0.0.1:9042: Error from server: code=0100 [Bad credentials] message="Provided username cassandra and/or password are incorrect"
22:13:47,552 cassandra.cluster ERROR Control connection failed to connect, shutting down Cluster:
Traceback (most recent call last):
  File "cassandra/cluster.py", line 1690, in cassandra.cluster.Cluster.connect
  File "cassandra/cluster.py", line 3488, in cassandra.cluster.ControlConnection.connect
  File "cassandra/cluster.py", line 3533, in cassandra.cluster.ControlConnection._reconnect_internal
cassandra.cluster.NoHostAvailable: ('Unable to connect to any servers', {'127.0.0.1:9042': AuthenticationFailed('Failed to authenticate to 127.0.0.1:9042: Error from server: code=0100 [Bad credentials] message="Provided username cassandra and/or password are incorrect"',)})
22:13:47,812 cassandra.cluster WARNING [control connection] Error connecting to 127.0.0.1:9042:
Traceback (most recent call last):
  File "cassandra/cluster.py", line 3522, in cassandra.cluster.ControlConnection._reconnect_internal
  File "cassandra/cluster.py", line 3544, in cassandra.cluster.ControlConnection._try_connect
  File "cassandra/cluster.py", line 1620, in cassandra.cluster.Cluster.connection_factory
  File "cassandra/connection.py", line 837, in cassandra.connection.Connection.factory
  File "cassandra/connection.py", line 600, in cassandra.connection.defunct_on_error.wrapper
  File "cassandra/connection.py", line 1421, in cassandra.connection.Connection._handle_auth_response
cassandra.AuthenticationFailed: Failed to authenticate to 127.0.0.1:9042: Error from server: code=0100 [Bad credentials] message="Provided username cassandra and/or password are incorrect"
22:13:47,814 cassandra.cluster ERROR Control connection failed to connect, shutting down Cluster:
Traceback (most recent call last):
  File "cassandra/cluster.py", line 1690, in cassandra.cluster.Cluster.connect
  File "cassandra/cluster.py", line 3488, in cassandra.cluster.ControlConnection.connect
  File "cassandra/cluster.py", line 3533, in cassandra.cluster.ControlConnection._reconnect_internal
cassandra.cluster.NoHostAvailable: ('Unable to connect to any servers', {'127.0.0.1:9042': AuthenticationFailed('Failed to authenticate to 127.0.0.1:9042: Error from server: code=0100 [Bad credentials] message="Provided username cassandra and/or password are incorrect"',)})
22:13:48,79 cassandra.cluster WARNING [control connection] Error connecting to 127.0.0.1:9042:
Traceback (most recent call last):
  File "cassandra/cluster.py", line 3522, in cassandra.cluster.ControlConnection._reconnect_internal
  File "cassandra/cluster.py", line 3544, in cassandra.cluster.ControlConnection._try_connect
  File "cassandra/cluster.py", line 1620, in cassandra.cluster.Cluster.connection_factory
  File "cassandra/connection.py", line 837, in cassandra.connection.Connection.factory
  File "cassandra/connection.py", line 600, in cassandra.connection.defunct_on_error.wrapper
  File "cassandra/connection.py", line 1421, in cassandra.connection.Connection._handle_auth_response
cassandra.AuthenticationFailed: Failed to authenticate to 127.0.0.1:9042: Error from server: code=0100 [Bad credentials] message="Provided username cassandra and/or password are incorrect"
22:13:48,81 cassandra.cluster ERROR Control connection failed to connect, shutting down Cluster:
Traceback (most recent call last):
  File "cassandra/cluster.py", line 1690, in cassandra.cluster.Cluster.connect
  File "cassandra/cluster.py", line 3488, in cassandra.cluster.ControlConnection.connect
  File "cassandra/cluster.py", line 3533, in cassandra.cluster.ControlConnection._reconnect_internal
cassandra.cluster.NoHostAvailable: ('Unable to connect to any servers', {'127.0.0.1:9042': AuthenticationFailed('Failed to authenticate to 127.0.0.1:9042: Error from server: code=0100 [Bad credentials] message="Provided username cassandra and/or password are incorrect"',)})
22:13:48,342 cassandra.cluster WARNING [control connection] Error connecting to 127.0.0.1:9042:
Traceback (most recent call last):
  File "cassandra/cluster.py", line 3522, in cassandra.cluster.ControlConnection._reconnect_internal
  File "cassandra/cluster.py", line 3544, in cassandra.cluster.ControlConnection._try_connect
  File "cassandra/cluster.py", line 1620, in cassandra.cluster.Cluster.connection_factory
  File "cassandra/connection.py", line 837, in cassandra.connection.Connection.factory
  File "cassandra/connection.py", line 600, in cassandra.connection.defunct_on_error.wrapper
  File "cassandra/connection.py", line 1421, in cassandra.connection.Connection._handle_auth_response
cassandra.AuthenticationFailed: Failed to authenticate to 127.0.0.1:9042: Error from server: code=0100 [Bad credentials] message="Provided username cassandra and/or password are incorrect"
22:13:48,343 cassandra.cluster ERROR Control connection failed to connect, shutting down Cluster:
Traceback (most recent call last):
  File "cassandra/cluster.py", line 1690, in cassandra.cluster.Cluster.connect
  File "cassandra/cluster.py", line 3488, in cassandra.cluster.ControlConnection.connect
  File "cassandra/cluster.py", line 3533, in cassandra.cluster.ControlConnection._reconnect_internal
cassandra.cluster.NoHostAvailable: ('Unable to connect to any servers', {'127.0.0.1:9042': AuthenticationFailed('Failed to authenticate to 127.0.0.1:9042: Error from server: code=0100 [Bad credentials] message="Provided username cassandra and/or password are incorrect"',)})
22:13:48,604 cassandra.cluster WARNING [control connection] Error connecting to 127.0.0.1:9042:
Traceback (most recent call last):
  File "cassandra/cluster.py", line 3522, in cassandra.cluster.ControlConnection._reconnect_internal
  File "cassandra/cluster.py", line 3544, in cassandra.cluster.ControlConnection._try_connect
  File "cassandra/cluster.py", line 1620, in cassandra.cluster.Cluster.connection_factory
  File "cassandra/connection.py", line 837, in cassandra.connection.Connection.factory
  File "cassandra/connection.py", line 600, in cassandra.connection.defunct_on_error.wrapper
  File "cassandra/connection.py", line 1421, in cassandra.connection.Connection._handle_auth_response
cassandra.AuthenticationFailed: Failed to authenticate to 127.0.0.1:9042: Error from server: code=0100 [Bad credentials] message="Provided username cassandra and/or password are incorrect"
22:13:48,605 cassandra.cluster ERROR Control connection failed to connect, shutting down Cluster:
Traceback (most recent call last):
  File "cassandra/cluster.py", line 1690, in cassandra.cluster.Cluster.connect
  File "cassandra/cluster.py", line 3488, in cassandra.cluster.ControlConnection.connect
  File "cassandra/cluster.py", line 3533, in cassandra.cluster.ControlConnection._reconnect_internal
cassandra.cluster.NoHostAvailable: ('Unable to connect to any servers', {'127.0.0.1:9042': AuthenticationFailed('Failed to authenticate to 127.0.0.1:9042: Error from server: code=0100 [Bad credentials] message="Provided username cassandra and/or password are incorrect"',)})
22:13:48,865 cassandra.cluster WARNING [control connection] Error connecting to 127.0.0.1:9042:
Traceback (most recent call last):
  File "cassandra/cluster.py", line 3522, in cassandra.cluster.ControlConnection._reconnect_internal
  File "cassandra/cluster.py", line 3544, in cassandra.cluster.ControlConnection._try_connect
  File "cassandra/cluster.py", line 1620, in cassandra.cluster.Cluster.connection_factory
  File "cassandra/connection.py", line 837, in cassandra.connection.Connection.factory
  File "cassandra/connection.py", line 600, in cassandra.connection.defunct_on_error.wrapper
  File "cassandra/connection.py", line 1421, in cassandra.connection.Connection._handle_auth_response
cassandra.AuthenticationFailed: Failed to authenticate to 127.0.0.1:9042: Error from server: code=0100 [Bad credentials] message="Provided username cassandra and/or password are incorrect"
22:13:48,866 cassandra.cluster ERROR Control connection failed to connect, shutting down Cluster:
Traceback (most recent call last):
  File "cassandra/cluster.py", line 1690, in cassandra.cluster.Cluster.connect
  File "cassandra/cluster.py", line 3488, in cassandra.cluster.ControlConnection.connect
  File "cassandra/cluster.py", line 3533, in cassandra.cluster.ControlConnection._reconnect_internal
cassandra.cluster.NoHostAvailable: ('Unable to connect to any servers', {'127.0.0.1:9042': AuthenticationFailed('Failed to authenticate to 127.0.0.1:9042: Error from server: code=0100 [Bad credentials] message="Provided username cassandra and/or password are incorrect"',)})
22:13:49,135 cassandra.cluster WARNING [control connection] Error connecting to 127.0.0.1:9042:
Traceback (most recent call last):
  File "cassandra/cluster.py", line 3522, in cassandra.cluster.ControlConnection._reconnect_internal
  File "cassandra/cluster.py", line 3544, in cassandra.cluster.ControlConnection._try_connect
  File "cassandra/cluster.py", line 1620, in cassandra.cluster.Cluster.connection_factory
  File "cassandra/connection.py", line 837, in cassandra.connection.Connection.factory
  File "cassandra/connection.py", line 600, in cassandra.connection.defunct_on_error.wrapper
  File "cassandra/connection.py", line 1421, in cassandra.connection.Connection._handle_auth_response
cassandra.AuthenticationFailed: Failed to authenticate to 127.0.0.1:9042: Error from server: code=0100 [Bad credentials] message="Provided username cassandra and/or password are incorrect"
22:13:49,136 cassandra.cluster ERROR Control connection failed to connect, shutting down Cluster:
Traceback (most recent call last):
  File "cassandra/cluster.py", line 1690, in cassandra.cluster.Cluster.connect
  File "cassandra/cluster.py", line 3488, in cassandra.cluster.ControlConnection.connect
  File "cassandra/cluster.py", line 3533, in cassandra.cluster.ControlConnection._reconnect_internal
cassandra.cluster.NoHostAvailable: ('Unable to connect to any servers', {'127.0.0.1:9042': AuthenticationFailed('Failed to authenticate to 127.0.0.1:9042: Error from server: code=0100 [Bad credentials] message="Provided username cassandra and/or password are incorrect"',)})
22:13:49,397 cassandra.cluster WARNING [control connection] Error connecting to 127.0.0.1:9042:
Traceback (most recent call last):
  File "cassandra/cluster.py", line 3522, in cassandra.cluster.ControlConnection._reconnect_internal
  File "cassandra/cluster.py", line 3544, in cassandra.cluster.ControlConnection._try_connect
  File "cassandra/cluster.py", line 1620, in cassandra.cluster.Cluster.connection_factory
  File "cassandra/connection.py", line 837, in cassandra.connection.Connection.factory
  File "cassandra/connection.py", line 600, in cassandra.connection.defunct_on_error.wrapper
  File "cassandra/connection.py", line 1421, in cassandra.connection.Connection._handle_auth_response
cassandra.AuthenticationFailed: Failed to authenticate to 127.0.0.1:9042: Error from server: code=0100 [Bad credentials] message="Provided username cassandra and/or password are incorrect"
22:13:49,398 cassandra.cluster ERROR Control connection failed to connect, shutting down Cluster:
Traceback (most recent call last):
  File "cassandra/cluster.py", line 1690, in cassandra.cluster.Cluster.connect
  File "cassandra/cluster.py", line 3488, in cassandra.cluster.ControlConnection.connect
  File "cassandra/cluster.py", line 3533, in cassandra.cluster.ControlConnection._reconnect_internal
cassandra.cluster.NoHostAvailable: ('Unable to connect to any servers', {'127.0.0.1:9042': AuthenticationFailed('Failed to authenticate to 127.0.0.1:9042: Error from server: code=0100 [Bad credentials] message="Provided username cassandra and/or password are incorrect"',)})
PASSED                                                                   [100%]
===Flaky Test Report===

test_creator_of_db_resource_granted_all_permissions passed 1 out of the required 1 times. Success!

===End Flaky Test Report===

========================== 1 passed in 19.83 seconds ===========================
[msx] rc = 0
mv /tmp/my_log.txt /users/masix/vm_images/ZebraConf/app_meta/logs/auth_test.py::TestAuthRoles::test_creator_of_db_resource_granted_all_permissions-output_1643170442296_2589216840.txt
